Workbook

Sheet #部分建筑buff配置索引
A1: 备注 | B1: 建筑等级 | C1: 解锁时代 | D1: 解锁建筑类型 | E1: 解锁等级 | F1: 建造数量 | G1: 索引 | H1: Buff名称1 | I1: Buff_Key1 | J1: Buff_ID1 | K1: Buff数值1 | L1: buff1总数值-统计用 | M1: Buff名称2 | N1: Buff_Key2 | O1: Buff_ID2 | P1: Buff数值2 | Q1: buff2总数值-统计用 | R1: Buff名称3 | S1: Buff_Key3 | T1: Buff_ID3 | U1: Buff数值3 | V1: buff3总数值-统计用 | W1: Buff名称4 | X1: Buff_Key4 | Y1: Buff_ID4 | Z1: Buff数值4 | AA1: Buff名称5 | AB1: Buff_Key5 | AC1: Buff_ID5 | AD1: Buff数值5 | AE1: Buff名称6 | AF1: Buff_Key6 | AG1: Buff_ID6 | AH1: Buff数值6 | AI1: Buff名称7 | AJ1: Buff_Key7 | AK1: Buff_ID7 | AL1: Buff数值7 | AM1: Buff名称8 | AN1: Buff_Key8 | AO1: Buff_ID8 | AP1: Buff数值8 | AQ1: 详情表格列 | AR1: 详情表格标题 | AS1: 文本key1 | AT1: 文本1 | AU1: 编号1 | AV1: 文本key2 | AW1: 文本2 | AX1: 编号2 | AY1: 文本key3 | AZ1: 文本3 | BA1: 编号3 | BB1: 文本key4 | BC1: 文本4 | BD1: 编号4 | BE1: 文本key5 | BF1: 文本5 | BG1: 编号5 | BH1: 整合编号 | BI1: 整合key1 | BJ1: 整合文本1 | BK1: 筛选 | BL1: 编号 | BM1: 整合编号 | BN1: 整合key1 | BO1: 整合文本1 | BS1: 原文本 | BT1: 新文本
A2: 城镇中心 | B2: 1 | G2: 城镇中心1 | H2: 领地占领上限 | I2: ResourceLandLimit | J2: 8026 | K2: 3 | L2: 3 | M2: 仓库上限 | N2: Warehouse_Limit | O2: 1252 | P2: 200000 | Q2: 200000 | R2: 居民房舍建造上限 | S2: BuildingCapacity_House | T2: 1202 | U2: 0 | V2: 0 | W2: 磨坊建造上限 | X2: BuildingCapacity_Mill | Y2: 1205 | Z2: 1 | AA2: 伐木场建造上限 | AB2: BuildingCapacity_Lumber | AC2: 1209 | AD2: 1 | AE2: 石矿建造上限 | AF2: BuildingCapacity_Ironmine | AG2: 1210 | AH2: 0 | AI2: 金矿建造上限 | AJ2: BuildingCapacity_Goldmine | AK2: 1237 | AL2: 0 | AQ2: 1:2:0 | AR2: Buff_BuilDetail_8026:Buff_BuilDetail_1252:Buff_BuilDetail_1 | AS2: Buff_BuilDetail_8026 | AT2: 领地占领上限 | AU2: 1 | AV2: Buff_BuilDetail_1252 | AW2: 仓库上限 | AX2: 19 | AY2: Buff_BuilDetail_1202 | AZ2: 居民房舍建造上限 | BA2: 33 | BB2: Buff_BuilDetail_1205 | BC2: 磨坊建造上限 | BD2: 36 | BE2: Buff_BuilDetail_1209 | BF2: 伐木场建造上限 | BG2: 38 | BH2: 1 | BI2: Buff_BuilDetail_8026 | BJ2: 领地占领上限 | BK2: 1 | BL2: 1 | BM2: 1 | BN2: Buff_BuilDetail_8026 | BO2: 领地上限 | BS2: 每小时居民房舍产出铜币 | BT2: 每小时铜币产量
A3: 城镇中心 | B3: 2 | G3: 城镇中心2 | H3: 领地占领上限 | I3: ResourceLandLimit | J3: 8026 | K3: 6 | L3: 6 | M3: 仓库上限 | N3: Warehouse_Limit | O3: 1252 | P3: 300000 | Q3: 300000 | R3: 居民房舍建造上限 | S3: BuildingCapacity_House | T3: 1202 | U3: 1 | V3: 1 | W3: 磨坊建造上限 | X3: BuildingCapacity_Mill | Y3: 1205 | Z3: 1 | AA3: 伐木场建造上限 | AB3: BuildingCapacity_Lumber | AC3: 1209 | AD3: 1 | AE3: 石矿建造上限 | AF3: BuildingCapacity_Ironmine | AG3: 1210 | AH3: 0 | AI3: 金矿建造上限 | AJ3: BuildingCapacity_Goldmine | AK3: 1237 | AL3: 0 | BH3: 2 | BI3: Buff_BuilDetail_1255 | BJ3: 每小时居民房舍产出铜币 | BK3: 1 | BL3: 2 | BM3: 2 | BN3: Buff_BuilDetail_1255 | BO3: 每小时铜币产量 | BS3: 每小时磨坊产出食物 | BT3: 每小时食物产量
A4: 城镇中心 | B4: 3 | G4: 城镇中心3 | H4: 领地占领上限 | I4: ResourceLandLimit | J4: 8026 | K4: 9 | L4: 9 | M4: 仓库上限 | N4: Warehouse_Limit | O4: 1252 | P4: 400000 | Q4: 400000 | R4: 居民房舍建造上限 | S4: BuildingCapacity_House | T4: 1202 | U4: 1 | V4: 1 | W4: 磨坊建造上限 | X4: BuildingCapacity_Mill | Y4: 1205 | Z4: 2 | AA4: 伐木场建造上限 | AB4: BuildingCapacity_Lumber | AC4: 1209 | AD4: 1 | AE4: 石矿建造上限 | AF4: BuildingCapacity_Ironmine | AG4: 1210 | AH4: 0 | AI4: 金矿建造上限 | AJ4: BuildingCapacity_Goldmine | AK4: 1237 | AL4: 0 | BH4: 3 | BI4: Buff_BuilDetail_1015 | BJ4: 每小时磨坊产出食物 | BK4: 1 | BL4: 3 | BM4: 3 | BN4: Buff_BuilDetail_1015 | BO4: 每小时食物产量 | BS4: 每小时伐木场产出木材 | BT4: 每小时木材产量
A5: 城镇中心 | B5: 4 | G5: 城镇中心4 | H5: 领地占领上限 | I5: ResourceLandLimit | J5: 8026 | K5: 12 | L5: 12 | M5: 仓库上限 | N5: Warehouse_Limit | O5: 1252 | P5: 600000 | Q5: 600000 | R5: 居民房舍建造上限 | S5: BuildingCapacity_House | T5: 1202 | U5: 1 | V5: 1 | W5: 磨坊建造上限 | X5: BuildingCapacity_Mill | Y5: 1205 | Z5: 2 | AA5: 伐木场建造上限 | AB5: BuildingCapacity_Lumber | AC5: 1209 | AD5: 2 | AE5: 石矿建造上限 | AF5: BuildingCapacity_Ironmine | AG5: 1210 | AH5: 0 | AI5: 金矿建造上限 | AJ5: BuildingCapacity_Goldmine | AK5: 1237 | AL5: 0 | BH5: 4 | BI5: Buff_BuilDetail_1017 | BJ5: 每小时伐木场产出木材 | BK5: 1 | BL5: 4 | BM5: 4 | BN5: Buff_BuilDetail_1017 | BO5: 每小时木材产量 | BS5: 每小时石矿场产出石头 | BT5: 每小时石头产量
A6: 城镇中心 | B6: 5 | G6: 城镇中心5 | H6: 领地占领上限 | I6: ResourceLandLimit | J6: 8026 | K6: 15 | L6: 15 | M6: 仓库上限 | N6: Warehouse_Limit | O6: 1252 | P6: 800000 | Q6: 800000 | R6: 居民房舍建造上限 | S6: BuildingCapacity_House | T6: 1202 | U6: 2 | V6: 2 | W6: 磨坊建造上限 | X6: BuildingCapacity_Mill | Y6: 1205 | Z6: 2 | AA6: 伐木场建造上限 | AB6: BuildingCapacity_Lumber | AC6: 1209 | AD6: 2 | AE6: 石矿建造上限 | AF6: BuildingCapacity_Ironmine | AG6: 1210 | AH6: 2 | AI6: 金矿建造上限 | AJ6: BuildingCapacity_Goldmine | AK6: 1237 | AL6: 0 | BH6: 5 | BI6: Buff_BuilDetail_1018 | BJ6: 每小时石矿场产出石头 | BK6: 1 | BL6: 5 | BM6: 5 | BN6: Buff_BuilDetail_1018 | BO6: 每小时石头产量 | BS6: 每小时金矿场产出黄金 | BT6: 每小时黄金产量
A7: 城镇中心 | B7: 6 | G7: 城镇中心6 | H7: 领地占领上限 | I7: ResourceLandLimit | J7: 8026 | K7: 18 | L7: 18 | M7: 仓库上限 | N7: Warehouse_Limit | O7: 1252 | P7: 1000000 | Q7: 1000000 | R7: 居民房舍建造上限 | S7: BuildingCapacity_House | T7: 1202 | U7: 2 | V7: 2 | W7: 磨坊建造上限 | X7: BuildingCapacity_Mill | Y7: 1205 | Z7: 2 | AA7: 伐木场建造上限 | AB7: BuildingCapacity_Lumber | AC7: 1209 | AD7: 2 | AE7: 石矿建造上限 | AF7: BuildingCapacity_Ironmine | AG7: 1210 | AH7: 2 | AI7: 金矿建造上限 | AJ7: BuildingCapacity_Goldmine | AK7: 1237 | AL7: 0 | BH7: 6 | BI7: Buff_BuilDetail_1019 | BJ7: 每小时金矿场产出黄金 | BK7: 1 | BL7: 6 | BM7: 6 | BN7: Buff_BuilDetail_1019 | BO7: 每小时黄金产量 | BS7: 防卫塔基础攻击力(显示) | BT7: 防卫塔攻击力
A8: 城镇中心 | B8: 7 | G8: 城镇中心7 | H8: 领地占领上限 | I8: ResourceLandLimit | J8: 8026 | K8: 21 | L8: 21 | M8: 仓库上限 | N8: Warehouse_Limit | O8: 1252 | P8: 1200000 | Q8: 1200000 | R8: 居民房舍建造上限 | S8: BuildingCapacity_House | T8: 1202 | U8: 2 | V8: 2 | W8: 磨坊建造上限 | X8: BuildingCapacity_Mill | Y8: 1205 | Z8: 2 | AA8: 伐木场建造上限 | AB8: BuildingCapacity_Lumber | AC8: 1209 | AD8: 2 | AE8: 石矿建造上限 | AF8: BuildingCapacity_Ironmine | AG8: 1210 | AH8: 2 | AI8: 金矿建造上限 | AJ8: BuildingCapacity_Goldmine | AK8: 1237 | AL8: 0 | BH8: 7 | BI8: Buff_BuilDetail_3000 | BJ8: 全兵种训练速度 | BK8: 1 | BL8: 7 | BM8: 7 | BN8: Buff_BuilDetail_3000 | BO8: 全兵种训练速度 | BS8: 领地占领上限 | BT8: 领地上限
A9: 城镇中心 | B9: 8 | G9: 城镇中心8 | H9: 领地占领上限 | I9: ResourceLandLimit | J9: 8026 | K9: 24 | L9: 24 | M9: 仓库上限 | N9: Warehouse_Limit | O9: 1252 | P9: 1400000 | Q9: 1400000 | R9: 居民房舍建造上限 | S9: BuildingCapacity_House | T9: 1202 | U9: 2 | V9: 2 | W9: 磨坊建造上限 | X9: BuildingCapacity_Mill | Y9: 1205 | Z9: 2 | AA9: 伐木场建造上限 | AB9: BuildingCapacity_Lumber | AC9: 1209 | AD9: 2 | AE9: 石矿建造上限 | AF9: BuildingCapacity_Ironmine | AG9: 1210 | AH9: 2 | AI9: 金矿建造上限 | AJ9: BuildingCapacity_Goldmine | AK9: 1237 | AL9: 0 | BH9: 8 | BI9: Buff_BuilDetail_3000 | BJ9: 全兵种训练速度 | BK9: 0.5 | BM9: 8 | BN9: Buff_BuilDetail_1253 | BO9: 屯兵上限 | BS9: 联盟帮助时间减少 | BT9: 帮助减少时间(秒)
A10: 城镇中心 | B10: 9 | G10: 城镇中心9 | H10: 领地占领上限 | I10: ResourceLandLimit | J10: 8026 | K10: 27 | L10: 27 | M10: 仓库上限 | N10: Warehouse_Limit | O10: 1252 | P10: 1600000 | Q10: 1600000 | R10: 居民房舍建造上限 | S10: BuildingCapacity_House | T10: 1202 | U10: 2 | V10: 2 | W10: 磨坊建造上限 | X10: BuildingCapacity_Mill | Y10: 1205 | Z10: 2 | AA10: 伐木场建造上限 | AB10: BuildingCapacity_Lumber | AC10: 1209 | AD10: 2 | AE10: 石矿建造上限 | AF10: BuildingCapacity_Ironmine | AG10: 1210 | AH10: 2 | AI10: 金矿建造上限 | AJ10: BuildingCapacity_Goldmine | AK10: 1237 | AL10: 0 | BH10: 9 | BI10: Buff_BuilDetail_3000 | BJ10: 全兵种训练速度 | BK10: 0.33333333 | BM10: 9 | BN10: Buff_BuilDetail_4004 | BO10: 城墙耐久
A11: 城镇中心 | B11: 10 | G11: 城镇中心10 | H11: 领地占领上限 | I11: ResourceLandLimit | J11: 8026 | K11: 30 | L11: 30 | M11: 仓库上限 | N11: Warehouse_Limit | O11: 1252 | P11: 1800000 | Q11: 1800000 | R11: 居民房舍建造上限 | S11: BuildingCapacity_House | T11: 1202 | U11: 2 | V11: 2 | W11: 磨坊建造上限 | X11: BuildingCapacity_Mill | Y11: 1205 | Z11: 3 | AA11: 伐木场建造上限 | AB11: BuildingCapacity_Lumber | AC11: 1209 | AD11: 2 | AE11: 石矿建造上限 | AF11: BuildingCapacity_Ironmine | AG11: 1210 | AH11: 2 | AI11: 金矿建造上限 | AJ11: BuildingCapacity_Goldmine | AK11: 1237 | AL11: 2 | BH11: 10 | BI11: Buff_BuilDetail_3000 | BJ11: 全兵种训练速度 | BK11: 0.25 | BM11: 10 | BN11: Buff_BuilDetail_3102 | BO11: 伤兵上限
A12: 城镇中心 | B12: 11 | G12: 城镇中心11 | H12: 领地占领上限 | I12: ResourceLandLimit | J12: 8026 | K12: 33 | L12: 33 | M12: 仓库上限 | N12: Warehouse_Limit | O12: 1252 | P12: 2000000 | Q12: 2000000 | R12: 居民房舍建造上限 | S12: BuildingCapacity_House | T12: 1202 | U12: 2 | V12: 2 | W12: 磨坊建造上限 | X12: BuildingCapacity_Mill | Y12: 1205 | Z12: 3 | AA12: 伐木场建造上限 | AB12: BuildingCapacity_Lumber | AC12: 1209 | AD12: 3 | AE12: 石矿建造上限 | AF12: BuildingCapacity_Ironmine | AG12: 1210 | AH12: 2 | AI12: 金矿建造上限 | AJ12: BuildingCapacity_Goldmine | AK12: 1237 | AL12: 2 | BH12: 11 | BI12: Buff_BuilDetail_1253 | BJ12: 屯兵上限 | BK12: 1 | BL12: 8 | BM12: 11 | BN12: Buff_BuilDetail_2553 | BO12: 侦察行军速度
A13: 城镇中心 | B13: 12 | G13: 城镇中心12 | H13: 领地占领上限 | I13: ResourceLandLimit | J13: 8026 | K13: 36 | L13: 36 | M13: 仓库上限 | N13: Warehouse_Limit | O13: 1252 | P13: 2500000 | Q13: 2500000 | R13: 居民房舍建造上限 | S13: BuildingCapacity_House | T13: 1202 | U13: 2 | V13: 2 | W13: 磨坊建造上限 | X13: BuildingCapacity_Mill | Y13: 1205 | Z13: 3 | AA13: 伐木场建造上限 | AB13: BuildingCapacity_Lumber | AC13: 1209 | AD13: 3 | AE13: 石矿建造上限 | AF13: BuildingCapacity_Ironmine | AG13: 1210 | AH13: 2 | AI13: 金矿建造上限 | AJ13: BuildingCapacity_Goldmine | AK13: 1237 | AL13: 2 | BH13: 12 | BI13: Buff_BuilDetail_4004 | BJ13: 城墙耐久 | BK13: 1 | BL13: 9 | BM13: 12 | BN13: Buff_BuilDetail_4207 | BO13: 防卫塔基础攻击力
A14: 城镇中心 | B14: 13 | G14: 城镇中心13 | H14: 领地占领上限 | I14: ResourceLandLimit | J14: 8026 | K14: 39 | L14: 39 | M14: 仓库上限 | N14: Warehouse_Limit | O14: 1252 | P14: 3000000 | Q14: 3000000 | R14: 居民房舍建造上限 | S14: BuildingCapacity_House | T14: 1202 | U14: 3 | V14: 3 | W14: 磨坊建造上限 | X14: BuildingCapacity_Mill | Y14: 1205 | Z14: 3 | AA14: 伐木场建造上限 | AB14: BuildingCapacity_Lumber | AC14: 1209 | AD14: 3 | AE14: 石矿建造上限 | AF14: BuildingCapacity_Ironmine | AG14: 1210 | AH14: 2 | AI14: 金矿建造上限 | AJ14: BuildingCapacity_Goldmine | AK14: 1237 | AL14: 2 | BH14: 13 | BI14: Buff_BuilDetail_3102 | BJ14: 伤兵上限 | BK14: 1 | BL14: 10 | BM14: 13 | BN14: Buff_BuilDetail_2575 | BO14: 参与组队行军速度
A15: 城镇中心 | B15: 14 | G15: 城镇中心14 | H15: 领地占领上限 | I15: ResourceLandLimit | J15: 8026 | K15: 42 | L15: 42 | M15: 仓库上限 | N15: Warehouse_Limit | O15: 1252 | P15: 4000000 | Q15: 4000000 | R15: 居民房舍建造上限 | S15: BuildingCapacity_House | T15: 1202 | U15: 3 | V15: 3 | W15: 磨坊建造上限 | X15: BuildingCapacity_Mill | Y15: 1205 | Z15: 4 | AA15: 伐木场建造上限 | AB15: BuildingCapacity_Lumber | AC15: 1209 | AD15: 3 | AE15: 石矿建造上限 | AF15: BuildingCapacity_Ironmine | AG15: 1210 | AH15: 2 | AI15: 金矿建造上限 | AJ15: BuildingCapacity_Goldmine | AK15: 1237 | AL15: 2 | BH15: 14 | BI15: Buff_BuilDetail_2553 | BJ15: 侦察行军速度 | BK15: 1 | BL15: 11 | BM15: 14 | BN15: Buff_BuilDetail_2601 | BO15: 援军上限
A16: 城镇中心 | B16: 15 | G16: 城镇中心15 | H16: 领地占领上限 | I16: ResourceLandLimit | J16: 8026 | K16: 45 | L16: 45 | M16: 仓库上限 | N16: Warehouse_Limit | O16: 1252 | P16: 6000000 | Q16: 6000000 | R16: 居民房舍建造上限 | S16: BuildingCapacity_House | T16: 1202 | U16: 3 | V16: 3 | W16: 磨坊建造上限 | X16: BuildingCapacity_Mill | Y16: 1205 | Z16: 4 | AA16: 伐木场建造上限 | AB16: BuildingCapacity_Lumber | AC16: 1209 | AD16: 4 | AE16: 石矿建造上限 | AF16: BuildingCapacity_Ironmine | AG16: 1210 | AH16: 2 | AI16: 金矿建造上限 | AJ16: BuildingCapacity_Goldmine | AK16: 1237 | AL16: 2 | BH16: 15 | BI16: Buff_BuilDetail_4207 | BJ16: 防卫塔基础攻击力 | BK16: 1 | BL16: 12 | BM16: 15 | BN16: Buff_BuilDetail_3308 | BO16: 人气值上限
A17: 城镇中心 | B17: 16 | G17: 城镇中心16 | H17: 领地占领上限 | I17: ResourceLandLimit | J17: 8026 | K17: 48 | L17: 48 | M17: 仓库上限 | N17: Warehouse_Limit | O17: 1252 | P17: 7000000 | Q17: 7000000 | R17: 居民房舍建造上限 | S17: BuildingCapacity_House | T17: 1202 | U17: 4 | V17: 4 | W17: 磨坊建造上限 | X17: BuildingCapacity_Mill | Y17: 1205 | Z17: 4 | AA17: 伐木场建造上限 | AB17: BuildingCapacity_Lumber | AC17: 1209 | AD17: 4 | AE17: 石矿建造上限 | AF17: BuildingCapacity_Ironmine | AG17: 1210 | AH17: 2 | AI17: 金矿建造上限 | AJ17: BuildingCapacity_Goldmine | AK17: 1237 | AL17: 2 | BH17: 16 | BI17: Buff_BuilDetail_2575 | BJ17: 参与组队行军速度 | BK17: 1 | BL17: 13 | BM17: 16 | BN17: Buff_BuilDetail_1252 | BO17: 仓库上限
A18: 城镇中心 | B18: 17 | G18: 城镇中心17 | H18: 领地占领上限 | I18: ResourceLandLimit | J18: 8026 | K18: 51 | L18: 51 | M18: 仓库上限 | N18: Warehouse_Limit | O18: 1252 | P18: 8000000 | Q18: 8000000 | R18: 居民房舍建造上限 | S18: BuildingCapacity_House | T18: 1202 | U18: 4 | V18: 4 | W18: 磨坊建造上限 | X18: BuildingCapacity_Mill | Y18: 1205 | Z18: 4 | AA18: 伐木场建造上限 | AB18: BuildingCapacity_Lumber | AC18: 1209 | AD18: 4 | AE18: 石矿建造上限 | AF18: BuildingCapacity_Ironmine | AG18: 1210 | AH18: 2 | AI18: 金矿建造上限 | AJ18: BuildingCapacity_Goldmine | AK18: 1237 | AL18: 2 | BH18: 17 | BI18: Buff_BuilDetail_2601 | BJ18: 援军上限 | BK18: 1 | BL18: 14 | BM18: 17 | BN18: Buff_BuilDetail_1200 | BO18: 村民人口上限
A19: 城镇中心 | B19: 18 | G19: 城镇中心18 | H19: 领地占领上限 | I19: ResourceLandLimit | J19: 8026 | K19: 54 | L19: 54 | M19: 仓库上限 | N19: Warehouse_Limit | O19: 1252 | P19: 9000000 | Q19: 9000000 | R19: 居民房舍建造上限 | S19: BuildingCapacity_House | T19: 1202 | U19: 4 | V19: 4 | W19: 磨坊建造上限 | X19: BuildingCapacity_Mill | Y19: 1205 | Z19: 4 | AA19: 伐木场建造上限 | AB19: BuildingCapacity_Lumber | AC19: 1209 | AD19: 4 | AE19: 石矿建造上限 | AF19: BuildingCapacity_Ironmine | AG19: 1210 | AH19: 2 | AI19: 金矿建造上限 | AJ19: BuildingCapacity_Goldmine | AK19: 1237 | AL19: 2 | BH19: 18 | BI19: Buff_BuilDetail_3308 | BJ19: 人气值上限 | BK19: 1 | BL19: 15 | BM19: 18 | BN19: Buff_BuilDetail_1206 | BO19: 农田建造上限
A20: 城镇中心 | B20: 19 | G20: 城镇中心19 | H20: 领地占领上限 | I20: ResourceLandLimit | J20: 8026 | K20: 57 | L20: 57 | M20: 仓库上限 | N20: Warehouse_Limit | O20: 1252 | P20: 10000000 | Q20: 10000000 | R20: 居民房舍建造上限 | S20: BuildingCapacity_House | T20: 1202 | U20: 4 | V20: 4 | W20: 磨坊建造上限 | X20: BuildingCapacity_Mill | Y20: 1205 | Z20: 4 | AA20: 伐木场建造上限 | AB20: BuildingCapacity_Lumber | AC20: 1209 | AD20: 4 | AE20: 石矿建造上限 | AF20: BuildingCapacity_Ironmine | AG20: 1210 | AH20: 2 | AI20: 金矿建造上限 | AJ20: BuildingCapacity_Goldmine | AK20: 1237 | AL20: 2 | BH20: 19 | BI20: Buff_BuilDetail_1252 | BJ20: 仓库上限 | BK20: 1 | BL20: 16 | BM20: 19 | BN20: Buff_BuilDetail_3013 | BO20: 剑士训练数量
A21: 城镇中心 | B21: 20 | G21: 城镇中心20 | H21: 领地占领上限 | I21: ResourceLandLimit | J21: 8026 | K21: 60 | L21: 60 | M21: 仓库上限 | N21: Warehouse_Limit | O21: 1252 | P21: 11000000 | Q21: 11000000 | R21: 居民房舍建造上限 | S21: BuildingCapacity_House | T21: 1202 | U21: 4 | V21: 4 | W21: 磨坊建造上限 | X21: BuildingCapacity_Mill | Y21: 1205 | Z21: 4 | AA21: 伐木场建造上限 | AB21: BuildingCapacity_Lumber | AC21: 1209 | AD21: 4 | AE21: 石矿建造上限 | AF21: BuildingCapacity_Ironmine | AG21: 1210 | AH21: 2 | AI21: 金矿建造上限 | AJ21: BuildingCapacity_Goldmine | AK21: 1237 | AL21: 2 | BH21: 20 | BI21: Buff_BuilDetail_1200 | BJ21: 村民人口上限 | BK21: 1 | BL21: 17 | BM21: 20 | BN21: Buff_BuilDetail_3016 | BO21: 枪兵训练数量
A22: 居民房舍 | B22: 1 | E22: 2 | F22: 0 | G22: 居民房舍1 | H22: 每小时居民房舍产出铜币 | I22: BronzePerHour | J22: 1255 | K22: 40 | L22: 40 | M22: 村民人口上限 | N22: Peasant_Capacity | O22: 1200 | P22: 1 | Q22: 1 | V22: 0 | AQ22: 1:2 | AR22: Buff_BuilDetail_1255:Buff_BuilDetail_1200 | AS22: Buff_BuilDetail_1255 | AT22: 每小时居民房舍产出铜币 | AU22: 2 | AV22: Buff_BuilDetail_1200 | AW22: 村民人口上限 | AX22: 20 | BH22: 21 | BI22: Buff_BuilDetail_1206 | BJ22: 农田建造上限 | BK22: 1 | BL22: 18 | BM22: 21 | BN22: Buff_BuilDetail_3014 | BO22: 骑士训练数量
A23: 居民房舍 | B23: 2 | E23: 2 | F23: 1 | G23: 居民房舍2 | H23: 每小时居民房舍产出铜币 | I23: BronzePerHour | J23: 1255 | K23: 80 | L23: 80 | M23: 村民人口上限 | N23: Peasant_Capacity | O23: 1200 | P23: 2 | Q23: 2 | V23: 0 | BH23: 22 | BI23: Buff_BuilDetail_3013 | BJ23: 剑士训练数量 | BK23: 1 | BL23: 19 | BM23: 22 | BN23: Buff_BuilDetail_3015 | BO23: 弓兵训练数量
A24: 居民房舍 | B24: 3 | E24: 2 | F24: 1 | G24: 居民房舍3 | H24: 每小时居民房舍产出铜币 | I24: BronzePerHour | J24: 1255 | K24: 120 | L24: 120 | M24: 村民人口上限 | N24: Peasant_Capacity | O24: 1200 | P24: 3 | Q24: 3 | V24: 0 | BH24: 23 | BI24: Buff_BuilDetail_3016 | BJ24: 枪兵训练数量 | BK24: 1 | BL24: 20 | BM24: 23 | BN24: Buff_BuilDetail_2555 | BO24: 出征队列
A25: 居民房舍 | B25: 4 | E25: 2 | F25: 1 | G25: 居民房舍4 | H25: 每小时居民房舍产出铜币 | I25: BronzePerHour | J25: 1255 | K25: 160 | L25: 160 | M25: 村民人口上限 | N25: Peasant_Capacity | O25: 1200 | P25: 4 | Q25: 4 | V25: 0 | BH25: 24 | BI25: Buff_BuilDetail_3014 | BJ25: 骑士训练数量 | BK25: 1 | BL25: 21 | BM25: 24 | BN25: Buff_BuilDetail_1261 | BO25: 仓库资源保护
A26: 居民房舍 | B26: 5 | E26: 2 | F26: 2 | G26: 居民房舍5 | H26: 每小时居民房舍产出铜币 | I26: BronzePerHour | J26: 1255 | K26: 200 | L26: 400 | M26: 村民人口上限 | N26: Peasant_Capacity | O26: 1200 | P26: 5 | Q26: 10 | V26: 0 | BH26: 25 | BI26: Buff_BuilDetail_3015 | BJ26: 弓兵训练数量 | BK26: 1 | BL26: 22 | BM26: 25 | BN26: Buff_BuilDetail_3100 | BO26: 伤兵治疗速度
A27: 居民房舍 | B27: 6 | E27: 2 | F27: 2 | G27: 居民房舍6 | H27: 每小时居民房舍产出铜币 | I27: BronzePerHour | J27: 1255 | K27: 260 | L27: 520 | M27: 村民人口上限 | N27: Peasant_Capacity | O27: 1200 | P27: 6 | Q27: 12 | V27: 0 | BH27: 26 | BI27: Buff_BuilDetail_2555 | BJ27: 出征队列 | BK27: 1 | BL27: 23 | BM27: 26 | BN27: Buff_BuilDetail_2570 | BO27: 侦察队列
A28: 居民房舍 | B28: 7 | E28: 2 | F28: 2 | G28: 居民房舍7 | H28: 每小时居民房舍产出铜币 | I28: BronzePerHour | J28: 1255 | K28: 320 | L28: 640 | M28: 村民人口上限 | N28: Peasant_Capacity | O28: 1200 | P28: 7 | Q28: 14 | V28: 0 | BH28: 27 | BI28: Buff_BuilDetail_1261 | BJ28: 仓库资源保护 | BK28: 1 | BL28: 24 | BM28: 27 | BN28: Buff_BuilDetail_1254 | BO28: 夺取上限
A29: 居民房舍 | B29: 8 | E29: 2 | F29: 2 | G29: 居民房舍8 | H29: 每小时居民房舍产出铜币 | I29: BronzePerHour | J29: 1255 | K29: 380 | L29: 760 | M29: 村民人口上限 | N29: Peasant_Capacity | O29: 1200 | P29: 8 | Q29: 16 | V29: 0 | BH29: 28 | BI29: Buff_BuilDetail_3100 | BJ29: 伤兵治疗速度 | BK29: 1 | BL29: 25 | BM29: 28 | BN29: Buff_BuilDetail_1400 | BO29: 联盟帮助次数
A30: 居民房舍 | B30: 9 | E30: 2 | F30: 2 | G30: 居民房舍9 | H30: 每小时居民房舍产出铜币 | I30: BronzePerHour | J30: 1255 | K30: 440 | L30: 880 | M30: 村民人口上限 | N30: Peasant_Capacity | O30: 1200 | P30: 9 | Q30: 18 | V30: 0 | BH30: 29 | BI30: Buff_BuilDetail_2570 | BJ30: 侦察队列 | BK30: 1 | BL30: 26 | BM30: 29 | BN30: Buff_BuilDetail_3307 | BO30: 每小时恢复人气值
A31: 居民房舍 | B31: 10 | E31: 2 | F31: 2 | G31: 居民房舍10 | H31: 每小时居民房舍产出铜币 | I31: BronzePerHour | J31: 1255 | K31: 500 | L31: 1000 | M31: 村民人口上限 | N31: Peasant_Capacity | O31: 1200 | P31: 10 | Q31: 20 | V31: 0 | BH31: 30 | BI31: Buff_BuilDetail_1254 | BJ31: 夺取上限 | BK31: 1 | BL31: 27 | BM31: 30 | BN31: Buff_BuilDetail_1202 | BO31: 居民房舍建造上限
A32: 居民房舍 | B32: 11 | E32: 2 | F32: 2 | G32: 居民房舍11 | H32: 每小时居民房舍产出铜币 | I32: BronzePerHour | J32: 1255 | K32: 580 | L32: 1160 | M32: 村民人口上限 | N32: Peasant_Capacity | O32: 1200 | P32: 11 | Q32: 22 | V32: 0 | BH32: 31 | BI32: Buff_BuilDetail_1400 | BJ32: 联盟帮助次数 | BK32: 1 | BL32: 28 | BM32: 31 | BN32: Buff_BuilDetail_3311 | BO32: 医馆加速恢复速度
A33: 居民房舍 | B33: 12 | E33: 2 | F33: 2 | G33: 居民房舍12 | H33: 每小时居民房舍产出铜币 | I33: BronzePerHour | J33: 1255 | K33: 660 | L33: 1320 | M33: 村民人口上限 | N33: Peasant_Capacity | O33: 1200 | P33: 12 | Q33: 24 | V33: 0 | BH33: 32 | BI33: Buff_BuilDetail_3307 | BJ33: 每小时恢复人气值 | BK33: 1 | BL33: 29 | BM33: 32 | BN33: Buff_BuilDetail_1403 | BO33: 帮助减少时间(秒)
A34: 居民房舍 | B34: 13 | E34: 2 | F34: 3 | G34: 居民房舍13 | H34: 每小时居民房舍产出铜币 | I34: BronzePerHour | J34: 1255 | K34: 740 | L34: 2220 | M34: 村民人口上限 | N34: Peasant_Capacity | O34: 1200 | P34: 13 | Q34: 39 | V34: 0 | BH34: 33 | BI34: Buff_BuilDetail_1202 | BJ34: 居民房舍建造上限 | BK34: 1 | BL34: 30 | BM34: 33 | BN34: Buff_BuilDetail_1205 | BO34: 磨坊建造上限
... A36: 居民房舍 | B36: 15 | E36: 2 | F36: 3 | G36: 居民房舍15 | H36: 每小时居民房舍产出铜币 | I36: BronzePerHour | J36: 1255 | K36: 900 | L36: 2700 | M36: 村民人口上限 | N36: Peasant_Capacity | O36: 1200 | P36: 15 | Q36: 45 | V36: 0 | BH36: 35 | BI36: Buff_BuilDetail_1403 | BJ36: 联盟帮助时间减少 | BK36: 1 | BL36: 32 | BM36: 35 | BN36: Buff_BuilDetail_1209 | BO36: 伐木场建造上限
A37: 居民房舍 | B37: 16 | E37: 2 | F37: 4 | G37: 居民房舍16 | H37: 每小时居民房舍产出铜币 | I37: BronzePerHour | J37: 1255 | K37: 1000 | L37: 4000 | M37: 村民人口上限 | N37: Peasant_Capacity | O37: 1200 | P37: 16 | Q37: 64 | V37: 0 | BH37: 36 | BI37: Buff_BuilDetail_1205 | BJ37: 磨坊建造上限 | BK37: 1 | BL37: 33 | BM37: 36
A38: 居民房舍 | B38: 17 | E38: 2 | F38: 4 | G38: 居民房舍17 | H38: 每小时居民房舍产出铜币 | I38: BronzePerHour | J38: 1255 | K38: 1100 | L38: 4400 | M38: 村民人口上限 | N38: Peasant_Capacity | O38: 1200 | P38: 17 | Q38: 68 | V38: 0 | BH38: 37 | BI38: Buff_BuilDetail_3312 | BJ38: 医馆加速储存上限 | BK38: 1 | BL38: 34 | BM38: 37 | BN38: #N/A | BO38: #N/A
A39: 居民房舍 | B39: 18 | E39: 2 | F39: 4 | G39: 居民房舍18 | H39: 每小时居民房舍产出铜币 | I39: BronzePerHour | J39: 1255 | K39: 1200 | L39: 4800 | M39: 村民人口上限 | N39: Peasant_Capacity | O39: 1200 | P39: 18 | Q39: 72 | V39: 0 | BH39: 38 | BI39: Buff_BuilDetail_1209 | BJ39: 伐木场建造上限 | BK39: 1 | BL39: 35 | BM39: 38 | BN39: #N/A | BO39: #N/A
A40: 居民房舍 | B40: 19 | E40: 2 | F40: 4 | G40: 居民房舍19 | H40: 每小时居民房舍产出铜币 | I40: BronzePerHour | J40: 1255 | K40: 1300 | L40: 5200 | M40: 村民人口上限 | N40: Peasant_Capacity | O40: 1200 | P40: 19 | Q40: 76 | V40: 0 | BH40: 39 | BK40: 1 | BL40: 36 | BM40: 39 | BN40: #N/A | BO40: #N/A
A41: 居民房舍 | B41: 20 | E41: 2 | F41: 4 | G41: 居民房舍20 | H41: 每小时居民房舍产出铜币 | I41: BronzePerHour | J41: 1255 | K41: 1400 | L41: 5600 | M41: 村民人口上限 | N41: Peasant_Capacity | O41: 1200 | P41: 20 | Q41: 80 | V41: 0 | BH41: 40 | BK41: 0.5 | BM41: 40 | BN41: #N/A | BO41: #N/A
...

Sheet #建筑消耗索引
A1: 建筑名称 | B1: 建筑等级 | C1: 辅助列 | D1: 建筑数量 | E1: 高活跃 | L1: 资源 | Z1: 设计时间 | AG1: 实际时间 | AJ1: 单建筑 总价值-RMB | AK1: 单建筑 战斗力 | AL1: 多建筑 战斗力 | AM1: 单建筑 累计战力 | AN1: 多建筑 累计战力 | AO1: 战力性价比 | AP1: 单建筑原始时间-分 | AQ1: 单建筑原始时间-小时 | AR1: 单建筑实际时间累积-S | AS1: 单建筑累积资源 | AT1: 单资源最大值
E2: 建筑加速 百分比 | F2: 建筑加速 绝对值 | G2: 资源修正系数 | H2: 资源消耗权重 | L2: 单建筑资源实际消耗 | P2: 数据验证(保证消耗递增，不可为负) | Q2: 多建筑资源实际消耗 | U2: 单建筑资源总消耗 | V2: 多建筑资源总消耗 | W2: 同建筑累计消耗 | X2: 单建筑资源价值-RMB | Y2: 多建筑资源价值-RMB | Z2: 时间消耗 | AA2: 时间修正 系数 | AB2: 原始时间消耗-S | AC2: 多建筑原始时间消耗-S | AD2: 同建筑累计时间-S | AE2: 单建筑时间价值-RMB | AF2: 多建筑时间价值-RMB | AG2: 单建筑实际时间-S | AH2: 多建筑实际时间-S | AI2: 多建筑实际累计时间
H3: 食物 | I3: 木材 | J3: 石头 | K3: 黄金 | L3: 食物 | M3: 木材 | N3: 石头 | O3: 黄金 | Q3: 食物 | R3: 木材 | S3: 石头 | T3: 黄金
A4: 城镇中心 | B4: 1 | C4: 城镇中心1 | D4: 1 | E4: 0 | F4: 0 | G4: 1 | H4: 0 | I4: 1 | J4: 0 | K4: 0 | L4: 0 | M4: 1500 | N4: 0 | O4: 0 | P4: 375 | Q4: 0 | R4: 1500 | S4: 0 | T4: 0 | U4: 1500 | V4: 1500 | W4: 1500 | X4: 0.15 | Y4: 0.15 | Z4: 120 | AA4: 0.001 | AB4: 1 | AC4: 1 | AD4: 1 | AE4: 0.00083333333 | AF4: 0.00083333333 | AG4: 1 | AH4: 1 | AI4: 1 | AJ4: 0.15083333 | AK4: 300 | AL4: 300 | AM4: 300 | AN4: 300 | AO4: 1988.9503 | AP4: 0.016666667 | AQ4: 0.00027777778 | AR4: 1 | AS4: 1500 | AT4: 1500
A5: 城镇中心 | B5: 2 | C5: 城镇中心2 | D5: 1 | E5: 0 | F5: 0 | G5: 1 | H5: 0 | I5: 1 | J5: 0 | K5: 0 | L5: 0 | M5: 3000 | N5: 0 | O5: 0 | P5: 375 | Q5: 0 | R5: 3000 | S5: 0 | T5: 0 | U5: 3000 | V5: 3000 | W5: 3000 | X5: 0.3 | Y5: 0.3 | Z5: 240 | AA5: 0.061 | AB5: 15 | AC5: 15 | AD5: 15 | AE5: 0.0125 | AF5: 0.0125 | AG5: 15 | AH5: 15 | AI5: 16 | AJ5: 0.3125 | AK5: 360 | AL5: 360 | AM5: 660 | AN5: 660 | AO5: 1152 | AP5: 0.25 | AQ5: 0.0041666667 | AR5: 16 | AS5: 4500 | AT5: 3000
A6: 城镇中心 | B6: 3 | C6: 城镇中心3 | D6: 1 | E6: 0 | F6: 0 | G6: 1 | H6: 0 | I6: 1 | J6: 0 | K6: 0 | L6: 0 | M6: 6000 | N6: 0 | O6: 0 | P6: 750 | Q6: 0 | R6: 6000 | S6: 0 | T6: 0 | U6: 6000 | V6: 6000 | W6: 6000 | X6: 0.6 | Y6: 0.6 | Z6: 480 | AA6: 0.1 | AB6: 48 | AC6: 48 | AD6: 48 | AE6: 0.04 | AF6: 0.04 | AG6: 48 | AH6: 48 | AI6: 64 | AJ6: 0.64 | AK6: 430 | AL6: 430 | AM6: 1090 | AN6: 1090 | AO6: 671.875 | AP6: 0.8 | AQ6: 0.013333333 | AR6: 64 | AS6: 10500 | AT6: 6000
A7: 城镇中心 | B7: 4 | C7: 城镇中心4 | D7: 1 | E7: 0 | F7: 0 | G7: 1 | H7: 0 | I7: 1 | J7: 0 | K7: 0 | L7: 0 | M7: 12000 | N7: 0 | O7: 0 | P7: 1500 | Q7: 0 | R7: 12000 | S7: 0 | T7: 0 | U7: 12000 | V7: 12000 | W7: 18000 | X7: 1.2 | Y7: 1.2 | Z7: 960 | AA7: 0.5 | AB7: 480 | AC7: 480 | AD7: 528 | AE7: 0.4 | AF7: 0.4 | AG7: 480 | AH7: 480 | AI7: 544 | AJ7: 1.6 | AK7: 520 | AL7: 520 | AM7: 1610 | AN7: 1610 | AO7: 325 | AP7: 8 | AQ7: 0.13333333 | AR7: 544 | AS7: 22500 | AT7: 12000
A8: 城镇中心 | B8: 5 | C8: 城镇中心5 | D8: 1 | E8: 0 | F8: 0 | G8: 1 | H8: 0 | I8: 1 | J8: 0 | K8: 0 | L8: 0 | M8: 24000 | N8: 0 | O8: 0 | P8: 3000 | Q8: 0 | R8: 24000 | S8: 0 | T8: 0 | U8: 24000 | V8: 24000 | W8: 42000 | X8: 2.4 | Y8: 2.4 | Z8: 1920 | AA8: 0.9 | AB8: 1728 | AC8: 1728 | AD8: 2256 | AE8: 1.44 | AF8: 1.44 | AG8: 1728 | AH8: 1728 | AI8: 2272 | AJ8: 3.84 | AK8: 620 | AL8: 620 | AM8: 2230 | AN8: 2230 | AO8: 161.45833 | AP8: 28.8 | AQ8: 0.48 | AR8: 2272 | AS8: 46500 | AT8: 24000
A9: 城镇中心 | B9: 6 | C9: 城镇中心6 | D9: 1 | E9: 0 | F9: 0 | G9: 1 | H9: 0 | I9: 1 | J9: 1 | K9: 0 | L9: 0 | M9: 24000 | N9: 24000 | O9: 0 | P9: 6000 | Q9: 0 | R9: 24000 | S9: 24000 | T9: 0 | U9: 48000 | V9: 48000 | W9: 90000 | X9: 4.8 | Y9: 4.8 | Z9: 3840 | AA9: 1 | AB9: 3840 | AC9: 3840 | AD9: 6096 | AE9: 3.2 | AF9: 3.2 | AG9: 3840 | AH9: 3840 | AI9: 6112 | AJ9: 8 | AK9: 740 | AL9: 740 | AM9: 2970 | AN9: 2970 | AO9: 92.5 | AP9: 64 | AQ9: 1.0666667 | AR9: 6112 | AS9: 94500 | AT9: 24000
A10: 城镇中心 | B10: 7 | C10: 城镇中心7 | D10: 1 | E10: 0 | F10: 0 | G10: 1 | H10: 0 | I10: 1 | J10: 1 | K10: 0 | L10: 0 | M10: 48000 | N10: 48000 | O10: 0 | P10: 12000 | Q10: 0 | R10: 48000 | S10: 48000 | T10: 0 | U10: 96000 | V10: 96000 | W10: 186000 | X10: 9.6 | Y10: 9.6 | Z10: 7680 | AA10: 1 | AB10: 7680 | AC10: 7680 | AD10: 13776 | AE10: 6.4 | AF10: 6.4 | AG10: 7680 | AH10: 7680 | AI10: 13792 | AJ10: 16 | AK10: 890 | AL10: 890 | AM10: 3860 | AN10: 3860 | AO10: 55.625 | AP10: 128 | AQ10: 2.1333333 | AR10: 13792 | AS10: 190500 | AT10: 48000
A11: 城镇中心 | B11: 8 | C11: 城镇中心8 | D11: 1 | E11: 0 | F11: 0 | G11: 1 | H11: 0 | I11: 1 | J11: 1 | K11: 0 | L11: 0 | M11: 96000 | N11: 96000 | O11: 0 | P11: 24000 | Q11: 0 | R11: 96000 | S11: 96000 | T11: 0 | U11: 192000 | V11: 192000 | W11: 378000 | X11: 19.2 | Y11: 19.2 | Z11: 15360 | AA11: 1 | AB11: 15360 | AC11: 15360 | AD11: 29136 | AE11: 12.8 | AF11: 12.8 | AG11: 15360 | AH11: 15360 | AI11: 29152 | AJ11: 32 | AK11: 1100 | AL11: 1100 | AM11: 4960 | AN11: 4960 | AO11: 34.375 | AP11: 256 | AQ11: 4.2666667 | AR11: 29152 | AS11: 382500 | AT11: 96000
A12: 城镇中心 | B12: 9 | C12: 城镇中心9 | D12: 1 | E12: 0 | F12: 0 | G12: 1 | H12: 0 | I12: 1 | J12: 1 | K12: 0 | L12: 0 | M12: 160000 | N12: 160000 | O12: 0 | P12: 32000 | Q12: 0 | R12: 160000 | S12: 160000 | T12: 0 | U12: 320000 | V12: 320000 | W12: 698000 | X12: 32 | Y12: 32 | Z12: 26112 | AA12: 1 | AB12: 26112 | AC12: 26112 | AD12: 55248 | AE12: 21.76 | AF12: 21.76 | AG12: 26112 | AH12: 26112 | AI12: 55264 | AJ12: 53.76 | AK12: 1300 | AL12: 1300 | AM12: 6260 | AN12: 6260 | AO12: 24.181548 | AP12: 435.2 | AQ12: 7.2533333 | AR12: 55264 | AS12: 702500 | AT12: 160000
A13: 城镇中心 | B13: 10 | C13: 城镇中心10 | D13: 1 | E13: 0 | F13: 0 | G13: 1 | H13: 0 | I13: 1 | J13: 1 | K13: 0 | L13: 0 | M13: 280000 | N13: 280000 | O13: 0 | P13: 60000 | Q13: 0 | R13: 280000 | S13: 280000 | T13: 0 | U13: 560000 | V13: 560000 | W13: 1258000 | X13: 56 | Y13: 56 | Z13: 41779 | AA13: 1 | AB13: 41779 | AC13: 41779 | AD13: 97027 | AE13: 34.815833 | AF13: 34.815833 | AG13: 41779 | AH13: 41779 | AI13: 97043 | AJ13: 90.815833 | AK13: 1600 | AL13: 1600 | AM13: 7860 | AN13: 7860 | AO13: 17.618073 | AP13: 696.31667 | AQ13: 11.605278 | AR13: 97043 | AS13: 1262500 | AT13: 280000
A14: 城镇中心 | B14: 11 | C14: 城镇中心11 | D14: 1 | E14: 0 | F14: 0 | G14: 1 | H14: 0 | I14: 1 | J14: 1 | K14: 1 | L14: 0 | M14: 300000 | N14: 300000 | O14: 300000 | P14: 85000 | Q14: 0 | R14: 300000 | S14: 300000 | T14: 300000 | U14: 900000 | V14: 900000 | W14: 2158000 | X14: 90 | Y14: 90 | Z14: 56402 | AA14: 1 | AB14: 56402 | AC14: 56402 | AD14: 153429 | AE14: 47.001667 | AF14: 47.001667 | AG14: 56402 | AH14: 56402 | AI14: 153445 | AJ14: 137.00167 | AK14: 2200 | AL14: 2200 | AM14: 10060 | AN14: 10060 | AO14: 16.058199 | AP14: 940.03333 | AQ14: 15.667222 | AR14: 153445 | AS14: 2162500 | AT14: 300000
A15: 城镇中心 | B15: 12 | C15: 城镇中心12 | D15: 1 | E15: 0 | F15: 0 | G15: 1 | H15: 0 | I15: 1 | J15: 1 | K15: 1 | L15: 0 | M15: 470000 | N15: 470000 | O15: 470000 | P15: 127500 | Q15: 0 | R15: 470000 | S15: 470000 | T15: 470000 | U15: 1410000 | V15: 1410000 | W15: 3568000 | X15: 141 | Y15: 141 | Z15: 76143 | AA15: 1 | AB15: 76143 | AC15: 76143 | AD15: 229572 | AE15: 63.4525 | AF15: 63.4525 | AG15: 76143 | AH15: 76143 | AI15: 229588 | AJ15: 204.4525 | AK15: 3000 | AL15: 3000 | AM15: 13060 | AN15: 13060 | AO15: 14.673335 | AP15: 1269.05 | AQ15: 21.150833 | AR15: 229588 | AS15: 3572500 | AT15: 470000
... A303: 治疗房舍 | B303: 20 | C303: 治疗房舍20 | D303: 1 | E303: 0 | F303: 0 | G303: 1 | H303: 0 | I303: 1 | J303: 1 | K303: 3 | L303: 0 | M303: 1700000 | N303: 1700000 | O303: 5100000 | P303: 500000 | Q303: 0 | R303: 1700000 | S303: 1700000 | T303: 5100000 | U303: 8500000 | V303: 8500000 | W303: 32772000 | X303: 850 | Y303: 850 | Z303: 414833 | AA303: 1 | AB303: 414833 | AC303: 414833 | AD303: 1376881 | AE303: 345.69417 | AF303: 345.69417 | AG303: 414833 | AH303: 414833 | AI303: 1376888 | AJ303: 1195.6942 | AK303: 14000 | AL303: 14000 | AM303: 53630 | AN303: 53630 | AO303: 11.70868 | AP303: 6913.8833 | AQ303: 115.23139 | AR303: 1376888 | AS303: 32773800 | AT303: 5100000
A304: 大使馆 | B304: 1 | C304: 大使馆1 | D304: 1 | E304: 0 | F304: 0 | G304: 1 | H304: 0 | I304: 2 | J304: 0 | K304: 0 | L304: 0 | M304: 900 | N304: 0 | O304: 0 | P304: #REF! | Q304: 0 | R304: 900 | S304: 0 | T304: 0 | U304: 900 | V304: 900 | W304: 900 | X304: 0.09 | Y304: 0.09 | Z304: 72 | AA304: 0.001 | AB304: 1 | AC304: 1 | AD304: 1 | AE304: 0.00083333333 | AF304: 0.00083333333 | AG304: 1 | AH304: 1 | AI304: 1 | AJ304: 0.090833333 | AK304: 180 | AL304: 180 | AM304: 180 | AN304: 180 | AO304: 1981.6514 | AP304: 0.016666667 | AQ304: 0.00027777778 | AR304: 1 | AS304: 900 | AT304: 900
A305: 大使馆 | B305: 2 | C305: 大使馆2 | D305: 1 | E305: 0 | F305: 0 | G305: 1 | H305: 0 | I305: 2 | J305: 0 | K305: 0 | L305: 0 | M305: 1800 | N305: 0 | O305: 0 | P305: 225 | Q305: 0 | R305: 1800 | S305: 0 | T305: 0 | U305: 1800 | V305: 1800 | W305: 1800 | X305: 0.18 | Y305: 0.18 | Z305: 144 | AA305: 0.061 | AB305: 9 | AC305: 9 | AD305: 9 | AE305: 0.0075 | AF305: 0.0075 | AG305: 9 | AH305: 9 | AI305: 10 | AJ305: 0.1875 | AK305: 216 | AL305: 216 | AM305: 400 | AN305: 400 | AO305: 1152 | AP305: 0.15 | AQ305: 0.0025 | AR305: 10 | AS305: 2700 | AT305: 1800
A306: 大使馆 | B306: 3 | C306: 大使馆3 | D306: 1 | E306: 0 | F306: 0 | G306: 1 | H306: 0 | I306: 2 | J306: 0 | K306: 0 | L306: 0 | M306: 3600 | N306: 0 | O306: 0 | P306: 450 | Q306: 0 | R306: 3600 | S306: 0 | T306: 0 | U306: 3600 | V306: 3600 | W306: 3600 | X306: 0.36 | Y306: 0.36 | Z306: 288 | AA306: 0.1 | AB306: 29 | AC306: 29 | AD306: 29 | AE306: 0.024166667 | AF306: 0.024166667 | AG306: 29 | AH306: 29 | AI306: 39 | AJ306: 0.38416667 | AK306: 258 | AL306: 258 | AM306: 660 | AN306: 660 | AO306: 671.58351 | AP306: 0.48333333 | AQ306: 0.0080555556 | AR306: 39 | AS306: 6300 | AT306: 3600
A307: 大使馆 | B307: 4 | C307: 大使馆4 | D307: 1 | E307: 0 | F307: 0 | G307: 1 | H307: 0 | I307: 2 | J307: 0 | K307: 0 | L307: 0 | M307: 7200 | N307: 0 | O307: 0 | P307: 900 | Q307: 0 | R307: 7200 | S307: 0 | T307: 0 | U307: 7200 | V307: 7200 | W307: 10800 | X307: 0.72 | Y307: 0.72 | Z307: 576 | AA307: 0.5 | AB307: 288 | AC307: 288 | AD307: 317 | AE307: 0.24 | AF307: 0.24 | AG307: 288 | AH307: 288 | AI307: 327 | AJ307: 0.96 | AK307: 312 | AL307: 312 | AM307: 970 | AN307: 970 | AO307: 325 | AP307: 4.8 | AQ307: 0.08 | AR307: 327 | AS307: 13500 | AT307: 7200
A308: 大使馆 | B308: 5 | C308: 大使馆5 | D308: 1 | E308: 0 | F308: 0 | G308: 1 | H308: 0 | I308: 2 | J308: 0 | K308: 0 | L308: 0 | M308: 14000 | N308: 0 | O308: 0 | P308: 1700 | Q308: 0 | R308: 14000 | S308: 0 | T308: 0 | U308: 14000 | V308: 14000 | W308: 24800 | X308: 1.4 | Y308: 1.4 | Z308: 1152 | AA308: 0.9 | AB308: 1037 | AC308: 1037 | AD308: 1354 | AE308: 0.86416667 | AF308: 0.86416667 | AG308: 1037 | AH308: 1037 | AI308: 1364 | AJ308: 2.2641667 | AK308: 372 | AL308: 372 | AM308: 1340 | AN308: 1340 | AO308: 164.29886 | AP308: 17.283333 | AQ308: 0.28805556 | AR308: 1364 | AS308: 27500 | AT308: 14000
A309: 大使馆 | B309: 6 | C309: 大使馆6 | D309: 1 | E309: 0 | F309: 0 | G309: 1 | H309: 0 | I309: 2 | J309: 2 | K309: 0 | L309: 0 | M309: 14000 | N309: 14000 | O309: 0 | P309: 3500 | Q309: 0 | R309: 14000 | S309: 14000 | T309: 0 | U309: 28000 | V309: 28000 | W309: 52800 | X309: 2.8 | Y309: 2.8 | Z309: 2304 | AA309: 1 | AB309: 2304 | AC309: 2304 | AD309: 3658 | AE309: 1.92 | AF309: 1.92 | AG309: 2304 | AH309: 2304 | AI309: 3668 | AJ309: 4.72 | AK309: 444 | AL309: 444 | AM309: 1780 | AN309: 1780 | AO309: 94.067797 | AP309: 38.4 | AQ309: 0.64 | AR309: 3668 | AS309: 55500 | AT309: 14000
A310: 大使馆 | B310: 7 | C310: 大使馆7 | D310: 1 | E310: 0 | F310: 0 | G310: 1 | H310: 0 | I310: 2 | J310: 2 | K310: 0 | L310: 0 | M310: 29000 | N310: 29000 | O310: 0 | P310: 7500 | Q310: 0 | R310: 29000 | S310: 29000 | T310: 0 | U310: 58000 | V310: 58000 | W310: 110800 | X310: 5.8 | Y310: 5.8 | Z310: 4608 | AA310: 1 | AB310: 4608 | AC310: 4608 | AD310: 8266 | AE310: 3.84 | AF310: 3.84 | AG310: 4608 | AH310: 4608 | AI310: 8276 | AJ310: 9.64 | AK310: 534 | AL310: 534 | AM310: 2310 | AN310: 2310 | AO310: 55.394191 | AP310: 76.8 | AQ310: 1.28 | AR310: 8276 | AS310: 113500 | AT310: 29000
A311: 大使馆 | B311: 8 | C311: 大使馆8 | D311: 1 | E311: 0 | F311: 0 | G311: 1 | H311: 0 | I311: 2 | J311: 2 | K311: 0 | L311: 0 | M311: 58000 | N311: 58000 | O311: 0 | P311: 14500 | Q311: 0 | R311: 58000 | S311: 58000 | T311: 0 | U311: 116000 | V311: 116000 | W311: 226800 | X311: 11.6 | Y311: 11.6 | Z311: 9216 | AA311: 1 | AB311: 9216 | AC311: 9216 | AD311: 17482 | AE311: 7.68 | AF311: 7.68 | AG311: 9216 | AH311: 9216 | AI311: 17492 | AJ311: 19.28 | AK311: 660 | AL311: 660 | AM311: 2970 | AN311: 2970 | AO311: 34.232365 | AP311: 153.6 | AQ311: 2.56 | AR311: 17492 | AS311: 229500 | AT311: 58000
A312: 大使馆 | B312: 9 | C312: 大使馆9 | D312: 1 | E312: 0 | F312: 0 | G312: 1 | H312: 0 | I312: 2 | J312: 2 | K312: 0 | L312: 0 | M312: 98000 | N312: 98000 | O312: 0 | P312: 20000 | Q312: 0 | R312: 98000 | S312: 98000 | T312: 0 | U312: 196000 | V312: 196000 | W312: 422800 | X312: 19.6 | Y312: 19.6 | Z312: 15667 | AA312: 1 | AB312: 15667 | AC312: 15667 | AD312: 33149 | AE312: 13.055833 | AF312: 13.055833 | AG312: 15667 | AH312: 15667 | AI312: 33159 | AJ312: 32.655833 | AK312: 780 | AL312: 780 | AM312: 3750 | AN312: 3750 | AO312: 23.885472 | AP312: 261.11667 | AQ312: 4.3519444 | AR312: 33159 | AS312: 425500 | AT312: 98000
A313: 大使馆 | B313: 10 | C313: 大使馆10 | D313: 1 | E313: 0 | F313: 0 | G313: 1 | H313: 0 | I313: 2 | J313: 2 | K313: 0 | L313: 0 | M313: 170000 | N313: 170000 | O313: 0 | P313: 36000 | Q313: 0 | R313: 170000 | S313: 170000 | T313: 0 | U313: 340000 | V313: 340000 | W313: 762800 | X313: 34 | Y313: 34 | Z313: 25068 | AA313: 1 | AB313: 25068 | AC313: 25068 | AD313: 58217 | AE313: 20.89 | AF313: 20.89 | AG313: 25068 | AH313: 25068 | AI313: 58227 | AJ313: 54.89 | AK313: 960 | AL313: 960 | AM313: 4710 | AN313: 4710 | AO313: 17.489525 | AP313: 417.8 | AQ313: 6.9633333 | AR313: 58227 | AS313: 765500 | AT313: 170000
A314: 大使馆 | B314: 11 | C314: 大使馆11 | D314: 1 | E314: 0 | F314: 0 | G314: 1 | H314: 0 | I314: 2 | J314: 2 | K314: 3 | L314: 0 | M314: 150000 | N314: 150000 | O314: 230000 | P314: 47500 | Q314: 0 | R314: 150000 | S314: 150000 | T314: 230000 | U314: 530000 | V314: 530000 | W314: 1292800 | X314: 53 | Y314: 53 | Z314: 33841 | AA314: 1 | AB314: 33841 | AC314: 33841 | AD314: 92058 | AE314: 28.200833 | AF314: 28.200833 | AG314: 33841 | AH314: 33841 | AI314: 92068 | AJ314: 81.200833 | AK314: 1320 | AL314: 1320 | AM314: 6030 | AN314: 6030 | AO314: 16.255991 | AP314: 564.01667 | AQ314: 9.4002778 | AR314: 92068 | AS314: 1295500 | AT314: 230000
A315: 大使馆 | B315: 12 | C315: 大使馆12 | D315: 1 | E315: 0 | F315: 0 | G315: 1 | H315: 0 | I315: 2 | J315: 2 | K315: 3 | L315: 0 | M315: 240000 | N315: 240000 | O315: 370000 | P315: 80000 | Q315: 0 | R315: 240000 | S315: 240000 | T315: 370000 | U315: 850000 | V315: 850000 | W315: 2142800 | X315: 85 | Y315: 85 | Z315: 45686 | AA315: 1 | AB315: 45686 | AC315: 45686 | AD315: 137744 | AE315: 38.071667 | AF315: 38.071667 | AG315: 45686 | AH315: 45686 | AI315: 137754 | AJ315: 123.07167 | AK315: 1800 | AL315: 1800 | AM315: 7830 | AN315: 7830 | AO315: 14.625625 | AP315: 761.43333 | AQ315: 12.690556 | AR315: 137754 | AS315: 2145500 | AT315: 370000
A316: 大使馆 | B316: 13 | C316: 大使馆13 | D316: 1 | E316: 0 | F316: 0 | G316: 1 | H316: 0 | I316: 2 | J316: 2 | K316: 3 | L316: 0 | M316: 390000 | N316: 390000 | O316: 580000 | P316: 127500 | Q316: 0 | R316: 390000 | S316: 390000 | T316: 580000 | U316: 1360000 | V316: 1360000 | W316: 3502800 | X316: 136 | Y316: 136 | Z316: 61675 | AA316: 1 | AB316: 61675 | AC316: 61675 | AD316: 199419 | AE316: 51.395833 | AF316: 51.395833 | AG316: 61675 | AH316: 61675 | AI316: 199429 | AJ316: 187.39583 | AK316: 2460 | AL316: 2460 | AM316: 10290 | AN316: 10290 | AO316: 13.127293 | AP316: 1027.9167 | AQ316: 17.131944 | AR316: 199429 | AS316: 3505500 | AT316: 580000
... A335: 战争大厅 | B335: 12 | C335: 战争大厅12 | D335: 1 | E335: 0 | F335: 0 | G335: 1 | H335: 0 | I335: 1 | J335: 3 | K335: 1 | L335: 0 | M335: 85000 | N335: 260000 | O335: 85000 | P335: 41000 | Q335: 0 | R335: 85000 | S335: 260000 | T335: 85000 | U335: 430000 | V335: 430000 | W335: 1068400 | X335: 43 | Y335: 43 | Z335: 22843 | AA335: 1 | AB335: 22843 | AC335: 22843 | AD335: 68872 | AE335: 19.035833 | AF335: 19.035833 | AG335: 22843 | AH335: 22843 | AI335: 68877 | AJ335: 62.035833 | AK335: 900 | AL335: 900 | AM335: 3930 | AN335: 3930 | AO335: 14.507744 | AP335: 380.71667 | AQ335: 6.3452778 | AR335: 68877 | AS335: 1069750 | AT335: 260000
A336: 战争大厅 | B336: 13 | C336: 战争大厅13 | D336: 1 | E336: 0 | F336: 0 | G336: 1 | H336: 0 | I336: 1 | J336: 3 | K336: 1 | L336: 0 | M336: 140000 | N336: 410000 | O336: 140000 | P336: 65000 | Q336: 0 | R336: 140000 | S336: 410000 | T336: 140000 | U336: 690000 | V336: 690000 | W336: 1758400 | X336: 69 | Y336: 69 | Z336: 30838 | AA336: 1 | AB336: 30838 | AC336: 30838 | AD336: 99710 | AE336: 25.698333 | AF336: 25.698333 | AG336: 30838 | AH336: 30838 | AI336: 99715 | AJ336: 94.698333 | AK336: 1230 | AL336: 1230 | AM336: 5160 | AN336: 5160 | AO336: 12.988613 | AP336: 513.96667 | AQ336: 8.5661111 | AR336: 99715 | AS336: 1759750 | AT336: 410000 | AW336: 100986311 | AX336: 28051.753
A337: 战争大厅 | B337: 14 | C337: 战争大厅14 | D337: 1 | E337: 0 | F337: 0 | G337: 1 | H337: 0 | I337: 1 | J337: 3 | K337: 1 | L337: 0 | M337: 220000 | N337: 650000 | O337: 220000 | P337: 100000 | Q337: 0 | R337: 220000 | S337: 650000 | T337: 220000 | U337: 1090000 | V337: 1090000 | W337: 2848400 | X337: 109 | Y337: 109 | Z337: 41631 | AA337: 1 | AB337: 41631 | AC337: 41631 | AD337: 141341 | AE337: 34.6925 | AF337: 34.6925 | AG337: 41631 | AH337: 41631 | AI337: 141346 | AJ337: 143.6925 | AK337: 1650 | AL337: 1650 | AM337: 6810 | AN337: 6810 | AO337: 11.482854 | AP337: 693.85 | AQ337: 11.564167 | AR337: 141346 | AS337: 2849750 | AT337: 650000
A338: 战争大厅 | B338: 15 | C338: 战争大厅15 | D338: 1 | E338: 0 | F338: 0 | G338: 1 | H338: 0 | I338: 1 | J338: 3 | K338: 1 | L338: 0 | M338: 330000 | N338: 980000 | O338: 330000 | P338: 137500 | Q338: 0 | R338: 330000 | S338: 980000 | T338: 330000 | U338: 1640000 | V338: 1640000 | W338: 4488400 | X338: 164 | Y338: 164 | Z338: 56202 | AA338: 1 | AB338: 56202 | AC338: 56202 | AD338: 197543 | AE338: 46.835 | AF338: 46.835 | AG338: 56202 | AH338: 56202 | AI338: 197548 | AJ338: 210.835 | AK338: 2220 | AL338: 2220 | AM338: 9030 | AN338: 9030 | AO338: 10.529561 | AP338: 936.7 | AQ338: 15.611667 | AR338: 197548 | AS338: 4489750 | AT338: 980000
A339: 战争大厅 | B339: 16 | C339: 战争大厅16 | D339: 1 | E339: 0 | F339: 0 | G339: 1 | H339: 0 | I339: 1 | J339: 3 | K339: 1 | L339: 0 | M339: 440000 | N339: 1300000 | O339: 440000 | P339: 135000 | Q339: 0 | R339: 440000 | S339: 1300000 | T339: 440000 | U339: 2180000 | V339: 2180000 | W339: 6668400 | X339: 218 | Y339: 218 | Z339: 75872 | AA339: 1 | AB339: 75872 | AC339: 75872 | AD339: 273415 | AE339: 63.226667 | AF339: 63.226667 | AG339: 75872 | AH339: 75872 | AI339: 273420 | AJ339: 281.22667 | AK339: 3000 | AL339: 3000 | AM339: 12030 | AN339: 12030 | AO339: 10.667552 | AP339: 1264.5333 | AQ339: 21.075556 | AR339: 273420 | AS339: 6669750 | AT339: 1300000 | AW339: 29584800 | AX339: 8218
A340: 战争大厅 | B340: 17 | C340: 战争大厅17 | D340: 1 | E340: 0 | F340: 0 | G340: 1 | H340: 0 | I340: 1 | J340: 3 | K340: 1 | L340: 0 | M340: 580000 | N340: 1700000 | O340: 580000 | P340: 170000 | Q340: 0 | R340: 580000 | S340: 1700000 | T340: 580000 | U340: 2860000 | V340: 2860000 | W340: 9528400 | X340: 286 | Y340: 286 | Z340: 102428 | AA340: 1 | AB340: 102428 | AC340: 102428 | AD340: 375843 | AE340: 85.356667 | AF340: 85.356667 | AG340: 102428 | AH340: 102428 | AI340: 375848 | AJ340: 371.35667 | AK340: 4200 | AL340: 4200 | AM340: 16230 | AN340: 16230 | AO340: 11.309882 | AP340: 1707.1333 | AQ340: 28.452222 | AR340: 375848 | AS340: 9529750 | AT340: 1700000
A341: 战争大厅 | B341: 18 | C341: 战争大厅18 | D341: 1 | E341: 0 | F341: 0 | G341: 1 | H341: 0 | I341: 1 | J341: 3 | K341: 1 | L341: 0 | M341: 750000 | N341: 2300000 | O341: 750000 | P341: 235000 | Q341: 0 | R341: 750000 | S341: 2300000 | T341: 750000 | U341: 3800000 | V341: 3800000 | W341: 13328400 | X341: 380 | Y341: 380 | Z341: 138278 | AA341: 1 | AB341: 138278 | AC341: 138278 | AD341: 514121 | AE341: 115.23167 | AF341: 115.23167 | AG341: 138278 | AH341: 138278 | AI341: 514126 | AJ341: 495.23167 | AK341: 5700 | AL341: 5700 | AM341: 21930 | AN341: 21930 | AO341: 11.509765 | AP341: 2304.6333 | AQ341: 38.410556 | AR341: 514126 | AS341: 13329750 | AT341: 2300000
A342: 战争大厅 | B342: 19 | C342: 战争大厅19 | D342: 1 | E342: 0 | F342: 0 | G342: 1 | H342: 0 | I342: 1 | J342: 3 | K342: 1 | L342: 0 | M342: 980000 | N342: 2900000 | O342: 980000 | P342: 265000 | Q342: 0 | R342: 980000 | S342: 2900000 | T342: 980000 | U342: 4860000 | V342: 4860000 | W342: 18188400 | X342: 486 | Y342: 486 | Z342: 207416 | AA342: 1 | AB342: 207416 | AC342: 207416 | AD342: 721537 | AE342: 172.84667 | AF342: 172.84667 | AG342: 207416 | AH342: 207416 | AI342: 721542 | AJ342: 658.84667 | AK342: 7800 | AL342: 7800 | AM342: 29730 | AN342: 29730 | AO342: 11.83887 | AP342: 3456.9333 | AQ342: 57.615556 | AR342: 721542 | AS342: 18189750 | AT342: 2900000
A343: 战争大厅 | B343: 20 | C343: 战争大厅20 | D343: 1 | E343: 0 | F343: 0 | G343: 1 | H343: 0 | I343: 1 | J343: 3 | K343: 1 | L343: 0 | M343: 1300000 | N343: 3800000 | O343: 1300000 | P343: 385000 | Q343: 0 | R343: 1300000 | S343: 3800000 | T343: 1300000 | U343: 6400000 | V343: 6400000 | W343: 24588400 | X343: 640 | Y343: 640 | Z343: 311124 | AA343: 1 | AB343: 311124 | AC343: 311124 | AD343: 1032661 | AE343: 259.27 | AF343: 259.27 | AG343: 311124 | AH343: 311124 | AI343: 1032666 | AJ343: 899.27 | AK343: 10500 | AL343: 10500 | AM343: 40230 | AN343: 40230 | AO343: 11.676137 | AP343: 5185.4 | AQ343: 86.423333 | AR343: 1032666 | AS343: 24589750 | AT343: 3800000
A344: 城堡 | B344: 1 | C344: 城堡1 | D344: 1 | E344: 0 | F344: 0 | G344: 1 | H344: 0 | I344: 2 | J344: 0 | K344: 0 | L344: 0 | M344: 0 | N344: 0 | O344: 0 | P344: 0 | Q344: 0 | R344: 0 | S344: 0 | T344: 0 | U344: 0 | V344: 0 | W344: 0 | X344: 0 | Y344: 0 | Z344: 0 | AA344: 0.001 | AB344: 1 | AC344: 1 | AD344: 1 | AE344: 0.00083333333 | AF344: 0.00083333333 | AG344: 1 | AH344: 1 | AI344: 1 | AJ344: 0.00083333333 | AK344: 0 | AL344: 0 | AM344: 0 | AN344: 0 | AO344: 0 | AP344: 0.016666667 | AQ344: 0.00027777778 | AR344: 1 | AS344: 0 | AT344: 0
A345: 城堡 | B345: 2 | C345: 城堡2 | D345: 1 | E345: 0 | F345: 0 | G345: 1 | H345: 0 | I345: 2 | J345: 0 | K345: 0 | L345: 0 | M345: 0 | N345: 0 | O345: 0 | P345: 0 | Q345: 0 | R345: 0 | S345: 0 | T345: 0 | U345: 0 | V345: 0 | W345: 0 | X345: 0 | Y345: 0 | Z345: 0 | AA345: 0.061 | AB345: 1 | AC345: 1 | AD345: 1 | AE345: 0.00083333333 | AF345: 0.00083333333 | AG345: 1 | AH345: 1 | AI345: 2 | AJ345: 0.00083333333 | AK345: 0 | AL345: 0 | AM345: 0 | AN345: 0 | AO345: 0 | AP345: 0.016666667 | AQ345: 0.00027777778 | AR345: 2 | AS345: 0 | AT345: 0
...

Sheet 建筑修复聚焦参数表(废弃）
A1: convert(ResCity.proto, table_CityBuildingFocusConfig, CityBuildingRepairFocusConfigData.pbin)
A2: 主键ID | B2: 建筑类型 | C2: 名称 | D2: 镜头距离 | E2: 镜头焦距 | F2: 镜头角度 | G2: 景深前景模糊起点 | H2: 景深前景模糊终点 | I2: 景深后景模糊起点 | J2: 景深后景模糊终点 | K2: 景深高斯模糊值 | L2: 建筑升级凝视高度
A3: id | B3: buildType | D3: cameraDis[;] | E3: cameraFov[;] | F3: cameraYaw[;] | G3: startFrondDOF[;] | H3: endFrondDOF[;] | I3: startBackDOF[;] | J3: endBackDOF[;] | K3: gaussianRadDOF[;] | L3: cameraForcusHeight[;]
A4: 15 | B4: 201 | C4: 城镇中心 | D4: 50 | E4: 30 | F4: 10 | G4: 30 | H4: 40 | I4: 60 | J4: 65 | K4: 1 | L4: 3

Sheet 建筑基础配置
A1: convert(ResCity.proto, table_CityBuildingBasicConfData, CityBuildingBasicConfData.pbin)
A2: 建筑类型 | B2: 名称 | C2: 城建列表展示顺序 | D2: 建筑分类 | E2: 建造数量上限buffID | F2: 建造上限红点ID | G2: 建造资源下降buffID | H2: 繁荣度权重 | I2: 不能升级 | J2: 宽度 | K2: 长度 | L2: 地基宽度 | M2: 地基长度 | N2: 阻挡宽度 | O2: 阻挡长度 | P2: 显示名字 | Q2: 描述 | R2: 升级默认文本 | S2: 通用挂点 | T2: 铭牌挂点 | U2: 按钮挂点 | V2: 镜头距离 | W2: 镜头焦距 | X2: 镜头角度 | Y2: 旋转起点 | Z2: 景深前景模糊起点 | AA2: 景深前景模糊终点 | AB2: 景深后景模糊起点 | AC2: 景深后景模糊终点 | AD2: 景深高斯模糊值 | AE2: 建筑升级凝视高度 | AF2: 建筑选中 | AG2: 建筑升级镜头推进聚焦 | AH2: 环境音开始 | AI2: 低级建造开始 | AJ2: 低级建造完成 | AK2: 高级建造开始 | AL2: 高级建造完成 | AM2: 低级开始升级 | AN2: 低级升级完成 | AO2: 高级开始升级 | AP2: 高级升级完成 | AQ2: 建造过程开始 | AR2: 建造过程结束 | AS2: 参与连路 | AT2: 升级描述 | AU2: 官职排序 | AV2: 官职1 | AW2: 官职2 | AX2: 官职描述 | AY2: 功能解锁 | AZ2: 迷雾解锁半径 | BA2: 建筑详情按钮
A3: id | C3: sortOrder | D3: buildClass | E3: cntLimitBuffID | F3: limitBuffRedDotID | G3: costDecBuffID | H3: proWeight | I3: notAllowUpgrade | J3: xSize | K3: zSize | L3: xBase | M3: zBase | N3: xNavObs | O3: zNavObs | P3: disName | Q3: desc | R3: upgradeDefault | S3: commonPoint | T3: namePoint | U3: buttonPoint | V3: cameraDis | W3: cameraFov | X3: cameraYaw | Y3: cameraRotateStart | Z3: startFrondDOF | AA3: endFrondDOF | AB3: startBackDOF | AC3: endBackDOF | AD3: gaussianRadDOF | AE3: cameraForcusHeight | AF3: sound2DBldSelect | AG3: sound2DBldCloseUp | AH3: sound3DBldStart | AI3: sound2DBldStartLow | AJ3: sound2DLowBldEnd | AK3: sound2DHighBldStart | AL3: sound2DHighBldEnd | AM3: sound2DLowBldLvStart | AN3: sound2DLowBldLvEnd | AO3: sound2DHighBldLvStart | AP3: sound2DHighBldLvEnd | AQ3: sound3DBldProcessStart | AR3: sound3DBldProcessEnd | AS3: linkRoad | AT3: upgradeDefault | AU3: officerSequence | AV3: officerId[0] | AW3: officerId[1] | AX3: offierDesc | AY3: unLockEnum | AZ3: fogUnlockRadius | BA3: isShowDetails
A4: 201 | B4: 城镇中心 | C4: 1 | D4: 1 | E4: BUFFER_ID_BUILDINGCAPACITY_CENTER | F4: 111 | H4: 100 | I4: 0 | J4: 6 | K4: 6 | L4: 5 | M4: 5 | N4: 6 | O4: 6 | P4: TID_CityBuildingBasicConfData_201_disName_CN_Main | Q4: TID_CityBuildingBasicConfData_201_desc_CN_Main | S4: 0:-1:0 | T4: 0:14:0 | U4: -1:-2:0 | V4: 50 | W4: 30 | X4: 10 | Y4: 15 | Z4: 30 | AA4: 40 | AB4: 60 | AC4: 65 | AD4: 1 | AE4: 3 | AF4: Play_click_Center | AG4: Play_center_closeup | AH4: Play_amb_st_center | AI4: Play_building_build_start_s | AJ4: Play_building_build_finish | AK4: Play_building_build_start_h | AL4: Play_building_build_finish_h | AM4: Play_building_build_start_s | AN4: Play_building_levelup_finish | AO4: Play_building_build_start_h | AP4: Play_building_levelup_finish | AQ4: Play_building_progress | AR4: Play_building_progress | AS4: 0 | AU4: 24 | AV4: 2011 | AW4: 0 | AZ4: 80
A5: 202 | B5: 居民房舍 | C5: 2 | D5: 1 | E5: BUFFER_ID_BUILDINGCAPACITY_HOUSE | H5: 95 | I5: 0 | J5: 4 | K5: 4 | L5: 3 | M5: 3 | N5: 3 | O5: 3 | P5: TID_CityBuildingBasicConfData_202_disName_CN_Main | Q5: TID_CityBuildingBasicConfData_202_desc_CN_Main | S5: 0:-1:0 | T5: 0:7:0 | U5: 0:0:0 | V5: 28 | W5: 30 | X5: 10 | Y5: 15 | Z5: 17 | AA5: 22 | AB5: 33 | AC5: 38 | AD5: 1 | AE5: 2 | AF5: Play_click_House | AG5: Play_house_closeup | AH5: Play_amb_st_house | AI5: Play_building_build_start_s | AJ5: Play_building_build_finish | AK5: Play_building_build_start_h | AL5: Play_building_build_finish_h | AM5: Play_building_build_start_s | AN5: Play_building_levelup_finish | AO5: Play_building_build_start_h | AP5: Play_building_levelup_finish | AQ5: Play_building_progress | AR5: Play_building_progress | AS5: 1 | AU5: 8 | AV5: 2021 | AW5: 2022 | AZ5: 30
A6: 203 | B6: 磨坊 | C6: 3 | D6: 1 | E6: BUFFER_ID_BUILDINGCAPACITY_MILL | H6: 71 | I6: 0 | J6: 4 | K6: 4 | L6: 3 | M6: 3 | N6: 2 | O6: 2 | P6: TID_CityBuildingBasicConfData_203_disName_CN_Main | Q6: TID_CityBuildingBasicConfData_203_desc_CN_Main | S6: 0:-1:0 | T6: 0:11:0 | U6: 0:0:0 | V6: 38 | W6: 30 | X6: 10 | Y6: 15 | Z6: 25 | AA6: 30 | AB6: 45 | AC6: 50 | AD6: 1 | AE6: 3 | AF6: Play_click_Mill | AG6: Play_mill_closeup | AH6: Play_amb_st_mill | AI6: Play_building_build_start_s | AJ6: Play_building_build_finish | AK6: Play_building_build_start_h | AL6: Play_building_build_finish_h | AM6: Play_building_build_start_s | AN6: Play_building_levelup_finish | AO6: Play_building_build_start_h | AP6: Play_building_levelup_finish | AQ6: Play_building_progress | AR6: Play_building_progress | AS6: 0 | AU6: 9 | AV6: 2031 | AW6: 0 | AY6: 内城磨坊建筑 | AZ6: 30
A7: 204 | B7: 伐木场 | C7: 5 | D7: 1 | E7: BUFFER_ID_BUILDINGCAPACITY_LUMBER | H7: 74 | I7: 0 | J7: 4 | K7: 4 | L7: 3 | M7: 3 | N7: 2 | O7: 2 | P7: TID_CityBuildingBasicConfData_204_disName_CN_Main | Q7: TID_CityBuildingBasicConfData_204_desc_CN_Main | S7: 0:-1:0 | T7: 0:9:0 | U7: 0:0:0 | V7: 28 | W7: 30 | X7: 10 | Y7: 15 | Z7: 17 | AA7: 22 | AB7: 33 | AC7: 38 | AD7: 1 | AE7: 3 | AF7: Play_click_Lumber | AG7: Play_lumber_closeup | AH7: Play_amb_st_lumber | AI7: Play_building_build_start_s | AJ7: Play_building_build_finish | AK7: Play_building_build_start_h | AL7: Play_building_build_finish_h | AM7: Play_building_build_start_s | AN7: Play_building_levelup_finish | AO7: Play_building_build_start_h | AP7: Play_building_levelup_finish | AQ7: Play_building_progress | AR7: Play_building_progress | AS7: 0 | AU7: 3 | AV7: 2041 | AW7: 0 | AY7: 内城伐木场建筑 | AZ7: 30
A8: 205 | B8: 石矿场 | C8: 6 | D8: 1 | E8: BUFFER_ID_BUILDINGCAPACITY_IRONMINE | H8: 73 | I8: 0 | J8: 4 | K8: 4 | L8: 3 | M8: 3 | N8: 2 | O8: 2 | P8: TID_CityBuildingBasicConfData_205_disName_CN_Main | Q8: TID_CityBuildingBasicConfData_205_desc_CN_Main | S8: 0:-1:0 | T8: 0:9:0 | U8: 0:0:0 | V8: 28 | W8: 30 | X8: 10 | Y8: 15 | Z8: 17 | AA8: 22 | AB8: 33 | AC8: 38 | AD8: 1 | AE8: 2 | AF8: Play_click_Ironmine | AG8: Play_mine_closeup | AH8: Play_amb_st_mine | AI8: Play_building_build_start_s | AJ8: Play_building_build_finish | AK8: Play_building_build_start_h | AL8: Play_building_build_finish_h | AM8: Play_building_build_start_s | AN8: Play_building_levelup_finish | AO8: Play_building_build_start_h | AP8: Play_building_levelup_finish | AQ8: Play_building_progress | AR8: Play_building_progress | AS8: 0 | AU8: 10 | AV8: 2051 | AW8: 0 | AY8: 内城石矿场建筑 | AZ8: 30
A9: 206 | B9: 剑士营 | C9: 101 | D9: 2 | E9: BUFFER_ID_BUILDINGCAPACITY_SWORDBARRACK | H9: 93 | I9: 0 | J9: 6 | K9: 6 | L9: 4 | M9: 4 | N9: 3 | O9: 3 | P9: TID_CityBuildingBasicConfData_206_disName_CN_Main | Q9: TID_CityBuildingBasicConfData_206_desc_CN_Main | S9: 0:-1:0 | T9: 0:10:0 | U9: 0:0:0 | V9: 38 | W9: 30 | X9: 10 | Y9: 15 | Z9: 25 | AA9: 30 | AB9: 45 | AC9: 50 | AD9: 1 | AE9: 3 | AF9: Play_click_Barrack | AG9: Play_barrack_closeup | AH9: Play_amb_st_barrack | AI9: Play_building_build_start_s | AJ9: Play_barrack_finish | AK9: Play_building_build_start_h | AL9: Play_building_build_finish_h | AM9: Play_building_build_start_s | AN9: Play_building_levelup_finish | AO9: Play_building_build_start_h | AP9: Play_building_levelup_finish_war | AQ9: Play_building_progress | AR9: Play_building_progress | AS9: 1 | AU9: 20 | AV9: 2061 | AW9: 0 | AY9: 内城剑士营建筑 | AZ9: 40
A10: 207 | B10: 农田 | C10: 4 | D10: 1 | E10: BUFFER_ID_BUILDINGCAPACITY_FARMLAND | H10: 0 | I10: 1 | J10: 4 | K10: 4 | L10: 3 | M10: 3 | N10: 3 | O10: 3 | P10: TID_CityBuildingBasicConfData_207_disName_CN_Main | Q10: TID_CityBuildingBasicConfData_207_desc_CN_Main | S10: 0:-1:0 | T10: 0:10:0 | U10: 0:0:0 | V10: 50 | W10: 30 | X10: 10 | Y10: 15 | Z10: 30 | AA10: 40 | AB10: 60 | AC10: 65 | AD10: 1 | AE10: 3 | AF10: Play_click_Farmland | AI10: Play_building_build_start_s | AJ10: Play_building_putdown_farm | AK10: Play_building_build_start_h | AL10: Play_building_putdown_farm | AM10: Play_building_build_start_s | AN10: Play_building_levelup_finish | AO10: Play_building_build_start_h | AP10: Play_building_levelup_finish | AQ10: Play_building_progress | AR10: Play_building_progress | AS10: 0 | AU10: 11 | AV10: 0 | AW10: 0 | AY10: 内城农田建筑 | AZ10: 20
A11: 208 | B11: 城堡 | C11: 107 | D11: 2 | E11: BUFFER_ID_BUILDINGCAPACITY_CASTLE | G11: BUFFER_ID_BUILDINGEXPEND_CASTLE_DEC | H11: 65 | I11: 1 | J11: 4 | K11: 4 | L11: 3 | M11: 3 | N11: 3 | O11: 3 | P11: TID_CityBuildingBasicConfData_208_disName_CN_Main | Q11: TID_CityBuildingBasicConfData_208_desc_CN_Main | S11: 0:-1:0 | T11: 0:25:0 | U11: 0:0:0 | V11: 50 | W11: 30 | X11: 10 | Y11: 15 | Z11: 30 | AA11: 40 | AB11: 60 | AC11: 65 | AD11: 1 | AE11: 8 | AF11: Play_click_Statuehero | AG11: Play_castle_closeup | AI11: Play_building_build_start_s | AJ11: Play_building_build_finish_h | AK11: Play_building_build_start_h | AL11: Play_building_build_finish_h | AM11: Play_building_build_start_s | AN11: Play_building_levelup_finish_h | AO11: Play_building_build_start_h | AP11: Play_building_levelup_finish_h | AQ11: Play_building_progress | AR11: Play_building_progress | AS11: 0 | AU11: 12 | AV11: 0 | AW11: 0 | AY11: 内城城堡建筑
A12: 209 | B12: 马厩 | C12: 103 | D12: 2 | E12: BUFFER_ID_BUILDINGCAPACITY_STABLE | H12: 90 | I12: 0 | J12: 4 | K12: 4 | L12: 3 | M12: 3 | N12: 3 | O12: 3 | P12: TID_CityBuildingBasicConfData_209_disName_CN_Main | Q12: TID_CityBuildingBasicConfData_209_desc_CN_Main | S12: 0:-1:0 | T12: 0:10:0 | U12: 0:0:0 | V12: 38 | W12: 30 | X12: 10 | Y12: 15 | Z12: 25 | AA12: 30 | AB12: 45 | AC12: 50 | AD12: 1 | AE12: 3 | AF12: Play_click_Stable | AG12: Play_stable_closeup | AH12: Play_amb_st_stable | AI12: Play_building_build_start_s | AJ12: Play_stable_finish | AK12: Play_building_build_start_h | AL12: Play_building_build_finish_h | AM12: Play_building_build_start_s | AN12: Play_building_levelup_finish | AO12: Play_building_build_start_h | AP12: Play_building_levelup_finish_war | AQ12: Play_building_progress | AR12: Play_building_progress | AS12: 1 | AU12: 21 | AV12: 2091 | AW12: 0 | AY12: 内城马厩建筑 | AZ12: 30
A13: 211 | B13: 学院 | C13: 11 | D13: 1 | E13: BUFFER_ID_BUILDINGCAPACITY_UNIVERSITY | H13: 55 | I13: 0 | J13: 5 | K13: 5 | L13: 5 | M13: 5 | N13: 3 | O13: 3 | P13: TID_CityBuildingBasicConfData_211_disName_CN_Main | Q13: TID_CityBuildingBasicConfData_211_desc_CN_Main | S13: 0:-1:0 | T13: 0:15:0 | U13: 0:0:0 | V13: 50 | W13: 30 | X13: 10 | Y13: 15 | Z13: 33 | AA13: 38 | AB13: 58 | AC13: 63 | AD13: 1 | AE13: 3 | AF13: Play_click_University | AG13: Play_university_closeup | AI13: Play_building_build_start_s | AJ13: Play_building_build_finish_h | AK13: Play_building_build_start_h | AL13: Play_building_build_finish_h | AM13: Play_building_build_start_s | AN13: Play_building_levelup_finish_h | AO13: Play_building_build_start_h | AP13: Play_building_levelup_finish_h | AQ13: Play_building_progress | AR13: Play_building_progress | AS13: 1 | AU13: 25 | AV13: 2111 | AW13: 0 | AY13: 内城学院建筑 | AZ13: 20
A14: 212 | B14: 校场 | C14: 106 | D14: 2 | E14: BUFFER_ID_BUILDINGCAPACITY_DRILLGROUND | H14: 60 | I14: 1 | J14: 10 | K14: 14 | L14: 10 | M14: 14 | N14: 10 | O14: 14 | P14: TID_CityBuildingBasicConfData_212_disName_CN_Main | Q14: TID_CityBuildingBasicConfData_212_desc_CN_Main | S14: 0:-1:0 | T14: 0:12:0 | U14: 0:0:0 | V14: 48 | W14: 30 | X14: 10 | Y14: 15 | Z14: 20 | AA14: 37 | AB14: 60 | AC14: 100 | AD14: 1 | AE14: 3 | AF14: Play_click_DrillGround | AG14: Play_drillground_closeup | AI14: Play_building_build_start_s | AJ14: Play_building_build_finish | AK14: Play_building_build_start_h | AL14: Play_building_build_finish_h | AM14: Play_building_build_start_s | AN14: Play_building_levelup_finish | AO14: Play_building_build_start_h | AP14: Play_building_levelup_finish | AQ14: Play_building_progress | AR14: Play_building_progress | AS14: 0 | AU14: 1 | AV14: 2121 | AW14: 0 | AY14: 内城校场建筑
A15: 213 | B15: 码头 | C15: 9 | D15: 1 | E15: BUFFER_ID_BUILDINGCAPACITY_DOCK | H15: 35 | I15: 1 | J15: 7 | K15: 7 | L15: 6 | M15: 6 | N15: 6 | O15: 6 | P15: TID_CityBuildingBasicConfData_213_disName_CN_Main | Q15: TID_CityBuildingBasicConfData_213_desc_CN_Main | S15: 0:-1:0 | T15: 0:12:0 | U15: 0:0:0 | V15: 63 | W15: 30 | X15: 10 | Y15: 15 | Z15: 48 | AA15: 53 | AB15: 73 | AC15: 78 | AD15: 1 | AE15: 6 | AF15: Play_click_Dock | AH15: Play_amb_st_wharf | AI15: Play_building_build_start_s | AJ15: Play_building_build_finish | AK15: Play_building_build_start_h | AL15: Play_building_build_finish_h | AM15: Play_building_build_start_s | AN15: Play_building_levelup_finish | AO15: Play_building_build_start_h | AP15: Play_building_levelup_finish | AQ15: Play_building_progress | AR15: Play_building_progress | AS15: 0 | AU15: 26 | AV15: 0 | AW15: 0 | AY15: 内城码头建筑
A16: 215 | B16: 城墙 | C16: 110 | D16: 2 | E16: BUFFER_ID_BUILDINGCAPACITY_GATE | H16: 30 | I16: 0 | J16: 4 | K16: 4 | L16: 3 | M16: 3 | N16: 0 | O16: 0 | P16: TID_CityBuildingBasicConfData_215_disName_CN_Main | Q16: TID_CityBuildingBasicConfData_215_desc_CN_Main | S16: 0:-1:0 | T16: 0:12:0 | U16: 0:0:0 | V16: 60 | W16: 30 | X16: 10 | Y16: 15 | Z16: 45 | AA16: 50 | AB16: 65 | AC16: 70 | AD16: 1 | AE16: 5 | AF16: Play_click_Wall | AG16: Play_wall_closeup | AI16: Play_building_build_start_s | AJ16: Play_building_build_finish | AK16: Play_building_build_start_h | AL16: Play_building_build_finish_h | AM16: Play_building_build_start_s | AN16: Play_building_levelup_finish | AO16: Play_building_build_start_h | AP16: Play_building_levelup_finish | AQ16: Play_building_progress | AR16: Play_building_progress | AS16: 0 | AU16: 2 | AV16: 2151 | AW16: 0 | AY16: 内城城墙建筑
A17: 222 | B17: 治疗房舍 | C17: 105 | D17: 2 | E17: BUFFER_ID_BUILDINGCAPACITY_MEDICALHOUSE | H17: 80 | I17: 0 | J17: 4 | K17: 4 | L17: 3 | M17: 3 | N17: 3 | O17: 3 | P17: TID_CityBuildingBasicConfData_222_disName_CN_Main | Q17: TID_CityBuildingBasicConfData_222_desc_CN_Main | S17: 0:-1:0 | T17: 0:8:0 | U17: 0:0:0 | V17: 28 | W17: 30 | X17: 10 | Y17: 15 | Z17: 17 | AA17: 22 | AB17: 33 | AC17: 38 | AD17: 1 | AE17: 2 | AF17: Play_click_MedicalHouse | AG17: Play_medicalhouse_closeup | AI17: Play_building_build_start_s | AJ17: Play_building_build_finish | AK17: Play_building_build_start_h | AL17: Play_building_build_finish_h | AM17: Play_building_build_start_s | AN17: Play_building_levelup_finish | AO17: Play_building_build_start_h | AP17: Play_building_levelup_finish | AQ17: Play_building_progress | AR17: Play_building_progress | AS17: 1 | AU17: 4 | AV17: 2221 | AW17: 0 | AY17: 内城治疗房舍建筑 | AZ17: 30
A18: 223 | B18: 征兵房舍 | C18: 113 | D18: 2 | E18: BUFFER_ID_BUILDINGCAPACITY_MILITARYHOUSE | H18: 50 | I18: 1 | J18: 4 | K18: 4 | L18: 3 | M18: 3 | N18: 4 | O18: 4 | P18: TID_CityBuildingBasicConfData_223_disName_CN_Main | Q18: TID_CityBuildingBasicConfData_223_desc_CN_Main | S18: 0:-1:0 | T18: 0:10:0 | U18: 0:0:0 | V18: 28 | W18: 30 | X18: 10 | Y18: 15 | Z18: 17 | AA18: 22 | AB18: 33 | AC18: 38 | AD18: 1 | AE18: 2 | AF18: Play_click_MilitaryHouse | AG18: Play_militaryhouse_closeup | AI18: Play_building_build_start_s | AJ18: Play_building_build_finish | AK18: Play_building_build_start_h | AL18: Play_building_build_finish_h | AM18: Play_building_build_start_s | AN18: Play_building_levelup_finish | AO18: Play_building_build_start_h | AP18: Play_building_levelup_finish | AQ18: Play_building_progress | AR18: Play_building_progress | AS18: 1 | AU18: 5 | AV18: 0 | AW18: 0 | AZ18: 20
A19: 224 | B19: 射箭场 | C19: 104 | D19: 2 | E19: BUFFER_ID_BUILDINGCAPACITY_ARCHERYRANGE | H19: 92 | I19: 0 | J19: 4 | K19: 4 | L19: 3 | M19: 3 | N19: 3 | O19: 3 | P19: TID_CityBuildingBasicConfData_224_disName_CN_Main | Q19: TID_CityBuildingBasicConfData_224_desc_CN_Main | S19: 0:-1:0 | T19: 0:10:0 | U19: 0:0:0 | V19: 38 | W19: 30 | X19: 10 | Y19: 15 | Z19: 25 | AA19: 30 | AB19: 45 | AC19: 50 | AD19: 1 | AE19: 3 | AF19: Play_click_ArcheryRange | AG19: Play_archeryrange_closeup | AH19: Play_amb_st_archeryrange | AI19: Play_building_build_start_s | AJ19: Play_archeryrange_finish | AK19: Play_building_build_start_h | AL19: Play_building_build_finish_h | AM19: Play_building_build_start_s | AN19: Play_building_levelup_finish | AO19: Play_building_build_start_h | AP19: Play_building_levelup_finish_war | AQ19: Play_building_progress | AR19: Play_building_progress | AS19: 1 | AU19: 22 | AV19: 2241 | AW19: 0 | AY19: 内城射箭场建筑 | AZ19: 30
