Workbook

Sheet 对话配置表
A1: convert(ResTask.proto, table_DialogueConf, DialogueConf.pbin)
A2: 对话id | B2: 策划备注 | C2: 对话序列 | D2: 策划备注 | E2: 版本 | F2: 角色名称 | G2: 角色名称（key） | H2: 图集路径 | I2: 图片 | J2: 文本内容 | K2: 文本内容(源文本) | L2: 【海外对话表演】模型路径配置 | M2: 【海外对话表演】模型动画名称 | N2: 【海外对话表演】模型结束动画名称 | O2: 海外对话表演】模型位置 | P2: 海外对话表演】结束模型位置 | Q2: 海外对话表演】模型运动时间 | R2: 【海外对话表演】镜头位置参数 | S2: 【海外对话表演】结束镜头位置参数 | T2: 不要翻译 | U2: 对话框样式 | V2: 对话框左右 | W2: 触发结点 | X2: 关卡 | Y2: 是否使用3D播放 | Z2: 语音和背景音 | AA2: 跳过对话终止语音（配了否依然会被其他语音卡掉） | AB2: 语音和背景结束音 | AC2: 口型配置 | AD2: 语音时长工具生成 | AE2: 自动关闭时间 | AF2: 多语言偏移生成 | AG2: 多语言偏移 | AH2: 允许跳过的最短时间 | AI2: 【海外】对话每页字显示完后停留时长 | AJ2: S3跳过时间(不配置无法跳过) | AK2: 跳过后提示文本 | AL2: 播放速度(每秒多少字） | AM2: 角色模型 | AN2: 表演动作 | AO2: 蓝图objID | AP2: 对话弹窗颜色 | AQ2: 气泡偏移 | AR2: 隐藏背景模糊 | AS2: 【海外对话表演】模型对话时音乐 | AT2: 标签后文本 | AU2: 初始对话文本 | AV2: 对话ID关联 | AW2: 标签文本1 | AX2: 标签文本2 | AY2: 标签文本3 | AZ2: 标签文本4 | BA2: 副本部队ID | BB2: 副本部队ID中的SoldiderID | BC2: 绑定副本部队ID中的Soldider尺寸要大于的值 | BD2: 迷雾战场中气泡对象,-1代表玩家部队，其他代表蓝图objID | BE2: 迷雾战场气泡偏移 | BF2: 【海外】背景对话样式(0蓝色,1红色) | BG2: timeline名 | BH2: 跳到的timeline时间（秒数） | BI2: 对应语音是否需要转换多语言事件
A3: dialogueID | C3: contextSequence | G3: name | H3: altasPath | I3: picture | J3: textList | L3: modelPathID | M3: modelAnimNameAndCount[|] | N3: modelEndAnimName | O3: modelPos[|] | P3: modelEndPos[|] | Q3: modelRunTime | R3: cameraParam[|] | S3: cameraEndParam[|] | T3: DNT | U3: dialogueType | V3: dialoguePos | W3: groupId | X3: raidId | Y3: isIn3D | Z3: voiceList[|] | AA3: stopVoiceWhenSkip | AB3: endVoiceList[|] | AC3: lipSyncData | AD3: endTimeGenerate | AE3: endTime | AF3: endTimeOffsetGenerate | AG3: endTimeOffset | AH3: skipDelay | AI3: cutPageShowTime | AJ3: skipTime | AK3: skipTipsContent | AL3: textSpeed | AM3: npcId | AN3: animationName | AO3: BPobjID | AP3: dialogueColor | AQ3: bubbleOffset[;] | AR3: hideBlur | AS3: overseaSetSwtich | BA3: bubbleBindObjId | BB3: bubbleBindSoldierId | BC3: bubbleBindSoldierScale | BD3: fogwarBubbleBindObj | BE3: fogwarBubbleBindOffset[|] | BF3: bgStyle | BG3: timeline.id | BH3: timeline.time | BI3: isVoiceNeedMultiLang
A4: 1 | C4: 1 | E4: DEMO | F4: =VLOOKUP(G4,'#TID_base_up'!B:C,2,0) -> 随从 | G4: TID_DialogueConf_1001_name_CN_Main | H4: icon_guidechara.smash | I4: frame_s_xsdh_002 | J4: TID_DialogueConf_1_textList_CN_Main | T4: 1 | U4: 1 | V4: 0 | W4: 1 | X4: 0 | AD4: 5.5 | AE4: 6.5 | AG4: tr_TR|0;zh_TW|0 | AH4: 0.1 | AL4: 10 | AM4: assets/bundleresources/characters/a/hero/p_ah_joa.prefab | AN4: DJ | AT4: =IF($AU4="","",SUBSTITUTE(SUBSTITUTE(SUBSTITUTE(SUBSTITUTE($AU4,IF($AW4="","",$AW4),IF($AW4="","",CONCATENATE("<color=#FFCC71>",$AW4,"</color>"))),IF($AX4="","",$AX4),IF($AX4="","",CONCATENATE("<color=#FFCC71>",$AX4,"</color>"))),IF($AY4="","",$AY4),IF($AY4="","",CONCATENATE("<color=#FFCC71>",$AY4,"</color>"))),IF($AZ4="","",$AZ4),IF($AZ4="","",CONCATENATE("<color=#FFCC71>",$AZ4,"</color>")))) -> 领主，关押村民们的营地就在前方。 | AU4: 领主，关押村民们的营地就在前方。
A5: 2 | C5: 1 | E5: DEMO | F5: =VLOOKUP(G5,'#TID_base_up'!B:C,2,0) -> 我 | G5: TID_DialogueConf_2_name_23996658795_CN_Main | H5: icon_guidechara.smash | I5: frame_s_xsdh_002 | J5: TID_DialogueConf_2_textList_CN_Main | T5: 1 | U5: 1 | V5: 0 | W5: 1 | X5: 0 | AD5: 5.5 | AE5: 6.5 | AH5: 0.1 | AL5: 10 | AM5: assets/bundleresources/characters/a/hero/p_ah_joa.prefab | AN5: talk_normal | AT5: =IF($AU5="","",SUBSTITUTE(SUBSTITUTE(SUBSTITUTE(SUBSTITUTE($AU5,IF($AW5="","",$AW5),IF($AW5="","",CONCATENATE("<color=#FFCC71>",$AW5,"</color>"))),IF($AX5="","",$AX5),IF($AX5="","",CONCATENATE("<color=#FFCC71>",$AX5,"</color>"))),IF($AY5="","",$AY5),IF($AY5="","",CONCATENATE("<color=#FFCC71>",$AY5,"</color>"))),IF($AZ5="","",$AZ5),IF($AZ5="","",CONCATENATE("<color=#FFCC71>",$AZ5,"</color>")))) -> 必须拯救他们。这是我跟姐姐的约定？ | AU5: 必须拯救他们。这是我跟姐姐的约定？
A6: 2 | C6: 2 | E6: DEMO | F6: =VLOOKUP(G6,'#TID_base_up'!B:C,2,0) -> 我 | G6: TID_DialogueConf_2_name_23996658795_CN_Main | H6: icon_guidechara.smash | I6: frame_s_xsdh_002 | J6: TID_DialogueConf_2_textList_705307478613_CN_Main | T6: 1 | U6: 1 | V6: 0 | W6: 1 | X6: 0 | AD6: 5.5 | AE6: 6.5 | AH6: 0.1 | AL6: 10 | AM6: assets/bundleresources/characters/a/hero/p_ah_joa.prefab | AN6: talk_normal | AT6: =IF($AU6="","",SUBSTITUTE(SUBSTITUTE(SUBSTITUTE(SUBSTITUTE($AU6,IF($AW6="","",$AW6),IF($AW6="","",CONCATENATE("<color=#FFCC71>",$AW6,"</color>"))),IF($AX6="","",$AX6),IF($AX6="","",CONCATENATE("<color=#FFCC71>",$AX6,"</color>"))),IF($AY6="","",$AY6),IF($AY6="","",CONCATENATE("<color=#FFCC71>",$AY6,"</color>"))),IF($AZ6="","",$AZ6),IF($AZ6="","",CONCATENATE("<color=#FFCC71>",$AZ6,"</color>")))) -> 出发！消灭守军。 | AU6: 出发！消灭守军。
A7: 3 | C7: 1 | E7: DEMO | F7: =VLOOKUP(G7,'#TID_base_up'!B:C,2,0) -> 村民甲 | G7: TID_DialogueConf_3_name_CN_Main | H7: icon_guidechara.smash | I7: frame_s_xsdh_002 | J7: TID_DialogueConf_3_textList_CN_Main | T7: 1 | U7: 1 | V7: 0 | W7: 1 | X7: 0 | AD7: 5.5 | AE7: 6.5 | AH7: 0.1 | AL7: 10 | AM7: assets/bundleresources/characters/a/hero/p_ah_joa.prefab | AN7: tv_idle | AT7: =IF($AU7="","",SUBSTITUTE(SUBSTITUTE(SUBSTITUTE(SUBSTITUTE($AU7,IF($AW7="","",$AW7),IF($AW7="","",CONCATENATE("<color=#FFCC71>",$AW7,"</color>"))),IF($AX7="","",$AX7),IF($AX7="","",CONCATENATE("<color=#FFCC71>",$AX7,"</color>"))),IF($AY7="","",$AY7),IF($AY7="","",CONCATENATE("<color=#FFCC71>",$AY7,"</color>"))),IF($AZ7="","",$AZ7),IF($AZ7="","",CONCATENATE("<color=#FFCC71>",$AZ7,"</color>")))) -> 天啊！敌人的将军来了，就在前方。 | AU7: 天啊！敌人的将军来了，就在前方。
A8: 4 | C8: 1 | E8: DEMO | F8: =VLOOKUP(G8,'#TID_base_up'!B:C,2,0) -> 魏兰 | G8: TID_DialogueConf_4_name_CN_Main | H8: icon_guidechara.smash | I8: frame_s_xsdh_002 | J8: TID_DialogueConf_4_textList_CN_Main | T8: 1 | U8: 1 | V8: 0 | W8: 1 | X8: 0 | AD8: 5.5 | AE8: 6.5 | AH8: 0.1 | AL8: 10 | AM8: assets/bundleresources/characters/a/hero/p_ah_joa.prefab | AN8: talk_normal | AT8: =IF($AU8="","",SUBSTITUTE(SUBSTITUTE(SUBSTITUTE(SUBSTITUTE($AU8,IF($AW8="","",$AW8),IF($AW8="","",CONCATENATE("<color=#FFCC71>",$AW8,"</color>"))),IF($AX8="","",$AX8),IF($AX8="","",CONCATENATE("<color=#FFCC71>",$AX8,"</color>"))),IF($AY8="","",$AY8),IF($AY8="","",CONCATENATE("<color=#FFCC71>",$AY8,"</color>"))),IF($AZ8="","",$AZ8),IF($AZ8="","",CONCATENATE("<color=#FFCC71>",$AZ8,"</color>")))) -> 我是花木兰。前来营救！ | AU8: 我是花木兰。前来营救！
A9: 5 | C9: 1 | E9: DEMO | F9: =VLOOKUP(G9,'#TID_base_up'!B:C,2,0) -> 随从 | G9: TID_DialogueConf_1001_name_CN_Main | H9: icon_campaign_npc.smash | I9: npc_campaign_half011 | J9: TID_DialogueConf_5_textList_CN_Main | T9: 1 | U9: 2 | V9: 0 | W9: 1 | X9: 0 | AD9: 5.5 | AE9: 6.5 | AH9: 0.1 | AL9: 10 | AT9: =IF($AU9="","",SUBSTITUTE(SUBSTITUTE(SUBSTITUTE(SUBSTITUTE($AU9,IF($AW9="","",$AW9),IF($AW9="","",CONCATENATE("<color=#FFCC71>",$AW9,"</color>"))),IF($AX9="","",$AX9),IF($AX9="","",CONCATENATE("<color=#FFCC71>",$AX9,"</color>"))),IF($AY9="","",$AY9),IF($AY9="","",CONCATENATE("<color=#FFCC71>",$AY9,"</color>"))),IF($AZ9="","",$AZ9),IF($AZ9="","",CONCATENATE("<color=#FFCC71>",$AZ9,"</color>")))) -> 这是小对话测试1 | AU9: 这是小对话测试1
A10: 5 | C10: 2 | E10: DEMO | F10: =VLOOKUP(G10,'#TID_base_up'!B:C,2,0) -> 随从 | G10: TID_DialogueConf_1001_name_CN_Main | H10: icon_guidechara.smash | I10: frame_s_xsdh_002 | J10: TID_DialogueConf_5_textList_960981524853_CN_Main | T10: 1 | U10: 2 | V10: 0 | W10: 1 | X10: 0 | AD10: 5.5 | AE10: 6.5 | AH10: 0.1 | AL10: 10 | AT10: =IF($AU10="","",SUBSTITUTE(SUBSTITUTE(SUBSTITUTE(SUBSTITUTE($AU10,IF($AW10="","",$AW10),IF($AW10="","",CONCATENATE("<color=#FFCC71>",$AW10,"</color>"))),IF($AX10="","",$AX10),IF($AX10="","",CONCATENATE("<color=#FFCC71>",$AX10,"</color>"))),IF($AY10="","",$AY10),IF($AY10="","",CONCATENATE("<color=#FFCC71>",$AY10,"</color>"))),IF($AZ10="","",$AZ10),IF($AZ10="","",CONCATENATE("<color=#FFCC71>",$AZ10,"</color>")))) -> 这是小对话测试2 | AU10: 这是小对话测试2
A11: 1001 | C11: 1 | E11: DEMO | F11: =VLOOKUP(G11,'#TID_base_up'!B:C,2,0) -> 随从 | G11: TID_DialogueConf_1001_name_CN_Main | J11: TID_DialogueConf_1001_textList_CN_Main | T11: 1 | U11: 3 | V11: 0 | W11: 1 | X11: 0 | AD11: 5.5 | AE11: 6.5 | AH11: 0.1 | AL11: 10 | AT11: =IF($AU11="","",SUBSTITUTE(SUBSTITUTE(SUBSTITUTE(SUBSTITUTE($AU11,IF($AW11="","",$AW11),IF($AW11="","",CONCATENATE("<color=#FFCC71>",$AW11,"</color>"))),IF($AX11="","",$AX11),IF($AX11="","",CONCATENATE("<color=#FFCC71>",$AX11,"</color>"))),IF($AY11="","",$AY11),IF($AY11="","",CONCATENATE("<color=#FFCC71>",$AY11,"</color>"))),IF($AZ11="","",$AZ11),IF($AZ11="","",CONCATENATE("<color=#FFCC71>",$AZ11,"</color>")))) -> 我是一个小气泡文本 | AU11: 我是一个小气泡文本
A12: 1002 | C12: 1 | E12: DEMO | F12: =VLOOKUP(G12,'#TID_base_up'!B:C,2,0) -> 随从 | G12: TID_DialogueConf_1001_name_CN_Main | J12: TID_DialogueConf_1002_textList_CN_Main | T12: 1 | U12: 3 | V12: 0 | W12: 1 | X12: 0 | AD12: 5.5 | AE12: 6.5 | AH12: 0.1 | AL12: 10 | AT12: =IF($AU12="","",SUBSTITUTE(SUBSTITUTE(SUBSTITUTE(SUBSTITUTE($AU12,IF($AW12="","",$AW12),IF($AW12="","",CONCATENATE("<color=#FFCC71>",$AW12,"</color>"))),IF($AX12="","",$AX12),IF($AX12="","",CONCATENATE("<color=#FFCC71>",$AX12,"</color>"))),IF($AY12="","",$AY12),IF($AY12="","",CONCATENATE("<color=#FFCC71>",$AY12,"</color>"))),IF($AZ12="","",$AZ12),IF($AZ12="","",CONCATENATE("<color=#FFCC71>",$AZ12,"</color>")))) -> 我是一个小气泡文本，但是我特别的长，用来测试气泡文本的自动缩放功能。哈哈哈哈哈哈哈哈。 | AU12: 我是一个小气泡文本，但是我特别的长，用来测试气泡文本的自动缩放功能。哈哈哈哈哈哈哈哈。
A13: 1002 | C13: 2 | E13: DEMO | F13: =VLOOKUP(G13,'#TID_base_up'!B:C,2,0) -> 随从 | G13: TID_DialogueConf_1001_name_CN_Main | J13: TID_DialogueConf_1002_textList_507990760778_CN_Main | T13: 1 | U13: 3 | V13: 0 | W13: 1 | X13: 0 | AD13: 5.5 | AE13: 6.5 | AH13: 0.1 | AL13: 10 | AT13: =IF($AU13="","",SUBSTITUTE(SUBSTITUTE(SUBSTITUTE(SUBSTITUTE($AU13,IF($AW13="","",$AW13),IF($AW13="","",CONCATENATE("<color=#FFCC71>",$AW13,"</color>"))),IF($AX13="","",$AX13),IF($AX13="","",CONCATENATE("<color=#FFCC71>",$AX13,"</color>"))),IF($AY13="","",$AY13),IF($AY13="","",CONCATENATE("<color=#FFCC71>",$AY13,"</color>"))),IF($AZ13="","",$AZ13),IF($AZ13="","",CONCATENATE("<color=#FFCC71>",$AZ13,"</color>")))) -> 这是小气泡文本的第二段，过了五秒钟我会出现。这是小气泡文本的第二段，过了五秒钟我会出现。这是小气泡文本的第二段，过了五秒钟我会出现。 | AU13: 这是小气泡文本的第二段，过了五秒钟我会出现。这是小气泡文本的第二段，过了五秒钟我会出现。这是小气泡文本的第二段，过了五秒钟我会出现。
A14: 10001 | C14: 1 | E14: DEMO | F14: =VLOOKUP(G14,'#TID_base_up'!B:C,2,0) -> 琼恩 | G14: TID_DialogueConf_10001_name_CN_Main | H14: icon_campaign_npc.smash | I14: npc_campaign_half006 | J14: TID_DialogueConf_10001_textList_CN_Main | T14: 1 | U14: 2 | V14: 0 | X14: 1005 | AD14: 4 | AE14: 5 | AH14: 0.1 | AL14: 10 | AT14: =IF($AU14="","",SUBSTITUTE(SUBSTITUTE(SUBSTITUTE(SUBSTITUTE($AU14,IF($AW14="","",$AW14),IF($AW14="","",CONCATENATE("<color=#FFCC71>",$AW14,"</color>"))),IF($AX14="","",$AX14),IF($AX14="","",CONCATENATE("<color=#FFCC71>",$AX14,"</color>"))),IF($AY14="","",$AY14),IF($AY14="","",CONCATENATE("<color=#FFCC71>",$AY14,"</color>"))),IF($AZ14="","",$AZ14),IF($AZ14="","",CONCATENATE("<color=#FFCC71>",$AZ14,"</color>")))) -> 说好了在这里汇合，怎么到现在都不见人影？ | AU14: 说好了在这里汇合，怎么到现在都不见人影？
A15: 10002 | C15: =IF(A15=A14,C14+1,1) -> 1 | E15: DEMO | F15: =VLOOKUP(G15,'#TID_base_up'!B:C,2,0) -> 强盗 | G15: TID_DialogueConf_10002_name_CN_Main | H15: icon_guidechara.smash | I15: =VLOOKUP(F15,'#Sheet1'!$J$2:$L$10,2,FALSE) -> frame_s_xsdh_005 | J15: TID_DialogueConf_10002_textList_CN_Main | T15: 1 | U15: 2 | V15: 0 | X15: 1005 | AD15: 3.7 | AE15: 4.7 | AH15: 0.1 | AL15: 10 | AT15: =IF($AU15="","",SUBSTITUTE(SUBSTITUTE(SUBSTITUTE(SUBSTITUTE($AU15,IF($AW15="","",$AW15),IF($AW15="","",CONCATENATE("<color=#FFCC71>",$AW15,"</color>"))),IF($AX15="","",$AX15),IF($AX15="","",CONCATENATE("<color=#FFCC71>",$AX15,"</color>"))),IF($AY15="","",$AY15),IF($AY15="","",CONCATENATE("<color=#FFCC71>",$AY15,"</color>"))),IF($AZ15="","",$AZ15),IF($AZ15="","",CONCATENATE("<color=#FFCC71>",$AZ15,"</color>")))) -> 喂！女人！快把值钱的东西全部交出来！ | AU15: 喂！女人！快把值钱的东西全部交出来！
A16: 10002 | C16: =IF(A16=A15,C15+1,1) -> 2 | E16: DEMO | F16: =VLOOKUP(G16,'#TID_base_up'!B:C,2,0) -> 琼恩 | G16: TID_DialogueConf_10001_name_CN_Main | H16: icon_campaign_npc.smash | I16: npc_campaign_half006 | J16: TID_DialogueConf_10002_textList_286297514590_CN_Main | T16: 1 | U16: 2 | V16: 0 | X16: 1005 | AD16: 5.2 | AE16: 6.2 | AH16: 0.1 | AL16: 10 | AT16: =IF($AU16="","",SUBSTITUTE(SUBSTITUTE(SUBSTITUTE(SUBSTITUTE($AU16,IF($AW16="","",$AW16),IF($AW16="","",CONCATENATE("<color=#FFCC71>",$AW16,"</color>"))),IF($AX16="","",$AX16),IF($AX16="","",CONCATENATE("<color=#FFCC71>",$AX16,"</color>"))),IF($AY16="","",$AY16),IF($AY16="","",CONCATENATE("<color=#FFCC71>",$AY16,"</color>"))),IF($AZ16="","",$AZ16),IF($AZ16="","",CONCATENATE("<color=#FFCC71>",$AZ16,"</color>")))) -> 外敌当前，你们这些人不想着为祖国效力，竟然还打劫自己人！ | AU16: 外敌当前，你们这些人不想着为祖国效力，竟然还打劫自己人！
A17: 10003 | C17: =IF(A17=A16,C16+1,1) -> 1 | E17: DEMO | F17: =VLOOKUP(G17,'#TID_base_up'!B:C,2,0) -> 德·梅斯 | G17: TID_DialogueConf_10003_name_CN_Main | H17: icon_guidechara.smash | I17: =VLOOKUP(F17,'#Sheet1'!$J$2:$L$10,2,FALSE) -> frame_s_xsdh_003 | J17: TID_DialogueConf_10003_textList_CN_Main | T17: 1 | U17: 2 | V17: 0 | X17: 1005 | AD17: 2.35 | AE17: 3.35 | AH17: 0.1 | AL17: 10 | AT17: =IF($AU17="","",SUBSTITUTE(SUBSTITUTE(SUBSTITUTE(SUBSTITUTE($AU17,IF($AW17="","",$AW17),IF($AW17="","",CONCATENATE("<color=#FFCC71>",$AW17,"</color>"))),IF($AX17="","",$AX17),IF($AX17="","",CONCATENATE("<color=#FFCC71>",$AX17,"</color>"))),IF($AY17="","",$AY17),IF($AY17="","",CONCATENATE("<color=#FFCC71>",$AY17,"</color>"))),IF($AZ17="","",$AZ17),IF($AZ17="","",CONCATENATE("<color=#FFCC71>",$AZ17,"</color>")))) -> 我就说要迟到了…… | AU17: 我就说要迟到了……
A18: 10003 | C18: =IF(A18=A17,C17+1,1) -> 2 | E18: DEMO | F18: =VLOOKUP(G18,'#TID_base_up'!B:C,2,0) -> 伯特兰 | G18: TID_DialogueConf_10003_name_332050718590_CN_Main | H18: icon_guidechara.smash | I18: =VLOOKUP(F18,'#Sheet1'!$J$2:$L$10,2,FALSE) -> frame_s_xsdh_006 | J18: TID_DialogueConf_10003_textList_236019767422_CN_Main | T18: 1 | U18: 2 | V18: 0 | X18: 1005 | AD18: 5.8 | AE18: 6.8 | AH18: 0.1 | AL18: 10 | AT18: =IF($AU18="","",SUBSTITUTE(SUBSTITUTE(SUBSTITUTE(SUBSTITUTE($AU18,IF($AW18="","",$AW18),IF($AW18="","",CONCATENATE("<color=#FFCC71>",$AW18,"</color>"))),IF($AX18="","",$AX18),IF($AX18="","",CONCATENATE("<color=#FFCC71>",$AX18,"</color>"))),IF($AY18="","",$AY18),IF($AY18="","",CONCATENATE("<color=#FFCC71>",$AY18,"</color>"))),IF($AZ18="","",$AZ18),IF($AZ18="","",CONCATENATE("<color=#FFCC71>",$AZ18,"</color>")))) -> 别废话了！快救人！ | AU18: 别废话了！快救人！
A19: 10004 | C19: =IF(A19=A18,C18+1,1) -> 1 | E19: DEMO | F19: =VLOOKUP(G19,'#TID_base_up'!B:C,2,0) -> 伯特兰 | G19: TID_DialogueConf_10003_name_332050718590_CN_Main | H19: icon_guidechara.smash | I19: =VLOOKUP(F19,'#Sheet1'!$J$2:$L$10,2,FALSE) -> frame_s_xsdh_006 | J19: TID_DialogueConf_10004_textList_CN_Main | T19: 1 | U19: 2 | V19: 0 | X19: 1005 | AD19: 3.4 | AE19: 4.4 | AH19: 0.1 | AL19: 10 | AT19: =IF($AU19="","",SUBSTITUTE(SUBSTITUTE(SUBSTITUTE(SUBSTITUTE($AU19,IF($AW19="","",$AW19),IF($AW19="","",CONCATENATE("<color=#FFCC71>",$AW19,"</color>"))),IF($AX19="","",$AX19),IF($AX19="","",CONCATENATE("<color=#FFCC71>",$AX19,"</color>"))),IF($AY19="","",$AY19),IF($AY19="","",CONCATENATE("<color=#FFCC71>",$AY19,"</color>"))),IF($AZ19="","",$AZ19),IF($AZ19="","",CONCATENATE("<color=#FFCC71>",$AZ19,"</color>")))) -> 将部队拖拽向敌人，可以发起攻击。 | AU19: 将部队拖拽向敌人，可以发起攻击。
A20: 10005 | C20: =IF(A20=A19,C19+1,1) -> 1 | E20: DEMO | F20: =VLOOKUP(G20,'#TID_base_up'!B:C,2,0) -> 伯特兰 | G20: TID_DialogueConf_10003_name_332050718590_CN_Main | H20: icon_guidechara.smash | I20: =VLOOKUP(F20,'#Sheet1'!$J$2:$L$10,2,FALSE) -> frame_s_xsdh_006 | J20: TID_DialogueConf_10005_textList_CN_Main | T20: 1 | U20: 2 | V20: 0 | X20: 1005 | AD20: 2.8 | AE20: 3.8 | AH20: 0.1 | AL20: 10 | AT20: =IF($AU20="","",SUBSTITUTE(SUBSTITUTE(SUBSTITUTE(SUBSTITUTE($AU20,IF($AW20="","",$AW20),IF($AW20="","",CONCATENATE("<color=#FFCC71>",$AW20,"</color>"))),IF($AX20="","",$AX20),IF($AX20="","",CONCATENATE("<color=#FFCC71>",$AX20,"</color>"))),IF($AY20="","",$AY20),IF($AY20="","",CONCATENATE("<color=#FFCC71>",$AY20,"</color>"))),IF($AZ20="","",$AZ20),IF($AZ20="","",CONCATENATE("<color=#FFCC71>",$AZ20,"</color>")))) -> 你好，琼恩，我是伯特兰。 | AU20: 你好，琼恩，我是伯特兰。
A21: 10005 | C21: =IF(A21=A20,C20+1,1) -> 2 | E21: DEMO | F21: =VLOOKUP(G21,'#TID_base_up'!B:C,2,0) -> 德·梅斯 | G21: TID_DialogueConf_10003_name_CN_Main | H21: icon_guidechara.smash | I21: =VLOOKUP(F21,'#Sheet1'!$J$2:$L$10,2,FALSE) -> frame_s_xsdh_003 | J21: TID_DialogueConf_10005_textList_571453909965_CN_Main | T21: 1 | U21: 2 | V21: 0 | X21: 1005 | AD21: 3.7 | AE21: 4.7 | AH21: 0.1 | AL21: 10 | AT21: =IF($AU21="","",SUBSTITUTE(SUBSTITUTE(SUBSTITUTE(SUBSTITUTE($AU21,IF($AW21="","",$AW21),IF($AW21="","",CONCATENATE("<color=#FFCC71>",$AW21,"</color>"))),IF($AX21="","",$AX21),IF($AX21="","",CONCATENATE("<color=#FFCC71>",$AX21,"</color>"))),IF($AY21="","",$AY21),IF($AY21="","",CONCATENATE("<color=#FFCC71>",$AY21,"</color>"))),IF($AZ21="","",$AZ21),IF($AZ21="","",CONCATENATE("<color=#FFCC71>",$AZ21,"</color>")))) -> 让·德·梅斯，很荣幸为您效劳，女士。 | AU21: 让·德·梅斯，很荣幸为您效劳，女士。
A22: 10005 | C22: =IF(A22=A21,C21+1,1) -> 3 | E22: DEMO | F22: =VLOOKUP(G22,'#TID_base_up'!B:C,2,0) -> 伯特兰 | G22: TID_DialogueConf_10003_name_332050718590_CN_Main | H22: icon_guidechara.smash | I22: =VLOOKUP(F22,'#Sheet1'!$J$2:$L$10,2,FALSE) -> frame_s_xsdh_006 | J22: TID_DialogueConf_10005_textList_26062455831_CN_Main | T22: 1 | U22: 2 | V22: 0 | X22: 1005 | AD22: 5.05 | AE22: 6.05 | AH22: 0.1 | AL22: 10 | AT22: =IF($AU22="","",SUBSTITUTE(SUBSTITUTE(SUBSTITUTE(SUBSTITUTE($AU22,IF($AW22="","",$AW22),IF($AW22="","",CONCATENATE("<color=#FFCC71>",$AW22,"</color>"))),IF($AX22="","",$AX22),IF($AX22="","",CONCATENATE("<color=#FFCC71>",$AX22,"</color>"))),IF($AY22="","",$AY22),IF($AY22="","",CONCATENATE("<color=#FFCC71>",$AY22,"</color>"))),IF($AZ22="","",$AZ22),IF($AZ22="","",CONCATENATE("<color=#FFCC71>",$AZ22,"</color>")))) -> 我和梅斯会一同护送你到前往齐侬，皇太子正在那里等着你。 | AU22: 我和梅斯会一同护送你到前往齐侬，皇太子正在那里等着你。
A23: 10006 | C23: =IF(A23=A22,C22+1,1) -> 1 | E23: DEMO | F23: =VLOOKUP(G23,'#TID_base_up'!B:C,2,0) -> 强盗伏兵 | G23: TID_DialogueConf_10006_name_CN_Main | H23: icon_guidechara.smash | I23: =VLOOKUP(F23,'#Sheet1'!$J$2:$L$10,2,FALSE) -> frame_s_xsdh_005 | J23: TID_DialogueConf_10006_textList_CN_Main | T23: 1 | U23: 2 | V23: 0 | X23: 1005 | AD23: 2.2 | AE23: 3.2 | AH23: 0.1 | AL23: 10 | AT23: =IF($AU23="","",SUBSTITUTE(SUBSTITUTE(SUBSTITUTE(SUBSTITUTE($AU23,IF($AW23="","",$AW23),IF($AW23="","",CONCATENATE("<color=#FFCC71>",$AW23,"</color>"))),IF($AX23="","",$AX23),IF($AX23="","",CONCATENATE("<color=#FFCC71>",$AX23,"</color>"))),IF($AY23="","",$AY23),IF($AY23="","",CONCATENATE("<color=#FFCC71>",$AY23,"</color>"))),IF($AZ23="","",$AZ23),IF($AZ23="","",CONCATENATE("<color=#FFCC71>",$AZ23,"</color>")))) -> 肥鸭子送上门啦！ | AU23: 肥鸭子送上门啦！
A24: 10007 | C24: =IF(A24=A23,C23+1,1) -> 1 | E24: DEMO | F24: =VLOOKUP(G24,'#TID_base_up'!B:C,2,0) -> 勃艮第人 | G24: TID_DialogueConf_10007_name_CN_Main | H24: icon_guidechara.smash | I24: =VLOOKUP(F24,'#Sheet1'!$J$2:$L$10,2,FALSE) -> frame_s_xsdh_005 | J24: TID_DialogueConf_10007_textList_CN_Main | T24: 1 | U24: 2 | V24: 0 | X24: 1005 | AD24: 3.85 | AE24: 4.85 | AH24: 0.1 | AL24: 10 | AT24: =IF($AU24="","",SUBSTITUTE(SUBSTITUTE(SUBSTITUTE(SUBSTITUTE($AU24,IF($AW24="","",$AW24),IF($AW24="","",CONCATENATE("<color=#FFCC71>",$AW24,"</color>"))),IF($AX24="","",$AX24),IF($AX24="","",CONCATENATE("<color=#FFCC71>",$AX24,"</color>"))),IF($AY24="","",$AY24),IF($AY24="","",CONCATENATE("<color=#FFCC71>",$AY24,"</color>"))),IF($AZ24="","",$AZ24),IF($AZ24="","",CONCATENATE("<color=#FFCC71>",$AZ24,"</color>")))) -> 你们法兰西人就是不知道什么时候该认输！ | AU24: 你们法兰西人就是不知道什么时候该认输！
A25: 10008 | C25: =IF(A25=A24,C24+1,1) -> 1 | E25: DEMO | F25: =VLOOKUP(G25,'#TID_base_up'!B:C,2,0) -> 伯特兰 | G25: TID_DialogueConf_10003_name_332050718590_CN_Main | H25: icon_guidechara.smash | I25: =VLOOKUP(F25,'#Sheet1'!$J$2:$L$10,2,FALSE) -> frame_s_xsdh_006 | J25: TID_DialogueConf_10008_textList_CN_Main | T25: 1 | U25: 2 | V25: 0 | X25: 1005 | AD25: 3.25 | AE25: 4.25 | AH25: 0.1 | AL25: 10 | AT25: =IF($AU25="","",SUBSTITUTE(SUBSTITUTE(SUBSTITUTE(SUBSTITUTE($AU25,IF($AW25="","",$AW25),IF($AW25="","",CONCATENATE("<color=#FFCC71>",$AW25,"</color>"))),IF($AX25="","",$AX25),IF($AX25="","",CONCATENATE("<color=#FFCC71>",$AX25,"</color>"))),IF($AY25="","",$AY25),IF($AY25="","",CONCATENATE("<color=#FFCC71>",$AY25,"</color>"))),IF($AZ25="","",$AZ25),IF($AZ25="","",CONCATENATE("<color=#FFCC71>",$AZ25,"</color>")))) -> 解救友军能够增强部队的战斗力。 | AU25: 解救友军能够增强部队的战斗力。
A26: 10008 | C26: =IF(A26=A25,C25+1,1) -> 2 | E26: DEMO | F26: =VLOOKUP(G26,'#TID_base_up'!B:C,2,0) -> 德·梅斯 | G26: TID_DialogueConf_10003_name_CN_Main | H26: icon_guidechara.smash | I26: =VLOOKUP(F26,'#Sheet1'!$J$2:$L$10,2,FALSE) -> frame_s_xsdh_003 | J26: TID_DialogueConf_10008_textList_10977554256_CN_Main | T26: 1 | U26: 2 | V26: 0 | X26: 1005 | AD26: 4.3 | AE26: 5.3 | AH26: 0.1 | AL26: 10 | AT26: =IF($AU26="","",SUBSTITUTE(SUBSTITUTE(SUBSTITUTE(SUBSTITUTE($AU26,IF($AW26="","",$AW26),IF($AW26="","",CONCATENATE("<color=#FFCC71>",$AW26,"</color>"))),IF($AX26="","",$AX26),IF($AX26="","",CONCATENATE("<color=#FFCC71>",$AX26,"</color>"))),IF($AY26="","",$AY26),IF($AY26="","",CONCATENATE("<color=#FFCC71>",$AY26,"</color>"))),IF($AZ26="","",$AZ26),IF($AZ26="","",CONCATENATE("<color=#FFCC71>",$AZ26,"</color>")))) -> 同时也会将琼恩置于危险境地，两难呐，两难…… | AU26: 同时也会将琼恩置于危险境地，两难呐，两难……
A27: 10009 | C27: =IF(A27=A26,C26+1,1) -> 1 | E27: DEMO | F27: =VLOOKUP(G27,'#TID_base_up'!B:C,2,0) -> 伯特兰 | G27: TID_DialogueConf_10003_name_332050718590_CN_Main | H27: icon_guidechara.smash | I27: =VLOOKUP(F27,'#Sheet1'!$J$2:$L$10,2,FALSE) -> frame_s_xsdh_006 | J27: TID_DialogueConf_10009_textList_CN_Main | T27: 1 | U27: 2 | V27: 0 | X27: 1005 | AD27: 3.25 | AE27: 4.25 | AH27: 0.1 | AL27: 10 | AT27: =IF($AU27="","",SUBSTITUTE(SUBSTITUTE(SUBSTITUTE(SUBSTITUTE($AU27,IF($AW27="","",$AW27),IF($AW27="","",CONCATENATE("<color=#FFCC71>",$AW27,"</color>"))),IF($AX27="","",$AX27),IF($AX27="","",CONCATENATE("<color=#FFCC71>",$AX27,"</color>"))),IF($AY27="","",$AY27),IF($AY27="","",CONCATENATE("<color=#FFCC71>",$AY27,"</color>"))),IF($AZ27="","",$AZ27),IF($AZ27="","",CONCATENATE("<color=#FFCC71>",$AZ27,"</color>")))) -> 齐侬的朋友，我们一起并肩作战！ | AU27: 齐侬的朋友，我们一起并肩作战！
A28: 10009 | C28: =IF(A28=A27,C27+1,1) -> 2 | E28: DEMO | F28: =VLOOKUP(G28,'#TID_base_up'!B:C,2,0) -> 齐侬巡逻队 | G28: TID_DialogueConf_10009_name_902916305739_CN_Main | H28: icon_guidechara.smash | I28: =VLOOKUP(F28,'#Sheet1'!$J$2:$L$10,2,FALSE) -> frame_s_xsdh_002 | J28: TID_DialogueConf_10009_textList_148802160042_CN_Main | T28: 1 | U28: 2 | V28: 0 | X28: 1005 | AD28: 2.35 | AE28: 3.35 | AH28: 0.1 | AL28: 10 | AT28: =IF($AU28="","",SUBSTITUTE(SUBSTITUTE(SUBSTITUTE(SUBSTITUTE($AU28,IF($AW28="","",$AW28),IF($AW28="","",CONCATENATE("<color=#FFCC71>",$AW28,"</color>"))),IF($AX28="","",$AX28),IF($AX28="","",CONCATENATE("<color=#FFCC71>",$AX28,"</color>"))),IF($AY28="","",$AY28),IF($AY28="","",CONCATENATE("<color=#FFCC71>",$AY28,"</color>"))),IF($AZ28="","",$AZ28),IF($AZ28="","",CONCATENATE("<color=#FFCC71>",$AZ28,"</color>")))) -> 是友军！友军来了！ | AU28: 是友军！友军来了！
... A60: 10024 | C60: =IF(A60=A59,C59+1,1) -> 2 | E60: DEMO | F60: =VLOOKUP(G60,'#TID_base_up'!B:C,2,0) -> 德·梅斯 | G60: TID_DialogueConf_10003_name_CN_Main | H60: icon_guidechara.smash | I60: =VLOOKUP(F60,'#Sheet1'!$J$2:$L$10,2,FALSE) -> frame_s_xsdh_003 | J60: TID_DialogueConf_10024_textList_290367274068_CN_Main | T60: 1 | U60: 2 | V60: 0 | X60: 1005 | AD60: 5.2 | AE60: 6.2 | AH60: 0.1 | AL60: 10 | AT60: =IF($AU60="","",SUBSTITUTE(SUBSTITUTE(SUBSTITUTE(SUBSTITUTE($AU60,IF($AW60="","",$AW60),IF($AW60="","",CONCATENATE("<color=#FFCC71>",$AW60,"</color>"))),IF($AX60="","",$AX60),IF($AX60="","",CONCATENATE("<color=#FFCC71>",$AX60,"</color>"))),IF($AY60="","",$AY60),IF($AY60="","",CONCATENATE("<color=#FFCC71>",$AY60,"</color>"))),IF($AZ60="","",$AZ60),IF($AZ60="","",CONCATENATE("<color=#FFCC71>",$AZ60,"</color>")))) -> 攻击强盗可以吸引他们火力。如果琼恩倒下了，大家都得完蛋。 | AU60: 攻击强盗可以吸引他们火力。如果琼恩倒下了，大家都得完蛋。
A61: 11001 | C61: =IF(A61=A60,C60+1,1) -> 1 | E61: DEMO | F61: =VLOOKUP(G61,'#TID_base_up'!B:C,2,0) -> 琼恩 | G61: TID_DialogueConf_10001_name_CN_Main | H61: icon_guidechara.smash | I61: frame_s_xsdh_001 | J61: TID_DialogueConf_11001_textList_CN_Main | T61: 1 | U61: 2 | V61: 0 | X61: 1006 | Y61: FALSE | Z61: Play_voice_campaign_demo00_02_Jeanne | AA61: FALSE | AD61: 2.977083 | AE61: 3.98 | AH61: 0.1 | AL61: 10 | AT61: =IF($AU61="","",SUBSTITUTE(SUBSTITUTE(SUBSTITUTE(SUBSTITUTE($AU61,IF($AW61="","",$AW61),IF($AW61="","",CONCATENATE("<color=#FFCC71>",$AW61,"</color>"))),IF($AX61="","",$AX61),IF($AX61="","",CONCATENATE("<color=#FFCC71>",$AX61,"</color>"))),IF($AY61="","",$AY61),IF($AY61="","",CONCATENATE("<color=#FFCC71>",$AY61,"</color>"))),IF($AZ61="","",$AZ61),IF($AZ61="","",CONCATENATE("<color=#FFCC71>",$AZ61,"</color>")))) -> 说好了在这里会合，怎么到现在都不见人影？ | AU61: 说好了在这里会合，怎么到现在都不见人影？
A62: 11001 | C62: =IF(A62=A61,C61+1,1) -> 2 | E62: DEMO | F62: =VLOOKUP(G62,'#TID_base_up'!B:C,2,0) -> 强盗 | G62: TID_DialogueConf_10002_name_CN_Main | H62: icon_guidechara.smash | I62: frame_s_xsdh_005 | J62: TID_DialogueConf_10002_textList_CN_Main | T62: 1 | U62: 2 | V62: 0 | X62: 1006 | Y62: TRUE | Z62: Play_voice_campaign_demo00_03_Bandit | AA62: FALSE | AD62: 3.7119999 | AE62: 4.71 | AH62: 0.1 | AL62: 10 | AT62: =IF($AU62="","",SUBSTITUTE(SUBSTITUTE(SUBSTITUTE(SUBSTITUTE($AU62,IF($AW62="","",$AW62),IF($AW62="","",CONCATENATE("<color=#FFCC71>",$AW62,"</color>"))),IF($AX62="","",$AX62),IF($AX62="","",CONCATENATE("<color=#FFCC71>",$AX62,"</color>"))),IF($AY62="","",$AY62),IF($AY62="","",CONCATENATE("<color=#FFCC71>",$AY62,"</color>"))),IF($AZ62="","",$AZ62),IF($AZ62="","",CONCATENATE("<color=#FFCC71>",$AZ62,"</color>")))) -> 喂！女人！快把值钱的东西全部交出来！ | AU62: 喂！女人！快把值钱的东西全部交出来！
A63: 11001 | C63: =IF(A63=A62,C62+1,1) -> 3 | E63: DEMO | F63: =VLOOKUP(G63,'#TID_base_up'!B:C,2,0) -> 琼恩 | G63: TID_DialogueConf_10001_name_CN_Main | H63: icon_guidechara.smash | I63: frame_s_xsdh_001 | J63: TID_DialogueConf_11001_textList_882144978695_CN_Main | T63: 1 | U63: 2 | V63: 0 | X63: 1006 | Y63: FALSE | Z63: Play_voice_campaign_demo00_04_Jeanne | AA63: FALSE | AD63: 4.4613328 | AE63: 5.46 | AH63: 0.1 | AL63: 10 | AT63: =IF($AU63="","",SUBSTITUTE(SUBSTITUTE(SUBSTITUTE(SUBSTITUTE($AU63,IF($AW63="","",$AW63),IF($AW63="","",CONCATENATE("<color=#FFCC71>",$AW63,"</color>"))),IF($AX63="","",$AX63),IF($AX63="","",CONCATENATE("<color=#FFCC71>",$AX63,"</color>"))),IF($AY63="","",$AY63),IF($AY63="","",CONCATENATE("<color=#FFCC71>",$AY63,"</color>"))),IF($AZ63="","",$AZ63),IF($AZ63="","",CONCATENATE("<color=#FFCC71>",$AZ63,"</color>")))) -> 国难当头，你们还在打劫同胞！真是法兰西的耻辱！ | AU63: 国难当头，你们还在打劫同胞！真是法兰西的耻辱！
A64: 11001 | C64: =IF(A64=A63,C63+1,1) -> 4 | E64: DEMO | F64: =VLOOKUP(G64,'#TID_base_up'!B:C,2,0) -> 伯特兰 | G64: TID_DialogueConf_10003_name_332050718590_CN_Main | H64: icon_guidechara.smash | I64: frame_s_xsdh_006 | J64: TID_DialogueConf_11001_textList_54802890190_CN_Main | T64: 1 | U64: 2 | V64: 0 | X64: 1006 | Y64: TRUE | Z64: Play_voice_campaign_demo00_05_Bertrand | AA64: FALSE | AD64: 1.133333 | AE64: 2.13 | AH64: 0.1 | AL64: 10 | AT64: =IF($AU64="","",SUBSTITUTE(SUBSTITUTE(SUBSTITUTE(SUBSTITUTE($AU64,IF($AW64="","",$AW64),IF($AW64="","",CONCATENATE("<color=#FFCC71>",$AW64,"</color>"))),IF($AX64="","",$AX64),IF($AX64="","",CONCATENATE("<color=#FFCC71>",$AX64,"</color>"))),IF($AY64="","",$AY64),IF($AY64="","",CONCATENATE("<color=#FFCC71>",$AY64,"</color>"))),IF($AZ64="","",$AZ64),IF($AZ64="","",CONCATENATE("<color=#FFCC71>",$AZ64,"</color>")))) -> 说得好，琼恩！ | AU64: 说得好，琼恩！
A65: 11002 | C65: =IF(A65=A64,C64+1,1) -> 1 | E65: DEMO | F65: =VLOOKUP(G65,'#TID_base_up'!B:C,2,0) -> 伯特兰 | G65: TID_DialogueConf_10003_name_332050718590_CN_Main | H65: icon_guidechara.smash | I65: frame_s_xsdh_006 | J65: TID_DialogueConf_11002_textList_CN_Main | T65: 1 | U65: 2 | V65: 0 | X65: 1006 | Y65: FALSE | Z65: Play_voice_campaign_demo00_06_tips_Bertrand | AA65: FALSE | AD65: 2.622 | AE65: 3.62 | AH65: 0.1 | AL65: 10 | AT65: =IF($AU65="","",SUBSTITUTE(SUBSTITUTE(SUBSTITUTE(SUBSTITUTE($AU65,IF($AW65="","",$AW65),IF($AW65="","",CONCATENATE("<color=#FFCC71>",$AW65,"</color>"))),IF($AX65="","",$AX65),IF($AX65="","",CONCATENATE("<color=#FFCC71>",$AX65,"</color>"))),IF($AY65="","",$AY65),IF($AY65="","",CONCATENATE("<color=#FFCC71>",$AY65,"</color>"))),IF($AZ65="","",$AZ65),IF($AZ65="","",CONCATENATE("<color=#FFCC71>",$AZ65,"</color>")))) -> 将部队拖拽向敌人，立即发起攻击。 | AU65: 将部队拖拽向敌人，立即发起攻击。
A66: 11003 | C66: =IF(A66=A65,C65+1,1) -> 1 | E66: DEMO | F66: =VLOOKUP(G66,'#TID_base_up'!B:C,2,0) -> 琼恩 | G66: TID_DialogueConf_10001_name_CN_Main | H66: icon_guidechara.smash | I66: frame_s_xsdh_001 | J66: TID_DialogueConf_11003_textList_CN_Main | T66: 1 | U66: 3 | V66: 0 | X66: 1006 | Y66: TRUE | Z66: Play_voice_campaign_demo00_07_bubble_Jeanne | AA66: FALSE | AD66: 1.425 | AE66: 2.42 | AH66: 0.1 | AL66: 10 | AT66: =IF($AU66="","",SUBSTITUTE(SUBSTITUTE(SUBSTITUTE(SUBSTITUTE($AU66,IF($AW66="","",$AW66),IF($AW66="","",CONCATENATE("<color=#FFCC71>",$AW66,"</color>"))),IF($AX66="","",$AX66),IF($AX66="","",CONCATENATE("<color=#FFCC71>",$AX66,"</color>"))),IF($AY66="","",$AY66),IF($AY66="","",CONCATENATE("<color=#FFCC71>",$AY66,"</color>"))),IF($AZ66="","",$AZ66),IF($AZ66="","",CONCATENATE("<color=#FFCC71>",$AZ66,"</color>")))) -> 伯特兰！你迟到了。 | AU66: 伯特兰！你迟到了。
A67: 11004 | C67: =IF(A67=A66,C66+1,1) -> 1 | E67: DEMO | F67: =VLOOKUP(G67,'#TID_base_up'!B:C,2,0) -> 伯特兰 | G67: TID_DialogueConf_10003_name_332050718590_CN_Main | H67: icon_guidechara.smash | I67: frame_s_xsdh_006 | J67: TID_DialogueConf_11004_textList_CN_Main | T67: 1 | U67: 3 | V67: 0 | X67: 1006 | Y67: FALSE | Z67: Play_voice_campaign_demo00_08_bubble_Bertrand | AA67: FALSE | AD67: 4.6079998 | AE67: 5.61 | AH67: 0.1 | AL67: 10 | AT67: =IF($AU67="","",SUBSTITUTE(SUBSTITUTE(SUBSTITUTE(SUBSTITUTE($AU67,IF($AW67="","",$AW67),IF($AW67="","",CONCATENATE("<color=#FFCC71>",$AW67,"</color>"))),IF($AX67="","",$AX67),IF($AX67="","",CONCATENATE("<color=#FFCC71>",$AX67,"</color>"))),IF($AY67="","",$AY67),IF($AY67="","",CONCATENATE("<color=#FFCC71>",$AY67,"</color>"))),IF($AZ67="","",$AZ67),IF($AZ67="","",CONCATENATE("<color=#FFCC71>",$AZ67,"</color>")))) -> 请见谅，女士，路上遇到了一队英国佬，耽误了一点时间。 | AU67: 请见谅，女士，路上遇到了一队英国佬，耽误了一点时间。
A68: 11005 | C68: =IF(A68=A67,C67+1,1) -> 1 | E68: DEMO | F68: =VLOOKUP(G68,'#TID_base_up'!B:C,2,0) -> 伯特兰 | G68: TID_DialogueConf_10003_name_332050718590_CN_Main | H68: icon_guidechara.smash | I68: frame_s_xsdh_006 | J68: TID_DialogueConf_11005_textList_CN_Main | T68: 1 | U68: 2 | V68: 0 | X68: 1006 | Y68: FALSE | Z68: Play_voice_campaign_demo00_09_Bertrand | AA68: FALSE | AD68: 6.333333 | AE68: 7.33 | AH68: 0.1 | AL68: 10 | AT68: =IF($AU68="","",SUBSTITUTE(SUBSTITUTE(SUBSTITUTE(SUBSTITUTE($AU68,IF($AW68="","",$AW68),IF($AW68="","",CONCATENATE("<color=#FFCC71>",$AW68,"</color>"))),IF($AX68="","",$AX68),IF($AX68="","",CONCATENATE("<color=#FFCC71>",$AX68,"</color>"))),IF($AY68="","",$AY68),IF($AY68="","",CONCATENATE("<color=#FFCC71>",$AY68,"</color>"))),IF($AZ68="","",$AZ68),IF($AZ68="","",CONCATENATE("<color=#FFCC71>",$AZ68,"</color>")))) -> 皇太子正在齐侬等着，我和德·梅斯会护送你……等等……德·梅斯人呢？ | AU68: 皇太子正在齐侬等着，我和德·梅斯会护送你……等等……德·梅斯人呢？
A69: 11005 | C69: =IF(A69=A68,C68+1,1) -> 2 | E69: DEMO | F69: =VLOOKUP(G69,'#TID_base_up'!B:C,2,0) -> #N/A | G69: TID_DialogueConf_11005_name_286024863093_CN_Main | H69: icon_guidechara.smash | I69: frame_s_xsdh_001 | J69: TID_DialogueConf_11005_textList_118216904678_CN_Main | T69: 1 | U69: 2 | V69: 0 | X69: 1006 | Y69: FALSE | Z69: Play_voice_campaign_demo00_10_Jeanne | AA69: FALSE | AD69: 2.508333 | AE69: 3.51 | AH69: 0.1 | AL69: 10 | AT69: =IF($AU69="","",SUBSTITUTE(SUBSTITUTE(SUBSTITUTE(SUBSTITUTE($AU69,IF($AW69="","",$AW69),IF($AW69="","",CONCATENATE("<color=#FFCC71>",$AW69,"</color>"))),IF($AX69="","",$AX69),IF($AX69="","",CONCATENATE("<color=#FFCC71>",$AX69,"</color>"))),IF($AY69="","",$AY69),IF($AY69="","",CONCATENATE("<color=#FFCC71>",$AY69,"</color>"))),IF($AZ69="","",$AZ69),IF($AZ69="","",CONCATENATE("<color=#FFCC71>",$AZ69,"</color>")))) -> 他在前面探查，就等你过去会合了。 | AU69: 他在前面探查，就等你过去会合了。
A70: 11006 | C70: =IF(A70=A69,C69+1,1) -> 1 | E70: DEMO | F70: =VLOOKUP(G70,'#TID_base_up'!B:C,2,0) -> 强盗伏兵 | G70: TID_DialogueConf_10006_name_CN_Main | H70: icon_guidechara.smash | I70: frame_s_xsdh_005 | J70: TID_DialogueConf_11006_textList_CN_Main | T70: 1 | U70: 3 | V70: 0 | X70: 1006 | Y70: FALSE | Z70: Play_voice_campaign_demo00_11_bubble_BanditAmbush | AA70: FALSE | AD70: 3.573333 | AE70: 4.57 | AH70: 0.1 | AL70: 10 | AT70: =IF($AU70="","",SUBSTITUTE(SUBSTITUTE(SUBSTITUTE(SUBSTITUTE($AU70,IF($AW70="","",$AW70),IF($AW70="","",CONCATENATE("<color=#FFCC71>",$AW70,"</color>"))),IF($AX70="","",$AX70),IF($AX70="","",CONCATENATE("<color=#FFCC71>",$AX70,"</color>"))),IF($AY70="","",$AY70),IF($AY70="","",CONCATENATE("<color=#FFCC71>",$AY70,"</color>"))),IF($AZ70="","",$AZ70),IF($AZ70="","",CONCATENATE("<color=#FFCC71>",$AZ70,"</color>")))) -> 肥鸭子送上门了！ | AU70: 肥鸭子送上门了！
A71: 11007 | C71: =IF(A71=A70,C70+1,1) -> 1 | E71: DEMO | F71: =VLOOKUP(G71,'#TID_base_up'!B:C,2,0) -> 伯特兰 | G71: TID_DialogueConf_10003_name_332050718590_CN_Main | H71: icon_guidechara.smash | I71: frame_s_xsdh_006 | J71: TID_DialogueConf_11007_textList_CN_Main | T71: 1 | U71: 2 | V71: 0 | X71: 1006 | Y71: FALSE | Z71: Play_voice_campaign_demo00_12_Bertrand | AA71: FALSE | AD71: 5.5093331 | AE71: 6.51 | AH71: 0.1 | AL71: 10 | AT71: =IF($AU71="","",SUBSTITUTE(SUBSTITUTE(SUBSTITUTE(SUBSTITUTE($AU71,IF($AW71="","",$AW71),IF($AW71="","",CONCATENATE("<color=#FFCC71>",$AW71,"</color>"))),IF($AX71="","",$AX71),IF($AX71="","",CONCATENATE("<color=#FFCC71>",$AX71,"</color>"))),IF($AY71="","",$AY71),IF($AY71="","",CONCATENATE("<color=#FFCC71>",$AY71,"</color>"))),IF($AZ71="","",$AZ71),IF($AZ71="","",CONCATENATE("<color=#FFCC71>",$AZ71,"</color>")))) -> 攻击敌人可以吸引他们的火力。琼恩是我们最后的希望，决不能让她受到伤害！ | AU71: 攻击敌人可以吸引他们的火力。琼恩是我们最后的希望，决不能让她受到伤害！
...

Sheet Spine配置表
A1: convert(ResTask.proto, table_SpineConf, SpineConf.pbin)
A2: SpineId | B2: 说明 | C2: 序列 | D2: Spine路径 | E2: 文本 | F2: 语音和背景音
A3: spineId | C3: contextSequence | D3: spineName | E3: textList | F3: voiceList[|]
A4: 1 | C4: 1 | E4: TID_SpineConf_11_textList_CN_Main
A5: 1 | C5: 2 | E5: TID_SpineConf_12_textList_CN_Main
A6: 1 | C6: 3 | E6: TID_SpineConf_13_textList_CN_Main
A7: 2 | C7: 1 | E7: TID_SpineConf_21_textList_CN_Main
A8: 2 | C8: 2 | E8: TID_SpineConf_22_textList_CN_Main

Sheet #Sheet2
A1: npcid | B1: 模型路径 | C1: 动作名称
A2: id | B2: modePath | C2: animations[|]
A3: 1 | B3: assets/bundleresources/characters/story/p_celine_n_story.prefab | C3: Idle | D3: Walk | E3: Talk | F3: Down_Cry
A4: 2 | B4: assets/bundleresources/characters/story/p_fa_lan_ke_shibing1_story_anim.prefab | C4: Idle_Story | D4: run_Story | E4: attack_Story | F4: moan_Story
A5: 3 | B5: assets/bundleresources/characters/story/p_lead.prefab | C5: Idle | D5: Walk | E5: Attack | F5: wave
A6: 4 | B6: assets/bundleresources/characters/story/p_ma_ke_bo_luo_story_anim.prefab | C6: idle | D6: idleSpecial | E6: interaction | F6: walk
A7: 5 | B7: assets/bundleresources/characters/tv_preview/p_vikin_tv.prefab | C7: idle
A8: 6 | B8: assets/bundleresources/characters/tv_preview/p_bfnpc_hawker_tv.prefab | C8: idle
A9: 7 | B9: assets/bundleresources/characters/tv_preview/p_celine_n_tv.prefab | C9: idle | D9: talk | E9: think | F9: shout
A10: 8 | B10: assets/bundleresources/characters/tv_preview/p_lead_tv.prefab | C10: idle | D10: talk | E10: weak
A11: 9 | B11: assets/bundleresources/characters/tv_preview/p_fa_lan_ke_shibing1_tv.prefab | C11: idle_story | D11: standby_story
A12: 10 | B12: assets/bundleresources/characters/lobby/p_hero_boudica.prefab
A13: 11 | B13: assets/bundleresources/characters/lobby/p_hero_boudica_tv.prefab
A14: 12 | B14: assets/bundleresources/characters/tv_preview/p_a_flora_tv.prefab | C14: talk_normal | D14: talk_happy | E14: talk_angry | H14: 芙罗拉
A15: 13 | B15: assets/bundleresources/characters/tv_preview/p_a_lead_tv.prefab | C15: talk_normal | D15: talk_happy | E15: talk_angry | H15: 法兰克默认君主形象
A16: 14 | B16: assets/bundleresources/characters/tv_preview/p_a_lead_e01_tv.prefab | C16: talk_normal | D16: talk_happy | E16: talk_angry | H16: 中国默认君主形象
A17: 15 | B17: assets/bundleresources/characters/tv_preview/p_afl1_pkemn_tv.prefab | C17: idle | H17: 法兰克1级枪兵
A18: 16 | B18: assets/bundleresources/characters/tv_preview/p_afl2_pkemn_tv.prefab | C18: idle | H18: 法兰克2级枪兵
A19: 17 | B19: assets/bundleresources/characters/tv_preview/p_afl3_pkemn_tv.prefab | C19: DJ | H19: 法兰克3级枪兵
A20: 18 | B20: assets/bundleresources/characters/tv_preview/p_afl4_pkemn_tv.prefab | C20: DJ | H20: 法兰克4级枪兵
A21: 19 | B21: assets/bundleresources/characters/tv_preview/p_hero_boudica_tv.prefab | C21: idle | H21: 布狄卡
A22: 20 | B22: assets/bundleresources/characters/tv_preview/p_acl1_archr_tv.prefab | C22: tv_idle | H22: 中国1级弓兵-农民
A23: 21 | B23: assets/bundleresources/characters/tv_preview/p_acl1_archr_tv.prefab | C23: tv_idle | H23: 中国1级弓兵-农民
A24: 22 | B24: assets/bundleresources/characters/peasant/p_bfnpc_hawker_tv.prefab | C24: idle | H24: 小贩
A25: 23 | B25: assets/bundleresources/characters/tv_preview/p_bml4_huns_tv.prefab | C25: DJ | H25: 野蛮人头目
A26: 24 | B26: assets/bundleresources/characters/tv_preview/p_acl1_pkemn_tv.prefab | C26: tv_idle | H26: 中国1级枪兵-水手
A27: 25 | B27: assets/bundleresources/characters/tv_preview/p_acl3_pkemn_tv.prefab | C27: DJ | H27: 中国3级枪兵-随从
A28: 26 | B28: assets/bundleresources/characters/tv_preview/p_hero_hml_tv.prefab | C28: talk_normal | D28: talk_happy | E28: talk_angry | H28: 花木兰
A29: 27 | B29: assets/bundleresources/characters/tv_preview/p_hero_daxueshi_tv.prefab | C29: talk_normal | H29: 中国学士
A30: 28 | B30: assets/bundleresources/characters/tv_preview/p_a_leadm_e02.prefab | C30: talk_normal | D30: talk_happy | E30: talk_angry | H30: 中国默认君主形象
A31: 29 | B31: assets/bundleresources/characters/tv_preview/p_actv_bachelor_e.prefab | C31: talk_normal | H31: 中国学士
A32: 30 | B32: assets/bundleresources/characters/tv_preview/p_actv_retinue_e.prefab | C32: tv_idle | H32: 中国随从
A33: 31 | B33: assets/bundleresources/characters/tv_preview/p_actv_farmer_e.prefab | C33: tv_idle | H33: 中国村民

Sheet #Sheet1
J2: 琼恩 | K2: ="frame_s_xsdh_00"&L2 -> frame_s_xsdh_001 | L2: 1
J3: 强盗 | K3: ="frame_s_xsdh_00"&L3 -> frame_s_xsdh_005 | L3: 5
J4: 德·梅斯 | K4: ="frame_s_xsdh_00"&L4 -> frame_s_xsdh_003 | L4: 3
J5: 伯特兰 | K5: ="frame_s_xsdh_00"&L5 -> frame_s_xsdh_006 | L5: 6
J6: 强盗伏兵 | K6: ="frame_s_xsdh_00"&L6 -> frame_s_xsdh_005 | L6: 5
J7: 勃艮第人 | K7: ="frame_s_xsdh_00"&L7 -> frame_s_xsdh_005 | L7: 5
J8: 齐侬巡逻队 | K8: ="frame_s_xsdh_00"&L8 -> frame_s_xsdh_002 | L8: 2
J9: 齐侬巡查队 | K9: ="frame_s_xsdh_00"&L9 -> frame_s_xsdh_002 | L9: 2
J10: 萨佛克伯爵 | K10: ="frame_s_xsdh_00"&L10 -> frame_s_xsdh_005 | L10: 5

Sheet #名称Key
A1: 随从 | B1: SuiCong
A2: 我 | B2: Wo
A3: 村民甲 | B3: CunMinJia
A4: 魏兰 | B4: WeiLan
A5: 琼恩 | B5: QiongEn
A6: 强盗 | B6: QiangDao
A7: 德·梅斯 | B7: DeMeiSi
A8: 伯特兰 | B8: BoTeLan
A9: 强盗伏兵 | B9: QiangDaoFuBing1
A10: 勃艮第人 | B10: BoGenDiRen
A11: 齐侬巡逻队 | B11: QiNongXunLuoDui
A12: 齐侬巡查队 | B12: QiNongXunChaDui
... A45: 兵仙 | B45: BingXian

Sheet #对话模型配置
A1: 角色名称 | B1: 策划用模型 | C1: 文本 | D1: 是否使用3D播放 | E1: 语音和背景音 | F1: 语音和背景结束音 | G1: 口型配置 | H1: 自动关闭时间 | I1: 角色模型 | J1: 表演动作 | K1: 蓝图objID | L1: 角色名字key | M1: 图集路径 | N1: 海外新手用图集 | O1: 海外新手用头像 | P1: 图片 | Q1: 对话文本 | R1: 标签后文本 | S1: 初始文本 | T1: 标签文本1 | U1: 标签文本2 | V1: 标签文本3 | W1: 标签文本4
A2: name | C2: textList | D2: isIn3D | E2: voiceList[|] | F2: endVoiceList[|] | H2: endTime | I2: npcId | J2: animationName | K2: BPobjID | L2: hideBlur | M2: altasPath | N2: altasPath | O2: picture | P2: picture
A3: 帝国斥候 | H3: 10 | I3: 20001001 | J3: chapter_1_6 | M3: icon_guidechara.smash | P3: frame_s_xsdh_002
A4: 安德莉娅 | H4: 10 | I4: 30001001 | J4: chapter_1_2 | M4: icon_guidechara.smash | N4: icon_newbie | O4: newbie_oversea_andrea | P4: frame_s_xsdh_002
A5: 尤里乌斯 | H5: 10 | I5: 20001003 | J5: Idle | M5: icon_guidechara.smash | P5: frame_s_xsdh_002
A6: 关羽 | H6: 10 | I6: 20001004 | J6: Idle | M6: icon_guidechara.smash | P6: frame_s_xsdh_002
A7: 魏兰 | H7: 10 | I7: 20001005 | J7: chapter_1_2 | M7: icon_guidechara.smash | P7: frame_s_xsdh_002
A8: 皇帝 | H8: 10 | I8: 20001006 | J8: chapter_2_13 | M8: icon_guidechara.smash | P8: frame_s_xsdh_002
A9: 花木兰 | H9: 10 | I9: 20001005 | J9: chapter_1_2 | M9: icon_guidechara.smash | P9: frame_s_xsdh_002
A10: 尤里乌斯 | H10: 10 | I10: 20001003 | J10: Idle | M10: icon_guidechara.smash | P10: frame_s_xsdh_002
A11: 李白 | I11: 20001099
A12: 贞德 | B12: 110002 | H12: 10 | I12: 30001002 | J12: chapter_1_2 | L12: TID_DialogueConf_1060715_name_CN_Main | M12: icon_guidechara.smash | N12: icon_newbie | O12: newbie_oversea_joa | P12: frame_s_xsdh_002
A13: 副官 | B13: 110008 | H13: 10 | I13: 30001003 | J13: Idle | L13: TID_DialogueConf_1060001_name_CN_Main | M13: icon_guidechara.smash | N13: icon_newbie | O13: newbie_oversea_axe | P13: frame_s_xsdh_002
A14: 村民 | L14: TID_DialogueConf_1060611_name_CN_Main | N14: icon_newbie | O14: newbie_oversea_farmernohat
A15: 乌尔丁 | L15: TID_DialogueConf_1060607_name_CN_Main | N15: icon_newbie | O15: newbie_oversea_enemy
A16: 血手阿提卡 | L16: TID_DialogueConf_1060620_name_CN_Main | N16: icon_newbie | O16: newbie_oversea_attila
A17: 安德莉亚 | B17: 110003 | L17: TID_DialogueConf_1060001_name_337966742914_CN_Main | N17: icon_newbie | O17: newbie_oversea_andrea
A18: 凯恩 | N18: icon_newbie | O18: newbie_oversea_leo
A19: 肖恩 | N19: icon_newbie | O19: newbie_oversea_leo
A20: 蒙杜克 | L20: TID_Name_mengduke_CN_Main | N20: icon_newbie | O20: newbie_oversea_monduk
A21: 士兵 | L21: TID_Name_shibing_CN_Main | N21: icon_newbie | O21: newbie_oversea_leo
A22: 蛮族 | L22: TID_Dialogue_Character_6 | N22: icon_newbie | O22: newbie_oversea_enemy
A23: 温德 | L23: TID_Name_wende_CN_Main | N23: icon_newbie | O23: newbie_oversea_leo
A24: 图尔坎 | L24: TID_Name_tuerkan_CN_Main | N24: icon_newbie | O24: newbie_oversea_enemy
A25: 保罗 | L25: TID_Name_baoluo_CN_Main | N25: icon_newbie | O25: newbie_oversea_enemy
A26: 蛮族士兵 | L26: TID_Name_manzushibing_CN_Main | N26: icon_newbie | O26: newbie_oversea_enemy
A27: 研究员 | L27: TID_Name_yanjiuyuan_CN_Main | N27: icon_newbie | O27: newbie_oversea_enemy
A28: 珍妮 | L28: TID_Name_zhenni_CN_Main | N28: icon_newbie | O28: newbie_oversea_leo
A29: 陌生的来客 | B29: 110001 | L29: TID_Dialogue_Character_4 | N29: icon_newbie | O29: newbie_oversea_caesar
A30: 凯撒 | B30: 110001 | L30: TID_Dialogue_Character_5 | N30: icon_newbie | O30: newbie_oversea_caesar
A31: 部落 | B31: 110005 | L31: TID_Dialogue_Character_6 | N31: icon_newbie | O31: newbie_oversea_enemy
A32: 克洛维 | B32: 110004 | L32: TID_Dialogue_Character_7 | N32: icon_newbie | O32: newbie_oversea_clovis
A33: 撕裂者 | B33: 110005 | L33: TID_Dialogue_Character_8 | N33: icon_newbie | O33: newbie_oversea_kabar
A34: 墨西 | B34: 110006 | L34: TID_Dialogue_Character_9 | N34: icon_newbie | O34: newbie_oversea_mose
A35: 克鲁维斯 | B35: 110007 | L35: TID_Dialogue_Character_10 | N35: icon_hero | O35: story_kruvis_big
A36: 约瑟芬 | B36: 110003 | L36: TID_Dialogue_Character_11 | N36: icon_newbie | O36: newbie_oversea_andrea
A37: 卡尔 | L37: TID_Dialogue_Character_12 | N37: icon_newbie | O37: newbie_oversea_carl
A38: 近卫 | L38: xinshou_story_charname01 | N38: icon_newbie | O38: newbie_oversea_leo
A39: 副官big | L39: TID_DialogueConf_1060001_name_CN_Main | N39: icon_hero | O39: icon_hero_206_big
A40: 村民big | L40: TID_DialogueConf_1060611_name_CN_Main | N40: icon_hero | O40: newbie_farmer_big
...

Sheet #TID_base_up
A1: 旧Key | B1: 新Key | C1: 文本
A2: DialogueConf_1001_name_CN_Main | B2: TID_DialogueConf_1001_name_CN_Main | C2: 随从
A3: DialogueConf_1_textList_CN_Main | B3: TID_DialogueConf_1_textList_CN_Main | C3: <color=#FFED6D>领主</color>，关押<color=#FFED6D>村民们</color>的营地就在前方。
A4: DialogueConf_2_name_23996658795_CN_Main | B4: TID_DialogueConf_2_name_23996658795_CN_Main | C4: 我
A5: DialogueConf_2_textList_CN_Main | B5: TID_DialogueConf_2_textList_CN_Main | C5: 必须<color=#FFED6D>拯救他们</color>。这是我跟<color=#FFED6D>姐姐</color>的约定？
A6: DialogueConf_2_textList_705307478613_CN_Main | B6: TID_DialogueConf_2_textList_705307478613_CN_Main | C6: 出发！消灭守军。
A7: DialogueConf_3_name_CN_Main | B7: TID_DialogueConf_3_name_CN_Main | C7: 村民甲
A8: DialogueConf_3_textList_CN_Main | B8: TID_DialogueConf_3_textList_CN_Main | C8: 天啊！敌人的将军来了，就在前方。
A9: DialogueConf_4_name_CN_Main | B9: TID_DialogueConf_4_name_CN_Main | C9: 魏兰
A10: DialogueConf_4_textList_CN_Main | B10: TID_DialogueConf_4_textList_CN_Main | C10: 我是<color=#FFED6D>魏兰</color>。前来营救！
A11: DialogueConf_5_textList_CN_Main | B11: TID_DialogueConf_5_textList_CN_Main | C11: 这是小对话测试1
A12: DialogueConf_5_textList_960981524853_CN_Main | B12: TID_DialogueConf_5_textList_960981524853_CN_Main | C12: 这是小对话测试2
... A847: SpineConf_22_textList_CN_Main | B847: TID_SpineConf_22_textList_CN_Main | C847: 新手剧情Spine5（占位） 皇帝阵亡之前，嘱托玩家一定要: “铲除蛮族，夺回皇城，统一帝国！”
