Workbook

Sheet 获取途径组
A1: convert(ResShowGet.proto, table_ShowGetGroupData,ShowGetGroupData.pbin)
A2: id | B2: 获取途径id | C2: 道具id | D2: 超值礼包Id | E2: 界面展示标题 | F2: 界面展示标题 | G2: 说明 | H2: 说明
A3: id | B3: idGroup[;] | C3: itemId | D3: valuePackageId | E3: title | G3: des | I3: 备注
A4: 1 | B4: 3 | E4: TID_ShowGetGroupData_1_des_CN_Main | F4: 获取贵族经验 | G4: TID_ShowGetGroupData_1_des_CN_Main | H4: 获取贵族经验 | I4: 贵族跳转
A5: 2 | B5: 4;5 | E5: TID_ShowGetGroupData_2_title_CN_Main | F5: 好感度礼物获取 | G5: TID_ShowGetGroupData_2_des_CN_Main | H5: 内政官好感度提升所需的礼物，可通过<color=#fff6ab>旅店寻访</color>、<color=#fff6ab>市集兑换商店</color>、等途径获取。 | I5: 内政官好感度升级材料获取
A6: 3 | B6: 6;7 | E6: TID_ShowGetGroupData_3_title_CN_Main | F6: 好感度突破材料获取 | G6: TID_ShowGetGroupData_3_des_CN_Main | H6: 内政官好感度突破所需的材料，可通过<color=#fff6ab>旅店寻访</color>、<color=#fff6ab>市集兑换商店</color>、等途径获取。 | I6: 内政官好感度突破材料获取
A7: 4 | B7: 8;21 | E7: TID_ShowGetGroupData_4_title_CN_Main | F7: 获取更多内政官传记 | G7: TID_ShowGetGroupData_4_des_CN_Main | H7: 内政官进阶需要消耗<color=#fff6ab>内政官传记</color>，通过<color=#fff6ab>旅店寻访、完成探险事件</color>等途径可以获得更多内政官传记。 | I7: 内政官碎片获取
A8: 5 | B8: 10;11 | E8: TID_ShowGetGroupData_5_des_CN_Main | F8: 英雄天赋养成道具获取 | G8: TID_ShowGetGroupData_5_des_CN_Main | H8: 英雄天赋养成道具获取 | I8: 英雄天赋养成道具获取
A9: 6 | B9: 12;13;14 | E9: TID_ShowGetGroupData_6_des_CN_Main | F9: 英雄技能养成道具获取 | G9: TID_ShowGetGroupData_6_des_CN_Main | H9: 英雄技能养成道具获取 | I9: 英雄技能养成道具获取
A10: 7 | B10: 20;15 | E10: TID_ShowGetGroupData_7_title_CN_Main | F10: 提升村民上限 | G10: TID_ShowGetGroupData_7_des_CN_Main | H10: 提升居民房舍等级可增加村民数量上限，在城镇中心可以训练村民。
A11: 8 | B11: 10 | E11: TID_ShowGetGroupData_8_title_CN_Main | F11: 英雄碎片 | G11: TID_ShowGetGroupData_8_des_CN_Main | H11: 使用英雄碎片提升星级，解锁更高的技能等级上限。
A12: 9 | B12: 17;16 | E12: TID_ShowGetGroupData_9_title_CN_Main | F12: 提升内政官属性总和 | G12: TID_ShowGetGroupData_9_des_CN_Main | H12: 探险队升级需要上阵内政官属性总和达到相应数值要求，前往<color=#fff6ab>培养内政官</color>提升内政官属性，前往<color=#fff6ab>旅店寻访</color>获得更多史诗内政官。
A13: 10 | B13: 11;55 | E13: TID_ShowGetGroupData_10_title_CN_Main | F13: 发展方略技术点数获取 | G13: TID_ShowGetGroupData_10_des_CN_Main | H13: 发展方略技术改良所需的技术点数，可以通过在城外清剿<color=#fff6ab>普通/稀有</color>蛮族部队获得。
A14: 11 | B14: 11;55 | E14: TID_ShowGetGroupData_11_title_CN_Main | F14: 发展方略文化点数获取 | G14: TID_ShowGetGroupData_11_des_CN_Main | H14: 发展方略文化发展所需的文化点数，可以通过在城外清剿<color=#fff6ab>普通/稀有</color>蛮族部队获得。
A15: 12 | B15: 16;26 | E15: TID_ShowGetGroupData_12_title_CN_Main | F15: 获取更多博学值 | G15: TID_ShowGetGroupData_12_des_CN_Main | H15: 内政官升级需要消耗<color=#fff6ab>博学值</color>，通过<color=#fff6ab>旅店寻访、完成探险事件</color>等途径可以获得更多博学值。
A16: 13 | B16: 55 | E16: TID_ShowGetGroupData_13_title_CN_Main | F16: 知识卷轴获取 | G16: TID_ShowGetGroupData_13_des_CN_Main | H16: 知识卷轴用于升级学院科技，可以通过在城外<color=#fff6ab>清剿稀有/精英蛮族部队</color>获得或者通过<color=#fff6ab>商城活动</color>获得。
A17: 14 | B17: 96;66 | E17: TID_ShowGetGroupData_14_title_CN_Main | F17: 获取更多信物 | G17: TID_ShowGetGroupData_14_des_CN_Main | H17: 招募获得<color=#fff6ab>重复【英雄或技能】</color>时会转化成信物。<color=#4fad6d>【优良信物】</color>或<color=#5f88dc>【稀有信物】</color>可以用来【分解技能点】，<color=#be78d8>【史诗信物】</color>或<color=#f1791c>【传说信物】</color>可以用来【进阶英雄】或【激活英雄天赋】。
A18: 15 | B18: 25;55 | E18: TID_ShowGetGroupData_15_title_CN_Main | F18: 提升英雄等级 | G18: TID_ShowGetGroupData_15_des_GL_Main | H18: 当前部队出征上限过低，在城外攻打【普通/稀有】蛮族，可以<color=#fff6ab>升级英雄增加带兵量</color>，提高部队出征上限。 | I18: 任意1个军团总士兵数达到XXXX名-英雄升级前期指引
A19: 16 | B19: 47;48 | E19: TID_ShowGetGroupData_16_title_CN_Main | F19: 治疗伤兵或训练士兵 | G19: TID_ShowGetGroupData_16_des_CN_Main | H19: 当前拥有士兵数量不足，治疗房舍还存在伤兵，请<color=#fff6ab>治疗或训练更多士兵</color>补充到部队中。 | I19: 任意1个军团总士兵数达到XXXX名-士兵获取指引
A20: 17 | B20: 27 | E20: TID_ShowGetGroupData_17_title_CN_Main | F20: 繁荣度获取 | G20: TID_ShowGetGroupData_17_des_CN_Main | H20: 建造或升级内城建筑可获取繁荣度
A21: 18 | B21: 33;37 | E21: TID_ShowGetGroupData_18_title_CN_Main | F21: 提升木材产量 | G21: TID_ShowGetGroupData_18_des_GL_Main | H21: 通过<color=#fff6ab>升级伐木场建筑、研究经济系科技</color>等途径，可以提升木材资源产量。 | I21: 前期提升资源产量途径
A22: 19 | B22: 32;37 | E22: TID_ShowGetGroupData_19_title_CN_Main | F22: 提升食物产量 | G22: TID_ShowGetGroupData_19_des_GL_Main | H22: 通过<color=#fff6ab>升级磨坊建筑、研究经济系科技</color>等途径，可以提升食物资源产量。 | I22: 前期提升资源产量途径
A23: 20 | B23: 34;37 | E23: TID_ShowGetGroupData_20_title_CN_Main | F23: 提升石头产量 | G23: TID_ShowGetGroupData_20_des_GL_Main | H23: 通过<color=#fff6ab>升级石矿场建筑、研究经济系科技</color>等途径，可以提升石头资源产量。 | I23: 前期提升资源产量途径
A24: 21 | B24: 35;37 | E24: TID_ShowGetGroupData_21_title_CN_Main | F24: 提升黄金产量 | G24: TID_ShowGetGroupData_21_des_GL_Main | H24: 通过<color=#fff6ab>升级金矿场建筑、研究经济系科技</color>等途径，可以提升黄金资源产量。 | I24: 前期提升资源产量途径
A25: 22 | B25: 29;33; | E25: TID_ShowGetGroupData_22_title_CN_Main | F25: 获得更多木材 | G25: TID_ShowGetGroupData_22_des_GL_Main | H25: 在城外<color=#fff6ab>攻占木材资源点</color>后，您可派遣村民前往采集木材资源，采集将会实时获得资源；\n在城内<color=#fff6ab>升级伐木场</color>，可以提升每小时的木材资源产量； | I25: 木材资源不足
A26: 23 | B26: 28;32;52;25;55 | E26: TID_ShowGetGroupData_23_title_CN_Main | F26: 获得更多食物 | G26: TID_ShowGetGroupData_23_des_GL_Main | H26: 在城外<color=#fff6ab>攻占食物资源点</color>后，您可派遣村民前往采集食物资源，采集将会实时获得资源；\n在城内<color=#fff6ab>升级磨坊和建造农田</color>，可以提升每小时的木材资源产量； | I26: 食物资源不足
A27: 24 | B27: 30;34 | E27: TID_ShowGetGroupData_24_title_CN_Main | F27: 获得更多石头 | G27: TID_ShowGetGroupData_24_des_GL_Main | H27: 在城外<color=#fff6ab>攻占石头资源点</color>后，您可派遣村民前往采集石头资源，采集将会实时获得资源；\n在城内<color=#fff6ab>升级石矿场</color>，可以提升每小时的石头资源产量； | I27: 石头资源不足
A28: 25 | B28: 31;35 | E28: TID_ShowGetGroupData_25_title_CN_Main | F28: 获得更多黄金 | G28: TID_ShowGetGroupData_25_des_GL_Main | H28: 在城外<color=#fff6ab>攻占黄金资源点</color>后，您可派遣村民前往采集黄金资源，采集将会实时获得资源；\n在城内<color=#fff6ab>升级金矿场</color>，可以提升每小时的黄金资源产量； | I28: 黄金资源不足
A29: 26 | B29: 50;51 | E29: TID_ShowGetGroupData_26_title_CN_Main | F29: 其他铜钱产量提升途径 | G29: TID_ShowGetGroupData_26_des_GL_Main | H29: 通过<color=#fff6ab>激活君主天赋、研究经济系科技</color>等途径也可增加铜钱产量。 | I29: 征税界面其他铜钱产量获得途径
A30: 27 | B30: 46 | E30: TID_ShowGetGroupData_27_title_CN_Main | F30: 上阵更多英雄 | G30: TID_ShowGetGroupData_27_des_CN_Main | H30: 当前部队还<color=#fff6ab存在>空位置可上阵英雄</color>，请前往部队编组<color=#fff6ab>上阵更多英雄</color>。 | I30: 任意1个军团总士兵数达到XXXX名-英雄上阵指引
A31: 28 | B31: 25;55 | E31: TID_ShowGetGroupData_15_title_CN_Main | F31: 提升英雄等级 | G31: TID_ShowGetGroupData_15_des_GL_Main | H31: 当前部队出征上限过低，在城外攻打【普通/稀有】蛮族，可以<color=#fff6ab>升级英雄增加带兵量</color>，提高部队出征上限。 | I31: 任意1个军团总士兵数达到XXXX名-英雄升级后期指引
A32: 29 | B32: 48 | E32: TID_ShowGetGroupData_61_title_CN_Main | F32: 训练更多士兵 | G32: TID_ShowGetGroupData_29_des_CN_Main | H32: 当前拥有士兵数量不足，请前往兵营<color=#fff6ab>训练更多士兵</color>补充到部队。 | I32: 任意1个军团总士兵数达到XXXX名-士兵获取指引
A33: 30 | B33: 33;37;36 | E33: TID_ShowGetGroupData_18_title_CN_Main | F33: 提升木材产量 | G33: TID_ShowGetGroupData_30_des_GL_Main | H33: 通过<color=#fff6ab>升级伐木场建筑、研究经济系科技、激活君主天赋</color>等途径，可以提升木材资源产量。
A34: 31 | B34: 32;37;36 | E34: TID_ShowGetGroupData_19_title_CN_Main | F34: 提升食物产量 | G34: TID_ShowGetGroupData_31_des_GL_Main | H34: 通过<color=#fff6ab>升级磨坊建筑、研究经济系科技、激活君主天赋</color>等途径，可以提升食物资源产量。
A35: 32 | B35: 34;37;36 | E35: TID_ShowGetGroupData_20_title_CN_Main | F35: 提升石头产量 | G35: TID_ShowGetGroupData_32_des_GL_Main | H35: 通过<color=#fff6ab>升级石矿场建筑、研究经济系科技、激活君主天赋</color>等途径，可以提升石头资源产量。
A36: 33 | B36: 35;37;36 | E36: TID_ShowGetGroupData_21_title_CN_Main | F36: 提升黄金产量 | G36: TID_ShowGetGroupData_33_des_GL_Main | H36: 通过<color=#fff6ab>升级金矿场建筑、研究经济系科技、激活君主天赋</color>等途径，可以提升黄金资源产量。
A37: 34 | B37: 60 | E37: TID_ShowGetGroupData_34_title_CN_Main | F37: 提升屯兵上限 | G37: TID_ShowGetGroupData_34_des_CN_Main | H37: 通过<color=#fff6ab>升级校场</color>途径可以提升士兵屯兵上限。 | I37: 提升士兵屯兵上限
A38: 35 | B38: 31;35;36;37;38 | E38: TID_ShowGetGroupData_35_des_CN_Main | F38: 时代升级 | G38: TID_ShowGetGroupData_35_des_CN_Main | H38: 时代升级 | I38: 已废弃后面把ID利用起来
A39: 36 | B39: 56;131;58 | E39: TID_ShowGetGroupData_36_title_CN_Main | F39: 提升伤兵容量 | G39: TID_ShowGetGroupData_36_des_GL_Main | H39: 通过<color=#fff6ab>升级治疗房舍、研究战争系科技、激活君主天赋</color>等途径可以提升伤兵容量。 | I39: 治疗房舍提升伤兵容量
A40: 37 | B40: 63;62;109 | E40: TID_ShowGetGroupData_37_title_CN_Main | F40: 获取士兵训练加速 | G40: TID_ShowGetGroupData_37_des_CN_Main | H40: 通过<color=#fff6ab>战功商店兑换、活动中心参加活动、联盟宝库兑换</color>等途径可以获得士兵训练加速。 | I40: 获取更多士兵训练加速
...

Sheet 获取途径配置
A1: convert(ResShowGet.proto, table_ShowGetData,ShowGetData.pbin)
A2: id | B2: 描述标题 | C2: 描述标题 | D2: 描述文本 | E2: 描述文本 | F2: 界面跳转id | G2: 跳转关联文本 | H2: 跳转ID | I2: icon所属图集名 | J2: icon名称 | K2: 功能解锁 | N2: 备注（策划用）
A3: id | B3: title | D3: desc | F3: JumpToId | I3: atlasName | J3: spriteName | K3: unLockEnum | L3: bgIndex | M3: redKey
A4: 1 | B4: TID_ShowGetData_1_title_CN_Main | C4: 充值 | D4: TID_ShowGetData_1_desc_CN_Main | E4: 前往充值 | F4: 336 | H4: =IF(G4="","",VLOOKUP(G4,[1]界面跳转!$I:$J,2,FALSE)) | I4: icon_task | J4: icon_task_p3_05
A5: 2 | B5: TID_ShowGetData_2_title_CN_Main | C5: 贵族积分 | D5: TID_ShowGetData_2_desc_CN_Main | E5: 前往使用贵族积分道具 | F5: 338 | H5: =IF(G5="","",VLOOKUP(G5,[1]界面跳转!$I:$J,2,FALSE)) | I5: icon_task | J5: icon_task_p3_05
A6: 3 | B6: TID_ShowGetData_3_title_CN_Main | C6: 签到 | D6: TID_ShowGetData_3_desc_CN_Main | E6: 前往签到获取 | F6: 1008 | H6: =IF(G6="","",VLOOKUP(G6,[1]界面跳转!$I:$J,2,FALSE)) | I6: icon_task | J6: icon_task_p3_05
A7: 4 | B7: TID_ShowGetData_16_title_CN_Main | C7: 内政官寻访 | D7: TID_ShowGetData_16_desc_CN_Main | E7: 前往旅店进行<color=#fff6ab>【内政官寻访】</color> | F7: 7074 | H7: =IF(G7="","",VLOOKUP(G7,[1]界面跳转!$I:$J,2,FALSE)) | I7: icon_task | J7: icon_task_p3_05 | K7: 内城酒馆建筑
A8: 5 | B8: TID_ShowGetData_5_title_CN_Main | C8: 市集兑换 | D8: TID_ShowGetData_5_desc_CN_Main | E8: 在市集建筑查看<color=#fff6ab>【兑换商店】</color> | F8: 1011 | H8: =IF(G8="","",VLOOKUP(G8,[1]界面跳转!$I:$J,2,FALSE)) | I8: icon_task | J8: icon_task_p3_05
A9: 6 | B9: TID_ShowGetData_6_title_CN_Main | C9: 内政官寻访 | D9: TID_ShowGetData_6_desc_CN_Main | E9: 在旅店建筑进行<color=#fff6ab>【内政官寻访】</color> | F9: 7074 | H9: =IF(G9="","",VLOOKUP(G9,[1]界面跳转!$I:$J,2,FALSE)) | I9: icon_task | J9: icon_task_p3_05 | K9: 内城酒馆建筑
A10: 7 | B10: TID_ShowGetData_5_title_CN_Main | C10: 市集兑换 | D10: TID_ShowGetData_5_desc_CN_Main | E10: 在市集建筑查看<color=#fff6ab>【兑换商店】</color> | F10: 1011 | H10: =IF(G10="","",VLOOKUP(G10,[1]界面跳转!$I:$J,2,FALSE)) | I10: icon_task | J10: icon_task_p3_05
A11: 8 | B11: TID_ShowGetData_6_title_CN_Main | C11: 内政官寻访 | D11: TID_ShowGetData_6_desc_CN_Main | E11: 在旅店建筑进行<color=#fff6ab>【内政官寻访】</color> | F11: =H11 -> 7074 | G11: 跳转到旅店【内政官寻访】菜单按钮 | H11: 7074 | I11: icon_task | J11: icon_task_p3_05 | K11: 内城酒馆建筑
A12: 9 | B12: TID_ShowGetData_5_title_CN_Main | C12: 市集兑换 | D12: TID_ShowGetData_5_desc_CN_Main | E12: 在市集建筑查看<color=#fff6ab>【兑换商店】</color> | F12: =H12 -> 7060 | G12: 跳转到市集【资源兑换】菜单按钮 | H12: =IF(G12="","",VLOOKUP(G12,[1]界面跳转!$I:$J,2,FALSE)) -> 7060 | I12: icon_task | J12: icon_task_p3_05
A13: 10 | B13: TID_ShowGetData_10_title_CN_Main | C13: 点将台 | D13: TID_ShowGetData_10_desc_CN_Main | E13: 前往点将台召唤英雄 | F13: =H13 | H13: =IF(G13="","",VLOOKUP(G13,[1]界面跳转!$I:$J,2,FALSE)) | I13: icon_task | J13: icon_task_p3_05
A14: 11 | B14: TID_ShowGetData_104_title_CN_Main | C14: 普通蛮族 | D14: TID_ShowGetData_104_desc_CN_Main | E14: 城外清剿<color=#fff6ab>普通</color>【蛮族部队】 | F14: =H14 -> 7569 | G14: 跳转到城外【可打下一等级】野怪进攻按钮 | H14: =IF(G14="","",VLOOKUP(G14,[1]界面跳转!$I:$J,2,FALSE)) -> 7569 | I14: icon_task | J14: icon_task_p3_05 | K14: 主界面功能功能【出城按钮】
A15: 12 | B15: TID_ShowGetData_10_title_CN_Main | C15: 点将台 | D15: TID_ShowGetData_10_desc_CN_Main | E15: 前往点将台召唤英雄 | F15: =H15 | H15: =IF(G15="","",VLOOKUP(G15,[1]界面跳转!$I:$J,2,FALSE)) | I15: icon_task | J15: icon_task_p3_05
A16: 13 | B16: TID_ShowGetData_104_title_CN_Main | C16: 普通蛮族 | D16: TID_ShowGetData_104_desc_CN_Main | E16: 城外清剿<color=#fff6ab>普通</color>【蛮族部队】 | F16: =H16 -> 7254 | G16: 跳转到城外【可打最高级】野怪进攻按钮 | H16: =IF(G16="","",VLOOKUP(G16,[1]界面跳转!$I:$J,2,FALSE)) -> 7254 | I16: icon_task | J16: icon_task_p3_05 | K16: 主界面功能功能【出城按钮】
A17: 14 | B17: TID_ShowGetData_14_title_CN_Main | C17: 商城 | D17: TID_ShowGetData_14_desc_CN_Main | E17: 前往商城购买 | F17: =H17 | H17: =IF(G17="","",VLOOKUP(G17,[1]界面跳转!$I:$J,2,FALSE)) | I17: icon_task | J17: icon_task_p3_05
A18: 15 | B18: TID_ShowGetData_15_title_CN_Main | C18: 居民房舍 | D18: TID_ShowGetData_15_desc_CN_Main | E18: 升级居民房舍增加人口上限 | F18: =H18 -> 6202 | G18: 跳转到【居民房舍】直接打开升级界面 | H18: =IF(G18="","",VLOOKUP(G18,[1]界面跳转!$I:$J,2,FALSE)) -> 6202 | I18: icon_task | J18: icon_task_p3_05
A19: 16 | B19: TID_ShowGetData_16_title_CN_Main | C19: 内政官寻访 | D19: TID_ShowGetData_16_desc_CN_Main | E19: 前往旅店进行<color=#fff6ab>【内政官寻访】</color> | F19: =H19 -> 5041 | G19: 直接跳转-旅店-寻访界面 | H19: =IF(G19="","",VLOOKUP(G19,[1]界面跳转!$I:$J,2,FALSE)) -> 5041 | I19: icon_task | J19: icon_task_p3_05 | K19: 内城酒馆建筑
A20: 17 | B20: TID_ShowGetData_17_title_CN_Main | C20: 内政官培养 | D20: TID_ShowGetData_17_desc_CN_Main | E20: 前往<color=#fff6ab>【内政官培养】</color> | F20: 5053 | G20: 直接跳转-旅店-名人列表界面 | H20: =IF(G20="","",VLOOKUP(G20,[1]界面跳转!$I:$J,2,FALSE)) -> 5042 | I20: icon_task | J20: icon_task_p3_05 | K20: 主界面核心系统【内政官】
A21: 18 | B21: TID_ShowGetData_14_title_CN_Main | C21: 商城 | D21: TID_ShowGetData_14_desc_CN_Main | E21: 前往商城购买 | F21: =H21 | H21: =IF(G21="","",VLOOKUP(G21,[1]界面跳转!$I:$J,2,FALSE)) | I21: icon_task | J21: icon_task_p3_05
A22: 19 | B22: TID_ShowGetData_19_title_CN_Main | C22: 蛮族部队 | D22: TID_ShowGetData_19_desc_CN_Main | E22: 打败蛮族部队有概率获得 | F22: =H22 | H22: =IF(G22="","",VLOOKUP(G22,[1]界面跳转!$I:$J,2,FALSE)) | I22: icon_task | J22: icon_task_p3_05
A23: 20 | B23: TID_ShowGetData_20_title_CN_Main | C23: 训练村民 | D23: TID_ShowGetData_20_desc_CN_Main | E23: 前往城镇中心训练村民 | F23: =H23 -> 7002 | G23: 跳转到城镇中心【训练村民】菜单按钮 | H23: =IF(G23="","",VLOOKUP(G23,[1]界面跳转!$I:$J,2,FALSE)) -> 7002 | I23: icon_task | J23: icon_task_p3_05
A24: 21 | B24: TID_ShowGetData_21_title_CN_Main | C24: 内政官探险 | D24: TID_ShowGetData_21_desc_CN_Main | E24: 前往探险玩法完成<color=#fff6ab>【探险事件】</color> | F24: =H24 -> 3018 | G24: 直接跳转-冒险 | H24: =IF(G24="","",VLOOKUP(G24,[1]界面跳转!$I:$J,2,FALSE)) -> 3018 | I24: icon_task | J24: icon_task_p3_05 | K24: 主界面核心系统【探险】
A25: 22 | B25: TID_ShowGetData_22_title_CN_Main | C25: 点将台 | D25: TID_ShowGetData_22_desc_CN_Main | E25: 前往点将台招募英雄 | F25: =H25 | H25: =IF(G25="","",VLOOKUP(G25,[1]界面跳转!$I:$J,2,FALSE)) | I25: icon_task | J25: icon_task_p3_05
A26: 23 | B26: TID_ShowGetData_104_title_CN_Main | C26: 普通蛮族 | D26: TID_ShowGetData_104_desc_CN_Main | E26: 城外清剿<color=#fff6ab>普通</color>【蛮族部队】 | F26: =H26 -> 7254 | G26: 跳转到城外【可打最高级】野怪进攻按钮 | H26: =IF(G26="","",VLOOKUP(G26,[1]界面跳转!$I:$J,2,FALSE)) -> 7254 | I26: icon_task | J26: icon_task_p3_05 | K26: 主界面功能功能【出城按钮】
A27: 24 | B27: TID_ShowGetData_24_title_CN_Main | C27: 资源点 | D27: TID_ShowGetData_24_desc_CN_Main | E27: 城外攻占更多<color=#fff6ab>【资源点】</color> | F27: =H27 -> 7253 | G27: 跳转到当前可攻打最高级【任意】资源点攻占按钮 | H27: =IF(G27="","",VLOOKUP(G27,[1]界面跳转!$I:$J,2,FALSE)) -> 7253 | I27: icon_task | J27: icon_task_p3_05 | K27: 主界面功能功能【出城按钮】
A28: 25 | B28: TID_ShowGetData_104_title_CN_Main | C28: 普通蛮族 | D28: TID_ShowGetData_104_desc_CN_Main | E28: 城外清剿<color=#fff6ab>普通</color>【蛮族部队】 | F28: =H28 -> 7254 | G28: 跳转到城外【可打最高级】野怪进攻按钮 | H28: =IF(G28="","",VLOOKUP(G28,[1]界面跳转!$I:$J,2,FALSE)) -> 7254 | I28: icon_task | J28: icon_task_p3_05 | K28: 主界面功能功能【出城按钮】
A29: 26 | B29: TID_ShowGetData_21_title_CN_Main | C29: 内政官探险 | D29: TID_ShowGetData_21_desc_CN_Main | E29: 前往探险玩法完成<color=#fff6ab>【探险事件】</color> | F29: =H29 -> 3018 | G29: 直接跳转-冒险 | H29: =IF(G29="","",VLOOKUP(G29,[1]界面跳转!$I:$J,2,FALSE)) -> 3018 | I29: icon_task | J29: icon_task_p3_05 | K29: 主界面核心系统【探险】
A30: 27 | B30: TID_ShowGetData_27_title_CN_Main | C30: 繁荣度 | D30: TID_ShowGetData_27_desc_CN_Main | E30: 前往打开<color=#fff6ab>【繁荣度】</color>界面 | F30: =H30 -> 7120 | G30: 跳转到主界面【繁荣度】入口 | H30: =IF(G30="","",VLOOKUP(G30,[1]界面跳转!$I:$J,2,FALSE)) -> 7120 | I30: icon_task | J30: icon_task_p3_05
A31: 28 | B31: TID_ShowGetData_28_title_CN_Main | C31: 食物资源点 | D31: TID_ShowGetData_28_desc_CN_Main | E31: 城外采集<color=#fff6ab>【食物资源点】</color> | F31: =H31 -> 7250 | G31: 跳转到当前可攻打最高级【食物】资源点攻占按钮 | H31: =IF(G31="","",VLOOKUP(G31,[1]界面跳转!$I:$J,2,FALSE)) -> 7250 | I31: icon_task | J31: icon_task_p3_05 | K31: 主界面功能功能【出城按钮】
A32: 29 | B32: TID_ShowGetData_29_title_CN_Main | C32: 木材资源点 | D32: TID_ShowGetData_29_desc_CN_Main | E32: 城外采集<color=#fff6ab>【木材资源点】</color> | F32: =H32 -> 7249 | G32: 跳转到当前可攻打最高级【木材】资源点攻占按钮 | H32: =IF(G32="","",VLOOKUP(G32,[1]界面跳转!$I:$J,2,FALSE)) -> 7249 | I32: icon_task | J32: icon_task_p3_05 | K32: 主界面功能功能【出城按钮】
A33: 30 | B33: TID_ShowGetData_30_title_CN_Main | C33: 石头资源点 | D33: TID_ShowGetData_30_desc_CN_Main | E33: 城外采集<color=#fff6ab>【石头资源点】</color> | F33: =H33 -> 7251 | G33: 跳转到当前可攻打最高级【石材】资源点攻占按钮 | H33: =IF(G33="","",VLOOKUP(G33,[1]界面跳转!$I:$J,2,FALSE)) -> 7251 | I33: icon_task | J33: icon_task_p3_05 | K33: 主界面功能功能【出城按钮】
A34: 31 | B34: TID_ShowGetData_31_title_CN_Main | C34: 黄金资源点 | D34: TID_ShowGetData_31_desc_CN_Main | E34: 城外采集<color=#fff6ab>【黄金资源点】</color> | F34: =H34 -> 7252 | G34: 跳转到当前可攻打最高级【黄金】资源点攻占按钮 | H34: =IF(G34="","",VLOOKUP(G34,[1]界面跳转!$I:$J,2,FALSE)) -> 7252 | I34: icon_task | J34: icon_task_p3_05 | K34: 主界面功能功能【出城按钮】
A35: 32 | B35: TID_ShowGetData_32_title_CN_Main | C35: 磨坊 | D35: TID_ShowGetData_32_desc_CN_Main | E35: 城内升级资源建筑<color=#fff6ab>【磨坊】</color> | F35: =H35 -> 6203 | G35: 跳转到【磨坊】直接打开升级界面 | H35: =IF(G35="","",VLOOKUP(G35,[1]界面跳转!$I:$J,2,FALSE)) -> 6203 | I35: icon_task | J35: icon_task_p3_05
A36: 33 | B36: TID_ShowGetData_33_title_CN_Main | C36: 伐木场 | D36: TID_ShowGetData_33_desc_CN_Main | E36: 城内升级资源建筑<color=#fff6ab>【伐木场】</color> | F36: =H36 -> 6204 | G36: 跳转到【伐木场】直接打开升级界面 | H36: =IF(G36="","",VLOOKUP(G36,[1]界面跳转!$I:$J,2,FALSE)) -> 6204 | I36: icon_task | J36: icon_task_p3_05
A37: 34 | B37: TID_ShowGetData_34_title_CN_Main | C37: 石矿场 | D37: TID_ShowGetData_34_desc_CN_Main | E37: 城内升级资源建筑<color=#fff6ab>【石矿场】</color> | F37: =H37 -> 6205 | G37: 跳转到【石矿场】直接打开升级界面 | H37: =IF(G37="","",VLOOKUP(G37,[1]界面跳转!$I:$J,2,FALSE)) -> 6205 | I37: icon_task | J37: icon_task_p3_05
A38: 35 | B38: TID_ShowGetData_35_title_CN_Main | C38: 金矿场 | D38: TID_ShowGetData_35_desc_CN_Main | E38: 城内升级资源建筑<color=#fff6ab>【金矿场】</color> | F38: =H38 -> 6234 | G38: 跳转到【金矿场】直接打开升级界面 | H38: =IF(G38="","",VLOOKUP(G38,[1]界面跳转!$I:$J,2,FALSE)) -> 6234 | I38: icon_task | J38: icon_task_p3_05
A39: 36 | B39: TID_ShowGetData_36_title_GL_Main | C39: 君主天赋 | D39: TID_ShowGetData_36_desc_GL_Main | E39: 前往激活相关<color=#fff6ab>【君主天赋】</color> | F39: =H39 -> 7113 | G39: 跳转到主界面【发展战略】按钮 | H39: =IF(G39="","",VLOOKUP(G39,[1]界面跳转!$I:$J,2,FALSE)) -> 7113 | I39: icon_task | J39: icon_task_p3_05 | K39: 主界面核心系统【发展方略】
A40: 37 | B40: TID_ShowGetData_37_title_GL_Main | C40: 经济系科技 | D40: TID_ShowGetData_37_desc_GL_Main | E40: 前往城堡研究<color=#fff6ab>【经济系科技】</color> | F40: =H40 -> 7030 | G40: 跳转到学院【研究科技】菜单按钮 | H40: =IF(G40="","",VLOOKUP(G40,[1]界面跳转!$I:$J,2,FALSE)) -> 7030 | I40: icon_task | J40: icon_task_p3_05 | K40: 内城学院建筑
...

Sheet 获取方式
A1: convert(ResShowGet.proto, table_ItemFetchPortal,ItemFetchPortal.pbin)
A2: id | B2: 图集名 | C2: SpriteName | D2: 途径名称 | E2: 途径描述 | F2: 获取途径
A3: id | B3: atlasName | C3: spriteName | D3: portalName | E3: portalDesc | F3: portalId
A4: 1 | B4: icon_entityselect | C4: icon_caiji | F4: 野外采集
A5: 2 | B5: icon_entityselect | C5: icon_rare_tradinghall_icon | F5: 交易所
A6: 3 | B6: icon_entityselect | C6: icon_maoyi | F6: 名城贸易
A7: 4 | B7: icon_entityselect | C7: icon_cangku | F7: 稀有资源仓库

Sheet 获取类别
A1: convert(ResShowGet.proto, table_ItemFetchingGuide,ItemFetchingGuide.pbin)
A2: id | B2: 客户端枚举 | C2: 获取方式 | D2: 备注 | E2: 标题 | F2: 描述
A3: id | C3: FetchPortal[;] | E3: TitleKey | F3: SubtitleKey
A4: 1 | B4: FGT_Type_SpecialResource | C4: 1;3 | D4: 珍品资源仓库
A5: 2 | B5: FGT_Type_MingChengCoin | C5: 4;3 | D5: 大流克币商店

Sheet 道具获取途径
A1: convert(ResShowGet.proto,table_ItemGetGroupData,ItemGetGroupData.pbin)
A2: itemId | B2: 获取途径Id
A3: itemId | B3: getGroupId

Sheet 资源获取途径
A1: convert(ResShowGet.proto,table_ResourceGetGroupData,ResourceGetGroupData.pbin)
A2: resourceId | B2: 获取途径Id
A3: resourceId | B3: getGroupId
A4: 1 | B4: 30
A5: 2 | B5: 31
A6: 3 | B6: 32
A7: 4 | B7: 33
A8: 7 | B8: 41

Sheet 货币获取途径
A1: convert(ResShowGet.proto,table_CoinGetGroupData,CoinGetGroupData.pbin)
A2: coinId | B2: 获取途径Id
A3: coinId | B3: getGroupId

Sheet #TID_base_up
A1: 旧Key | B1: 新Key | C1: 文本
A2: ShowGetGroupData_1_des_CN_Main | B2: TID_ShowGetGroupData_1_des_CN_Main | C2: 获取贵族经验
A3: ShowGetGroupData_2_title_CN_Main | B3: TID_ShowGetGroupData_2_title_CN_Main | C3: 好感度礼物获取
A4: ShowGetGroupData_2_des_CN_Main | B4: TID_ShowGetGroupData_2_des_CN_Main | C4: 内政官好感度提升所需的礼物，可通过<color=#fff6ab>旅店寻访</color>、<color=#fff6ab>市集兑换商店</color>、等途径获取。
A5: ShowGetGroupData_3_title_CN_Main | B5: TID_ShowGetGroupData_3_title_CN_Main | C5: 好感度突破材料获取
A6: ShowGetGroupData_3_des_CN_Main | B6: TID_ShowGetGroupData_3_des_CN_Main | C6: 内政官好感度突破所需的材料，可通过<color=#fff6ab>旅店寻访</color>、<color=#fff6ab>市集兑换商店</color>、等途径获取。
A7: ShowGetGroupData_4_title_CN_Main | B7: TID_ShowGetGroupData_4_title_CN_Main | C7: 获取更多内政官传记
A8: ShowGetGroupData_4_des_CN_Main | B8: TID_ShowGetGroupData_4_des_CN_Main | C8: 内政官进阶需要消耗<color=#fff6ab>内政官传记</color>，通过<color=#fff6ab>旅店寻访、完成探险事件</color>等途径可以获得更多内政官传记。
A9: ShowGetGroupData_5_des_CN_Main | B9: TID_ShowGetGroupData_5_des_CN_Main | C9: 英雄天赋养成道具获取
A10: ShowGetGroupData_6_des_CN_Main | B10: TID_ShowGetGroupData_6_des_CN_Main | C10: 英雄技能养成道具获取
A11: ShowGetGroupData_7_title_CN_Main | B11: TID_ShowGetGroupData_7_title_CN_Main | C11: 提升村民上限
A12: ShowGetGroupData_7_des_CN_Main | B12: TID_ShowGetGroupData_7_des_CN_Main | C12: 提升居民房舍等级可增加村民数量上限，在城镇中心可以训练村民。
... A333: ShowGetData_132_title_GL_Main | B333: TID_ShowGetData_132_title_GL_Main | C333: 前往完成更多<color=#fff6ab>【主线任务】</color>
