Workbook

Sheet 奖励配置表
A1: convert(ResReward.proto, table_RewardConfData, RewardConfData_10.pbin) | F1: 相对随机配置
A2: 奖励ID | B2: 策划描述 | C2: 道具id | D2: 道具名称 | E2: 道具数量 | F2: 相对权重最小个数 | G2: 相对权重最大个数 | H2: 数量权重 | I2: 相对权重（整数） | J2: 绝对概率[0,1] | K2: 过期时间 | L2: 自定义顺序 | M2: 自选宝箱（可选数量）
A3: id | C3: item.id | E3: item.num | F3: minNum | G3: maxNum | H3: numWeight[;] | I3: item.relativeWeight | J3: item.absoluteProbability | K3: item.expire | L3: customizedOrder | M3: chooseNum
A4: 1800001 | B4: 寻访第1次抽奖特殊礼包 | C4: 14304 | D4: =VLOOKUP(C4,[1]道具配置表!$A:$D,4,FALSE) -> 沐南风 | E4: 10 | F4: 1 | G4: 1 | I4: 10000 | L4: 1
A5: 1800002 | B5: 寻访正常掉落包 | C5: 14101 | D5: =VLOOKUP(C5,[1]道具配置表!$A:$D,4,FALSE) -> 陆芊岚 | E5: 1 | F5: 1 | G5: 1 | I5: 50 | L5: 1
C6: 14105 | D6: =VLOOKUP(C6,[1]道具配置表!$A:$D,4,FALSE) -> 顾盼儿 | E6: 1 | I6: 50 | L6: 2
C7: 14106 | D7: =VLOOKUP(C7,[1]道具配置表!$A:$D,4,FALSE) -> 穆离 | E7: 1 | I7: 50 | L7: 3
C8: 14107 | D8: =VLOOKUP(C8,[1]道具配置表!$A:$D,4,FALSE) -> 伊丽莎白 | E8: 1 | I8: 50 | L8: 4
C9: 14108 | D9: =VLOOKUP(C9,[1]道具配置表!$A:$D,4,FALSE) -> 娜娜丽 | E9: 1 | I9: 1200 | L9: 5
C10: 14109 | D10: =VLOOKUP(C10,[1]道具配置表!$A:$D,4,FALSE) -> 埃托雷 | E10: 1 | I10: 166 | L10: 6
C11: 14201 | D11: =VLOOKUP(C11,[1]道具配置表!$A:$D,4,FALSE) -> 维托里奥 | E11: 1 | I11: 50 | L11: 7
C12: 14202 | D12: =VLOOKUP(C12,[1]道具配置表!$A:$D,4,FALSE) -> 苏安 | E12: 1 | I12: 166 | L12: 8
C13: 14203 | D13: =VLOOKUP(C13,[1]道具配置表!$A:$D,4,FALSE) -> 范文定 | E13: 1 | I13: 10 | L13: 9
C14: 14204 | D14: =VLOOKUP(C14,[1]道具配置表!$A:$D,4,FALSE) -> 亚历山德罗 | E14: 1 | I14: 10 | L14: 10
C15: 14206 | D15: =VLOOKUP(C15,[1]道具配置表!$A:$D,4,FALSE) -> 杜若 | E15: 1 | I15: 10 | L15: 11
C16: 14207 | D16: =VLOOKUP(C16,[1]道具配置表!$A:$D,4,FALSE) -> 艾洛缇丝 | E16: 1 | I16: 1200 | L16: 12
C17: 14301 | D17: =VLOOKUP(C17,[1]道具配置表!$A:$D,4,FALSE) -> 梅芙 | E17: 1 | I17: 1200 | L17: 13
... C124: 17200 | D124: =VLOOKUP(C124,[1]道具配置表!$A:$D,4,FALSE) -> 名人博学值+100 | E124: 10 | I124: 500 | L124: 120
A125: 1800113 | B125: 寻访预览奖励包 | C125: 14107 | D125: =VLOOKUP(C125,[1]道具配置表!$A:$D,4,FALSE) -> 伊丽莎白 | E125: 1 | F125: 1 | G125: 1 | I125: 10000 | L125: 16
A126: 1800114 | B126: 寻访预览奖励包 | C126: 14107 | D126: =VLOOKUP(C126,[1]道具配置表!$A:$D,4,FALSE) -> 伊丽莎白 | E126: 5 | F126: 1 | G126: 1 | I126: 10000 | L126: 17
A127: 1800115 | B127: 寻访预览奖励包 | C127: 14107 | D127: =VLOOKUP(C127,[1]道具配置表!$A:$D,4,FALSE) -> 伊丽莎白 | E127: 10 | F127: 1 | G127: 1 | I127: 10000 | L127: 18
A128: 1800116 | B128: 寻访预览奖励包 | C128: 14107 | D128: =VLOOKUP(C128,[1]道具配置表!$A:$D,4,FALSE) -> 伊丽莎白 | E128: 20 | F128: 1 | G128: 1 | I128: 10000 | L128: 19
A131: 1811001 | B131: 征程金币0.99 | C131: 64001 | D131: 征程金币 | E131: 200 | F131: 5 | G131: 5 | I131: 10000 | L131: TRUE
C132: 7228 | D132: 经验书*10000 | E132: 5 | I132: 10000 | L132: TRUE
C133: 2065 | D133: 技能点*500 | E133: 1 | I133: 10000 | L133: TRUE
C134: 6999 | D134: 帝国币 | E134: 500 | I134: 10000 | L134: TRUE
C135: 49603 | D135: vip经验50 | E135: 5 | I135: 10000 | L135: TRUE
A136: 1811002 | B136: 征程金币4.99 | C136: 64001 | D136: 征程金币 | E136: 500 | F136: 5 | G136: 5 | I136: 10000 | L136: TRUE
C137: 7228 | D137: 经验书*10000 | E137: 5 | I137: 10000 | L137: TRUE
C138: 2065 | D138: 技能点*500 | E138: 1 | I138: 10000 | L138: TRUE
C139: 6999 | D139: 帝国币 | E139: 2500 | I139: 10000 | L139: TRUE
C140: 49603 | D140: vip经验50 | E140: 25 | I140: 10000 | L140: TRUE
A141: 1811003 | B141: 征程金币9.99 | C141: 64001 | D141: 征程金币 | E141: 800 | F141: 5 | G141: 5 | I141: 10000 | L141: TRUE
C142: 7228 | D142: 经验书*10000 | E142: 5 | I142: 10000 | L142: TRUE
C143: 2065 | D143: 技能点*500 | E143: 1 | I143: 10000 | L143: TRUE
C144: 6999 | D144: 帝国币 | E144: 5000 | I144: 10000 | L144: TRUE
C145: 49603 | D145: vip经验50 | E145: 50 | I145: 10000 | L145: TRUE
A146: 1811004 | B146: 征程金币19.99 | C146: 64001 | D146: 征程金币 | E146: 1000 | F146: 5 | G146: 5 | I146: 10000 | L146: TRUE
C147: 7228 | D147: 经验书*10000 | E147: 10 | I147: 10000 | L147: TRUE
C148: 2065 | D148: 技能点*500 | E148: 2 | I148: 10000 | L148: TRUE
...

Sheet #索引
A1: ID | B1: 奖励名称 | C1: 奖励数量 | D1: 知名度 | E1: 奖励关联 | G1: 权重 | M1: 奖励名称 | N1: 索引用 | O1: 奖励数量 | P1: 奖励关联 | Q1: 总权值 | R1: 名人数量 | S1: 单一名人权值
A2: 14101 | B2: =VLOOKUP(A2,[1]道具配置表!$A:$D,4,FALSE) -> 陆芊岚 | C2: 1 | D2: =VLOOKUP(B2,$W:$X,2,FALSE) -> 橙 | E2: =CONCATENATE(B2,"x",C2) -> 陆芊岚x1 | F2: =D2&"色道具碎片"&"X"&C2 -> 橙色道具碎片X1 | G2: =VLOOKUP(F2,$P$2:$S$21,4,FALSE) -> 50 | L2: 蓝 | M2: 蓝色名人碎片 | N2: 蓝色道具碎片 | O2: 1 | P2: =CONCATENATE($N2,"x",$O2) -> 蓝色道具碎片x1 | Q2: 6000 | R2: =COUNTIF(X:X,L2) -> 5 | S2: =INT(Q2/R2) -> 1200 | V2: 14101 | W2: =VLOOKUP(V2,[1]道具配置表!$A:$D,4,FALSE) -> 陆芊岚 | X2: 橙 | Y2: 14101 | Z2: S
A3: 14105 | B3: =VLOOKUP(A3,[1]道具配置表!$A:$D,4,FALSE) -> 顾盼儿 | C3: 1 | D3: =VLOOKUP(B3,$W:$X,2,FALSE) -> 橙 | E3: =CONCATENATE(B3,"x",C3) -> 顾盼儿x1 | F3: =D3&"色道具碎片"&"X"&C3 -> 橙色道具碎片X1 | G3: =VLOOKUP(F3,$P$2:$S$21,4,FALSE) -> 50 | L3: 蓝 | M3: 蓝色名人碎片 | N3: 蓝色道具碎片 | O3: 2 | P3: =CONCATENATE($N3,"x",$O3) -> 蓝色道具碎片x2 | Q3: 3000 | R3: =COUNTIF(X:X,L3) -> 5 | S3: =INT(Q3/R3) -> 600 | V3: 14105 | W3: =VLOOKUP(V3,[1]道具配置表!$A:$D,4,FALSE) -> 顾盼儿 | X3: 橙 | Y3: 14105 | Z3: S
A4: 14106 | B4: =VLOOKUP(A4,[1]道具配置表!$A:$D,4,FALSE) -> 穆离 | C4: 1 | D4: =VLOOKUP(B4,$W:$X,2,FALSE) -> 橙 | E4: =CONCATENATE(B4,"x",C4) -> 穆离x1 | F4: =D4&"色道具碎片"&"X"&C4 -> 橙色道具碎片X1 | G4: =VLOOKUP(F4,$P$2:$S$21,4,FALSE) -> 50 | L4: 蓝 | M4: 蓝色名人碎片 | N4: 蓝色道具碎片 | O4: 4 | P4: =CONCATENATE($N4,"x",$O4) -> 蓝色道具碎片x4 | Q4: 1500 | R4: =COUNTIF(X:X,L4) -> 5 | S4: =INT(Q4/R4) -> 300 | V4: 14106 | W4: =VLOOKUP(V4,[1]道具配置表!$A:$D,4,FALSE) -> 穆离 | X4: 橙 | Y4: 14106 | Z4: S
A5: 14107 | B5: =VLOOKUP(A5,[1]道具配置表!$A:$D,4,FALSE) -> 伊丽莎白 | C5: 1 | D5: =VLOOKUP(B5,$W:$X,2,FALSE) -> 橙 | E5: =CONCATENATE(B5,"x",C5) -> 伊丽莎白x1 | F5: =D5&"色道具碎片"&"X"&C5 -> 橙色道具碎片X1 | G5: =VLOOKUP(F5,$P$2:$S$21,4,FALSE) -> 50 | L5: 蓝 | M5: 蓝色名人碎片 | N5: 蓝色道具碎片 | O5: 10 | P5: =CONCATENATE($N5,"x",$O5) -> 蓝色道具碎片x10 | Q5: 750 | R5: =COUNTIF(X:X,L5) -> 5 | S5: =INT(Q5/R5) -> 150 | V5: 14107 | W5: =VLOOKUP(V5,[1]道具配置表!$A:$D,4,FALSE) -> 伊丽莎白 | X5: 橙 | Y5: 14107 | Z5: S
A6: 14108 | B6: =VLOOKUP(A6,[1]道具配置表!$A:$D,4,FALSE) -> 娜娜丽 | C6: 1 | D6: =VLOOKUP(B6,$W:$X,2,FALSE) -> 蓝 | E6: =CONCATENATE(B6,"x",C6) -> 娜娜丽x1 | F6: =D6&"色道具碎片"&"X"&C6 -> 蓝色道具碎片X1 | G6: =VLOOKUP(F6,$P$2:$S$21,4,FALSE) -> 1200 | L6: 紫 | M6: 紫色名人碎片 | N6: 紫色道具碎片 | O6: 1 | P6: =CONCATENATE($N6,"x",$O6) -> 紫色道具碎片x1 | Q6: 2000 | R6: =COUNTIF(X:X,L6) -> 12 | S6: =INT(Q6/R6) -> 166 | V6: 14108 | W6: =VLOOKUP(V6,[1]道具配置表!$A:$D,4,FALSE) -> 娜娜丽 | X6: 蓝 | Y6: 14108 | Z6: B
A7: 14109 | B7: =VLOOKUP(A7,[1]道具配置表!$A:$D,4,FALSE) -> 埃托雷 | C7: 1 | D7: =VLOOKUP(B7,$W:$X,2,FALSE) -> 紫 | E7: =CONCATENATE(B7,"x",C7) -> 埃托雷x1 | F7: =D7&"色道具碎片"&"X"&C7 -> 紫色道具碎片X1 | G7: =VLOOKUP(F7,$P$2:$S$21,4,FALSE) -> 166 | L7: 紫 | M7: 紫色名人碎片 | N7: 紫色道具碎片 | O7: 2 | P7: =CONCATENATE($N7,"x",$O7) -> 紫色道具碎片x2 | Q7: 1000 | R7: =COUNTIF(X:X,L7) -> 12 | S7: =INT(Q7/R7) -> 83 | V7: 14109 | W7: =VLOOKUP(V7,[1]道具配置表!$A:$D,4,FALSE) -> 埃托雷 | X7: 紫 | Y7: 14109 | Z7: A
A8: 14201 | B8: =VLOOKUP(A8,[1]道具配置表!$A:$D,4,FALSE) -> 维托里奥 | C8: 1 | D8: =VLOOKUP(B8,$W:$X,2,FALSE) -> 橙 | E8: =CONCATENATE(B8,"x",C8) -> 维托里奥x1 | F8: =D8&"色道具碎片"&"X"&C8 -> 橙色道具碎片X1 | G8: =VLOOKUP(F8,$P$2:$S$21,4,FALSE) -> 50 | L8: 紫 | M8: 紫色名人碎片 | N8: 紫色道具碎片 | O8: 4 | P8: =CONCATENATE($N8,"x",$O8) -> 紫色道具碎片x4 | Q8: 500 | R8: =COUNTIF(X:X,L8) -> 12 | S8: =INT(Q8/R8) -> 41 | V8: 14201 | W8: =VLOOKUP(V8,[1]道具配置表!$A:$D,4,FALSE) -> 维托里奥 | X8: 橙 | Y8: 14201 | Z8: S
A9: 14202 | B9: =VLOOKUP(A9,[1]道具配置表!$A:$D,4,FALSE) -> 苏安 | C9: 1 | D9: =VLOOKUP(B9,$W:$X,2,FALSE) -> 紫 | E9: =CONCATENATE(B9,"x",C9) -> 苏安x1 | F9: =D9&"色道具碎片"&"X"&C9 -> 紫色道具碎片X1 | G9: =VLOOKUP(F9,$P$2:$S$21,4,FALSE) -> 166 | L9: 紫 | M9: 紫色名人碎片 | N9: 紫色道具碎片 | O9: 10 | P9: =CONCATENATE($N9,"x",$O9) -> 紫色道具碎片x10 | Q9: 250 | R9: =COUNTIF(X:X,L9) -> 12 | S9: =INT(Q9/R9) -> 20 | V9: 14202 | W9: =VLOOKUP(V9,[1]道具配置表!$A:$D,4,FALSE) -> 苏安 | X9: 紫 | Y9: 14202 | Z9: A
A10: 14203 | B10: =VLOOKUP(A10,[1]道具配置表!$A:$D,4,FALSE) -> 范文定 | C10: 1 | D10: =VLOOKUP(B10,$W:$X,2,FALSE) -> 稀有橙 | E10: =CONCATENATE(B10,"x",C10) -> 范文定x1 | F10: =D10&"色道具碎片"&"X"&C10 -> 稀有橙色道具碎片X1 | G10: =VLOOKUP(F10,$P$2:$S$21,4,FALSE) -> 10 | L10: 橙 | M10: 橙色名人碎片 | N10: 橙色道具碎片 | O10: 1 | P10: =CONCATENATE($N10,"x",$O10) -> 橙色道具碎片x1 | Q10: 300 | R10: =COUNTIF(X:X,L10) -> 6 | S10: =INT(Q10/R10) -> 50 | V10: 14203 | W10: =VLOOKUP(V10,[1]道具配置表!$A:$D,4,FALSE) -> 范文定 | X10: 稀有橙 | Y10: 14203 | Z10: S
A11: 14204 | B11: =VLOOKUP(A11,[1]道具配置表!$A:$D,4,FALSE) -> 亚历山德罗 | C11: 1 | D11: =VLOOKUP(B11,$W:$X,2,FALSE) -> 稀有橙 | E11: =CONCATENATE(B11,"x",C11) -> 亚历山德罗x1 | F11: =D11&"色道具碎片"&"X"&C11 -> 稀有橙色道具碎片X1 | G11: =VLOOKUP(F11,$P$2:$S$21,4,FALSE) -> 10 | L11: 橙 | M11: 橙色名人碎片 | N11: 橙色道具碎片 | O11: 2 | P11: =CONCATENATE($N11,"x",$O11) -> 橙色道具碎片x2 | Q11: 150 | R11: =COUNTIF(X:X,L11) -> 6 | S11: =INT(Q11/R11) -> 25 | V11: 14204 | W11: =VLOOKUP(V11,[1]道具配置表!$A:$D,4,FALSE) -> 亚历山德罗 | X11: 稀有橙 | Y11: 14204 | Z11: S
A12: 14206 | B12: =VLOOKUP(A12,[1]道具配置表!$A:$D,4,FALSE) -> 杜若 | C12: 1 | D12: =VLOOKUP(B12,$W:$X,2,FALSE) -> 稀有橙 | E12: =CONCATENATE(B12,"x",C12) -> 杜若x1 | F12: =D12&"色道具碎片"&"X"&C12 -> 稀有橙色道具碎片X1 | G12: =VLOOKUP(F12,$P$2:$S$21,4,FALSE) -> 10 | L12: 橙 | M12: 橙色名人碎片 | N12: 橙色道具碎片 | O12: 4 | P12: =CONCATENATE($N12,"x",$O12) -> 橙色道具碎片x4 | Q12: 75 | R12: =COUNTIF(X:X,L12) -> 6 | S12: =INT(Q12/R12) -> 12 | V12: 14206 | W12: =VLOOKUP(V12,[1]道具配置表!$A:$D,4,FALSE) -> 杜若 | X12: 稀有橙 | Y12: 14206 | Z12: S
A13: 14207 | B13: =VLOOKUP(A13,[1]道具配置表!$A:$D,4,FALSE) -> 艾洛缇丝 | C13: 1 | D13: =VLOOKUP(B13,$W:$X,2,FALSE) -> 蓝 | E13: =CONCATENATE(B13,"x",C13) -> 艾洛缇丝x1 | F13: =D13&"色道具碎片"&"X"&C13 -> 蓝色道具碎片X1 | G13: =VLOOKUP(F13,$P$2:$S$21,4,FALSE) -> 1200 | L13: 橙 | M13: 橙色名人碎片 | N13: 橙色道具碎片 | O13: 10 | P13: =CONCATENATE($N13,"x",$O13) -> 橙色道具碎片x10 | Q13: 37 | R13: =COUNTIF(X:X,L13) -> 6 | S13: =INT(Q13/R13) -> 6 | V13: 14207 | W13: =VLOOKUP(V13,[1]道具配置表!$A:$D,4,FALSE) -> 艾洛缇丝 | X13: 蓝 | Y13: 14207 | Z13: B
... A21: 14308 | B21: =VLOOKUP(A21,[1]道具配置表!$A:$D,4,FALSE) -> 卢卡 | C21: 1 | D21: =VLOOKUP(B21,$W:$X,2,FALSE) -> 紫 | E21: =CONCATENATE(B21,"x",C21) -> 卢卡x1 | F21: =D21&"色道具碎片"&"X"&C21 -> 紫色道具碎片X1 | G21: =VLOOKUP(F21,$P$2:$S$21,4,FALSE) -> 166 | L21: 绿 | M21: 100点名人经验 | N21: 绿色道具碎片 | O21: 10 | P21: =CONCATENATE($N21,"x",$O21) -> 绿色道具碎片x10 | Q21: 500 | R21: =COUNTIF(X:X,L21) -> 1 | S21: =INT(Q21/R21) -> 500 | V21: 14308 | W21: =VLOOKUP(V21,[1]道具配置表!$A:$D,4,FALSE) -> 卢卡 | X21: 紫 | Y21: 14308 | Z21: A
A22: 14309 | B22: =VLOOKUP(A22,[1]道具配置表!$A:$D,4,FALSE) -> 爱德华多 | C22: 1 | D22: =VLOOKUP(B22,$W:$X,2,FALSE) -> 紫 | E22: =CONCATENATE(B22,"x",C22) -> 爱德华多x1 | F22: =D22&"色道具碎片"&"X"&C22 -> 紫色道具碎片X1 | G22: =VLOOKUP(F22,$P$2:$S$21,4,FALSE) -> 166 | V22: 14309 | W22: =VLOOKUP(V22,[1]道具配置表!$A:$D,4,FALSE) -> 爱德华多 | X22: 紫 | Y22: 14309 | Z22: A
A23: 14312 | B23: =VLOOKUP(A23,[1]道具配置表!$A:$D,4,FALSE) -> 鱼妙妙 | C23: 1 | D23: =VLOOKUP(B23,$W:$X,2,FALSE) -> 橙 | E23: =CONCATENATE(B23,"x",C23) -> 鱼妙妙x1 | F23: =D23&"色道具碎片"&"X"&C23 -> 橙色道具碎片X1 | G23: =VLOOKUP(F23,$P$2:$S$21,4,FALSE) -> 50 | V23: 14312 | W23: =VLOOKUP(V23,[1]道具配置表!$A:$D,4,FALSE) -> 鱼妙妙 | X23: 橙 | Y23: 14312 | Z23: S
A24: 14313 | B24: =VLOOKUP(A24,[1]道具配置表!$A:$D,4,FALSE) -> 玛丽夫人 | C24: 1 | D24: =VLOOKUP(B24,$W:$X,2,FALSE) -> 紫 | E24: =CONCATENATE(B24,"x",C24) -> 玛丽夫人x1 | F24: =D24&"色道具碎片"&"X"&C24 -> 紫色道具碎片X1 | G24: =VLOOKUP(F24,$P$2:$S$21,4,FALSE) -> 166 | V24: 14313 | W24: =VLOOKUP(V24,[1]道具配置表!$A:$D,4,FALSE) -> 玛丽夫人 | X24: 紫 | Y24: 14313 | Z24: A
A25: 14314 | B25: =VLOOKUP(A25,[1]道具配置表!$A:$D,4,FALSE) -> 琼鸣玉 | C25: 1 | D25: =VLOOKUP(B25,$W:$X,2,FALSE) -> 蓝 | E25: =CONCATENATE(B25,"x",C25) -> 琼鸣玉x1 | F25: =D25&"色道具碎片"&"X"&C25 -> 蓝色道具碎片X1 | G25: =VLOOKUP(F25,$P$2:$S$21,4,FALSE) -> 1200 | V25: 14314 | W25: =VLOOKUP(V25,[1]道具配置表!$A:$D,4,FALSE) -> 琼鸣玉 | X25: 蓝 | Y25: 14314 | Z25: B
A26: 14315 | B26: =VLOOKUP(A26,[1]道具配置表!$A:$D,4,FALSE) -> 姚清珏 | C26: 1 | D26: =VLOOKUP(B26,$W:$X,2,FALSE) -> 稀有橙 | E26: =CONCATENATE(B26,"x",C26) -> 姚清珏x1 | F26: =D26&"色道具碎片"&"X"&C26 -> 稀有橙色道具碎片X1 | G26: =VLOOKUP(F26,$P$2:$S$21,4,FALSE) -> 10 | V26: 14315 | W26: =VLOOKUP(V26,[1]道具配置表!$A:$D,4,FALSE) -> 姚清珏 | X26: 稀有橙 | Y26: 14315 | Z26: S
A27: 14316 | B27: =VLOOKUP(A27,[1]道具配置表!$A:$D,4,FALSE) -> 姬闾 | C27: 1 | D27: =VLOOKUP(B27,$W:$X,2,FALSE) -> 紫 | E27: =CONCATENATE(B27,"x",C27) -> 姬闾x1 | F27: =D27&"色道具碎片"&"X"&C27 -> 紫色道具碎片X1 | G27: =VLOOKUP(F27,$P$2:$S$21,4,FALSE) -> 166 | V27: 14316 | W27: =VLOOKUP(V27,[1]道具配置表!$A:$D,4,FALSE) -> 姬闾 | X27: 紫 | Y27: 14316 | Z27: A
A28: 14317 | B28: =VLOOKUP(A28,[1]道具配置表!$A:$D,4,FALSE) -> 卡多姆 | C28: 1 | D28: =VLOOKUP(B28,$W:$X,2,FALSE) -> 稀有橙 | E28: =CONCATENATE(B28,"x",C28) -> 卡多姆x1 | F28: =D28&"色道具碎片"&"X"&C28 -> 稀有橙色道具碎片X1 | G28: =VLOOKUP(F28,$P$2:$S$21,4,FALSE) -> 10 | V28: 14317 | W28: =VLOOKUP(V28,[1]道具配置表!$A:$D,4,FALSE) -> 卡多姆 | X28: 稀有橙 | Y28: 14317 | Z28: S
A29: 14318 | B29: =VLOOKUP(A29,[1]道具配置表!$A:$D,4,FALSE) -> 巴希斯 | C29: 1 | D29: =VLOOKUP(B29,$W:$X,2,FALSE) -> 稀有橙 | E29: =CONCATENATE(B29,"x",C29) -> 巴希斯x1 | F29: =D29&"色道具碎片"&"X"&C29 -> 稀有橙色道具碎片X1 | G29: =VLOOKUP(F29,$P$2:$S$21,4,FALSE) -> 10 | V29: 14318 | W29: =VLOOKUP(V29,[1]道具配置表!$A:$D,4,FALSE) -> 巴希斯 | X29: 稀有橙 | Y29: 14318 | Z29: S
A30: 14319 | B30: =VLOOKUP(A30,[1]道具配置表!$A:$D,4,FALSE) -> 约恩 | C30: 1 | D30: =VLOOKUP(B30,$W:$X,2,FALSE) -> 蓝 | E30: =CONCATENATE(B30,"x",C30) -> 约恩x1 | F30: =D30&"色道具碎片"&"X"&C30 -> 蓝色道具碎片X1 | G30: =VLOOKUP(F30,$P$2:$S$21,4,FALSE) -> 1200 | V30: 14319 | W30: =VLOOKUP(V30,[1]道具配置表!$A:$D,4,FALSE) -> 约恩 | X30: 蓝 | Y30: 14319 | Z30: B
A31: 17200 | B31: =VLOOKUP(A31,[1]道具配置表!$A:$D,4,FALSE) -> 名人博学值+100 | C31: 1 | D31: =VLOOKUP(B31,$W:$X,2,FALSE) -> 绿 | E31: =CONCATENATE(B31,"x",C31) -> 名人博学值+100x1 | F31: =D31&"色道具碎片"&"X"&C31 -> 绿色道具碎片X1 | G31: =VLOOKUP(F31,$P$2:$S$21,4,FALSE) -> 4000 | V31: 17200 | W31: =VLOOKUP(V31,[1]道具配置表!$A:$D,4,FALSE) -> 名人博学值+100 | X31: 绿 | Y31: 17200
A32: =A2 -> 14101 | B32: =VLOOKUP(A32,[1]道具配置表!$A:$D,4,FALSE) -> 陆芊岚 | C32: 2 | D32: =VLOOKUP(B32,$W:$X,2,FALSE) -> 橙 | E32: =CONCATENATE(B32,"x",C32) -> 陆芊岚x2 | F32: =D32&"色道具碎片"&"X"&C32 -> 橙色道具碎片X2 | G32: =VLOOKUP(F32,$P$2:$S$21,4,FALSE) -> 25
A33: =A3 -> 14105 | B33: =VLOOKUP(A33,[1]道具配置表!$A:$D,4,FALSE) -> 顾盼儿 | C33: 2 | D33: =VLOOKUP(B33,$W:$X,2,FALSE) -> 橙 | E33: =CONCATENATE(B33,"x",C33) -> 顾盼儿x2 | F33: =D33&"色道具碎片"&"X"&C33 -> 橙色道具碎片X2 | G33: =VLOOKUP(F33,$P$2:$S$21,4,FALSE) -> 25
A34: =A4 -> 14106 | B34: =VLOOKUP(A34,[1]道具配置表!$A:$D,4,FALSE) -> 穆离 | C34: 2 | D34: =VLOOKUP(B34,$W:$X,2,FALSE) -> 橙 | E34: =CONCATENATE(B34,"x",C34) -> 穆离x2 | F34: =D34&"色道具碎片"&"X"&C34 -> 橙色道具碎片X2 | G34: =VLOOKUP(F34,$P$2:$S$21,4,FALSE) -> 25
A35: =A5 -> 14107 | B35: =VLOOKUP(A35,[1]道具配置表!$A:$D,4,FALSE) -> 伊丽莎白 | C35: 2 | D35: =VLOOKUP(B35,$W:$X,2,FALSE) -> 橙 | E35: =CONCATENATE(B35,"x",C35) -> 伊丽莎白x2 | F35: =D35&"色道具碎片"&"X"&C35 -> 橙色道具碎片X2 | G35: =VLOOKUP(F35,$P$2:$S$21,4,FALSE) -> 25
A36: =A6 -> 14108 | B36: =VLOOKUP(A36,[1]道具配置表!$A:$D,4,FALSE) -> 娜娜丽 | C36: 2 | D36: =VLOOKUP(B36,$W:$X,2,FALSE) -> 蓝 | E36: =CONCATENATE(B36,"x",C36) -> 娜娜丽x2 | F36: =D36&"色道具碎片"&"X"&C36 -> 蓝色道具碎片X2 | G36: =VLOOKUP(F36,$P$2:$S$21,4,FALSE) -> 600
A37: =A7 -> 14109 | B37: =VLOOKUP(A37,[1]道具配置表!$A:$D,4,FALSE) -> 埃托雷 | C37: 2 | D37: =VLOOKUP(B37,$W:$X,2,FALSE) -> 紫 | E37: =CONCATENATE(B37,"x",C37) -> 埃托雷x2 | F37: =D37&"色道具碎片"&"X"&C37 -> 紫色道具碎片X2 | G37: =VLOOKUP(F37,$P$2:$S$21,4,FALSE) -> 83
A38: =A8 -> 14201 | B38: =VLOOKUP(A38,[1]道具配置表!$A:$D,4,FALSE) -> 维托里奥 | C38: 2 | D38: =VLOOKUP(B38,$W:$X,2,FALSE) -> 橙 | E38: =CONCATENATE(B38,"x",C38) -> 维托里奥x2 | F38: =D38&"色道具碎片"&"X"&C38 -> 橙色道具碎片X2 | G38: =VLOOKUP(F38,$P$2:$S$21,4,FALSE) -> 25
A39: =A9 -> 14202 | B39: =VLOOKUP(A39,[1]道具配置表!$A:$D,4,FALSE) -> 苏安 | C39: 2 | D39: =VLOOKUP(B39,$W:$X,2,FALSE) -> 紫 | E39: =CONCATENATE(B39,"x",C39) -> 苏安x2 | F39: =D39&"色道具碎片"&"X"&C39 -> 紫色道具碎片X2 | G39: =VLOOKUP(F39,$P$2:$S$21,4,FALSE) -> 83
A40: =A10 -> 14203 | B40: =VLOOKUP(A40,[1]道具配置表!$A:$D,4,FALSE) -> 范文定 | C40: 2 | D40: =VLOOKUP(B40,$W:$X,2,FALSE) -> 稀有橙 | E40: =CONCATENATE(B40,"x",C40) -> 范文定x2 | F40: =D40&"色道具碎片"&"X"&C40 -> 稀有橙色道具碎片X2 | G40: =VLOOKUP(F40,$P$2:$S$21,4,FALSE) -> 5
A41: =A11 -> 14204 | B41: =VLOOKUP(A41,[1]道具配置表!$A:$D,4,FALSE) -> 亚历山德罗 | C41: 2 | D41: =VLOOKUP(B41,$W:$X,2,FALSE) -> 稀有橙 | E41: =CONCATENATE(B41,"x",C41) -> 亚历山德罗x2 | F41: =D41&"色道具碎片"&"X"&C41 -> 稀有橙色道具碎片X2 | G41: =VLOOKUP(F41,$P$2:$S$21,4,FALSE) -> 5
A42: =A12 -> 14206 | B42: =VLOOKUP(A42,[1]道具配置表!$A:$D,4,FALSE) -> 杜若 | C42: 2 | D42: =VLOOKUP(B42,$W:$X,2,FALSE) -> 稀有橙 | E42: =CONCATENATE(B42,"x",C42) -> 杜若x2 | F42: =D42&"色道具碎片"&"X"&C42 -> 稀有橙色道具碎片X2 | G42: =VLOOKUP(F42,$P$2:$S$21,4,FALSE) -> 5
A43: =A13 -> 14207 | B43: =VLOOKUP(A43,[1]道具配置表!$A:$D,4,FALSE) -> 艾洛缇丝 | C43: 2 | D43: =VLOOKUP(B43,$W:$X,2,FALSE) -> 蓝 | E43: =CONCATENATE(B43,"x",C43) -> 艾洛缇丝x2 | F43: =D43&"色道具碎片"&"X"&C43 -> 蓝色道具碎片X2 | G43: =VLOOKUP(F43,$P$2:$S$21,4,FALSE) -> 600
... A121: =A91 -> 17200 | B121: =VLOOKUP(A121,[1]道具配置表!$A:$D,4,FALSE) -> 名人博学值+100 | C121: 10 | D121: =VLOOKUP(B121,$W:$X,2,FALSE) -> 绿 | E121: =CONCATENATE(B121,"x",C121) -> 名人博学值+100x10 | F121: =D121&"色道具碎片"&"X"&C121 -> 绿色道具碎片X10 | G121: =VLOOKUP(F121,$P$2:$S$21,4,FALSE) -> 500

Sheet #配表须知
A1: 分表须知
B2: * 每个策划占用10万ID段
B3: * 新增xlsx后需要将新表第一行pb名字和分表配置里对应起来(参考已有分表A1单元格的写法)
B4: * 告知服务器同学添加加载新分表的代码（ResMapAllServerLite.java.conv）
B5: * 新增分表后需转《奖励分表配置》并提交，后续只需要修改自己的分表即可
K10: 奖励随机流程
J12: 1. 产出【绝对概率】道具 | K12: 2. 产出【相对权重】道具 | L12: 3. 将第1步，第2步随机结果合并返回
J14: 1.1对每个绝对概率道具进行一次随机，决定出不出 | K14: 2.1 将所有配置了相对权重的道具组建一个随机池子
J16: 1.2 绝对概率配置范围为【0, 1】，配1必出，配置0必不出（用于预配置） | K16: 2.2 如果配置了二项权重，则从最大最小两个数字中随机选一个数字n
K18: 2.3 如果没配置二项权重，从最小最大数量范围中随机一个数字
K20: 2.4 随机数为0不进行相对权重随机，随机数大于池子大小全出

Sheet #TID_base_up
A1: 旧Key | B1: 新Key | C1: 文本
