Workbook

Sheet 奖励配置表
A1: convert(ResReward.proto, table_RewardConfData, RewardConfData_5.pbin) | F1: 相对随机配置
A2: 奖励ID | B2: 策划描述 | C2: 道具id | D2: 道具名称 | E2: 道具数量 | F2: 相对权重最小个数 | G2: 相对权重最大个数 | H2: 数量权重 | I2: 相对权重（整数） | J2: 绝对概率[0,1] | K2: 过期时间 | L2: 自定义顺序
A3: id | C3: item.id | E3: item.num | F3: minNum | G3: maxNum | H3: numWeight[;] | I3: item.relativeWeight | J3: item.absoluteProbability | K3: item.expire | L3: customizedOrder
A4: 1900001 | B4: 冒险蓝色名人宝箱 | C4: 17204 | D4: =VLOOKUP(C4,[1]道具配置表!$A:$D,4,FALSE) -> 名人博学值+1 | E4: 100 | F4: 1 | G4: 1 | J4: 1 | L4: TRUE
C5: 14108 | D5: =VLOOKUP(C5,[1]道具配置表!$A:$D,4,FALSE) -> 娜娜丽 | E5: 1 | I5: 10 | L5: TRUE
C6: 14207 | D6: =VLOOKUP(C6,[1]道具配置表!$A:$D,4,FALSE) -> 莎芙 | E6: 1 | I6: 10 | L6: TRUE
C7: 14301 | D7: =VLOOKUP(C7,[1]道具配置表!$A:$D,4,FALSE) -> 梅芙 | E7: 1 | I7: 10 | L7: TRUE
C8: 14314 | D8: =VLOOKUP(C8,[1]道具配置表!$A:$D,4,FALSE) -> 琼鸣玉 | E8: 1 | I8: 10 | L8: TRUE
C9: 14319 | D9: =VLOOKUP(C9,[1]道具配置表!$A:$D,4,FALSE) -> 约恩 | E9: 1 | I9: 10 | L9: TRUE
A10: 1900002 | B10: 冒险紫名人宝箱 | C10: 17204 | D10: =VLOOKUP(C10,[1]道具配置表!$A:$D,4,FALSE) -> 名人博学值+1 | E10: 200 | F10: 1 | G10: 1 | J10: 1 | L10: TRUE
C11: 14109 | D11: =VLOOKUP(C11,[1]道具配置表!$A:$D,4,FALSE) -> 亚基 | E11: 1 | I11: 10 | L11: TRUE
C12: 14202 | D12: =VLOOKUP(C12,[1]道具配置表!$A:$D,4,FALSE) -> 方选 | E12: 1 | I12: 10 | L12: TRUE
C13: 14302 | D13: =VLOOKUP(C13,[1]道具配置表!$A:$D,4,FALSE) -> 尼古劳斯 | E13: 1 | I13: 10 | L13: TRUE
C14: 14303 | D14: =VLOOKUP(C14,[1]道具配置表!$A:$D,4,FALSE) -> 拉格纳 | E14: 1 | I14: 10 | L14: TRUE
C15: 14304 | D15: =VLOOKUP(C15,[1]道具配置表!$A:$D,4,FALSE) -> 公孙 | E15: 1 | I15: 10 | L15: TRUE
C16: 14305 | D16: =VLOOKUP(C16,[1]道具配置表!$A:$D,4,FALSE) -> 德罗茜 | E16: 1 | I16: 10 | L16: TRUE
C17: 14306 | D17: =VLOOKUP(C17,[1]道具配置表!$A:$D,4,FALSE) -> 佩里克勒斯 | E17: 1 | I17: 10 | L17: TRUE
C18: 14307 | D18: =VLOOKUP(C18,[1]道具配置表!$A:$D,4,FALSE) -> 元元公主 | E18: 1 | I18: 10 | L18: TRUE
C19: 14308 | D19: =VLOOKUP(C19,[1]道具配置表!$A:$D,4,FALSE) -> 倪克罗 | E19: 1 | I19: 10 | L19: TRUE
C20: 14309 | D20: =VLOOKUP(C20,[1]道具配置表!$A:$D,4,FALSE) -> 瓦斯克 | E20: 1 | I20: 10 | L20: TRUE
C21: 14313 | D21: =VLOOKUP(C21,[1]道具配置表!$A:$D,4,FALSE) -> 玛丽夫人 | E21: 1 | I21: 10 | L21: TRUE
C22: 14316 | D22: =VLOOKUP(C22,[1]道具配置表!$A:$D,4,FALSE) -> 姬敬 | E22: 1 | I22: 10 | L22: TRUE
A23: 1900003 | B23: 冒险橙色名人宝箱 | C23: 17204 | D23: =VLOOKUP(C23,[1]道具配置表!$A:$D,4,FALSE) -> 名人博学值+1 | E23: 400 | F23: 1 | G23: 1 | J23: 1 | L23: TRUE
C24: 14101 | D24: =VLOOKUP(C24,[1]道具配置表!$A:$D,4,FALSE) -> 李芊岚 | E24: 1 | I24: 10 | L24: TRUE
C25: 14105 | D25: =VLOOKUP(C25,[1]道具配置表!$A:$D,4,FALSE) -> 顾烟 | E25: 1 | I25: 10 | L25: TRUE
C26: 14106 | D26: =VLOOKUP(C26,[1]道具配置表!$A:$D,4,FALSE) -> 翟黎 | E26: 1 | I26: 10 | L26: TRUE
C27: 14107 | D27: =VLOOKUP(C27,[1]道具配置表!$A:$D,4,FALSE) -> 伊丽莎白 | E27: 1 | I27: 10 | L27: TRUE
C28: 14201 | D28: =VLOOKUP(C28,[1]道具配置表!$A:$D,4,FALSE) -> 密克安哲 | E28: 1 | I28: 10 | L28: TRUE
C29: 14312 | D29: =VLOOKUP(C29,[1]道具配置表!$A:$D,4,FALSE) -> 施浣 | E29: 1 | I29: 10 | L29: TRUE
A30: 1900005 | B30: 冒险测试奖励 | C30: 17001 | D30: =VLOOKUP(C30,[1]道具配置表!$A:$D,4,FALSE) -> 冒险经验+10 | E30: 1 | J30: 1 | L30: TRUE
C31: 17201 | D31: =VLOOKUP(C31,[1]道具配置表!$A:$D,4,FALSE) -> 名人博学值+200 | E31: 1 | J31: 1 | L31: TRUE
A32: 1900006 | B32: 冒险测试奖励 | C32: 101 | D32: =VLOOKUP(C32,[1]道具配置表!$A:$D,4,FALSE) -> 1木材 | E32: 1 | J32: 1 | L32: TRUE
A33: 1900007 | B33: 冒险测试奖励 | C33: 102 | D33: =VLOOKUP(C33,[1]道具配置表!$A:$D,4,FALSE) -> 1食物 | E33: 1 | J33: 1 | L33: TRUE
A34: 1900008 | B34: 冒险测试奖励 | C34: 103 | D34: =VLOOKUP(C34,[1]道具配置表!$A:$D,4,FALSE) -> 1石头 | E34: 1 | J34: 1 | L34: TRUE
A35: 1900009 | B35: 冒险测试奖励 | C35: 104 | D35: =VLOOKUP(C35,[1]道具配置表!$A:$D,4,FALSE) -> 1黄金 | E35: 1 | J35: 1 | L35: TRUE
A36: 1900010 | B36: 冒险测试奖励 | C36: 14303 | D36: =VLOOKUP(C36,[1]道具配置表!$A:$D,4,FALSE) -> 拉格纳 | E36: 10 | J36: 1 | L36: TRUE
A37: 1900011 | B37: 冒险测试奖励 | C37: 14109 | D37: =VLOOKUP(C37,[1]道具配置表!$A:$D,4,FALSE) -> 亚基 | E37: 10 | J37: 1 | L37: TRUE
A38: 1900012 | B38: 冒险测试奖励 | C38: 14101 | D38: =VLOOKUP(C38,[1]道具配置表!$A:$D,4,FALSE) -> 李芊岚 | E38: 10 | J38: 1 | L38: TRUE
A39: 1900013 | B39: 冒险测试奖励 | C39: 7001 | D39: =VLOOKUP(C39,[1]道具配置表!$A:$D,4,FALSE) -> 1钻石（立即使用，不进背包） | E39: 10 | J39: 1 | L39: TRUE
A40: 1900014 | B40: 冒险测试奖励 | C40: 7000 | D40: =VLOOKUP(C40,[1]道具配置表!$A:$D,4,FALSE) -> 1钻石（进背包） | E40: 10 | J40: 1 | L40: TRUE
...

Sheet #配表须知
A1: 分表须知
B2: * 每个策划占用10万ID段
B3: * 新增xlsx后需要将新表第一行pb名字和分表配置里对应起来(参考已有分表A1单元格的写法)
B4: * 告知服务器同学添加加载新分表的代码（ResMapAllServerLite.java.conv）
B5: * 新增分表后需转《奖励分表配置》并提交，后续只需要修改自己的分表即可
K10: 奖励随机流程
J12: 1. 产出【绝对概率】道具 | K12: 2. 产出【相对权重】道具 | L12: 3. 将第1步，第2步随机结果合并返回
J14: 1.1对每个绝对概率道具进行一次随机，决定出不出 | K14: 2.1 将所有配置了相对权重的道具组建一个随机池子
J16: 1.2 绝对概率配置范围为【0, 1】，配1必出，配置0必不出（用于预配置） | K16: 2.2 如果配置了二项权重，则从最大最小两个数字中随机选一个数字n
K18: 2.3 如果没配置二项权重，从最小最大数量范围中随机一个数字
K20: 2.4 随机数为0不进行相对权重随机，随机数大于池子大小全出

Sheet #道具ID
A1: convert(ResItem.proto, table_ItemConfData, ItemConfData.pbin) | C1: convert(ResItem.proto, table_ItemConfData, ItemConfData.pbin)
A2: 道具ID | B2: 简略描述 | C2: 道具ID
A3: id | B3: debugDesc | C3: id
A4: 1 | B4: 1万木材 | C4: 1
A5: 2 | B5: 1万食物 | C5: 2 | H5: 1分钟加速 | I5: 100 | J5: =I5/SUM($I$5:$I$81) -> 0.046146747
A6: 3 | B6: 1万石头 | C6: 3 | H6: 1分钟建造加速 | I6: 100 | J6: =I6/SUM($I$5:$I$81) -> 0.046146747
A7: 4 | B7: 1千黄金 | C7: 4 | H7: 1分钟科技研究加速 | I7: 100 | J7: =I7/SUM($I$5:$I$81) -> 0.046146747
A8: 5 | B8: 1千木材 | C8: 5 | H8: 1分钟训练加速 | I8: 100 | J8: =I8/SUM($I$5:$I$81) -> 0.046146747
A9: 6 | B9: 1千食物 | C9: 6 | H9: 1分钟医疗加速 | I9: 100 | J9: =I9/SUM($I$5:$I$81) -> 0.046146747
A10: 7 | B10: 1千石头 | C10: 7 | H10: 5分钟加速 | I10: 50 | J10: =I10/SUM($I$5:$I$81) -> 0.023073373
A11: 8 | B11: 1千黄金 | C11: 8 | H11: 1小时加速 | I11: 10 | J11: =I11/SUM($I$5:$I$81) -> 0.0046146747
A12: 11 | B12: 1千木材 | C12: 11 | H12: 2小时加速 | I12: 5 | J12: =I12/SUM($I$5:$I$81) -> 0.0023073373
A13: 12 | B13: 1千食物 | C13: 12 | H13: 8小时加速 | I13: 2 | J13: =I13/SUM($I$5:$I$81) -> 0.00092293493
A14: 13 | B14: 1千石头 | C14: 13 | H14: 12小时加速 | I14: 1 | J14: =I14/SUM($I$5:$I$81) -> 0.00046146747
A15: 14 | B15: 100黄金 | C15: 14 | H15: 24小时加速 | I15: 1 | J15: =I15/SUM($I$5:$I$81) -> 0.00046146747
A16: 15 | B16: 1木材 | C16: 15 | H16: 5分钟建造加速 | I16: 50 | J16: =I16/SUM($I$5:$I$81) -> 0.023073373
... A81: 715 | B81: 【残破】阿基米德之镜 | C81: 715 | H81: 1铜币货币 | I81: 2 | J81: =I81/SUM($I$5:$I$81) -> 0.00092293493
A82: 716 | B82: 【残破】乌尔王军标 | C82: 716
A83: 717 | B83: 【残破】图坦卡蒙黄金面具 | C83: 717
A84: 718 | B84: 【残破】月桂王冠 | C84: 718
A85: 719 | B85: 【残破】萧后冠 | C85: 719
A86: 720 | B86: 【残破】《高卢战记》 | C86: 720
A87: 721 | B87: 【残破】贝希斯敦铭文 | C87: 721
A88: 722 | B88: 【残破】传国玉玺 | C88: 722
A89: 723 | B89: 【残破】赤道日晷仪 | C89: 723
A90: 724 | B90: 【残破】西洋棋 | C90: 724
A91: 725 | B91: 【残破】敦煌飞天壁画 | C91: 725
A92: 726 | B92: 【残破】奥林匹亚宙斯神像摹本 | C92: 726
A93: 727 | B93: 【残破】七弦竖琴 | C93: 727
... A633: 16000 | B633: 马可波罗的笔记 | C633: 16000

Sheet #TID_base_up
A1: 旧Key | B1: 新Key | C1: 文本
