Workbook

Sheet 奖励配置表
A1: convert(ResReward.proto, table_RewardConfData, RewardConfData_11.pbin) | G1: 相对随机配置
A2: 奖励ID | B2: 策划描述 | C2: 重复检查 | D2: 道具id | E2: 道具名称 | F2: 道具数量 | G2: 相对权重最小个数 | H2: 相对权重最大个数 | I2: 数量权重 | J2: 相对权重（整数） | K2: 绝对概率[0,1] | L2: 过期时间 | M2: 自定义顺序 | N2: 可选数量
A3: id | D3: item.id | F3: item.num | G3: minNum | H3: maxNum | I3: numWeight[;] | J3: item.relativeWeight | K3: item.absoluteProbability | L3: item.expire | M3: customizedOrder | N3: chooseNum
A4: 6600101 | B4: =MOD(A4,100)&"级城全盟奖励" -> 1级城全盟奖励 | C4: =IF(A4="","",IF((COUNTIFS(A:A,A4))>1,"ID重复","")) | D4: 501 | E4: =INDEX([1]道具配置表!$D:$D,MATCH(D4,[1]道具配置表!$A:$A,0)) -> 1千资源自选宝箱 | F4: 100 | K4: 1 | M4: TRUE
C5: =IF(A5="","",IF((COUNTIFS(A:A,A5))>1,"ID重复","")) | D5: 6120 | E5: =INDEX([1]道具配置表!$D:$D,MATCH(D5,[1]道具配置表!$A:$A,0)) -> 1分钟建造加速 | F5: 50 | K5: 1 | M5: TRUE
C6: =IF(A6="","",IF((COUNTIFS(A:A,A6))>1,"ID重复","")) | D6: 6140 | E6: =INDEX([1]道具配置表!$D:$D,MATCH(D6,[1]道具配置表!$A:$A,0)) -> 1分钟科技加速 | F6: 50 | K6: 1 | M6: TRUE
A7: =A4+1 -> 6600102 | B7: =MOD(A7,100)&"级城全盟奖励" -> 2级城全盟奖励 | C7: =IF(A7="","",IF((COUNTIFS(A:A,A7))>1,"ID重复","")) | D7: 501 | E7: =INDEX([1]道具配置表!$D:$D,MATCH(D7,[1]道具配置表!$A:$A,0)) -> 1千资源自选宝箱 | F7: =F4+20 -> 120 | K7: 1 | M7: TRUE
C8: =IF(A8="","",IF((COUNTIFS(A:A,A8))>1,"ID重复","")) | D8: 6120 | E8: =INDEX([1]道具配置表!$D:$D,MATCH(D8,[1]道具配置表!$A:$A,0)) -> 1分钟建造加速 | F8: =F5+10 -> 60 | K8: 1 | M8: TRUE
C9: =IF(A9="","",IF((COUNTIFS(A:A,A9))>1,"ID重复","")) | D9: 6140 | E9: =INDEX([1]道具配置表!$D:$D,MATCH(D9,[1]道具配置表!$A:$A,0)) -> 1分钟科技加速 | F9: =F6+10 -> 60 | K9: 1 | M9: TRUE
A10: =A7+1 -> 6600103 | B10: =MOD(A10,100)&"级城全盟奖励" -> 3级城全盟奖励 | C10: =IF(A10="","",IF((COUNTIFS(A:A,A10))>1,"ID重复","")) | D10: 501 | E10: =INDEX([1]道具配置表!$D:$D,MATCH(D10,[1]道具配置表!$A:$A,0)) -> 1千资源自选宝箱 | F10: =F7+20 -> 140 | K10: 1 | M10: TRUE
C11: =IF(A11="","",IF((COUNTIFS(A:A,A11))>1,"ID重复","")) | D11: 6120 | E11: =INDEX([1]道具配置表!$D:$D,MATCH(D11,[1]道具配置表!$A:$A,0)) -> 1分钟建造加速 | F11: =F8+10 -> 70 | K11: 1 | M11: TRUE
C12: =IF(A12="","",IF((COUNTIFS(A:A,A12))>1,"ID重复","")) | D12: 6140 | E12: =INDEX([1]道具配置表!$D:$D,MATCH(D12,[1]道具配置表!$A:$A,0)) -> 1分钟科技加速 | F12: =F9+10 -> 70 | K12: 1 | M12: TRUE
A13: =A10+1 -> 6600104 | B13: =MOD(A13,100)&"级城全盟奖励" -> 4级城全盟奖励 | C13: =IF(A13="","",IF((COUNTIFS(A:A,A13))>1,"ID重复","")) | D13: 501 | E13: =INDEX([1]道具配置表!$D:$D,MATCH(D13,[1]道具配置表!$A:$A,0)) -> 1千资源自选宝箱 | F13: =F10+20 -> 160 | K13: 1 | M13: TRUE
C14: =IF(A14="","",IF((COUNTIFS(A:A,A14))>1,"ID重复","")) | D14: 6120 | E14: =INDEX([1]道具配置表!$D:$D,MATCH(D14,[1]道具配置表!$A:$A,0)) -> 1分钟建造加速 | F14: =F11+10 -> 80 | K14: 1 | M14: TRUE
C15: =IF(A15="","",IF((COUNTIFS(A:A,A15))>1,"ID重复","")) | D15: 6140 | E15: =INDEX([1]道具配置表!$D:$D,MATCH(D15,[1]道具配置表!$A:$A,0)) -> 1分钟科技加速 | F15: =F12+10 -> 80 | K15: 1 | M15: TRUE
A16: =A13+1 -> 6600105 | B16: =MOD(A16,100)&"级城全盟奖励" -> 5级城全盟奖励 | C16: =IF(A16="","",IF((COUNTIFS(A:A,A16))>1,"ID重复","")) | D16: 501 | E16: =INDEX([1]道具配置表!$D:$D,MATCH(D16,[1]道具配置表!$A:$A,0)) -> 1千资源自选宝箱 | F16: =F13+20 -> 180 | K16: 1 | M16: TRUE
C17: =IF(A17="","",IF((COUNTIFS(A:A,A17))>1,"ID重复","")) | D17: 6120 | E17: =INDEX([1]道具配置表!$D:$D,MATCH(D17,[1]道具配置表!$A:$A,0)) -> 1分钟建造加速 | F17: =F14+10 -> 90 | K17: 1 | M17: TRUE
C18: =IF(A18="","",IF((COUNTIFS(A:A,A18))>1,"ID重复","")) | D18: 6140 | E18: =INDEX([1]道具配置表!$D:$D,MATCH(D18,[1]道具配置表!$A:$A,0)) -> 1分钟科技加速 | F18: =F15+10 -> 90 | K18: 1 | M18: TRUE
A19: =A16+1 -> 6600106 | B19: =MOD(A19,100)&"级城全盟奖励" -> 6级城全盟奖励 | C19: =IF(A19="","",IF((COUNTIFS(A:A,A19))>1,"ID重复","")) | D19: 501 | E19: =INDEX([1]道具配置表!$D:$D,MATCH(D19,[1]道具配置表!$A:$A,0)) -> 1千资源自选宝箱 | F19: =F16+20 -> 200 | K19: 1 | M19: TRUE
C20: =IF(A20="","",IF((COUNTIFS(A:A,A20))>1,"ID重复","")) | D20: 6120 | E20: =INDEX([1]道具配置表!$D:$D,MATCH(D20,[1]道具配置表!$A:$A,0)) -> 1分钟建造加速 | F20: =F17+10 -> 100 | K20: 1 | M20: TRUE
C21: =IF(A21="","",IF((COUNTIFS(A:A,A21))>1,"ID重复","")) | D21: 6140 | E21: =INDEX([1]道具配置表!$D:$D,MATCH(D21,[1]道具配置表!$A:$A,0)) -> 1分钟科技加速 | F21: =F18+10 -> 100 | K21: 1 | M21: TRUE
A22: =A19+1 -> 6600107 | B22: =MOD(A22,100)&"级城全盟奖励" -> 7级城全盟奖励 | C22: =IF(A22="","",IF((COUNTIFS(A:A,A22))>1,"ID重复","")) | D22: 501 | E22: =INDEX([1]道具配置表!$D:$D,MATCH(D22,[1]道具配置表!$A:$A,0)) -> 1千资源自选宝箱 | F22: =F19+20 -> 220 | K22: 1 | M22: TRUE
C23: =IF(A23="","",IF((COUNTIFS(A:A,A23))>1,"ID重复","")) | D23: 6120 | E23: =INDEX([1]道具配置表!$D:$D,MATCH(D23,[1]道具配置表!$A:$A,0)) -> 1分钟建造加速 | F23: =F20+10 -> 110 | K23: 1 | M23: TRUE
C24: =IF(A24="","",IF((COUNTIFS(A:A,A24))>1,"ID重复","")) | D24: 6140 | E24: =INDEX([1]道具配置表!$D:$D,MATCH(D24,[1]道具配置表!$A:$A,0)) -> 1分钟科技加速 | F24: =F21+10 -> 110 | K24: 1 | M24: TRUE
A25: =A22+1 -> 6600108 | B25: =MOD(A25,100)&"级城全盟奖励" -> 8级城全盟奖励 | C25: =IF(A25="","",IF((COUNTIFS(A:A,A25))>1,"ID重复","")) | D25: 501 | E25: =INDEX([1]道具配置表!$D:$D,MATCH(D25,[1]道具配置表!$A:$A,0)) -> 1千资源自选宝箱 | F25: =F22+20 -> 240 | K25: 1 | M25: TRUE
C26: =IF(A26="","",IF((COUNTIFS(A:A,A26))>1,"ID重复","")) | D26: 6120 | E26: =INDEX([1]道具配置表!$D:$D,MATCH(D26,[1]道具配置表!$A:$A,0)) -> 1分钟建造加速 | F26: =F23+10 -> 120 | K26: 1 | M26: TRUE
C27: =IF(A27="","",IF((COUNTIFS(A:A,A27))>1,"ID重复","")) | D27: 6140 | E27: =INDEX([1]道具配置表!$D:$D,MATCH(D27,[1]道具配置表!$A:$A,0)) -> 1分钟科技加速 | F27: =F24+10 -> 120 | K27: 1 | M27: TRUE
A28: =A25+1 -> 6600109 | B28: =MOD(A28,100)&"级城全盟奖励" -> 9级城全盟奖励 | C28: =IF(A28="","",IF((COUNTIFS(A:A,A28))>1,"ID重复","")) | D28: 501 | E28: =INDEX([1]道具配置表!$D:$D,MATCH(D28,[1]道具配置表!$A:$A,0)) -> 1千资源自选宝箱 | F28: =F25+20 -> 260 | K28: 1 | M28: TRUE
C29: =IF(A29="","",IF((COUNTIFS(A:A,A29))>1,"ID重复","")) | D29: 6120 | E29: =INDEX([1]道具配置表!$D:$D,MATCH(D29,[1]道具配置表!$A:$A,0)) -> 1分钟建造加速 | F29: =F26+10 -> 130 | K29: 1 | M29: TRUE
C30: =IF(A30="","",IF((COUNTIFS(A:A,A30))>1,"ID重复","")) | D30: 6140 | E30: =INDEX([1]道具配置表!$D:$D,MATCH(D30,[1]道具配置表!$A:$A,0)) -> 1分钟科技加速 | F30: =F27+10 -> 130 | K30: 1 | M30: TRUE
A31: =A28+1 -> 6600110 | B31: =MOD(A31,100)&"级城全盟奖励" -> 10级城全盟奖励 | C31: =IF(A31="","",IF((COUNTIFS(A:A,A31))>1,"ID重复","")) | D31: 501 | E31: =INDEX([1]道具配置表!$D:$D,MATCH(D31,[1]道具配置表!$A:$A,0)) -> 1千资源自选宝箱 | F31: =F28+20 -> 280 | K31: 1 | M31: TRUE
C32: =IF(A32="","",IF((COUNTIFS(A:A,A32))>1,"ID重复","")) | D32: 6120 | E32: =INDEX([1]道具配置表!$D:$D,MATCH(D32,[1]道具配置表!$A:$A,0)) -> 1分钟建造加速 | F32: =F29+10 -> 140 | K32: 1 | M32: TRUE
C33: =IF(A33="","",IF((COUNTIFS(A:A,A33))>1,"ID重复","")) | D33: 6140 | E33: =INDEX([1]道具配置表!$D:$D,MATCH(D33,[1]道具配置表!$A:$A,0)) -> 1分钟科技加速 | F33: =F30+10 -> 140 | K33: 1 | M33: TRUE
A34: 6600201 | B34: =MOD(A34,100)&"级城参与奖励" -> 1级城参与奖励 | C34: =IF(A34="","",IF((COUNTIFS(A:A,A34))>1,"ID重复","")) | D34: 7003 | E34: =INDEX([1]道具配置表!$D:$D,MATCH(D34,[1]道具配置表!$A:$A,0)) -> 1银币（立即使用，不进背包） | F34: 300 | K34: 1 | M34: TRUE
C35: =IF(A35="","",IF((COUNTIFS(A:A,A35))>1,"ID重复","")) | D35: 6160 | E35: =INDEX([1]道具配置表!$D:$D,MATCH(D35,[1]道具配置表!$A:$A,0)) -> 1分钟训练加速 | F35: 100 | K35: 1 | M35: TRUE
C36: =IF(A36="","",IF((COUNTIFS(A:A,A36))>1,"ID重复","")) | D36: 6180 | E36: =INDEX([1]道具配置表!$D:$D,MATCH(D36,[1]道具配置表!$A:$A,0)) -> 1分钟治疗加速 | F36: 50 | K36: 1 | M36: TRUE
A37: =A34+1 -> 6600202 | B37: =MOD(A37,100)&"级城参与奖励" -> 2级城参与奖励 | C37: =IF(A37="","",IF((COUNTIFS(A:A,A37))>1,"ID重复","")) | D37: 7003 | E37: =INDEX([1]道具配置表!$D:$D,MATCH(D37,[1]道具配置表!$A:$A,0)) -> 1银币（立即使用，不进背包） | F37: =F34+60 -> 360 | K37: 1 | M37: TRUE
C38: =IF(A38="","",IF((COUNTIFS(A:A,A38))>1,"ID重复","")) | D38: 6160 | E38: =INDEX([1]道具配置表!$D:$D,MATCH(D38,[1]道具配置表!$A:$A,0)) -> 1分钟训练加速 | F38: =F35+20 -> 120 | K38: 1 | M38: TRUE
C39: =IF(A39="","",IF((COUNTIFS(A:A,A39))>1,"ID重复","")) | D39: 6180 | E39: =INDEX([1]道具配置表!$D:$D,MATCH(D39,[1]道具配置表!$A:$A,0)) -> 1分钟治疗加速 | F39: =F36+10 -> 60 | K39: 1 | M39: TRUE
A40: =A37+1 -> 6600203 | B40: =MOD(A40,100)&"级城参与奖励" -> 3级城参与奖励 | C40: =IF(A40="","",IF((COUNTIFS(A:A,A40))>1,"ID重复","")) | D40: 7003 | E40: =INDEX([1]道具配置表!$D:$D,MATCH(D40,[1]道具配置表!$A:$A,0)) -> 1银币（立即使用，不进背包） | F40: =F37+60 -> 420 | K40: 1 | M40: TRUE
...

Sheet #配表须知
A1: 分表须知
B2: * 每个策划占用10万ID段
B3: * 新增xlsx后需要将新表第一行pb名字和分表配置里对应起来(参考已有分表A1单元格的写法)
B4: * 告知服务器同学添加加载新分表的代码（ResMapAllServerLite.java.conv）
B5: * 新增分表后需转《奖励分表配置》并提交，后续只需要修改自己的分表即可
K10: 奖励随机流程
J12: 1. 产出【绝对概率】道具 | K12: 2. 产出【相对权重】道具 | L12: 3. 将第1步，第2步随机结果合并返回
J14: 1.1对每个绝对概率道具进行一次随机，决定出不出 | K14: 2.1 将所有配置了相对权重的道具组建一个随机池子
J16: 1.2 绝对概率配置范围为【0, 1】，配1必出，配置0必不出（用于预配置） | K16: 2.2 如果配置了二项权重，则从最大最小两个数字中随机选一个数字n
K18: 2.3 如果没配置二项权重，从最小最大数量范围中随机一个数字
K20: 2.4 随机数为0不进行相对权重随机，随机数大于池子大小全出

Sheet #TID_base_up
A1: 旧Key | B1: 新Key | C1: 文本
