Workbook

Sheet 奖励配置表
A1: convert(ResReward.proto, table_RewardConfData, RewardConfData_0.pbin) | G1: 相对随机配置
A2: 奖励ID | B2: 策划描述 | C2: 道具id | D2: 道具名称 | E2: 道具数量 | F2: 道具价值(帝国币) | G2: 相对权重最小个数 | H2: 相对权重最大个数 | I2: 二项权重 | J2: 相对权重（整数） | K2: 绝对概率[0,1] | L2: 过期时间 | M2: 自定义顺序
A3: id | C3: item.id | E3: item.num | G3: minNum | H3: maxNum | I3: numWeight[;] | J3: item.relativeWeight | K3: item.absoluteProbability | L3: item.expire | M3: customizedOrder
A4: 101 | B4: 初始账号道具-匹配第一章总共奖励 | C4: 6120 | D4: =VLOOKUP(C4,[1]道具配置表!$A:$D,4,FALSE) -> 1分钟建造加速 | E4: 30 | F4: {=INDEX([2]道具配置表!T:T,MATCH(C4,[2]道具配置表!A:A,0))*E4} -> 1800 | K4: 1
C5: 6121 | D5: =VLOOKUP(C5,[1]道具配置表!$A:$D,4,FALSE) -> 5分钟建造加速 | E5: 24 | F5: {=INDEX([2]道具配置表!T:T,MATCH(C5,[2]道具配置表!A:A,0))*E5} -> 7200 | K5: 1
C6: 6122 | D6: =VLOOKUP(C6,[1]道具配置表!$A:$D,4,FALSE) -> 10分钟建造加速 | E6: 6 | F6: {=INDEX([2]道具配置表!T:T,MATCH(C6,[2]道具配置表!A:A,0))*E6} -> 3600 | K6: 1
C7: 6123 | D7: =VLOOKUP(C7,[1]道具配置表!$A:$D,4,FALSE) -> 15分钟建造加速 | E7: 2 | F7: {=INDEX([2]道具配置表!T:T,MATCH(C7,[2]道具配置表!A:A,0))*E7} -> 1800 | K7: 1
C8: 6124 | D8: =VLOOKUP(C8,[1]道具配置表!$A:$D,4,FALSE) -> 30分钟建造加速 | E8: 2 | F8: {=INDEX([2]道具配置表!T:T,MATCH(C8,[2]道具配置表!A:A,0))*E8} -> 3600 | K8: 1
C9: 6125 | D9: =VLOOKUP(C9,[1]道具配置表!$A:$D,4,FALSE) -> 60分钟建造加速 | E9: 1 | F9: {=INDEX([2]道具配置表!T:T,MATCH(C9,[2]道具配置表!A:A,0))*E9} -> 3600 | K9: 1
C10: 6140 | D10: =VLOOKUP(C10,[1]道具配置表!$A:$D,4,FALSE) -> 1分钟科技加速 | E10: 30 | F10: {=INDEX([2]道具配置表!T:T,MATCH(C10,[2]道具配置表!A:A,0))*E10} -> 1800 | K10: 1
C11: 6141 | D11: =VLOOKUP(C11,[1]道具配置表!$A:$D,4,FALSE) -> 5分钟科技加速 | E11: 24 | F11: {=INDEX([2]道具配置表!T:T,MATCH(C11,[2]道具配置表!A:A,0))*E11} -> 7200 | K11: 1
C12: 6142 | D12: =VLOOKUP(C12,[1]道具配置表!$A:$D,4,FALSE) -> 10分钟科技加速 | E12: 6 | F12: {=INDEX([2]道具配置表!T:T,MATCH(C12,[2]道具配置表!A:A,0))*E12} -> 3600 | K12: 1
C13: 6143 | D13: =VLOOKUP(C13,[1]道具配置表!$A:$D,4,FALSE) -> 15分钟科技加速 | E13: 2 | F13: {=INDEX([2]道具配置表!T:T,MATCH(C13,[2]道具配置表!A:A,0))*E13} -> 1800 | K13: 1
C14: 6144 | D14: =VLOOKUP(C14,[1]道具配置表!$A:$D,4,FALSE) -> 30分钟科技加速 | E14: 2 | F14: {=INDEX([2]道具配置表!T:T,MATCH(C14,[2]道具配置表!A:A,0))*E14} -> 3600 | K14: 1
C15: 6145 | D15: =VLOOKUP(C15,[1]道具配置表!$A:$D,4,FALSE) -> 60分钟科技加速 | E15: 1 | F15: {=INDEX([2]道具配置表!T:T,MATCH(C15,[2]道具配置表!A:A,0))*E15} -> 3600 | K15: 1
C16: 6100 | D16: =VLOOKUP(C16,[1]道具配置表!$A:$D,4,FALSE) -> 1分钟通用加速 | E16: 60 | F16: {=INDEX([2]道具配置表!T:T,MATCH(C16,[2]道具配置表!A:A,0))*E16} -> 3600 | K16: 1
... C23: 6165 | D23: =VLOOKUP(C23,[1]道具配置表!$A:$D,4,FALSE) -> 60分钟训练加速 | E23: 1 | F23: {=INDEX([2]道具配置表!T:T,MATCH(C23,[2]道具配置表!A:A,0))*E23} -> 3600 | K23: 1
C24: 3080 | D24: =VLOOKUP(C24,[3]道具配置表!$A:$D,4,FALSE) -> 君主改名券 | E24: 1 | F24: {=INDEX([2]道具配置表!T:T,MATCH(C24,[2]道具配置表!A:A,0))*E24} -> 1 | K24: 1
C25: 6680 | D25: =VLOOKUP(C25,[3]道具配置表!$A:$D,4,FALSE) -> 城市风格切换券 | E25: 1 | F25: {=INDEX([2]道具配置表!T:T,MATCH(C25,[2]道具配置表!A:A,0))*E25} -> 1 | K25: 1
C26: 7003 | D26: =VLOOKUP(C26,[3]道具配置表!$A:$D,4,FALSE) -> 1银币（立即使用，不进背包） | E26: 200 | F26: {=INDEX([2]道具配置表!T:T,MATCH(C26,[2]道具配置表!A:A,0))*E26} -> 200 | K26: 1
C27: 50080 | D27: =VLOOKUP(C27,[1]道具配置表!$A:$D,4,FALSE) -> 24小时紧急和平护盾 | E27: 1 | F27: {=INDEX([2]道具配置表!T:T,MATCH(C27,[2]道具配置表!A:A,0))*E27} -> 86400 | K27: 1
C28: 601 | D28: =VLOOKUP(C28,[1]道具配置表!$A:$D,4,FALSE) -> 定点迁城（限时） | E28: 5 | F28: {=INDEX([2]道具配置表!T:T,MATCH(C28,[2]道具配置表!A:A,0))*E28} -> 5 | K28: 1
C29: 20000 | D29: =VLOOKUP(C29,[3]道具配置表!$A:$D,4,FALSE) -> 技能点1 | E29: 1000 | F29: {=INDEX([2]道具配置表!T:T,MATCH(C29,[2]道具配置表!A:A,0))*E29} -> 0 | K29: 1
C30: 2061 | D30: =VLOOKUP(C30,[4]道具配置表!$A:$D,4,FALSE) -> 伟大蓝图 | E30: 690 | F30: {=INDEX([2]道具配置表!T:T,MATCH(C30,[2]道具配置表!A:A,0))*E30} -> 690 | K30: 1
C31: 7227 | D31: =VLOOKUP(C31,[4]道具配置表!$A:$D,4,FALSE) -> 经验书*1000 | E31: 10 | F31: {=INDEX([2]道具配置表!T:T,MATCH(C31,[2]道具配置表!A:A,0))*E31} -> 10000 | K31: 1
A32: 102 | B32: 邮件系统测试专用奖励 | C32: 102 | D32: =VLOOKUP(C32,[3]道具配置表!$A:$D,4,FALSE) -> 1食物 | E32: 1 | F32: {=INDEX([2]道具配置表!T:T,MATCH(C32,[2]道具配置表!A:A,0))*E32} -> 1 | K32: 1
A33: 103 | B33: 预制账号用_外部体验向奖励 | C33: 50080 | D33: =VLOOKUP(C33,[1]道具配置表!$A:$D,4,FALSE) -> 24小时紧急和平护盾 | E33: 10 | F33: {=INDEX([2]道具配置表!T:T,MATCH(C33,[2]道具配置表!A:A,0))*E33} -> 864000 | K33: 1
C34: 6041 | D34: =VLOOKUP(C34,[3]道具配置表!$A:$D,4,FALSE) -> 1小时训练加速 | E34: 9999 | F34: {=INDEX([2]道具配置表!T:T,MATCH(C34,[2]道具配置表!A:A,0))*E34} -> 35996400 | K34: 1
C35: 6031 | D35: =VLOOKUP(C35,[3]道具配置表!$A:$D,4,FALSE) -> 1小时科技加速 | E35: 9999 | F35: {=INDEX([2]道具配置表!T:T,MATCH(C35,[2]道具配置表!A:A,0))*E35} -> 35996400 | K35: 1
C36: 2005 | D36: =VLOOKUP(C36,[3]道具配置表!$A:$D,4,FALSE) -> 新手奖池招募券 | E36: 10 | F36: {=INDEX([2]道具配置表!T:T,MATCH(C36,[2]道具配置表!A:A,0))*E36} -> 0 | K36: 1
C37: 6680 | D37: =VLOOKUP(C37,[3]道具配置表!$A:$D,4,FALSE) -> 城市风格切换券 | E37: 5 | F37: {=INDEX([2]道具配置表!T:T,MATCH(C37,[2]道具配置表!A:A,0))*E37} -> 5 | K37: 1
C38: 4000 | D38: =VLOOKUP(C38,[3]道具配置表!$A:$D,4,FALSE) -> 知识卷轴X1 | E38: 9999 | F38: {=INDEX([2]道具配置表!T:T,MATCH(C38,[2]道具配置表!A:A,0))*E38} -> 0 | K38: 1
C39: 15000 | D39: =VLOOKUP(C39,[3]道具配置表!$A:$D,4,FALSE) -> 寻访令 | E39: 100 | F39: {=INDEX([2]道具配置表!T:T,MATCH(C39,[2]道具配置表!A:A,0))*E39} -> 10000 | K39: 1
C40: 7001 | D40: =VLOOKUP(C40,[3]道具配置表!$A:$D,4,FALSE) -> 1钻石（立即使用，不进背包） | E40: 50000 | F40: {=INDEX([2]道具配置表!T:T,MATCH(C40,[2]道具配置表!A:A,0))*E40} -> 50000 | K40: 1
C41: 7003 | D41: =VLOOKUP(C41,[3]道具配置表!$A:$D,4,FALSE) -> 1银币（立即使用，不进背包） | E41: 50000 | F41: {=INDEX([2]道具配置表!T:T,MATCH(C41,[2]道具配置表!A:A,0))*E41} -> 50000 | K41: 1
C42: 7007 | D42: =VLOOKUP(C42,[3]道具配置表!$A:$D,4,FALSE) -> 100铜币（立即使用，不进背包） | E42: 50000 | F42: {=INDEX([2]道具配置表!T:T,MATCH(C42,[2]道具配置表!A:A,0))*E42} -> 5000000 | K42: 1
A43: 104 | B43: 边玩边下奖励-杂项表 | C43: 102 | D43: =VLOOKUP(C43,[3]道具配置表!$A:$D,4,FALSE) -> 1食物 | E43: 10000 | F43: {=INDEX([2]道具配置表!T:T,MATCH(C43,[2]道具配置表!A:A,0))*E43} -> 10000 | K43: 1
C44: 101 | D44: =VLOOKUP(C44,[3]道具配置表!$A:$D,4,FALSE) -> 1木材 | E44: 10000 | F44: {=INDEX([2]道具配置表!T:T,MATCH(C44,[2]道具配置表!A:A,0))*E44} -> 10000 | K44: 1
C45: 103 | D45: =VLOOKUP(C45,[3]道具配置表!$A:$D,4,FALSE) -> 1石头 | E45: 10000 | F45: {=INDEX([2]道具配置表!T:T,MATCH(C45,[2]道具配置表!A:A,0))*E45} -> 10000 | K45: 1
C46: 7003 | D46: =VLOOKUP(C46,[3]道具配置表!$A:$D,4,FALSE) -> 1银币（立即使用，不进背包） | E46: 100 | F46: {=INDEX([2]道具配置表!T:T,MATCH(C46,[2]道具配置表!A:A,0))*E46} -> 100 | K46: 1
...

Sheet #奖励分表配置
A1: 修改后不需要转表
A2: id | B2: 每人占用10万ID段， 标识占用哪个10万段 | C2: 奖励分表pb名 | D2: 占用ID端最小值 | E2: 占用ID端最大值 | F2: 负责人
A3: id | B3: occupyIdRange | C3: pbName | D3: idRangeStart | E3: idRangeEnd
A4: 1 | B4: 0 | C4: RewardConfData | D4: 1 | E4: 99999
A5: 2 | B5: 10 | C5: RewardConfData_1 | D5: 1000000 | E5: 1099999 | F5: algao
A6: 3 | B6: 11 | C6: RewardConfData_3 | D6: 1100000 | E6: 1199999 | F6: louieshen
A7: 4 | B7: 12 | C7: 七彩石 | D7: 1200000 | E7: 1299999 | F7: 七彩石
A8: 5 | B8: 13 | C8: RewardConfData_2 | D8: 1300000 | E8: 1399999 | F8: altmansun
A9: 6 | B9: 14 | D9: 1400000 | E9: 1499999
A10: 7 | B10: 15 | C10: RewardConfData_4 | D10: 1500000 | E10: 1599999 | F10: halelin
A11: 8 | B11: 16 | D11: 1600000 | E11: 1699999
A12: 9 | B12: 17 | C12: RewardConfData_7 | D12: 1700000 | E12: 1799999 | F12: lotxu
A13: 10 | B13: 18 | C13: RewardConfData_10 | D13: 1800000 | E13: 1899999 | F13: charliejia
A14: 11 | B14: 19 | C14: RewardConfData_5 | D14: 1900000 | E14: 1999999 | F14: Jensencheng
A15: 12 | B15: 20 | C15: RewardConfData_12 | D15: 2000000 | E15: 2099999 | F15: jianzili
A16: 13 | B16: 21 | C16: RewardConfData_13 | D16: 2100000 | E16: 2199999 | F16: grantlu
A17: 14 | B17: 22 | C17: RewardConfData_14 | D17: 2200000 | E17: 2299999 | F17: waaaghwang
A18: 15 | B18: 23 | C18: RewardConfData_15 | D18: 2300000 | E18: 2399999 | F18: pinoyao
A19: 16 | B19: 24 | C19: RewardConfData_16 | D19: 2400000 | E19: 2499999 | F19: reniexu
A20: 17 | B20: 25 | C20: RewardConfData_17 | D20: 2500000 | E20: 2599999 | F20: hedyxu
A21: 18 | B21: 26 | C21: RewardConfData_18 | D21: 2600000 | E21: 2699999 | F21: yuweitu
A22: 19 | B22: 66 | C22: RewardConfData_66 | D22: 6600000 | E22: 6699999 | F22: proqin
A23: 20 | B23: 29 | C23: RewardConfData_20 | D23: 2900000 | E23: 2999999 | F23: cardixu
B24: 严格使用自己专属的ID段，严禁使用他人ID段，切记

Sheet #配表须知
A1: 分表须知
B2: * 每个策划占用10万ID段
B3: * 新增xlsx后需要将新表第一行pb名字和分表配置里对应起来(参考已有分表A1单元格的写法)
B4: * 告知服务器同学添加加载新分表的代码（ResMapAllServerLite.java.conv）
B5: * 新增分表后需转《奖励分表配置》并提交，后续只需要修改自己的分表即可
K10: 奖励随机流程
J12: 1. 产出【绝对概率】道具 | K12: 2. 产出【相对权重】道具 | L12: 3. 将第1步，第2步随机结果合并返回
J14: 1.1对每个绝对概率道具进行一次随机，决定出不出 | K14: 2.1 将所有配置了相对权重的道具组建一个随机池子
J16: 1.2 绝对概率配置范围为【0, 1】，配1必出，配置0必不出（用于预配置） | K16: 2.2 如果配置了二项权重，则从最大最小两个数字中随机选一个数字n
K18: 2.3 如果没配置二项权重，从最小最大数量范围中随机一个数字
K20: 2.4 随机数为0不进行相对权重随机，随机数大于池子大小全出

Sheet #TID_base_up
A1: 旧Key | B1: 新Key | C1: 文本
