Workbook

Sheet 支线子任务
A1: convert(ResTask.proto, table_LineTaskConf, BranchLineTaskConf.pbin)
A2: 任务ID | B2: 城镇中心等级 | C2: 分组 | D2: 序号 | E2: ID规划 | F2: 任务名称 | G2: 任务前缀 | H2: 任务数值 | I2: 任务单位 | J2: 任务名称(源文本) | K2: 任务ID辅助 | L2: 前置主线任务 | M2: 前置主线ID | N2: 解锁条件文本 | O2: 解锁条件关系 | P2: 解锁条件组 | Q2: 完成条件关系 | R2: 完成条件文本 | S2: 完成条件组 | T2: 进行中条件关系 | U2: 进行条件 | V2: 跳转名称 | W2: 跳转id | X2: 任务描述 | Y2: 图集 | Z2: sprite | AA2: 排序 | AB2: 奖励 | AC2: 替换奖励{检测是否完成的任务id;替换的奖励} | AD2: 排序分组 | AE2: 排序编号 | AF2: 是否隐藏任务 | AG2: 是否主线道具奖励类任务 | AH2: 是否是主线任务 | AI2: 任务进度显示比例(总数) | AJ2: 任务进度显示比例(已完成) | AK2: 是否自动领奖 | AL2: 是否隐藏任务
A3: id | F3: taskName | O3: common.resTriggerConditionGroup.conditionRelation | P3: common.resTriggerConditionGroup.condition.condOneOf | Q3: common.resCompleteConditionGroup.conditionRelation | S3: common.resCompleteConditionGroup.condition.condOneOf | T3: common.resDoingConditionGroup.conditionRelation | U3: common.resDoingConditionGroup.condition.condOneOf | W3: common.jumpTo | X3: taskDesc | Y3: atlas | Z3: sprite | AA3: order | AB3: common.rewardId | AC3: common.replaceReward{taskId;replaceRewardId} | AF3: hideBeforeComplete | AG3: isItemRewardShowTask | AH3: isMainTaskLine | AI3: showRatioTotal | AJ3: showRatioFinish | AK3: common.isAutoReward | AL3: isHide
A4: =10000000+B4*100000+C4*1000+D4*10 -> 10401010 | B4: 4 | C4: 1 | D4: =IF(B4=B3,D3+1,1) -> 1 | E4: 主线任务链 | F4: TID_BranchLineTaskConf_10410115_taskName_GL_Main | G4: 升级居民房舍至 | H4: 4 | I4: 级 | J4: =G4&H4&I4 -> 升级居民房舍至4级 | K4: =A4 -> 10401010 | M4: 667710 | N4: taskReward{taskId:@@@} | O4: 条件与 | P4: taskComplete{taskId:667710} | Q4: 条件与 | R4: buildingLevelUp{buildingType:202,buildingLevel:@@@} | S4: =SUBSTITUTE(R4,"@@@",H4) -> buildingLevelUp{buildingType:202,buildingLevel:4} | T4: 条件与 | V4: 跳转到居民房舍【升级】菜单按钮 | W4: 100178 | Y4: icon_task | Z4: icon_task_p3_01 | AB4: 6622004
A5: 10401020 | B5: 4 | C5: 1 | D5: 2 | E5: 主线任务链 | F5: TID_BranchLineTaskConf_10401050_taskName_GL_Main | J5: [启程之光]累计招募5次 | K5: =A5 -> 10401020 | L5: =F4 -> TID_BranchLineTaskConf_10410115_taskName_GL_Main | M5: =A4 -> 10401010 | N5: taskReward{taskId:@@@} | O5: 条件与 | P5: taskComplete{taskId:667710} | Q5: 条件与 | S5: statisticReach{type:"HeroRecruitForTypeEvent2",value:1} | T5: 条件与 | V5: 跳转到城墙【升级】菜单按钮7039 | W5: 100192 | Y5: icon_task | Z5: icon_task_p3_01 | AB5: 6622004
A6: =10000000+B6*100000+C6*1000+D6*10 -> 10401030 | B6: 4 | C6: 1 | D6: =IF(B6=B5,D5+1,1) -> 3 | E6: 主线任务链 | F6: TID_BranchLineTaskConf_30000001_01_taskName_GL_Main | G6: 通过经验书升级任意英雄至 | H6: 5 | I6: 级 | J6: =G6&H6&I6 -> 通过经验书升级任意英雄至5级 | K6: =A6 -> 10401030 | L6: =F5 -> TID_BranchLineTaskConf_10401050_taskName_GL_Main | M6: =A5 -> 10401020 | N6: taskReward{taskId:@@@} | O6: 条件与 | P6: taskComplete{taskId:667710} | Q6: 条件与 | R6: heroLevelUp{heroId:0,level:@@@} | S6: =SUBSTITUTE(R6,"@@@",H6) -> heroLevelUp{heroId:0,level:5} | T6: 条件与 | V6: 备注：新手期结束右下角只有三个hud按键，需要先暂时用到联盟的跳转才能跳到英雄上 | W6: 7110 | Y6: icon_task | Z6: icon_task_p3_01 | AB6: 6622004
A7: =10000000+B7*100000+C7*1000+D7*10 -> 10401040 | B7: 4 | C7: 1 | D7: =IF(B7=B6,D6+1,1) -> 4 | E7: 主线任务链 | F7: TID_BranchLineTaskConf_20000001_01_taskName_GL_Main | G7: 完成海岛战弈第 | H7: 1 | I7: 关 | J7: =G7&H7&I7 -> 完成海岛战弈第1关 | K7: =A7 -> 10401040 | L7: =F6 -> TID_BranchLineTaskConf_30000001_01_taskName_GL_Main | M7: =A6 -> 10401030 | N7: taskReward{taskId:@@@} | O7: 条件与 | P7: taskComplete{taskId:667710} | Q7: 条件与 | R7: autoChessPassLevel { level: @@@,value:1} | S7: =SUBSTITUTE(R7,"@@@",H7) -> autoChessPassLevel { level: 1,value:1} | T7: 条件与 | W7: 100342 | Y7: icon_task | Z7: icon_task_p3_01 | AB7: 6622004
A8: =10000000+B8*100000+C8*1000+D8*10 -> 10401050 | B8: 4 | C8: 1 | D8: =IF(B8=B7,D7+1,1) -> 5 | E8: 主线任务链 | F8: TID_BranchLineTaskConf_peasant_1_taskName_GL_Main | G8: 训练农民到16名 | J8: =G8&H8&I8 -> 训练农民到16名 | K8: =A8 -> 10401050 | L8: =F7 -> TID_BranchLineTaskConf_20000001_01_taskName_GL_Main | M8: =A7 -> 10401040 | N8: taskReward{taskId:@@@} | O8: 条件与 | Q8: 条件与 | R8: statisticReach{type:"InnerPeasantTrainEvent",value:16} | S8: =SUBSTITUTE(R8,"@@@",H8) -> statisticReach{type:"InnerPeasantTrainEvent",value:16} | T8: 条件与 | U8: buildingLevelUpNow{buildingType:205,buildingWantLevel:30} | W8: 100190 | Y8: icon_task | Z8: icon_task_p3_01 | AB8: 6622004
A9: =10000000+B9*100000+C9*1000+D9*10 -> 10401060 | B9: 4 | C9: 1 | D9: =IF(B9=B8,D8+1,1) -> 6 | E9: 主线任务链 | F9: TID_BranchLineTaskConf_10601031_taskName_GL_Main | G9: 派遣农民进伐木场 | J9: =G9&H9&I9 -> 派遣农民进伐木场 | K9: =A9 -> 10401060 | L9: =F8 -> TID_BranchLineTaskConf_peasant_1_taskName_GL_Main | M9: =A8 -> 10401050 | N9: taskReward{taskId:@@@} | O9: 条件与 | Q9: 条件与 | R9: deployedFarmerToBuildingResource{cityElementType:204,value:1} | S9: =SUBSTITUTE(R9,"@@@",H9) -> deployedFarmerToBuildingResource{cityElementType:204,value:1} | T9: 条件与 | U9: buildingLevelUpNow{buildingType:205,buildingWantLevel:30} | V9: 跳转到伐木场【升级】菜单按钮7011 | W9: 100212 | Y9: icon_task | Z9: icon_task_p3_01 | AB9: 6622006
A10: =10000000+B10*100000+C10*1000+D10*10 -> 10401070 | B10: 4 | C10: 1 | D10: =IF(B10=B9,D9+1,1) -> 7 | E10: 主线任务链 | F10: TID_BranchLineTaskConfSpecial_204_1_taskName_GL_Main | G10: 升级伐木场至 | H10: 4 | I10: 级 | J10: =G10&H10&I10 -> 升级伐木场至4级 | K10: =A10 -> 10401070 | L10: =F9 -> TID_BranchLineTaskConf_10601031_taskName_GL_Main | M10: =A9 -> 10401060 | N10: taskReward{taskId:@@@} | O10: 条件与 | Q10: 条件与 | R10: buildingLevelUp{buildingType:204,buildingLevel:@@@} | S10: =SUBSTITUTE(R10,"@@@",H10) -> buildingLevelUp{buildingType:204,buildingLevel:4} | T10: 条件与 | U10: buildingLevelUpNow{buildingType:204,buildingWantLevel:20} | V10: 跳转到磨坊【升级】菜单按钮7009 | W10: 100180 | Y10: icon_task | Z10: icon_task_p3_01 | AB10: 6622006
A11: =10000000+B11*100000+C11*1000+D11*10 -> 10401080 | B11: 4 | C11: 1 | D11: =IF(B11=B10,D10+1,1) -> 8 | E11: 主线任务链 | F11: TID_BranchLineTaskConfSpecial_203_1_taskName_GL_Main | G11: 升级磨坊至 | H11: 4 | I11: 级 | J11: =G11&H11&I11 -> 升级磨坊至4级 | K11: =A11 -> 10401080 | L11: =F10 -> TID_BranchLineTaskConfSpecial_204_1_taskName_GL_Main | M11: =A10 -> 10401070 | N11: taskReward{taskId:@@@} | O11: 条件与 | Q11: 条件与 | R11: buildingLevelUp{buildingType:203,buildingLevel:@@@} | S11: =SUBSTITUTE(R11,"@@@",H11) -> buildingLevelUp{buildingType:203,buildingLevel:4} | T11: 条件与 | U11: buildingLevelUpNow{buildingType:203,buildingWantLevel:30} | V11: 跳转到旅店【建造】确认 | W11: 100179 | Y11: icon_task | Z11: icon_task_p3_01 | AB11: 6622004
A12: =10000000+B12*100000+C12*1000+D12*10 -> 10401090 | B12: 4 | C12: 1 | D12: =IF(B12=B11,D11+1,1) -> 9 | E12: 主线任务链 | F12: TID_BranchLineTaskConf_20000001_02_taskName_GL_Main | G12: 完成海岛战弈第 | H12: 2 | I12: 关 | J12: =G12&H12&I12 -> 完成海岛战弈第2关 | K12: =A12 -> 10401090 | L12: =F11 -> TID_BranchLineTaskConfSpecial_203_1_taskName_GL_Main | M12: =A11 -> 10401080 | N12: taskReward{taskId:@@@} | O12: 条件与 | Q12: 条件与 | R12: autoChessPassLevel { level: @@@,value:1} | S12: =SUBSTITUTE(R12,"@@@",H12) -> autoChessPassLevel { level: 2,value:1} | T12: 条件与 | W12: 100342 | Y12: icon_task | Z12: icon_task_p3_01 | AB12: 6622004
A13: =10000000+B13*100000+C13*1000+D13*10 -> 10401100 | B13: 4 | C13: 1 | D13: =IF(B13=B12,D12+1,1) -> 10 | E13: 主线任务链 | F13: TID_BranchLineTaskConf_10510114_taskName_GL_Main | G13: 任意英雄固有技能升级至 | H13: 5 | I13: 级 | J13: =G13&H13&I13 -> 任意英雄固有技能升级至5级 | K13: =A13 -> 10401100 | L13: =F12 -> TID_BranchLineTaskConf_20000001_02_taskName_GL_Main | M13: =A12 -> 10401090 | N13: taskReward{taskId:@@@} | O13: 条件与 | Q13: 条件与 | S13: alwaysTrue{} | T13: 条件与 | V13: 备注：新手期结束右下角只有三个hud按键，需要先暂时用到联盟的跳转才能跳到英雄上 | W13: 7110 | Y13: icon_task | Z13: icon_task_p3_01 | AB13: 6622004 | AK13: TRUE | AL13: TRUE
A14: =10000000+B14*100000+C14*1000+D14*10 -> 10401110 | B14: 4 | C14: 1 | D14: =IF(B14=B13,D13+1,1) -> 11 | E14: 主线任务链 | F14: TID_BranchLineTaskConf_10401030_2_taskName_GL_Main | G14: 训练1级剑士 | H14: 1 | I14: 名 | J14: =G14&H14&I14 -> 训练1级剑士1名 | K14: =A14 -> 10401110 | L14: =F13 -> TID_BranchLineTaskConf_10510114_taskName_GL_Main | M14: =A13 -> 10401100 | N14: taskReward{taskId:@@@} | O14: 条件与 | Q14: 条件或 | S14: soldierTraining{soldierType1:0,soldierLevel:1} | T14: 条件与 | U14: soldierTraining{soldierType1:0,soldierLevel:1} | V14: 【海外】跳转到剑士营【训练】700名1级剑士 | W14: 100207 | Y14: icon_task | Z14: icon_task_p3_01 | AB14: 6622004
S15: soldierTrain{soldierType1:SNV_Swordsman,soldierLevel:0,value:1}
A16: =10000000+B16*100000+C16*1000+D16*10 -> 10401120 | B16: 4 | C16: 1 | D16: =IF(B16=B14,D14+1,1) -> 12 | E16: 主线任务链 | F16: TID_BranchLineTaskConf_10401020_taskName_GL_Main | G16: 升级剑士营至 | H16: 4 | I16: 级 | J16: =G16&H16&I16 -> 升级剑士营至4级 | K16: =A16 -> 10401120 | L16: =F14 -> TID_BranchLineTaskConf_10401030_2_taskName_GL_Main | M16: =A14 -> 10401110 | N16: taskReward{taskId:@@@} | O16: 条件与 | Q16: 条件与 | R16: buildingLevelUp{buildingType:206,buildingLevel:@@@} | S16: =SUBSTITUTE(R16,"@@@",H16) -> buildingLevelUp{buildingType:206,buildingLevel:4} | T16: 条件与 | V16: 跳转到剑士营【升级】菜单按钮7015 | W16: 100182 | Y16: icon_task | Z16: icon_task_p3_01 | AB16: 6622004
A17: =10000000+B17*100000+C17*1000+D17*10 -> 10401130 | B17: 4 | C17: 1 | D17: =IF(B17=B16,D16+1,1) -> 13 | E17: 主线任务链 | F17: TID_BranchLineTaskConf_20000001_03_taskName_GL_Main | G17: 完成海岛战弈第 | H17: 3 | I17: 关 | J17: =G17&H17&I17 -> 完成海岛战弈第3关 | K17: =A17 -> 10401130 | L17: =F16 -> TID_BranchLineTaskConf_10401020_taskName_GL_Main | M17: =A16 -> 10401120 | N17: taskReward{taskId:@@@} | O17: 条件与 | Q17: 条件与 | R17: autoChessPassLevel { level: @@@,value:1} | S17: =SUBSTITUTE(R17,"@@@",H17) -> autoChessPassLevel { level: 3,value:1} | T17: 条件与 | W17: 100342 | Y17: icon_task | Z17: icon_task_p3_01 | AB17: 6622004
A18: =10000000+B18*100000+C18*1000+D18*10 -> 10401140 | B18: 4 | C18: 1 | D18: =IF(B18=B17,D17+1,1) -> 14 | E18: 主线任务链 | F18: TID_BranchLineTaskConf_30000001_02_taskName_GL_Main | G18: 通过经验书升级任意英雄至 | H18: 8 | I18: 级 | J18: =G18&H18&I18 -> 通过经验书升级任意英雄至8级 | K18: =A18 -> 10401140 | L18: =F20 -> TID_BranchLineTaskConf_222_1_taskName_GL_Main | M18: =A17 -> 10401130 | N18: taskReward{taskId:@@@} | O18: 条件与 | Q18: 条件与 | R18: heroLevelUp{heroId:0,level:@@@} | S18: =SUBSTITUTE(R18,"@@@",H18) -> heroLevelUp{heroId:0,level:8} | T18: 条件与 | V18: 备注：新手期结束右下角只有三个hud按键，需要先暂时用到联盟的跳转才能跳到英雄上 | W18: 7110 | Y18: icon_task | Z18: icon_task_p3_01 | AB18: 6622005
A19: =10000000+B19*100000+C19*1000+D19*10 -> 10401150 | B19: 4 | C19: 1 | D19: =IF(B19=B18,D18+1,1) -> 15 | E19: 主线任务链 | F19: TID_BranchLineTaskConf_10410121_taskName_GL_Main | G19: 升级城镇中心至 | H19: 5 | I19: 级 | J19: =G19&H19&I19 -> 升级城镇中心至5级 | K19: =A19 -> 10401150 | L19: =F21 -> TID_BranchLineTaskConf_215_1_taskName_GL_Main | M19: =A18 -> 10401140 | N19: taskReward{taskId:@@@} | O19: 条件与 | Q19: 条件与 | R19: buildingLevelUp{buildingType:201,buildingLevel:@@@} | S19: =SUBSTITUTE(R19,"@@@",H19) -> buildingLevelUp{buildingType:201,buildingLevel:5} | T19: 条件与 | U19: buildingLevelUpNow{buildingType:201,buildingWantLevel:20} | V19: 跳转到城镇中心【升级】菜单按钮7001 | W19: 100177 | Y19: icon_task | Z19: icon_task_p3_01 | AB19: 6622005
A20: =10000000+B20*100000+C20*1000+D20*10 -> 10401160 | B20: 4 | C20: 1 | D20: =IF(B20=B19,D19+1,1) -> 16 | E20: 主线任务链 | F20: TID_BranchLineTaskConf_222_1_taskName_GL_Main | G20: 升级治疗房舍至 | H20: 4 | I20: 级 | J20: =G20&H20&I20 -> 升级治疗房舍至4级 | K20: =A20 -> 10401160 | L20: =F33 -> TID_BranchLineTaskConf_10410122_taskName_GL_Main | M20: =A19 -> 10401150 | N20: taskReward{taskId:@@@} | O20: 条件与 | Q20: 条件与 | R20: buildingLevelUp{buildingType:222,buildingLevel:@@@} | S20: =SUBSTITUTE(R20,"@@@",H20) -> buildingLevelUp{buildingType:222,buildingLevel:4} | T20: 条件与 | U20: buildingLevelUpNow{buildingType:222,buildingWantLevel:20} | V20: 跳转到治疗房舍【升级】菜单按钮7041 | W20: 100185 | Y20: icon_task | Z20: icon_task_p3_01 | AB20: 6622005
A21: =10000000+B21*100000+C21*1000+D21*10 -> 10401170 | B21: 4 | C21: 1 | D21: =IF(B21=B20,D20+1,1) -> 17 | E21: 主线任务链 | F21: TID_BranchLineTaskConf_215_1_taskName_GL_Main | G21: 升级城墙至 | H21: 4 | I21: 级 | J21: =G21&H21&I21 -> 升级城墙至4级 | K21: =A21 -> 10401170 | L21: =F34 -> TID_BranchLineTaskConf_226_1_taskName_GL_Main | M21: =A20 -> 10401160 | N21: taskReward{taskId:@@@} | O21: 条件与 | Q21: 条件与 | R21: buildingLevelUp{buildingType:215,buildingLevel:@@@} | S21: =SUBSTITUTE(R21,"@@@",H21) -> buildingLevelUp{buildingType:215,buildingLevel:4} | T21: 条件与 | U21: buildingLevelUpNow{buildingType:215,buildingWantLevel:30} | V21: 跳转到城墙【升级】菜单按钮7039 | W21: 100184 | Y21: icon_task | Z21: icon_task_p3_01 | AB21: 6622004
A22: =10000000+B22*100000+C22*1000+D22*10 -> 10501010 | B22: 5 | C22: 1 | D22: 1 | E22: 主线任务链 | F22: TID_MainSubTaskConf_1111010_taskName_CN_Main | G22: 建造 | H22: 1 | I22: 个学院 | J22: =G22&H22&I22 -> 建造1个学院 | K22: =A22 -> 10501010 | L22: =F35 -> TID_BranchLineTaskConf_215_2_taskName_GL_Main | M22: =A21 -> 10401170 | N22: taskReward{taskId:@@@} | O22: 条件与 | Q22: 条件与 | R22: buildingSum{buildingType:211,sum:1} | S22: =SUBSTITUTE(R22,"@@@",H22) -> buildingSum{buildingType:211,sum:1} | T22: 条件与 | W22: 100305 | Y22: icon_task | Z22: icon_task_p3_01 | AB22: 6622004
A23: =10000000+B23*100000+C23*1000+D23*10 -> 10501020 | B23: 5 | C23: 1 | D23: 2 | E23: 主线任务链 | F23: TID_BranchLineTaskConf_10501110_taskName_GL_Main | G23: 研究[全兵种训练速度1]科技至 | H23: 1 | I23: 级 | J23: =G23&H23&I23 -> 研究[全兵种训练速度1]科技至1级 | K23: =A23 -> 10501020 | L23: =F36 -> TID_BranchLineTaskConf_10510118_taskName_GL_Main | M23: =A22 -> 10501010 | N23: taskReward{taskId:@@@} | O23: 条件与 | Q23: 条件与 | R23: castleScienceMultiLevelUp {techId:10101,level:1,relationIfWith:true} | S23: =SUBSTITUTE(R23,"@@@",H23) -> castleScienceMultiLevelUp {techId:10101,level:1,relationIfWith:true} | T23: 条件与 | U23: scienceLevelUping{scienceId:0,wantLevel:0} | V23: 【海外】跳转到学院【研究科技】菜单按钮 | W23: 100208 | Y23: icon_task | Z23: icon_task_p3_01 | AB23: 6622005
A24: =10000000+B24*100000+C24*1000+D24*10 -> 10501030 | B24: 5 | C24: 1 | D24: 3 | E24: 主线任务链 | F24: TID_BranchLineTaskConf_211_2_taskName_GL_Main | G24: 升级学院至 | H24: 3 | I24: 级 | J24: =G24&H24&I24 -> 升级学院至3级 | K24: =A24 -> 10501030 | L24: =F37 -> TID_BranchLineTaskConf_10410111_taskName_GL_Main | M24: =A23 -> 10501020 | N24: taskReward{taskId:@@@} | O24: 条件与 | Q24: 条件与 | R24: buildingLevelUp{buildingType:211,buildingLevel:@@@} | S24: =SUBSTITUTE(R24,"@@@",H24) -> buildingLevelUp{buildingType:211,buildingLevel:3} | T24: 条件与 | U24: buildingLevelUpNow{buildingType:211,buildingWantLevel:30} | V24: 跳转到学院【升级】菜单按钮 | W24: 100328 | Y24: icon_task | Z24: icon_task_p3_01 | AB24: 6622012
A25: =10000000+B25*100000+C25*1000+D25*10 -> 10501040 | B25: 5 | C25: 1 | D25: 4 | E25: 主线任务链 | F25: TID_NewbieStepsData_2_10801110_tipsText_GL_Share | G25: 研究科技解锁 | I25: [剑士攻击1级] | J25: =G25&H25&I25 -> 研究科技解锁[剑士攻击1级] | K25: =A25 -> 10501040 | L25: =F38 -> TID_BranchLineTaskConf_10510104_taskName_GL_Main | M25: =A24 -> 10501030 | N25: taskReward{taskId:@@@} | O25: 条件与 | Q25: 条件与 | R25: castleScienceMultiLevelUp {techId:10201,level:1,relationIfWith:false} | S25: =SUBSTITUTE(R25,"@@@",H25) -> castleScienceMultiLevelUp {techId:10201,level:1,relationIfWith:false} | T25: 条件与 | U25: scienceLevelUping{scienceId:0,wantLevel:0} | V25: 【海外】跳转到学院【剑士攻击3级】菜单按钮 | W25: 100142 | Y25: icon_task | Z25: icon_task_p3_01 | AB25: 6622008
A26: =10000000+B26*100000+C26*1000+D26*10 -> 10501050 | B26: 5 | C26: 1 | D26: 5 | E26: 主线任务链 | F26: TID_BranchLineTaskConf_20000001_04_taskName_GL_Main | G26: 完成海岛战弈第 | H26: 4 | I26: 关 | J26: =G26&H26&I26 -> 完成海岛战弈第4关 | K26: =A26 -> 10501050 | L26: =F39 -> TID_BranchLineTaskConf_peasant_2_taskName_GL_Main | M26: =A25 -> 10501040 | N26: taskReward{taskId:@@@} | O26: 条件与 | Q26: 条件与 | R26: autoChessPassLevel { level: @@@,value:1} | S26: =SUBSTITUTE(R26,"@@@",H26) -> autoChessPassLevel { level: 4,value:1} | T26: 条件与 | W26: 100342 | Y26: icon_task | Z26: icon_task_p3_01 | AB26: 6622004
A27: =10000000+B27*100000+C27*1000+D27*10 -> 10501060 | B27: 5 | C27: 1 | D27: 6 | E27: 主线任务链 | F27: TID_BranchLineTaskConf_10014010_taskName_GL_Main | G27: 任意2个英雄等级提升至 | H27: 10 | I27: 级 | J27: 任意2个英雄等级提升至10级 | K27: =A27 -> 10501060 | L27: =F40 -> TID_BranchLineTaskConf_10401141_taskName_GL_Main | M27: =A26 -> 10501050 | N27: taskReward{taskId:@@@} | O27: 条件与 | Q27: 条件与 | R27: heroLevel{level:@@@,count:2} | S27: =SUBSTITUTE(R27,"@@@",H27) -> heroLevel{level:10,count:2} | T27: 条件与 | U27: attackingMonsterNow{categoryType:0,rarity:0,level:0} | V27: 【海外】跳转英雄界面指向加号按钮 | W27: 100147 | Y27: icon_task | Z27: icon_task_p3_01 | AB27: 6622005
A28: =10000000+B28*100000+C28*1000+D28*10 -> 10501070 | B28: 5 | C28: 1 | D28: 7 | E28: 主线任务链 | F28: TID_BranchLineTaskConf_10410121_1_taskName_GL_Main | G28: 升级酒馆至 | H28: 5 | I28: 级 | J28: =G28&H28&I28 -> 升级酒馆至5级 | K28: =A28 -> 10501070 | L28: =F41 -> TID_BranchLineTaskConf_10012020_taskName_GL_Main | M28: =A27 -> 10501060 | N28: taskReward{taskId:@@@} | O28: 条件与 | Q28: 条件或 | S28: buildingLevelUpNow{buildingType:237,buildingWantLevel:5} | T28: 条件与 | W28: 100339 | Y28: icon_task | Z28: icon_task_p3_01 | AB28: 6622005 | AI28: 0.19 | AJ28: 0.19
S29: buildingLevelUp{buildingType:237,buildingLevel:5}
A30: =10000000+B30*100000+C30*1000+D30*10 -> 10501080 | B30: 5 | C30: 1 | D30: 8 | E30: 主线任务链 | F30: TID_BranchLineTaskConf_10410105_taskName_GL_Main | G30: 前往城外探查 | J30: =G30&H30&I30 -> 前往城外探查 | K30: =A30 -> 10501080 | L30: =F42 -> TID_BranchLineTaskConf_10601080_taskName_GL_Main | M30: =A28 -> 10501070 | N30: taskReward{taskId:@@@} | O30: 条件与 | Q30: 条件与 | R30: playerEnterBigScene{count:1} | S30: =SUBSTITUTE(R30,"@@@",H30) -> playerEnterBigScene{count:1} | T30: 条件与 | V30: 跳转到城外(默认为当前屏幕中心位置) | W30: 100097 | Y30: icon_task | Z30: icon_task_p3_01 | AB30: 6622004
A31: =10000000+B31*100000+C31*1000+D31*10 -> 10601010 | B31: 6 | C31: 1 | D31: 1 | E31: 主线任务链 | F31: TID_ExploreSubTaskConf_667212_taskName_GL_Main_spe | G31: 清剿1级蛮族 | H31: 1 | I31: 次 | J31: =G31&H31&I31 -> 清剿1级蛮族1次 | K31: =A31 -> 10601010 | L31: =F43 -> TID_BranchLineTaskConf_10401030_1_taskName_GL_Main | M31: =A30 -> 10501080 | N31: taskReward{taskId:@@@} | O31: 条件与 | Q31: 条件与 | R31: statisticReach{type:"BattleKillMonsterEvent1_1",value:@@@} | S31: =SUBSTITUTE(R31,"@@@",H31) -> statisticReach{type:"BattleKillMonsterEvent1_1",value:1} | T31: 条件与 | U31: attackingMonsterNow{categoryType:0,rarity:0,level:0} | V31: 跳转到城外【可打下一等级】野怪进攻按钮 | W31: 7569 | Y31: icon_task | Z31: icon_task_p3_01 | AB31: 6622005
A32: =10000000+B32*100000+C32*1000+D32*10 -> 10601020 | B32: 6 | C32: 1 | D32: 2 | E32: 主线任务链 | F32: TID_BranchLineTaskConf_10410118_taskName_GL_Main | G32: 攻占1个 | H32: 1 | I32: 级或更高级的资源点 | J32: =G32&H32&I32 -> 攻占1个1级或更高级的资源点 | K32: =A32 -> 10601020 | L32: =F44 -> TID_BranchLineTaskConf_AnySpeedUp_1_taskName_GL_Main | M32: =A31 -> 10601010 | N32: taskReward{taskId:@@@} | O32: 条件与 | Q32: 条件与 | R32: occupyResourceLand{level:@@@,occupyNum:1,needTrace:true} | S32: =SUBSTITUTE(R32,"@@@",H32) -> occupyResourceLand{level:1,occupyNum:1,needTrace:true} | T32: 条件与 | V32: 跳转到1级【任意】资源点采集按钮 | W32: 100101 | Y32: icon_task | Z32: icon_task_p3_01 | AB32: 6622005
A33: =10000000+B33*100000+C33*1000+D33*10 -> 10601030 | B33: 6 | C33: 1 | D33: 3 | E33: 主线任务链 | F33: TID_BranchLineTaskConf_10410122_taskName_GL_Main | G33: 加入任意 | H33: 1 | I33: 个联盟 | J33: =G33&H33&I33 -> 加入任意1个联盟 | K33: =A33 -> 10601030 | L33: =F45 -> TID_BranchLineTaskConf_10012030_taskName_GL_Main | M33: =A32 -> 10601020 | N33: taskReward{taskId:@@@} | O33: 条件与 | Q33: 条件与 | R33: allianceJoin{count:1} | S33: =SUBSTITUTE(R33,"@@@",H33) -> allianceJoin{count:1} | T33: 条件与 | W33: 100353 | Y33: icon_task | Z33: icon_task_p3_01 | AB33: 6622006
A34: =10000000+B34*100000+C34*1000+D34*10 -> 10601040 | B34: 6 | C34: 1 | D34: 4 | E34: 主线任务链 | F34: TID_BranchLineTaskConf_226_1_taskName_GL_Main | G34: 升级瞭望塔至 | H34: 5 | I34: 级 | J34: =G34&H34&I34 -> 升级瞭望塔至5级 | K34: =A34 -> 10601040 | L34: =F46 -> TID_BranchLineTaskConf_10910101_taskName_GL_Main | M34: =A33 -> 10601030 | N34: taskReward{taskId:@@@} | O34: 条件与 | Q34: 条件与 | R34: buildingLevelUp{buildingType:226,buildingLevel:@@@} | S34: =SUBSTITUTE(R34,"@@@",H34) -> buildingLevelUp{buildingType:226,buildingLevel:5} | T34: 条件与 | V34: 跳转到瞭望塔【升级】菜单按钮7049 | W34: 100186 | Y34: icon_task | Z34: icon_task_p3_01 | AB34: 6622004
A35: =10000000+B35*100000+C35*1000+D35*10 -> 10601050 | B35: 6 | C35: 1 | D35: 5 | E35: 主线任务链 | F35: TID_BranchLineTaskConf_215_2_taskName_GL_Main | G35: 升级城墙至 | H35: 5 | I35: 级 | J35: =G35&H35&I35 -> 升级城墙至5级 | K35: =A35 -> 10601050 | L35: =F47 -> TID_BranchLineTaskConf_400_0_taskName_GL_Main | M35: =A34 -> 10601040 | N35: taskReward{taskId:@@@} | O35: 条件与 | Q35: 条件与 | R35: buildingLevelUp{buildingType:215,buildingLevel:@@@} | S35: =SUBSTITUTE(R35,"@@@",H35) -> buildingLevelUp{buildingType:215,buildingLevel:5} | T35: 条件与 | V35: 跳转到城墙【升级】菜单按钮7039 | W35: 100184 | Y35: icon_task | Z35: icon_task_p3_01 | AB35: 6622004
A36: =10000000+B36*100000+C36*1000+D36*10 -> 10601060 | B36: 6 | C36: 1 | D36: 6 | E36: 主线任务链 | F36: TID_BranchLineTaskConf_10510118_taskName_GL_Main | G36: 升级城镇中心至 | H36: 6 | I36: 级 | J36: =G36&H36&I36 -> 升级城镇中心至6级 | K36: =A36 -> 10601060 | L36: =F61 -> TID_BranchLineTaskConf_10012050_taskName_GL_Main | M36: =A35 -> 10601050 | N36: taskReward{taskId:@@@} | O36: 条件与 | Q36: 条件与 | R36: buildingLevelUp{buildingType:201,buildingLevel:@@@} | S36: =SUBSTITUTE(R36,"@@@",H36) -> buildingLevelUp{buildingType:201,buildingLevel:6} | T36: 条件与 | V36: 跳转到城镇中心【升级】菜单按钮7001 | W36: 100177 | Y36: icon_task | Z36: icon_task_p3_01 | AB36: 6622004
A37: =10000000+B37*100000+C37*1000+D37*10 -> 10601070 | B37: 6 | C37: 1 | D37: 7 | E37: 主线任务链 | F37: TID_BranchLineTaskConf_10410111_taskName_GL_Main | G37: 建造 | H37: 1 | I37: 个石矿场 | J37: =G37&H37&I37 -> 建造1个石矿场 | K37: =A37 -> 10601070 | L37: =F39 -> TID_BranchLineTaskConf_peasant_2_taskName_GL_Main | M37: =A36 -> 10601060 | N37: taskReward{taskId:@@@} | O37: 条件与 | Q37: 条件与 | R37: buildingSum{buildingType:205,sum:1} | S37: =SUBSTITUTE(R37,"@@@",H37) -> buildingSum{buildingType:205,sum:1} | T37: 条件与 | V37: 跳转到石矿场【建造】确认 | W37: 100165 | Y37: icon_task | Z37: icon_task_p3_01 | AB37: 6622004
A38: =10000000+B38*100000+C38*1000+D38*10 -> 10601080 | B38: 6 | C38: 1 | D38: 8 | E38: 主线任务链 | F38: TID_BranchLineTaskConf_10510104_taskName_GL_Main | G38: 升级居民房舍至 | H38: 5 | I38: 级 | J38: =G38&H38&I38 -> 升级居民房舍至5级 | K38: =A38 -> 10601080 | L38: =F56 -> TID_BranchLineTaskConf_10710112_taskName_GL_Main | M38: =A37 -> 10601070 | N38: taskReward{taskId:@@@} | O38: 条件与 | Q38: 条件与 | R38: buildingLevelUp{buildingType:202,buildingLevel:@@@} | S38: =SUBSTITUTE(R38,"@@@",H38) -> buildingLevelUp{buildingType:202,buildingLevel:5} | T38: 条件与 | U38: barracksIsLevelUpNow{type:0,level:20} | V38: 跳转到居民房舍【升级】菜单按钮 | W38: 100178 | Y38: icon_task | Z38: icon_task_p3_01 | AB38: 6622008
A39: =10000000+B39*100000+C39*1000+D39*10 -> 10601090 | B39: 6 | C39: 1 | D39: 9 | E39: 主线任务链 | F39: TID_BranchLineTaskConf_peasant_2_taskName_GL_Main | G39: 训练农民到17名 | J39: =G39&H39&I39 -> 训练农民到17名 | K39: =A39 -> 10601090 | L39: =F57 -> TID_BranchLineTaskConf_10810101_taskName_GL_Main | M39: =A38 -> 10601080 | N39: taskReward{taskId:@@@} | O39: 条件与 | Q39: 条件与 | R39: statisticReach{type:"InnerPeasantTrainEvent",value:17} | S39: =SUBSTITUTE(R39,"@@@",H39) -> statisticReach{type:"InnerPeasantTrainEvent",value:17} | T39: 条件与 | W39: 100190 | Y39: icon_task | Z39: icon_task_p3_01 | AB39: 6622004
A40: =10000000+B40*100000+C40*1000+D40*10 -> 10601100 | B40: 6 | C40: 1 | D40: 10 | E40: 主线任务链 | F40: TID_BranchLineTaskConf_10401141_taskName_GL_Main | G40: 派遣农民进采石场 | J40: =G40&H40&I40 -> 派遣农民进采石场 | K40: =A40 -> 10601100 | L40: =F17 -> TID_BranchLineTaskConf_20000001_03_taskName_GL_Main | M40: =A39 -> 10601090 | N40: taskReward{taskId:@@@} | O40: 条件与 | Q40: 条件与 | R40: deployedFarmerToBuildingResource{cityElementType:205,value:1} | S40: =SUBSTITUTE(R40,"@@@",H40) -> deployedFarmerToBuildingResource{cityElementType:205,value:1} | T40: 条件与 | W40: 100211 | Y40: icon_task | Z40: icon_task_p3_01 | AB40: 6622004
...

Sheet 支线章节
A1: convert(ResTask.proto, table_BranchLineChapterConf, BranchLineChapterConf.pbin)
A2: 章节ID | B2: 章节任务ID | C2: 奖励ID | D2: 子任务ID | E2: 章节标题 | F2: 章节描述 | G2: 章节转场视频 | H2: 视频时长 | I2: 章节转场bgmBank | J2: 章节转场bgm事件名 | K2: 对话 | L2: timeline | M2: 过场顺序
A3: chapterId | B3: taskId | C3: rewardId | D3: subTaskId | E3: taskName | F3: taskDescr | G3: chapterVideo | H3: videoDuration | I3: chapterBgmBank | J3: chapterBgmName | K3: chapterDialog | L3: chapterTimeline | M3: chapterSequence[;]
A4: 1 | B4: 100001 | C4: 1933391 | D4: 10401010 | E4: TID_Chapter_100001_title | F4: TID_Chapter_100001_desc | G4: charpter0_cutscene | H4: 5 | I4: BGM_ChapterTitle | J4: Play_bgm_chapter01_Chaptertitle | K4: 2100180 | L4: assets/bundleresources/timelineprefabs/p_oversea_newbie_story37.prefab | M4: 1;2;3
D5: 10401020
D6: 10401030
D7: 10401040
A8: 2 | B8: 100002 | C8: 1933392 | D8: 10401050 | E8: TID_Chapter_100002_title | F8: TID_Chapter_100002_desc | G8: charpter0_cutscene | H8: 5 | I8: BGM_ChapterTitle | J8: Play_bgm_chapter01_Chaptertitle | K8: 2100180 | M8: 1;2
D9: 10401060
D10: 10401070
D11: 10401080
A12: 3 | B12: 100003 | C12: 1933393 | D12: 10401090 | E12: TID_Chapter_100003_title | F12: TID_Chapter_100003_desc | G12: charpter0_cutscene | H12: 5 | I12: BGM_ChapterTitle | J12: Play_bgm_chapter01_Chaptertitle
D13: 10401100
D14: 10401110
D15: 10401120
A16: 4 | B16: 100004 | C16: 1933394 | D16: 10401130 | E16: TID_Chapter_100004_title | F16: TID_Chapter_100004_desc | G16: charpter0_cutscene | H16: 5 | I16: BGM_ChapterTitle | J16: Play_bgm_chapter01_Chaptertitle
D17: 10401140
D18: 10401150
D19: 10401160
D20: 10401170
A21: 5 | B21: 100005 | C21: 1933395 | D21: 10501010 | E21: TID_Chapter_100005_title | F21: TID_Chapter_100005_desc | G21: charpter0_cutscene | H21: 5 | I21: BGM_ChapterTitle | J21: Play_bgm_chapter01_Chaptertitle
D22: 10501020
D23: 10501030
D24: 10501040
A25: 6 | B25: 100006 | C25: 1933396 | D25: 10501050 | E25: TID_Chapter_100006_title | F25: TID_Chapter_100006_desc | G25: charpter0_cutscene | H25: 5 | I25: BGM_ChapterTitle | J25: Play_bgm_chapter01_Chaptertitle
D26: 10501060
D27: 10501070
A28: 7 | B28: 100007 | C28: 1933397 | D28: 10501080 | E28: TID_Chapter_100007_title | F28: TID_Chapter_100007_desc | G28: charpter0_cutscene | H28: 5 | I28: BGM_ChapterTitle | J28: Play_bgm_chapter01_Chaptertitle
D29: 10601010
D30: 10601020
A31: 8 | B31: 100008 | C31: 1933398 | D31: 10601030 | E31: TID_Chapter_100008_title | F31: TID_Chapter_100008_desc | G31: charpter0_cutscene | H31: 5 | I31: BGM_ChapterTitle | J31: Play_bgm_chapter01_Chaptertitle
D32: 10601040
D33: 10601050
D34: 10601060
A35: 9 | B35: 100009 | C35: 1933399 | D35: 10601070 | E35: TID_Chapter_100009_title | F35: TID_Chapter_100009_desc | G35: charpter0_cutscene | H35: 5 | I35: BGM_ChapterTitle | J35: Play_bgm_chapter01_Chaptertitle
D36: 10601080
D37: 10601090
D38: 10601100
D39: 10601110
A40: 10 | B40: 100010 | C40: 1933400 | D40: 10601120 | E40: TID_Chapter_100010_title | F40: TID_Chapter_100010_desc | G40: charpter0_cutscene | H40: 5 | I40: BGM_ChapterTitle | J40: Play_bgm_chapter01_Chaptertitle
...

Sheet 支线子任务链
A1: convert(ResTask.proto, table_LineTaskListConf, BranchLineTaskListConf.pbin)
A2: id | B2: 任务ID | C2: 城镇中心等级 | D2: 分组 | E2: 序号 | F2: ID规划 | G2: 任务名称 | H2: 是否是海外主线任务链 | I2: 初始化任务链需要完成的章节任务ID
A3: id | B3: taskList[;] | H3: isImportantTask | I3: initChapterId
A4: 11001010 | B4: 11001010 | C4: 10 | D4: 1 | E4: 1 | F4: 主线任务链 | G4: 建造2个金矿场 | H4: 1 | I4: 100015
A5: =IF(F5=F4,"",B5) | B5: 11001020 | C5: 10 | D5: 1 | E5: 2 | F5: 主线任务链 | G5: 派遣农民进金矿场
A6: =IF(F6=F5,"",B6) | B6: 11001030 | C6: 10 | D6: 1 | E6: 3 | F6: 主线任务链 | G6: 升级2个金矿场至10级
A7: =IF(F7=F5,"",B7) | B7: 11001040 | C7: 10 | D7: 1 | E7: 4 | F7: 主线任务链 | G7: 升级2个伐木场至10级
A8: =IF(F8=F7,"",B8) | B8: 11001050 | C8: 10 | D8: 1 | E8: 5 | F8: 主线任务链 | G8: 升级2个石矿场至10级
A9: =IF(F9=F8,"",B9) | B9: 11001060 | C9: 10 | D9: 1 | E9: 6 | F9: 主线任务链 | G9: 升级2个磨坊至10级
A10: =IF(F10=F9,"",B10) | B10: 11001070 | C10: 10 | D10: 1 | E10: 7 | F10: 主线任务链 | G10: 升级居民房舍至10级
A11: =IF(F11=F10,"",B11) | B11: 11001080 | C11: 10 | D11: 1 | E11: 8 | F11: 主线任务链 | G11: 升级治疗房舍至10级
A12: =IF(F12=F11,"",B12) | B12: 11001090 | C12: 10 | D12: 1 | E12: 9 | F12: 主线任务链 | G12: 升级任意1个兵营至10级
A13: =IF(F13=F12,"",B13) | B13: 11001100 | C13: 10 | D13: 1 | E13: 10 | F13: 主线任务链 | G13: 清剿4级或更高级【普通】蛮族
A14: =IF(F14=F12,"",B14) | B14: 11001110 | C14: 10 | D14: 1 | E14: 11 | F14: 主线任务链 | G14: 任意英雄等级提升至20级
A15: =IF(F15=F13,"",B15) | B15: 11001120 | C15: 10 | D15: 1 | E15: 12 | F15: 主线任务链 | G15: 任意英雄固有技能升级至10级
A16: =IF(F16=F15,"",B16) | B16: 11001130 | C16: 10 | D16: 1 | E16: 13 | F16: 主线任务链 | G16: 任意英雄进行1次天赋升级
A17: =IF(F17=F16,"",B17) | B17: 11001140 | C17: 10 | D17: 1 | E17: 14 | F17: 主线任务链 | G17: 升级城墙至10级
A18: =IF(F18=F17,"",B18) | B18: 11001150 | C18: 10 | D18: 1 | E18: 15 | F18: 主线任务链 | G18: 升级城镇中心至11级
A19: =IF(F19=F18,"",B19) | B19: 11001160 | C19: 10 | D19: 1 | E19: 16 | F19: 主线任务链 | G19: 进入活动中心1次
A20: =IF(F20=F19,"",B20) | B20: 11101010 | C20: 11 | D20: 1 | E20: 1 | F20: 主线任务链 | G20: 升级2个伐木场至11级
A21: =IF(F21=F20,"",B21) | B21: 11101020 | C21: 11 | D21: 1 | E21: 2 | F21: 主线任务链 | G21: 升级2个石矿场至11级
A22: =IF(F22=F20,"",B22) | B22: 11101030 | C22: 11 | D22: 1 | E22: 3 | F22: 主线任务链 | G22: 采集任意资源点累计获取200000资源
A23: =IF(F23=F21,"",B23) | B23: 11101040 | C23: 11 | D23: 1 | E23: 4 | F23: 主线任务链 | G23: 升级2个金矿场至11级
A24: =IF(F24=F23,"",B24) | B24: 11101050 | C24: 11 | D24: 1 | E24: 5 | F24: 主线任务链 | G24: 升级2个磨坊至11级
A25: =IF(F25=F24,"",B25) | B25: 11101060 | C25: 11 | D25: 1 | E25: 6 | F25: 主线任务链 | G25: 升级仓库至11级
A26: =IF(F26=F25,"",B26) | B26: 11101070 | C26: 11 | D26: 1 | E26: 7 | F26: 主线任务链 | G26: 升级市集至11级
A27: =IF(F27=F26,"",B27) | B27: 11101080 | C27: 11 | D27: 1 | E27: 8 | F27: 主线任务链 | G27: 升级居民房舍至11级
A28: =IF(F28=F27,"",B28) | B28: 11101090 | C28: 11 | D28: 1 | E28: 9 | F28: 主线任务链 | G28: 升级治疗房舍至11级
A29: =IF(F29=F28,"",B29) | B29: 11101100 | C29: 11 | D29: 1 | E29: 10 | F29: 主线任务链 | G29: 升级城墙至11级
A30: =IF(F30=F29,"",B30) | B30: 11101110 | C30: 11 | D30: 1 | E30: 11 | F30: 主线任务链 | G30: 升级瞭望塔至7级
A31: =IF(F31=F30,"",B31) | B31: 11101120 | C31: 11 | D31: 1 | E31: 12 | F31: 主线任务链 | G31: 升级城镇中心至12级
A32: =IF(F32=F30,"",B32) | B32: 11201010 | C32: 12 | D32: 1 | E32: 1 | F32: 主线任务链 | G32: 一个编队上阵2名英雄
A33: =IF(F33=F31,"",B33) | B33: 11201020 | C33: 12 | D33: 1 | E33: 2 | F33: 主线任务链 | G33: 建造1个战争大厅
A34: =IF(F34=F33,"",B34) | B34: 11201030 | C34: 12 | D34: 1 | E34: 3 | F34: 主线任务链 | G34: 升级战争大厅至10级
A35: =IF(F35=F36,"",B35) | B35: 11201040 | C35: 12 | D35: 1 | E35: 4 | F35: 主线任务链 | G35: 升级2个伐木场至12级
A36: =IF(F36=F34,"",B36) | B36: 11201050 | C36: 12 | D36: 1 | E36: 5 | F36: 主线任务链 | G36: 升级枪兵营至12级
A37: =IF(F37=F36,"",B37) | B37: 11201060 | C37: 12 | D37: 1 | E37: 6 | F37: 主线任务链 | G37: 清剿任意等级【普通】蛮族3次
A38: =IF(F38=F35,"",B38) | B38: 11201070 | C38: 12 | D38: 1 | E38: 7 | F38: 主线任务链 | G38: 升级2个石矿场至12级
A39: =IF(F39=F38,"",B39) | B39: 11201080 | C39: 12 | D39: 1 | E39: 8 | F39: 主线任务链 | G39: 升级2个金矿场至12级
A40: =IF(F40=F39,"",B40) | B40: 11201090 | C40: 12 | D40: 1 | E40: 9 | F40: 主线任务链 | G40: 升级2个磨坊至12级
...

Sheet #隐藏支线子任务
A1: convert(ResTask.proto, table_LineTaskConf, HideBranchLineTaskConf.pbin)
A2: 任务id | B2: 任务名称 | C2: 触发条件组与或关系 | D2: 触发条件组 | E2: 完成条件组与或关系 | F2: 完成条件组 | G2: 跳转id | H2: 任务描述 | I2: 图集 | J2: sprite | K2: 排序 | L2: 奖励
A3: id | B3: taskName | C3: common.resTriggerConditionGroup.conditionRelation | D3: common.resTriggerConditionGroup.condition.condOneOf | E3: common.resCompleteConditionGroup.conditionRelation | F3: common.resCompleteConditionGroup.condition.condOneOf | G3: common.jumpTo | H3: taskDesc | I3: atlas | J3: sprite | K3: order | L3: common.rewardId

Sheet #隐藏支线子任务链
A1: convert(ResTask.proto, table_LineTaskListConf, HideBranchLineTaskListConf.pbin)
A2: id | B2: 任务链
A3: id | B3: taskList[;]

Sheet #杂项配置
A1: convertTrans(ResTask.proto, table_LineTaskMiscConf, LineTaskMiscConf.pbin) | B1: 字段 | C1: 值
A2: 配置项 | B2: id | C2: 1
A3: 前置主线剧情任务id | B3: preMainTaskId | C3: 110010
A4: 自动领奖上限【测试环境生效】（0没有上限，>0代表最多多少个支线+隐藏支线处于未领奖状态，多于自动领奖） | B4: autoRewardLimit | C4: 10

Sheet #主线任务集（废弃）
A1: convert(ResTask.proto, table_LineTaskConf, MainLineTaskConf.pbin)
A2: 任务id | B2: 任务名称 | C2: 解锁条件关系 | D2: 解锁条件组 | E2: 完成条件关系 | F2: 完成条件组 | G2: 进行中条件关系 | H2: 进行条件 | I2: 跳转id | J2: 任务描述 | K2: 图集 | L2: sprite | M2: 排序 | N2: 奖励
A3: id | B3: taskName | C3: common.resTriggerConditionGroup.conditionRelation | D3: common.resTriggerConditionGroup.condition.condOneOf | E3: common.resCompleteConditionGroup.conditionRelation | F3: common.resCompleteConditionGroup.condition.condOneOf | G3: common.resDoingConditionGroup.conditionRelation | H3: common.resDoingConditionGroup.condition.condOneOf | I3: jumpTo | J3: taskDesc | K3: atlas | L3: sprite | M3: order | N3: common.rewardId

Sheet #主线任务链（废弃）
A1: convert(ResTask.proto, table_LineTaskListConf, MainLineTaskListConf.pbin)
A2: id | B2: 任务链
A3: id | B3: taskList

Sheet #TID_base_up
A1: 旧Key | B1: 新Key | C1: 文本
A2: BranchLineTaskConf_10410101_taskName_GL_Main | B2: TID_BranchLineTaskConf_10410101_taskName_GL_Main | C2: 选择任意1个文明
A3: BranchLineTaskConf_10401020_taskName_GL_Main | B3: TID_BranchLineTaskConf_10401020_taskName_GL_Main | C3: 升级剑士营至4级
A4: BranchLineTaskConf_10401030_taskName_GL_Main | B4: TID_BranchLineTaskConf_10401030_taskName_GL_Main | C4: 训练1级剑士700名
A5: BranchLineTaskConf_10410104_taskName_GL_Main | B5: TID_BranchLineTaskConf_10410104_taskName_GL_Main | C5: 使用训练加速20分钟
A6: BranchLineTaskConf_10401050_taskName_GL_Main | B6: TID_BranchLineTaskConf_10401050_taskName_GL_Main | C6: [启程之光]累计招募10次
A7: BranchLineTaskConf_10410105_taskName_GL_Main | B7: TID_BranchLineTaskConf_10410105_taskName_GL_Main | C7: 前往城外探查
A8: BranchLineTaskConf_10410106_taskName_GL_Main | B8: TID_BranchLineTaskConf_10410106_taskName_GL_Main | C8: 编组1支上阵2个英雄的部队
A9: BranchLineTaskConf_10410107_taskName_GL_Main | B9: TID_BranchLineTaskConf_10410107_taskName_GL_Main | C9: 城外搜索任意类型蛮族1次
A10: BranchLineTaskConf_10410108_taskName_GL_Main | B10: TID_BranchLineTaskConf_10410108_taskName_GL_Main | C10: 城外清剿1级蛮族1次
A11: BranchLineTaskConf_10410110_taskName_GL_Main | B11: TID_BranchLineTaskConf_10410110_taskName_GL_Main | C11: 城外清剿2级蛮族1次
A12: BranchLineTaskConf_10401100_taskName_GL_Main | B12: TID_BranchLineTaskConf_10401100_taskName_GL_Main | C12: 激活任意一个1000要求的发展方略
... A689: BranchLineTaskConf_20123072_taskName_GL_Main | B689: TID_BranchLineTaskConf_20123072_taskName_GL_Main | C689: 升级战争大厅至20级
