Workbook

Sheet 探索等级
A1: convert(ResExploration.proto, table_ExplorationLevelConf, ExplorationLevelConf.pbin)
A2: 探索等级 | B2: 条件关联 | C2: 满足条件则升级 | D2: 刷新半径(<100) | E2: 刷新半径(<100) | F2: 事件数量 | G2: 每日新增数量到槽位 | H2: 槽位数量 | I2: 是否展示特效 | J2: 缩放比例 | K2: 战斗事件缩放比例 | L2: 显示数量-宝箱 | M2: 显示数量-战斗 | N2: 显示数量-委任 | O2: 显示数量-对话
A3: level | B3: levelUpConditionGroup.conditionRelation | C3: levelUpConditionGroup.condition.condOneOf | D3: eventBornRadiusMin | E3: eventBornRadiusMax | F3: eventLimit | G3: refreshNumber | H3: slotNumber | I3: showEffect | J3: uiSize | K3: battleUISize | L3: eventShowNumLimit[1] | M3: eventShowNumLimit[2] | N3: eventShowNumLimit[3] | O3: eventShowNumLimit[4]
A4: 1 | D4: 5 | E4: 10 | F4: 1 | G4: 1 | H4: 24 | J4: 1.2 | K4: 2.8 | L4: 3 | M4: 4 | N4: 1 | O4: 1
A5: 2 | B5: 条件与 | C5: explorationFinishCount{count:1} | D5: 5 | E5: 15 | F5: 2 | G5: 2 | H5: 24 | I5: 1 | J5: 1.2 | K5: 2.8 | L5: 3 | M5: 4 | N5: 1 | O5: 1
A6: 3 | B6: 条件与 | C6: explorationFinishCount{count:2} | D6: 5 | E6: 20 | F6: 3 | G6: 3 | H6: 24 | J6: 1.2 | K6: 2.8 | L6: 3 | M6: 4 | N6: 1 | O6: 1
A7: 4 | B7: 条件与 | C7: explorationFinishCount{count:3} | D7: 5 | E7: 25 | F7: 4 | G7: 4 | H7: 24 | J7: 1.2 | K7: 2.8 | L7: 3 | M7: 4 | N7: 1 | O7: 1
A8: 5 | B8: 条件与 | C8: explorationFinishCount{count:6} | D8: 10 | E8: 30 | F8: 5 | G8: 5 | H8: 24 | J8: 1.2 | K8: 2.8 | L8: 3 | M8: 4 | N8: 1 | O8: 1
A9: 6 | B9: 条件与 | C9: explorationFinishCount{count:20} | D9: 15 | E9: 40 | F9: 6 | G9: 6 | H9: 24 | I9: 1 | J9: 1.2 | K9: 2.8 | L9: 3 | M9: 4 | N9: 1 | O9: 1
A10: 7 | B10: 条件与 | C10: explorationFinishCount{count:30} | D10: 15 | E10: 50 | F10: 7 | G10: 7 | H10: 24 | J10: 1.2 | K10: 2.8 | L10: 3 | M10: 4 | N10: 1 | O10: 1
A11: 8 | B11: 条件与 | C11: explorationFinishCount{count:40} | D11: 25 | E11: 60 | F11: 8 | G11: 8 | H11: 24 | J11: 1.2 | K11: 2.8 | L11: 3 | M11: 4 | N11: 1 | O11: 1
A12: 9 | B12: 条件与 | C12: explorationFinishCount{count:50} | D12: 25 | E12: 60 | F12: 8 | G12: 8 | H12: 24 | J12: 1.2 | K12: 2.8 | L12: 3 | M12: 4 | N12: 1 | O12: 1
A13: 10 | B13: 条件与 | C13: explorationFinishCount{count:60} | D13: 25 | E13: 60 | F13: 8 | G13: 8 | H13: 24 | J13: 1.2 | K13: 2.8 | L13: 3 | M13: 4 | N13: 1 | O13: 1
A14: 11 | B14: 条件与 | C14: explorationFinishCount{count:70} | D14: 25 | E14: 60 | F14: 8 | G14: 8 | H14: 24 | J14: 1.2 | K14: 2.8 | L14: 3 | M14: 4 | N14: 1 | O14: 1
A15: 12 | B15: 条件与 | C15: explorationFinishCount{count:80} | D15: 25 | E15: 60 | F15: 8 | G15: 8 | H15: 24 | J15: 1.2 | K15: 2.8 | L15: 3 | M15: 4 | N15: 1 | O15: 1
A16: 13 | B16: 条件与 | C16: explorationFinishCount{count:90} | D16: 25 | E16: 60 | F16: 8 | G16: 8 | H16: 24 | J16: 1.2 | K16: 2.8 | L16: 3 | M16: 4 | N16: 1 | O16: 1
A17: 14 | B17: 条件与 | C17: explorationFinishCount{count:100} | D17: 25 | E17: 60 | F17: 8 | G17: 8 | H17: 24 | J17: 1.2 | K17: 2.8 | L17: 3 | M17: 4 | N17: 1 | O17: 1
A18: 15 | B18: 条件与 | C18: explorationFinishCount{count:110} | D18: 25 | E18: 60 | F18: 8 | G18: 8 | H18: 24 | J18: 1.2 | K18: 2.8 | L18: 3 | M18: 4 | N18: 1 | O18: 1
A19: 16 | B19: 条件与 | C19: explorationFinishCount{count:120} | D19: 25 | E19: 60 | F19: 8 | G19: 8 | H19: 24 | J19: 1.2 | K19: 2.8 | L19: 3 | M19: 4 | N19: 1 | O19: 1
A20: 17 | B20: 条件与 | C20: explorationFinishCount{count:130} | D20: 25 | E20: 60 | F20: 8 | G20: 8 | H20: 24 | J20: 1.2 | K20: 2.8 | L20: 3 | M20: 4 | N20: 1 | O20: 1
A21: 18 | B21: 条件与 | C21: explorationFinishCount{count:140} | D21: 25 | E21: 60 | F21: 8 | G21: 8 | H21: 24 | J21: 1.2 | K21: 2.8 | L21: 3 | M21: 4 | N21: 1 | O21: 1
... A23: 20 | B23: 条件与 | C23: explorationFinishCount{count:160} | D23: 25 | E23: 60 | F23: 8 | G23: 8 | H23: 24 | J23: 1.2 | K23: 2.8 | L23: 3 | M23: 4 | N23: 1 | O23: 1

Sheet 探索事件
A1: convert(ResExploration.proto, table_ExplorationEventConf, ExplorationEventConfData.pbin)
A2: 事件id | B2: 备注 | C2: quality ExplorationEventQuality | D2: 文案id | E2: 玩法类型 | F2: 是否自动接取任务 | G2: 是否需要侦查 | H2: 事件描述 | I2: 体力消耗 (野怪配置在野怪表) | J2: 自动领奖 | K2: 是否需要选择奖励 | L2: 奖励id 选择奖励是数组,否则只发放第一个 | M2: 任务过期时间(小时) | N2: 扩展字段Id--配合eventType玩法类型使用,关联其他配置表 | O2: 扩展字段 | P2: 事件的最大半径 | Q2: 事件的最大半径
A3: id | C3: quality | D3: descId | E3: eventType | F3: autoAccept | G3: needDetect | H3: desc | I3: staminaCost | J3: autoReward | K3: needChooseReward | L3: rewardId[;] | M3: expireTimeHour | N3: extraId | O3: extra[;] | P3: bornRadiusMin | Q3: bornRadiusMax
A4: 1000 | B4: 测试-对话-1000 | C4: 白 | D4: 4001 | E4: 对话 | F4: TRUE | H4: test_dec | I4: 5 | J4: FALSE | K4: TRUE | L4: 6636101;6636111 | M4: 14 | N4: 4001
A5: 1001 | B5: 测试-对话-1001 | C5: 绿 | D5: 4002 | E5: 对话 | F5: TRUE | H5: test_dec | I5: 5 | J5: FALSE | K5: TRUE | L5: 6636102;6636112 | M5: 14 | N5: 4002
A6: 1002 | B6: 测试-对话-1003 | C6: 蓝 | D6: 4003 | E6: 对话 | F6: TRUE | H6: test_dec | I6: 5 | J6: FALSE | K6: TRUE | L6: 6636103;6636113 | M6: 14 | N6: 4003
A7: 1003 | B7: 测试-对话-1004 | C7: 紫 | D7: 4004 | E7: 对话 | F7: TRUE | H7: test_dec | I7: 5 | J7: FALSE | K7: TRUE | L7: 6636104;6636114 | M7: 14 | N7: 4004
A8: 1004 | B8: 测试-对话-1005 | C8: 橙 | D8: 4005 | E8: 对话 | F8: TRUE | H8: test_dec | I8: 5 | J8: FALSE | K8: TRUE | L8: 6636105;6636115 | M8: 14 | N8: 4005
A9: 1005 | B9: 测试-对话-1006 | C9: 橙 | D9: 4005 | E9: 对话 | F9: TRUE | H9: test_dec | I9: 6 | J9: FALSE | K9: TRUE | L9: 6636106;6636116 | M9: 14 | N9: 4005
A10: 2000 | B10: 测试-委托英雄-2000 | C10: 白 | D10: 3001 | E10: 委任 | F10: FALSE | H10: test_dec | I10: 5 | J10: FALSE | L10: 6636201 | M10: 14 | O10: 31001;31002;31003;31004;31005;31006;31007;31008;31009
A11: 2001 | B11: 测试-委托英雄-2001 | C11: 白 | D11: 3002 | E11: 委任 | F11: FALSE | I11: 5 | J11: FALSE | L11: 6636201 | M11: 14 | O11: 31001;31002;31003;31004;31005;31006;31007;31008;31009
A12: 2002 | B12: 测试-委托英雄-2002 | C12: 绿 | D12: 3003 | E12: 委任 | F12: FALSE | H12: test_dec | I12: 5 | J12: FALSE | L12: 6636202 | M12: 14 | O12: =委任玩法!M348 -> 14001;14002;14003;14004;14005;14006;14007;14008;14009;14010;14011;14012;14013;14014;14101;14102;14103;14104;14105;14106;14107;14108;14109;14110;14111;14112;14113;14114;14201;14202;14203;14204;14205;14206;14207;14208;14209;14210;14211;14212;14213;14214
A13: 2003 | B13: 测试-委托英雄-2003 | C13: 绿 | D13: 3004 | E13: 委任 | F13: FALSE | I13: 5 | J13: FALSE | L13: 6636202 | M13: 14 | O13: =委任玩法!M348 -> 14001;14002;14003;14004;14005;14006;14007;14008;14009;14010;14011;14012;14013;14014;14101;14102;14103;14104;14105;14106;14107;14108;14109;14110;14111;14112;14113;14114;14201;14202;14203;14204;14205;14206;14207;14208;14209;14210;14211;14212;14213;14214
A14: 2004 | B14: 测试-委托英雄-2004 | C14: 蓝 | D14: 3005 | E14: 委任 | F14: FALSE | H14: test_dec | I14: 5 | J14: FALSE | L14: 6636203 | M14: 14 | O14: =委任玩法!M350 -> 13001;13002;13003;13004;13005;13006;13007;13008;13009;13010;13011;13012;13013;13014;13101;13102;13103;13104;13105;13106;13107;13108;13109;13110;13111;13112;13113;13114;13201;13202;13203;13204;13205;13206;13207;13208;13209;13210;13211;13212;13213;13214
A15: 2005 | B15: 测试-委托英雄-2005 | C15: 蓝 | D15: 3006 | E15: 委任 | F15: FALSE | I15: 5 | J15: FALSE | L15: 6636203 | M15: 14 | O15: =委任玩法!M350 -> 13001;13002;13003;13004;13005;13006;13007;13008;13009;13010;13011;13012;13013;13014;13101;13102;13103;13104;13105;13106;13107;13108;13109;13110;13111;13112;13113;13114;13201;13202;13203;13204;13205;13206;13207;13208;13209;13210;13211;13212;13213;13214
A16: 2006 | B16: 测试-委托英雄-2006 | C16: 紫 | D16: 3007 | E16: 委任 | F16: FALSE | H16: test_dec | I16: 5 | J16: FALSE | L16: 6636204 | M16: 14 | O16: =委任玩法!L52 -> 12001;12002;12003;12004;12005;12006;12007;12008;12009;12010;12011;12013;12014;12016;12101;12102;12103;12104;12105;12106;12107;12108;12109;12110;12111;12113;12114;12116;12201;12202;12203;12204;12205;12206;12207;12208;12209;12210;12211;12213
A17: 2007 | B17: 测试-委托英雄-2007 | C17: 紫 | D17: 3008 | E17: 委任 | F17: FALSE | I17: 5 | J17: FALSE | L17: 6636204 | M17: 14 | O17: =委任玩法!L52 -> 12001;12002;12003;12004;12005;12006;12007;12008;12009;12010;12011;12013;12014;12016;12101;12102;12103;12104;12105;12106;12107;12108;12109;12110;12111;12113;12114;12116;12201;12202;12203;12204;12205;12206;12207;12208;12209;12210;12211;12213
A18: 2008 | B18: 测试-委托英雄-2008 | C18: 橙 | D18: 3009 | E18: 委任 | F18: FALSE | I18: 5 | J18: FALSE | L18: 6636205 | M18: 14 | O18: =委任玩法!L25 -> 11001;11002;11003;11004;11005;11006;11007;11008;11009;11010;11011;11012;11013
A19: 2009 | B19: 测试-委托英雄-2009 | C19: 橙 | D19: 3010 | E19: 委任 | F19: FALSE | H19: test_dec | I19: 5 | J19: FALSE | L19: 6636205 | M19: 14 | O19: =委任玩法!L25 -> 11001;11002;11003;11004;11005;11006;11007;11008;11009;11010;11011;11012;11013
A20: 2010 | B20: 测试-委托英雄 | C20: 白 | D20: 3001 | E20: 委任 | F20: FALSE | H20: test_dec | I20: 5 | J20: FALSE | L20: 6636201 | M20: 14 | O20: 31001
A21: 2011 | B21: 测试-委托英雄 | C21: 橙 | D21: 3010 | E21: 委任 | F21: FALSE | H21: test_dec | I21: 5 | J21: FALSE | L21: 6636206 | M21: 14 | O21: =委任玩法!L27 -> 0
A22: 3000 | B22: 测试-大地图野怪-3000 | C22: 白 | D22: 2001 | E22: 大地图战斗 | F22: TRUE | H22: TID_AdventureEventRandomDescConfData_1004_preSurveyContent_CN_Main | I22: 5 | J22: FALSE | L22: 6636301 | M22: 14 | P22: 1 | Q22: 7
A23: 3001 | B23: 测试-大地图野怪-3001 | C23: 白 | D23: 2002 | E23: 大地图战斗 | F23: TRUE | H23: TID_AdventureEventRandomDescConfData_1006_preSurveyContent_CN_Main | I23: 5 | J23: FALSE | L23: 6636301 | M23: 14 | P23: 1 | Q23: 7
A24: 3002 | B24: 测试-大地图野怪-3002 | C24: 绿 | D24: 2003 | E24: 大地图战斗 | F24: TRUE | I24: 5 | J24: FALSE | L24: 6636302 | M24: 14 | P24: 2 | Q24: 7
A25: 3003 | B25: 测试-大地图野怪-3003 | C25: 蓝 | D25: 2004 | E25: 大地图战斗 | F25: TRUE | I25: 5 | J25: FALSE | L25: 6636303 | M25: 14 | P25: 2 | Q25: 7
A26: 3004 | B26: 测试-大地图野怪-3004 | C26: 紫 | D26: 2007 | E26: 大地图战斗 | F26: TRUE | I26: 5 | J26: FALSE | L26: 6636304 | M26: 14 | P26: 3 | Q26: 7
A27: 3005 | B27: 测试-大地图野怪-3005 | C27: 紫 | D27: 2008 | E27: 大地图战斗 | F27: TRUE | I27: 5 | J27: FALSE | L27: 6636304 | M27: 14 | P27: 3 | Q27: 7
A28: 3006 | B28: 测试-大地图野怪-3000 | C28: 白 | D28: 2009 | E28: 大地图战斗 | F28: TRUE | H28: test_dec | I28: 5 | J28: FALSE | K28: TRUE | L28: 6636301 | M28: 14 | P28: 4 | Q28: 7
A29: 3501 | B29: 测试-大地图野怪-3501 | C29: 橙 | D29: 2010 | E29: 大地图战斗 | F29: TRUE | H29: TID_AdventureEventRandomDescConfData_1009_preSurveyContent_CN_Main | I29: 5 | J29: FALSE | L29: 6636305 | M29: 14 | P29: 4 | Q29: 7
A30: 3502 | B30: 测试-大地图野怪-3502 | C30: 橙 | D30: 2011 | E30: 大地图战斗 | F30: TRUE | H30: TID_BountyTaskPoolConfData_21001_taskDesc_CN_Main | I30: 5 | J30: FALSE | L30: 6636305 | M30: 14 | P30: 5 | Q30: 7
A31: 3503 | B31: 测试-大地图野怪-3503 | C31: 橙 | D31: 2012 | E31: 大地图战斗 | F31: TRUE | H31: TID_BountyTaskPoolConfData_21004_taskDesc_CN_Main | I31: 5 | J31: FALSE | L31: 6636305 | M31: 14 | P31: 5 | Q31: 7
A32: 3504 | B32: 测试-大地图野怪-3504 | C32: 橙 | D32: 2012 | E32: 大地图战斗 | F32: TRUE | H32: TID_BountyTaskPoolConfData_21004_taskDesc_CN_Main | I32: 5 | J32: FALSE | L32: 6636306 | M32: 14 | P32: 5 | Q32: 7
A33: 3505 | B33: 测试-大地图野怪-3505 | C33: 橙 | D33: 2012 | E33: 大地图战斗 | F33: TRUE | H33: TID_BountyTaskPoolConfData_21004_taskDesc_CN_Main | I33: 5 | J33: FALSE | L33: 6636307 | M33: 14 | P33: 5 | Q33: 7
A34: 3506 | B34: 测试-大地图野怪-3506 | C34: 橙 | D34: 2012 | E34: 大地图战斗 | F34: TRUE | H34: TID_BountyTaskPoolConfData_21004_taskDesc_CN_Main | I34: 5 | J34: FALSE | L34: 6636308 | M34: 14 | P34: 5 | Q34: 7
A35: 3507 | B35: 测试-大地图野怪-3507 | C35: 橙 | D35: 2012 | E35: 大地图战斗 | F35: TRUE | H35: TID_BountyTaskPoolConfData_21004_taskDesc_CN_Main | I35: 5 | J35: FALSE | L35: 6636309 | M35: 14 | P35: 5 | Q35: 7
A36: 3508 | B36: 测试-大地图野怪-3508 | C36: 橙 | D36: 2012 | E36: 大地图战斗 | F36: TRUE | H36: TID_BountyTaskPoolConfData_21004_taskDesc_CN_Main | I36: 5 | J36: FALSE | L36: 6636310 | M36: 14 | P36: 5 | Q36: 7
A37: 3509 | B37: 测试-大地图野怪-3509 | C37: 橙 | D37: 2012 | E37: 大地图战斗 | F37: TRUE | H37: TID_BountyTaskPoolConfData_21004_taskDesc_CN_Main | I37: 5 | J37: FALSE | L37: 6636311 | M37: 14 | P37: 5 | Q37: 7
A38: 4000 | B38: 测试-大地图宝箱-4000 | C38: 白 | D38: 1001 | E38: 大地图探索 | F38: TRUE | H38: TID_AdventureEventRandomDescConfData_3000001_preSurveyContent_CN_Main | I38: 5 | J38: FALSE | L38: 6636401 | M38: 14
A39: 4001 | B39: 测试-大地图宝箱-4001 | C39: 绿 | D39: 1002 | E39: 大地图探索 | F39: TRUE | H39: TID_AdventureEventRandomDescConfData_3000002_preSurveyContent_CN_Main | I39: 5 | J39: FALSE | L39: 6636402 | M39: 14
A40: 4002 | B40: 测试-大地图宝箱-4004 | C40: 蓝 | D40: 1003 | E40: 大地图探索 | F40: TRUE | H40: TID_AdventureEventRandomDescConfData_3000001_text2_CN_Main | I40: 5 | J40: FALSE | L40: 6636403 | M40: 14
...

Sheet 等级-事件池
A1: convert(ResExploration.proto, table_ExplorationLevelRefreshConf, ExplorationLevelRefreshConfData.pbin)
A2: 探索等级(x~) | B2: 事件id | C2: 品质关联(关联) | D2: 类型关联 | E2: 权重数值 | F2: 一次最多刷新的数量
A3: level | B3: refreshWeight.eventId | E3: refreshWeight.weight | F3: refreshWeight.numberLimit
A4: 1 | B4: 3006 | C4: =VLOOKUP(B4,探索事件!A:C,3,FALSE) -> 白 | D4: =VLOOKUP(B4,探索事件!A:E,5,FALSE) -> 大地图战斗 | E4: 20 | F4: 1
A5: 2 | B5: 1000 | C5: =VLOOKUP(B5,探索事件!A:C,3,FALSE) -> 白 | D5: =VLOOKUP(B5,探索事件!A:E,5,FALSE) -> 对话 | E5: 100 | F5: 1
B6: 4000 | C6: =VLOOKUP(B6,探索事件!A:C,3,FALSE) -> 白 | D6: =VLOOKUP(B6,探索事件!A:E,5,FALSE) -> 大地图探索 | E6: 100 | F6: 1
A7: 3 | B7: 3002 | C7: =VLOOKUP(B7,探索事件!A:C,3,FALSE) -> 绿 | D7: =VLOOKUP(B7,探索事件!A:E,5,FALSE) -> 大地图战斗 | E7: 100 | F7: 1
B8: 4001 | C8: =VLOOKUP(B8,探索事件!A:C,3,FALSE) -> 绿 | D8: =VLOOKUP(B8,探索事件!A:E,5,FALSE) -> 大地图探索 | E8: 100 | F8: 1
B9: 4002 | C9: =VLOOKUP(B9,探索事件!A:C,3,FALSE) -> 蓝 | D9: =VLOOKUP(B9,探索事件!A:E,5,FALSE) -> 大地图探索 | E9: 100 | F9: 1
A10: 4 | B10: 3003 | C10: =VLOOKUP(B10,探索事件!A:C,3,FALSE) -> 蓝 | D10: =VLOOKUP(B10,探索事件!A:E,5,FALSE) -> 大地图战斗 | E10: 100 | F10: 1
B11: 4001 | C11: =VLOOKUP(B11,探索事件!A:C,3,FALSE) -> 绿 | D11: =VLOOKUP(B11,探索事件!A:E,5,FALSE) -> 大地图探索 | E11: 100 | F11: 1
B12: 4002 | C12: =VLOOKUP(B12,探索事件!A:C,3,FALSE) -> 蓝 | D12: =VLOOKUP(B12,探索事件!A:E,5,FALSE) -> 大地图探索 | E12: 100 | F12: 1
B13: 2000 | C13: =VLOOKUP(B13,探索事件!A:C,3,FALSE) -> 白 | D13: =VLOOKUP(B13,探索事件!A:E,5,FALSE) -> 委任 | E13: 100 | F13: 1
A14: 5 | B14: 3003 | C14: =VLOOKUP(B14,探索事件!A:C,3,FALSE) -> 蓝 | D14: =VLOOKUP(B14,探索事件!A:E,5,FALSE) -> 大地图战斗 | E14: 100 | F14: 1
B15: 3003 | C15: =VLOOKUP(B15,探索事件!A:C,3,FALSE) -> 蓝 | D15: =VLOOKUP(B15,探索事件!A:E,5,FALSE) -> 大地图战斗 | E15: 100 | F15: 1
B16: 4002 | C16: =VLOOKUP(B16,探索事件!A:C,3,FALSE) -> 蓝 | D16: =VLOOKUP(B16,探索事件!A:E,5,FALSE) -> 大地图探索 | E16: 100 | F16: 1
B17: 4002 | C17: =VLOOKUP(B17,探索事件!A:C,3,FALSE) -> 蓝 | D17: =VLOOKUP(B17,探索事件!A:E,5,FALSE) -> 大地图探索 | E17: 100 | F17: 1
B18: 2002 | C18: =VLOOKUP(B18,探索事件!A:C,3,FALSE) -> 绿 | D18: =VLOOKUP(B18,探索事件!A:E,5,FALSE) -> 委任 | E18: 100 | F18: 1
A19: 6 | B19: 2004 | C19: =VLOOKUP(B19,探索事件!A:C,3,FALSE) -> 蓝 | D19: =VLOOKUP(B19,探索事件!A:E,5,FALSE) -> 委任 | E19: 100 | F19: 1
B20: 1002 | C20: =VLOOKUP(B20,探索事件!A:C,3,FALSE) -> 蓝 | D20: =VLOOKUP(B20,探索事件!A:E,5,FALSE) -> 对话 | E20: 100 | F20: 1
B21: 3003 | C21: =VLOOKUP(B21,探索事件!A:C,3,FALSE) -> 蓝 | D21: =VLOOKUP(B21,探索事件!A:E,5,FALSE) -> 大地图战斗 | E21: 100 | F21: 1
B22: 3004 | C22: =VLOOKUP(B22,探索事件!A:C,3,FALSE) -> 紫 | D22: =VLOOKUP(B22,探索事件!A:E,5,FALSE) -> 大地图战斗 | E22: 100 | F22: 1
B23: 4002 | C23: =VLOOKUP(B23,探索事件!A:C,3,FALSE) -> 蓝 | D23: =VLOOKUP(B23,探索事件!A:E,5,FALSE) -> 大地图探索 | E23: 100 | F23: 1
B24: 4003 | C24: =VLOOKUP(B24,探索事件!A:C,3,FALSE) -> 紫 | D24: =VLOOKUP(B24,探索事件!A:E,5,FALSE) -> 大地图探索 | E24: 100 | F24: 1
A25: 7 | B25: 2004 | C25: =VLOOKUP(B25,探索事件!A:C,3,FALSE) -> 蓝 | D25: =VLOOKUP(B25,探索事件!A:E,5,FALSE) -> 委任 | E25: 100 | F25: 1
B26: 1002 | C26: =VLOOKUP(B26,探索事件!A:C,3,FALSE) -> 蓝 | D26: =VLOOKUP(B26,探索事件!A:E,5,FALSE) -> 对话 | E26: 100
B27: 3003 | C27: =VLOOKUP(B27,探索事件!A:C,3,FALSE) -> 蓝 | D27: =VLOOKUP(B27,探索事件!A:E,5,FALSE) -> 大地图战斗 | E27: 100 | F27: 1
B28: 3003 | C28: =VLOOKUP(B28,探索事件!A:C,3,FALSE) -> 蓝 | D28: =VLOOKUP(B28,探索事件!A:E,5,FALSE) -> 大地图战斗 | E28: 100 | F28: 1
B29: 3004 | C29: =VLOOKUP(B29,探索事件!A:C,3,FALSE) -> 紫 | D29: =VLOOKUP(B29,探索事件!A:E,5,FALSE) -> 大地图战斗 | E29: 100 | F29: 1
B30: 4002 | C30: =VLOOKUP(B30,探索事件!A:C,3,FALSE) -> 蓝 | D30: =VLOOKUP(B30,探索事件!A:E,5,FALSE) -> 大地图探索 | E30: 100 | F30: 1
B31: 4003 | C31: =VLOOKUP(B31,探索事件!A:C,3,FALSE) -> 紫 | D31: =VLOOKUP(B31,探索事件!A:E,5,FALSE) -> 大地图探索 | E31: 100 | F31: 1
A32: 8 | B32: 1002 | C32: =VLOOKUP(B32,探索事件!A:C,3,FALSE) -> 蓝 | D32: =VLOOKUP(B32,探索事件!A:E,5,FALSE) -> 对话 | E32: 50 | F32: 1
B33: 1003 | C33: =VLOOKUP(B33,探索事件!A:C,3,FALSE) -> 紫 | D33: =VLOOKUP(B33,探索事件!A:E,5,FALSE) -> 对话 | E33: 40 | F33: 1
B34: 1004 | C34: =VLOOKUP(B34,探索事件!A:C,3,FALSE) -> 橙 | D34: =VLOOKUP(B34,探索事件!A:E,5,FALSE) -> 对话 | E34: 10 | F34: 1
B35: 2005 | C35: =VLOOKUP(B35,探索事件!A:C,3,FALSE) -> 蓝 | D35: =VLOOKUP(B35,探索事件!A:E,5,FALSE) -> 委任 | E35: 50 | F35: 1
B36: 2006 | C36: =VLOOKUP(B36,探索事件!A:C,3,FALSE) -> 紫 | D36: =VLOOKUP(B36,探索事件!A:E,5,FALSE) -> 委任 | E36: 40 | F36: 1
B37: 2008 | C37: =VLOOKUP(B37,探索事件!A:C,3,FALSE) -> 橙 | D37: =VLOOKUP(B37,探索事件!A:E,5,FALSE) -> 委任 | E37: 10 | F37: 1
B38: 3003 | C38: =VLOOKUP(B38,探索事件!A:C,3,FALSE) -> 蓝 | D38: =VLOOKUP(B38,探索事件!A:E,5,FALSE) -> 大地图战斗 | E38: 150 | F38: 3
B39: 3004 | C39: =VLOOKUP(B39,探索事件!A:C,3,FALSE) -> 紫 | D39: =VLOOKUP(B39,探索事件!A:E,5,FALSE) -> 大地图战斗 | E39: 120 | F39: 3
B40: 3501 | C40: =VLOOKUP(B40,探索事件!A:C,3,FALSE) -> 橙 | D40: =VLOOKUP(B40,探索事件!A:E,5,FALSE) -> 大地图战斗 | E40: 30 | F40: 3
...

Sheet 探索品质
A1: convert(ResExploration.proto, table_ExplorationQualityConf, ExplorationQualityConf.pbin)
A2: 品质等级 | B2: 条件关联 | C2: 满足条件则升级
A3: quality | B3: qualityUpConditionGroup.conditionRelation | C3: qualityUpConditionGroup.condition.condOneOf
A4: 白 | B4: 条件与 | C4: buildingLevelUp{buildingType:201,buildingLevel:1}
A5: 绿 | B5: 条件与 | C5: buildingLevelUp{buildingType:201,buildingLevel:5}
A6: 蓝 | B6: 条件与 | C6: buildingLevelUp{buildingType:201,buildingLevel:8}
A7: 紫 | B7: 条件与 | C7: buildingLevelUp{buildingType:201,buildingLevel:12}
A8: 橙 | B8: 条件与 | C8: buildingLevelUp{buildingType:201,buildingLevel:16}

Sheet 大地图实体等级配置
A1: convert(ResExploration.proto, table_ExplorationBigMapEntityLevelConf, ExplorationBigMapEntityLevelConf.pbin)
A2: 怪物强度 | B2: 类型 | C2: 野外怪物id | D2: 条件关联 | E2: 满足条件则升级
A3: id | B3: entityType | C3: monsterIds[;] | D3: entityType | E3: entityLevelConditionGroup.condition.condOneOf | F3: qualityUpConditionGroup.condition[1].condOneOf
A4: 1 | B4: 野怪 | C4: 2300101;2300102;2300103;2300104 | D4: 条件与 | E4: =G4&H4 -> explorationLevel{level:1} | G4: explorationLevel | H4: {level:1}
A5: 2 | B5: 野怪 | C5: 2300201;2300202;2300203;2300204 | D5: 条件与 | E5: =G5&H5 -> explorationLevel{level:2} | G5: explorationLevel | H5: {level:2}
A6: 3 | B6: 野怪 | C6: 2300301;2300302;2300303;2300304 | D6: 条件与 | E6: =G6&H6 -> explorationLevel{level:3} | G6: explorationLevel | H6: {level:3}
A7: 4 | B7: 野怪 | C7: 2300401;2300402;2300403;2300404 | D7: 条件与 | E7: =G7&H7 -> explorationLevel{level:4} | G7: explorationLevel | H7: {level:4}
A8: 5 | B8: 野怪 | C8: 2300501;2300502;2300503;2300504 | D8: 条件与 | E8: =G8&H8 -> explorationLevel{level:5} | G8: explorationLevel | H8: {level:5}
A9: 6 | B9: 野怪 | C9: 2300601;2300602;2300603;2300604 | D9: 条件与 | E9: =G9&H9 -> explorationLevel{level:6} | G9: explorationLevel | H9: {level:6}
A10: 7 | B10: 野怪 | C10: 2300701;2300702;2300703;2300704 | D10: 条件与 | E10: =G10&H10 -> explorationLevel{level:7} | G10: explorationLevel | H10: {level:7}
A11: 8 | B11: 野怪 | C11: 2300801;2300802;2300803;2300804 | D11: 条件与 | E11: =G11&H11 -> explorationLevel{level:8} | G11: explorationLevel | H11: {level:8}
A12: 9 | B12: 野怪 | C12: 2300901;2300902;2300903;2300904 | D12: 条件与 | E12: =G12&H12 -> explorationLevel{level:9} | G12: explorationLevel | H12: {level:9}
A13: 10 | B13: 野怪 | C13: 2301001;2301002;2301003;2301004 | D13: 条件与 | E13: =G13&H13 -> explorationLevel{level:10} | G13: explorationLevel | H13: {level:10}
A14: 11 | B14: 野怪 | C14: 2301101;2301102;2301103;2301104 | D14: 条件与 | E14: =G14&H14 -> explorationLevel{level:11} | G14: explorationLevel | H14: {level:11}
A15: 12 | B15: 野怪 | C15: 2301201;2301202;2301203;2301204 | D15: 条件与 | E15: =G15&H15 -> explorationLevel{level:12} | G15: explorationLevel | H15: {level:12}
... A23: 20 | B23: 野怪 | C23: 2302001;2302002;2302003;2302004 | D23: 条件与 | E23: =G23&H23 -> explorationLevel{level:20} | G23: explorationLevel | H23: {level:20}

Sheet 委任玩法
A1: convert(ResExploration.proto, table_ExplorationHeroAppointConf, ExplorationHeroAppointConfData.pbin)
A2: ID | B2: 派遣人数 | C2: 派遣时间(单位S) | D2: 派遣需求 | E2: 派遣需求参数1 | F2: 派遣需求参数2 | G2: 派遣英雄描述
A3: id | B3: dispatchInfo.dispatchHeroNum | C3: dispatchInfo.dispatchNeedTime | D3: dispatchInfo.dispatchArg.argType | E3: dispatchInfo.dispatchArg.parameters1 | F3: dispatchInfo.dispatchArg.parameters2 | G3: dispatchInfo.dispatchHeroDescs
A4: 11001 | B4: 3 | C4: 5400 | D4: 英雄等级 | E4: argInt1:25 | F4: argInt2:3 | G4: TID_BountyTaskPoolConfData_11001_dispatchHeroDescs_CN_Main
D5: 兵种标签 | E5: argSoldierType1:SNV_Spearman | F5: argInt2:2 | G5: TID_BountyTaskPoolConfData_11001_dispatchHeroDescs_532318218660_CN_Main
D6: 战斗风格 | E6: argHeroBattleStyle1:HBS_Bravery | F6: argInt2:2 | G6: TID_BountyTaskPoolConfData_11001_dispatchHeroDescs_838312066024_CN_Main
A7: 11002 | B7: 3 | C7: 5400 | D7: 英雄等级 | E7: argInt1:25 | F7: argInt2:3 | G7: TID_BountyTaskPoolConfData_11001_dispatchHeroDescs_CN_Main
D8: 兵种标签 | E8: argSoldierType1:SNV_Bowman | F8: argInt2:2 | G8: TID_BountyTaskPoolConfData_11002_dispatchHeroDescs_493476557234_CN_Main
D9: 战斗风格 | E9: argHeroBattleStyle1:HBS_Bravery | F9: argInt2:2 | G9: TID_BountyTaskPoolConfData_11001_dispatchHeroDescs_838312066024_CN_Main
A10: 11003 | B10: 3 | C10: 5400 | D10: 英雄等级 | E10: argInt1:25 | F10: argInt2:3 | G10: TID_BountyTaskPoolConfData_11001_dispatchHeroDescs_CN_Main
D11: 兵种标签 | E11: argSoldierType1:SNV_Cavalry | F11: argInt2:2 | G11: TID_BountyTaskPoolConfData_11003_dispatchHeroDescs_701841893877_CN_Main
D12: 战斗风格 | E12: argHeroBattleStyle1:HBS_Bravery | F12: argInt2:2 | G12: TID_BountyTaskPoolConfData_11001_dispatchHeroDescs_838312066024_CN_Main
A13: 11004 | B13: 3 | C13: 5400 | D13: 英雄等级 | E13: argInt1:25 | F13: argInt2:3 | G13: TID_BountyTaskPoolConfData_11001_dispatchHeroDescs_CN_Main
D14: 兵种标签 | E14: argSoldierType1:SNV_Swordsman | F14: argInt2:2 | G14: TID_BountyTaskPoolConfData_11004_dispatchHeroDescs_365669573143_CN_Main
D15: 战斗风格 | E15: argHeroBattleStyle1:HBS_Bravery | F15: argInt2:2 | G15: TID_BountyTaskPoolConfData_11001_dispatchHeroDescs_838312066024_CN_Main
A16: 11005 | B16: 3 | C16: 5400 | D16: 英雄等级 | E16: argInt1:25 | F16: argInt2:3 | G16: TID_BountyTaskPoolConfData_11001_dispatchHeroDescs_CN_Main
D17: 兵种标签 | E17: argSoldierType1:SNV_Spearman | F17: argInt2:2 | G17: TID_BountyTaskPoolConfData_11001_dispatchHeroDescs_532318218660_CN_Main
D18: 战斗风格 | E18: argHeroBattleStyle1:HBS_Bravery | F18: argInt2:2 | G18: TID_BountyTaskPoolConfData_11001_dispatchHeroDescs_838312066024_CN_Main
A19: 11006 | B19: 3 | C19: 5400 | D19: 英雄等级 | E19: argInt1:25 | F19: argInt2:3 | G19: TID_BountyTaskPoolConfData_11001_dispatchHeroDescs_CN_Main
D20: 兵种标签 | E20: argSoldierType1:SNV_Bowman | F20: argInt2:2 | G20: TID_BountyTaskPoolConfData_11002_dispatchHeroDescs_493476557234_CN_Main
D21: 战斗风格 | E21: argHeroBattleStyle1:HBS_Bravery | F21: argInt2:2 | G21: TID_BountyTaskPoolConfData_11001_dispatchHeroDescs_838312066024_CN_Main
A22: 11007 | B22: 3 | C22: 5400 | D22: 英雄等级 | E22: argInt1:25 | F22: argInt2:3 | G22: TID_BountyTaskPoolConfData_11001_dispatchHeroDescs_CN_Main
D23: 兵种标签 | E23: argSoldierType1:SNV_Cavalry | F23: argInt2:2 | G23: TID_BountyTaskPoolConfData_11003_dispatchHeroDescs_701841893877_CN_Main
D24: 战斗风格 | E24: argHeroBattleStyle1:HBS_Bravery | F24: argInt2:2 | G24: TID_BountyTaskPoolConfData_11001_dispatchHeroDescs_838312066024_CN_Main
A25: 11008 | B25: 3 | C25: 5400 | D25: 英雄等级 | E25: argInt1:25 | F25: argInt2:3 | G25: TID_BountyTaskPoolConfData_11001_dispatchHeroDescs_CN_Main | L25: =_xlfn.TEXTJOIN(";",TRUE,A4:A40) -> 11001;11002;11003;11004;11005;11006;11007;11008;11009;11010;11011;11012;11013
D26: 兵种标签 | E26: argSoldierType1:SNV_Swordsman | F26: argInt2:2 | G26: TID_BountyTaskPoolConfData_11004_dispatchHeroDescs_365669573143_CN_Main
D27: 战斗风格 | E27: argHeroBattleStyle1:HBS_Bravery | F27: argInt2:2 | G27: TID_BountyTaskPoolConfData_11001_dispatchHeroDescs_838312066024_CN_Main
A28: 11009 | B28: 3 | C28: 5400 | D28: 英雄等级 | E28: argInt1:25 | F28: argInt2:3 | G28: TID_BountyTaskPoolConfData_11001_dispatchHeroDescs_CN_Main
D29: 兵种标签 | E29: argSoldierType1:SNV_Spearman | F29: argInt2:2 | G29: TID_BountyTaskPoolConfData_11001_dispatchHeroDescs_532318218660_CN_Main
D30: 战斗风格 | E30: argHeroBattleStyle1:HBS_Bravery | F30: argInt2:2 | G30: TID_BountyTaskPoolConfData_11001_dispatchHeroDescs_838312066024_CN_Main
A31: 11010 | B31: 3 | C31: 5400 | D31: 英雄等级 | E31: argInt1:25 | F31: argInt2:3 | G31: TID_BountyTaskPoolConfData_11001_dispatchHeroDescs_CN_Main
D32: 兵种标签 | E32: argSoldierType1:SNV_Bowman | F32: argInt2:2 | G32: TID_BountyTaskPoolConfData_11002_dispatchHeroDescs_493476557234_CN_Main
D33: 战斗风格 | E33: argHeroBattleStyle1:HBS_Bravery | F33: argInt2:2 | G33: TID_BountyTaskPoolConfData_11001_dispatchHeroDescs_838312066024_CN_Main
A34: 11011 | B34: 3 | C34: 5400 | D34: 英雄等级 | E34: argInt1:25 | F34: argInt2:3 | G34: TID_BountyTaskPoolConfData_11001_dispatchHeroDescs_CN_Main
D35: 兵种标签 | E35: argSoldierType1:SNV_Cavalry | F35: argInt2:2 | G35: TID_BountyTaskPoolConfData_11003_dispatchHeroDescs_701841893877_CN_Main
D36: 战斗风格 | E36: argHeroBattleStyle1:HBS_Bravery | F36: argInt2:2 | G36: TID_BountyTaskPoolConfData_11001_dispatchHeroDescs_838312066024_CN_Main
A37: 11012 | B37: 3 | C37: 5400 | D37: 英雄等级 | E37: argInt1:25 | F37: argInt2:3 | G37: TID_BountyTaskPoolConfData_11001_dispatchHeroDescs_CN_Main
D38: 兵种标签 | E38: argSoldierType1:SNV_Swordsman | F38: argInt2:2 | G38: TID_BountyTaskPoolConfData_11004_dispatchHeroDescs_365669573143_CN_Main
D39: 战斗风格 | E39: argHeroBattleStyle1:HBS_Bravery | F39: argInt2:2 | G39: TID_BountyTaskPoolConfData_11001_dispatchHeroDescs_838312066024_CN_Main
A40: 11013 | B40: 3 | C40: 5400 | D40: 英雄等级 | E40: argInt1:25 | F40: argInt2:3 | G40: TID_BountyTaskPoolConfData_11001_dispatchHeroDescs_CN_Main
...

Sheet 文案表
A1: convert(ResExploration.proto,table_ExplorationEventDescConf, ExplorationEventDescConf.pbin)
A2: descId | B2: 备注 | C2: 匹配类型 | E2: 建筑配图 | F2: NPC配图 | G2: 调查前名称 | H2: 调查前正文 | I2: 事后名称 | J2: 调查后正文 | K2: 事后选项文本1 | L2: 事后选项文本2 | M2: 事后选项文本3
A3: id | C3: eventType | D3: subType | E3: buildingIcon | F3: npcIcon | G3: preSurveyName | H3: preSurveyContent | I3: afterSurveyName | J3: afterSurveyContent | K3: text1 | L3: text2 | M3: text3
A4: 1001 | C4: 大地图探索 | E4: adventure_event12 | F4: chara_college_1 | G4: Exploration_ExploreName1 | H4: Exploration_ExploreDesc1 | I4: TID_AdventureEventRandomDescConfData_1001_afterSurveyName_CN_Main | J4: TID_AdventureEventRandomDescConfData_1001_afterSurveyContent_CN_Main | K4: TID_AdventureEventRandomDescConfData_1001_text1_CN_Main
A5: 1002 | C5: 大地图探索 | E5: adventure_event12 | F5: chara_college_1 | G5: Exploration_ExploreName2 | H5: Exploration_ExploreDesc2 | I5: TID_AdventureEventRandomDescConfData_1001_afterSurveyName_CN_Main | J5: TID_AdventureEventRandomDescConfData_1001_afterSurveyContent_CN_Main | K5: TID_AdventureEventRandomDescConfData_1001_text1_CN_Main
A6: 1003 | C6: 大地图探索 | E6: adventure_event12 | F6: chara_college_1 | G6: Exploration_ExploreName3 | H6: Exploration_ExploreDesc3 | I6: TID_AdventureEventRandomDescConfData_1002_afterSurveyName_CN_Main | J6: TID_AdventureEventRandomDescConfData_1002_afterSurveyContent_CN_Main | K6: TID_AdventureEventRandomDescConfData_1002_text1_CN_Main
A7: 1004 | C7: 大地图探索 | E7: adventure_event12 | G7: Exploration_ExploreName4 | H7: Exploration_ExploreDesc4
A8: 2001 | C8: 大地图战斗 | E8: adventure_event4 | F8: chara_college_1 | G8: Exploration_BattleName1 | H8: Exploration_BattleDesc1 | I8: TID_AdventureEventRandomDescConfData_1001_afterSurveyName_CN_Main | J8: TID_AdventureEventRandomDescConfData_1001_afterSurveyContent_CN_Main | K8: TID_AdventureEventRandomDescConfData_1001_text1_CN_Main
A9: 2002 | C9: 大地图战斗 | E9: adventure_event4 | F9: chara_college_1 | G9: Exploration_BattleName2 | H9: Exploration_BattleDesc2 | I9: TID_AdventureEventRandomDescConfData_1001_afterSurveyName_CN_Main | J9: TID_AdventureEventRandomDescConfData_1001_afterSurveyContent_CN_Main | K9: TID_AdventureEventRandomDescConfData_1001_text1_CN_Main
A10: 2003 | C10: 大地图战斗 | E10: adventure_event4 | F10: chara_college_1 | G10: Exploration_BattleName3 | H10: Exploration_BattleDesc3
A11: 2004 | C11: 大地图战斗 | E11: adventure_event4 | G11: Exploration_BattleName4 | H11: Exploration_BattleDesc4
A12: 2011 | C12: 大地图战斗 | E12: adventure_event4 | G12: Exploration_BattleName5 | H12: Exploration_BattleDesc5
A13: 2012 | C13: 大地图战斗 | E13: adventure_event4 | G13: Exploration_BattleName6 | H13: Exploration_BattleDesc6
A14: 2007 | C14: 大地图战斗 | E14: adventure_event4 | G14: Exploration_BattleName7 | H14: Exploration_BattleDesc7
A15: 2008 | C15: 大地图战斗 | E15: adventure_event4 | G15: Exploration_BattleName8 | H15: Exploration_BattleDesc8
A16: 2009 | C16: 大地图战斗 | E16: adventure_event4 | G16: Exploration_BattleName9 | H16: Exploration_BattleDesc9
A17: 2010 | C17: 大地图战斗 | E17: adventure_event4 | G17: Exploration_BattleName10 | H17: Exploration_BattleDesc10
A18: 2005 | C18: 大地图战斗 | E18: adventure_event4 | G18: TID_ShowGetData_89_title_CN_Main | H18: TID_DialogNewbieFogWarGuide_1
A19: 2006 | C19: 大地图战斗 | E19: adventure_event4 | G19: TID_RaidMarchConf_30009_desc_CN_Main | H19: TID_DialogNewbieFogWarGuide_2
A20: 3001 | C20: 委任 | E20: adventure_event1 | F20: chara_college_1 | G20: TID_BountyTaskPoolConfData_11008_taskName_CN_Main | H20: TID_BountyTaskPoolConfData_11008_taskDesc_CN_Main | I20: TID_AdventureEventRandomDescConfData_1001_afterSurveyName_CN_Main | J20: TID_AdventureEventRandomDescConfData_1001_afterSurveyContent_CN_Main | K20: TID_AdventureEventRandomDescConfData_1001_text1_CN_Main
A21: 3002 | C21: 委任 | E21: adventure_event2 | F21: chara_college_1 | G21: TID_AdventureEventRandomDescConfData_1005_afterSurveyName_CN_Main | H21: TID_AdventureEventRandomDescConfData_1005_preSurveyContent_CN_Main
A22: 3003 | C22: 委任 | E22: adventure_event1 | F22: chara_college_1 | G22: TID_AdventureEventRandomDescConfData_1001_afterSurveyName_CN_Main | H22: TID_AdventureEventRandomDescConfData_1001_preSurveyContent_CN_Main | I22: TID_AdventureEventRandomDescConfData_1001_afterSurveyName_CN_Main | J22: TID_AdventureEventRandomDescConfData_1001_afterSurveyContent_CN_Main | K22: TID_AdventureEventRandomDescConfData_1001_text1_CN_Main
A23: 3004 | C23: 委任 | E23: adventure_event3 | F23: chara_college_1 | G23: TID_AdventureEventRandomDescConfData_3000001_afterSurveyName_CN_Main | H23: TID_AdventureEventRandomDescConfData_3000001_text1_CN_Main
A24: 3005 | C24: 委任 | E24: adventure_event2 | F24: chara_college_1 | G24: TID_AdventureEventRandomDescConfData_1014_afterSurveyName_CN_Main | H24: TID_AdventureEventRandomDescConfData_1014_preSurveyContent_CN_Main
A25: 3006 | C25: 委任 | E25: adventure_event4 | F25: chara_college_1 | G25: TID_BountyTaskPoolConfData_11002_taskName_CN_Main | H25: TID_BountyTaskPoolConfData_11002_taskDesc_CN_Main
A26: 3007 | C26: 委任 | E26: adventure_event3 | F26: chara_college_1 | G26: TID_AdventureEventRandomDescConfData_1013_afterSurveyName_CN_Main | H26: TID_BountyTaskPoolConfData_24013_taskDesc_CN_Main
A27: 3008 | C27: 委任 | E27: adventure_event5 | F27: chara_college_1 | G27: TID_BountyTaskPoolConfData_11003_taskName_CN_Main | H27: TID_BountyTaskPoolConfData_11003_taskDesc_CN_Main
A28: 3009 | C28: 委任 | E28: adventure_event5 | F28: chara_college_1 | G28: TID_BountyTaskPoolConfData_11001_taskName_CN_Main | H28: TID_BountyTaskPoolConfData_11001_taskDesc_CN_Main
A29: 3010 | C29: 委任 | E29: adventure_event4 | F29: chara_college_1 | G29: TID_AdventureEventRandomDescConfData_1002_afterSurveyName_CN_Main | H29: TID_BountyTaskPoolConfData_24009_taskDesc_CN_Main
A30: 4001 | C30: 对话 | E30: adventure_event1 | F30: chara_college_1 | G30: Exploration_TalkName1 | H30: Exploration_TalkDesc1 | I30: TID_AdventureEventRandomDescConfData_1001_afterSurveyName_CN_Main | J30: TID_AdventureEventRandomDescConfData_1001_afterSurveyContent_CN_Main | K30: TID_AdventureEventRandomDescConfData_1001_text1_CN_Main
A31: 4002 | C31: 对话 | E31: adventure_event1 | F31: chara_college_1 | G31: Exploration_TalkName2 | H31: Exploration_TalkDesc2 | I31: TID_AdventureEventRandomDescConfData_1001_afterSurveyName_CN_Main | J31: TID_AdventureEventRandomDescConfData_1001_afterSurveyContent_CN_Main | K31: TID_AdventureEventRandomDescConfData_1001_text1_CN_Main
A32: 4003 | C32: 对话 | E32: adventure_event1 | G32: Exploration_TalkName3 | H32: Exploration_TalkDesc3
A33: 4004 | C33: 对话 | E33: adventure_event1 | G33: Exploration_TalkName4 | H33: Exploration_TalkDesc4
A34: 4005 | C34: 对话 | E34: adventure_event1 | G34: Exploration_TalkName5 | H34: Exploration_TalkDesc5

Sheet 对话文案表
A1: convert(ResExploration.proto,table_ExplorationDialogConf,ExplorationDialogConf.pbin)
A2: 对话id | B2: 道具数目 | C2: 左边人物spine | D2: 右边人物spine | E2: 左边的人名 | F2: 右边的人名 | G2: 左边的spine缩放 | H2: 右边的spine缩放 | I2: 左边的spine位置 | J2: 右边的spine位置 | K2: 对话人物 | L2: 内容 | M2: 按钮一的内容 | N2: 按钮二的内容
A3: id | B3: data.num | C3: data.roleSpine1 | D3: data.roleSpine2 | E3: data.name1 | F3: data.name2 | G3: data.scale1[|] | H3: data.scale2[|] | I3: data.pos1[|] | J3: data.pos2[|] | K3: data.roleIndex | L3: data.text | M3: data.btnText1 | N3: data.btnText2
A4: 4001 | B4: 10 | D4: boss/p_celebrity_FN_BOSS | F4: TID_CelebrityDialogConf_14101_name2_CN_Main | H4: 175|175|100 | J4: 3000|-45000|0 | K4: 2 | L4: Exploration_Talk1Sentence1 | M4: Exploration_Talk1Answer1 | N4: Exploration_Talk1Answer2
K5: 2 | L5: Exploration_Talk1Sentence2
K6: 2 | L6: Exploration_Talk1Sentence3
K7: 2 | L7: Exploration_Talk1Sentence4 | P7: 101 | Q7: 李芊岚
K8: 2 | L8: Exploration_Talk1Sentence5 | P8: 105 | Q8: 顾烟
P9: 106 | Q9: 翟黎
A10: 4002 | B10: 10 | D10: boss/p_celebrity_FN_BOSS | F10: TID_CelebrityDialogConf_14101_name2_CN_Main | H10: 175|175|100 | J10: 3000|-45000|0 | K10: 2 | L10: Exploration_Talk2Sentence1 | M10: Exploration_Talk2Answer1 | N10: Exploration_Talk2Answer2 | P10: 107 | Q10: 伊丽莎白
K11: 2 | L11: Exploration_Talk2Sentence2 | P11: 108 | Q11: 娜娜丽
K12: 2 | L12: Exploration_Talk2Sentence3 | P12: 109 | Q12: 亚基
K13: 2 | L13: Exploration_Talk2Sentence4 | P13: 201 | Q13: 密克安哲
P14: 202 | Q14: 方选
A15: 4003 | B15: 10 | D15: boss/p_celebrity_FN_BOSS | F15: TID_CelebrityDialogConf_14101_name2_CN_Main | H15: 175|175|100 | J15: 3000|-45000|0 | K15: 2 | L15: Exploration_Talk3Sentence1 | M15: Exploration_Talk3Answer1 | N15: Exploration_Talk3Answer2 | P15: 203 | Q15: 任行之
K16: 2 | L16: Exploration_Talk3Sentence2 | P16: 204 | Q16: 列奥那
K17: 2 | L17: Exploration_Talk3Sentence3 | P17: 206 | Q17: 秦粤
K18: 2 | L18: Exploration_Talk3Sentence4
A20: 4004 | B20: 10 | D20: boss/p_celebrity_FN_BOSS | F20: TID_CelebrityDialogConf_14101_name2_CN_Main | H20: 175|175|100 | J20: 3000|-45000|0 | K20: 2 | L20: Exploration_Talk4Sentence1 | M20: Exploration_Talk4Answer1 | N20: Exploration_Talk4Answer2
K21: 2 | L21: Exploration_Talk4Sentence2
K22: 2 | L22: Exploration_Talk4Sentence3
K23: 2 | L23: Exploration_Talk4Sentence4
A25: 4005 | B25: 10 | D25: boss/p_celebrity_FN_BOSS | F25: TID_CelebrityDialogConf_14101_name2_CN_Main | H25: 175|175|100 | J25: 3000|-45000|0 | K25: 2 | L25: Exploration_Talk5Sentence1 | M25: Exploration_Talk5Answer1 | N25: Exploration_Talk5Answer2
K26: 2 | L26: Exploration_Talk5Sentence2
K27: 2 | L27: Exploration_Talk5Sentence3
K28: 2 | L28: Exploration_Talk5Sentence4

Sheet 杂项表
A1: convertTrans(ResExploration.proto,table_ExplorationMiscConf,ExplorationMiscConf.pbin)
A2: 配置项 | B2: id | C2: 1
A3: 定时刷新开始时间（小时） | B3: refreshStartHour | C3: 12
A4: 定时刷新开始间隔（小时） | B4: refreshIntervalHour | C4: 8
A5: 事件位置刷新半径 | B5: worldPointRadius | C5: 100
A6: 每天刷新特殊事件个数 | B6: refreshSpecialEventCount | C6: 3

Sheet 特殊事件
A1: convert(ResExploration.proto,table_ExplorationSpecialConfig,ExplorationSpecialConfigData.pbin)
A2: 特殊事件id | B2: 事件ID | C2: 野外怪物id
A3: eventId | B3: conditionGroup.condition.condOneOf | C3: monsterIds
A4: 100001 | B4: explorationLevel{level:5} | C4: 2400101
A5: 100002 | B5: explorationFinishEvent{eventId:100001,count:1} | C5: 2400202
A6: 100003 | B6: explorationFinishEvent{eventId:100002,count:1} | C6: 2400303
A7: 100004 | B7: explorationFinishEvent{eventId:100003,count:1} | C7: 2400404
A8: 100005 | B8: explorationFinishEvent{eventId:100004,count:1} | C8: 2400501
A9: 100006 | B9: explorationFinishEvent{eventId:100005,count:1} | C9: 2400502
A10: 100007 | B10: explorationFinishEvent{eventId:100006,count:1} | C10: 2400603
A11: 100008 | B11: ="explorationFinishEvent{eventId:"&A9+1&",count:1}" -> explorationFinishEvent{eventId:100007,count:1} | C11: 2400604
A12: 100009 | B12: ="explorationFinishEvent{eventId:"&A10+1&",count:1}" -> explorationFinishEvent{eventId:100008,count:1} | C12: 2400701
A13: 100010 | B13: ="explorationFinishEvent{eventId:"&A11+1&",count:1}" -> explorationFinishEvent{eventId:100009,count:1} | C13: 2400702
A14: 100011 | B14: ="explorationFinishEvent{eventId:"&A12+1&",count:1}" -> explorationFinishEvent{eventId:100010,count:1} | C14: 2400703
A15: 100012 | B15: ="explorationFinishEvent{eventId:"&A13+1&",count:1}" -> explorationFinishEvent{eventId:100011,count:1} | C15: 2400804
A16: 100013 | B16: ="explorationFinishEvent{eventId:"&A14+1&",count:1}" -> explorationFinishEvent{eventId:100012,count:1} | C16: 2400801
A17: 100014 | B17: ="explorationFinishEvent{eventId:"&A15+1&",count:1}" -> explorationFinishEvent{eventId:100013,count:1} | C17: 2400802
A18: 100015 | B18: ="explorationFinishEvent{eventId:"&A16+1&",count:1}" -> explorationFinishEvent{eventId:100014,count:1} | C18: 2400903
A19: 100016 | B19: ="explorationFinishEvent{eventId:"&A17+1&",count:1}" -> explorationFinishEvent{eventId:100015,count:1} | C19: 2400904
A20: 100017 | B20: ="explorationFinishEvent{eventId:"&A18+1&",count:1}" -> explorationFinishEvent{eventId:100016,count:1} | C20: 2400901
A21: 100018 | B21: ="explorationFinishEvent{eventId:"&A19+1&",count:1}" -> explorationFinishEvent{eventId:100017,count:1} | C21: 2401002
A22: 100019 | B22: ="explorationFinishEvent{eventId:"&A20+1&",count:1}" -> explorationFinishEvent{eventId:100018,count:1} | C22: 2401003
... A655: 100652 | B655: ="explorationFinishEvent{eventId:"&A653+1&",count:1}" -> explorationFinishEvent{eventId:100651,count:1} | C655: 2421004

Sheet #备注
A6: // 探索玩法扩展交互类型
A7: enum ExplorationEventInteractionType {//@useCli// //@useSvr
A8: EEIT_Delegate = 0 [(name) = "委托交互"]; //@useCli// //@useSvr
A9: EEIT_Map = 1 [(name) = "大地图交互"]; // @useCli// //@useSvr
A10: EEIT_UI = 2 [(name) = "界面交互"]; // @useCli// //@useSvr
A11: }
A18: // 探索玩法扩展大地图类型
A19: enum ExplorationEventMapType {//@useCli// //@useSvr
A20: EEMT_Visible_Self = 0 [(name) = "自己可见"]; //@useCli// //@useSvr
A21: EEMT_Invisible = 1 [(name) = "不可见"]; // @useCli// //@useSvr
A22: }
A27: // 品质,适用于英雄，技能，圣物
... A47: }
