Workbook
Name horse2id: #REF!
Name id2Data: #REF!
Name id2des: #REF!
Name id2guidedata: #REF!
Name id2ma: #REF!
Name id2name: #REF!
Name name2guidedata: #REF!
Name name2id: #REF!
Name skilldatabase: #REF!
Name skillId: #REF!
Name t2k: #REF!
Name TalentId2Des: #REF!
Name 英雄战力系数: #REF!

Sheet 英雄攻略配置表
A1: convert(ResHero.proto, table_HeroTeamStrategy, HeroTeamStrategy.pbin)
A2: id | B2: 名称 | C2: 名称（备注） | D2: 推荐id | E2: 策划用 | F2: 阵容兵种
A3: id | B3: name | D3: recommendId[|] | F3: soldierType
A4: 1 | B4: TID_TEXT_LINEUP_GUIDE_TAB_1 | C4: 新手阵容 | D4: 1|2|3|4|27 | E4: 1|2|3|4|27
A5: 2 | B5: TID_TEXT_LINEUP_GUIDE_TAB_2 | C5: 剑士阵容 | D5: 36|35|31|30|5|22|7|17|23|8 | E5: {=_xlfn.TEXTJOIN("|", TRUE, _xlfn._xlws.SORT(_xlfn._xlws.FILTER([1]阵容详细配置表!A:A, ([1]阵容详细配置表!K:K=F5) * ([1]阵容详细配置表!N:N<>"新手")), 1, -1))} -> 37|36|35|31|30|23|22|17|8|7|5 | F5: 剑士
A6: 3 | B6: TID_TEXT_LINEUP_GUIDE_TAB_3 | C6: 枪兵阵容 | D6: 41|34|28|25|21|10|9 | E6: {=_xlfn.TEXTJOIN("|", TRUE, _xlfn._xlws.SORT(_xlfn._xlws.FILTER([1]阵容详细配置表!A:A, ([1]阵容详细配置表!K:K=F6) * ([1]阵容详细配置表!N:N<>"新手")), 1, -1))} -> 41|34|28|25|21|10|9 | F6: 枪兵
A7: 4 | B7: TID_TEXT_LINEUP_GUIDE_TAB_4 | C7: 骑士阵容 | D7: 42|40|39|33|19|16|12|11|13|24 | E7: {=_xlfn.TEXTJOIN("|", TRUE, _xlfn._xlws.SORT(_xlfn._xlws.FILTER([1]阵容详细配置表!A:A, ([1]阵容详细配置表!K:K=F7) * ([1]阵容详细配置表!N:N<>"新手")), 1, -1))} -> 42|40|39|33|24|19|16|13|12|11 | F7: 骑兵
A8: 5 | B8: TID_TEXT_LINEUP_GUIDE_TAB_5 | C8: 弓兵阵容 | D8: 38|32|29|15|20|18|26 | E8: {=_xlfn.TEXTJOIN("|", TRUE, _xlfn._xlws.SORT(_xlfn._xlws.FILTER([1]阵容详细配置表!A:A, ([1]阵容详细配置表!K:K=F8) * ([1]阵容详细配置表!N:N<>"新手")), 1, -1))} -> 38|32|29|26|20|18|15 | F8: 弓兵

Sheet 阵容详细配置表
A1: convert(ResHero.proto, table_HeroTeamStrategyDetail, HeroTeamStrategyDetail.pbin)
A2: id | B2: 阵容名称（文本） | C2: 阵容名称 | D2: 阵容介绍 | E2: 阵容介绍（文本） | F2: 玺戒解锁后的阵容介绍 | G2: 玺戒解锁后的阵容介绍（文本） | H2: 槽位1英雄id | I2: 槽位2英雄id | J2: 槽位3英雄id | K2: 阵容兵种 | L2: 阵容风格 | M2: 显示icon图集 | N2: 标签文本 | O2: 阵容类型 | P2: 阵容优先级 | Q2: 备注
A3: id | C3: name | D3: desc | F3: unlockDesc | H3: pos1[|] | I3: pos2[|] | J3: pos3[|] | K3: soldierType | L3: battleStyle | M3: iconAtlas | N3: tagTxt | O3: type | P3: sort
A4: 1 | B4: 开荒公主剑 | C4: TID_TEXT_LINEUP_GUIDE_TITLE_1 | D4: TID_TEXT_LINEUP_GUIDE_CONTENT_1 | E4: <color=#ffc766>哈拉尔</color>可提升我军主将<color=#ffc766>主动</color>和<color=#ffc766>追击</color>装配技能的伤害，<color=#ffc766>约瑟芬</color>装备<color=#ffc766>追击</color>技能可享受<color=#ffc766>哈拉尔</color>的增伤效果，同时<color=#ffc766>连击</color>技能可进一步提升约瑟芬固有和装配追击技能的输出效率。该队伍的英雄均容易获取，适合新手使用。 | F4: TID_TEXT_LINEUP_GUIDE_CONTENT_1 | G4: <color=#ffc766>哈拉尔</color>可提升我军主将<color=#ffc766>主动</color>和<color=#ffc766>追击</color>装配技能的伤害，<color=#ffc766>约瑟芬</color>装备<color=#ffc766>追击</color>技能可享受<color=#ffc766>哈拉尔</color>的增伤效果，同时<color=#ffc766>连击</color>技能可进一步提升约瑟芬固有和装配追击技能的输出效率。该队伍的英雄均容易获取，适合新手使用。 | H4: 1036 | I4: 1056|1211 | J4: 1055|12111 | K4: 剑士 | L4: 勇武 | M4: icon_packageitem | N4: 新手 | Q4: 新手剑
A5: 2 | B5: 新手红颜弓 | C5: TID_TEXT_LINEUP_GUIDE_TITLE_2 | D5: TID_TEXT_LINEUP_GUIDE_CONTENT_2 | E5: <color=#ffc766>杜加瓦蒂</color>固有技能提供的<color=#ffc766>连击</color>效果，能极大的提升花木兰的输出效率。注意装配技能多选择追击技能，力争输出最大化。队伍的第三名英雄可选择<color=#ffc766>大卫王</color>，进一步提升<color=#ffc766>花木兰</color>的输出能力；也可选择<color=#ffc766>约瑟芬</color>，提升队伍的综合能力。 | F5: TID_TEXT_LINEUP_GUIDE_CONTENT_2 | G5: <color=#ffc766>杜加瓦蒂</color>固有技能提供的<color=#ffc766>连击</color>效果，能极大的提升花木兰的输出效率。注意装配技能多选择追击技能，力争输出最大化。队伍的第三名英雄可选择<color=#ffc766>大卫王</color>，进一步提升<color=#ffc766>花木兰</color>的输出能力；也可选择<color=#ffc766>约瑟芬</color>，提升队伍的综合能力。 | H5: 2009|2036 | I5: 2036|2055|2208 | J5: 2076|20551|22081 | K5: 弓兵 | L5: 勇武 | M5: icon_packageitem | N5: 新手 | Q5: 新手弓
A6: 3 | B6: 群战反击枪 | C6: TID_TEXT_LINEUP_GUIDE_TITLE_3 | D6: TID_TEXT_LINEUP_GUIDE_CONTENT_3 | E6: 反击技能在<color=#ffc766>面对大量敌人同时进攻时</color>，触发频率将提高，配合<color=#ffc766>巴巴罗萨</color>出色的减伤能力，很适合在战斗中用来承受伤害，并通过反击技能进行输出。该队伍中<color=#ffc766>列奥尼达一世</color>和<color=#ffc766>贞德</color>的固有技能均为反击技能，且较容易获取，适合新手适用。 | F6: TID_TEXT_LINEUP_GUIDE_CONTENT_3 | G6: 反击技能在<color=#ffc766>面对大量敌人同时进攻时</color>，触发频率将提高，配合<color=#ffc766>巴巴罗萨</color>出色的减伤能力，很适合在战斗中用来承受伤害，并通过反击技能进行输出。该队伍中<color=#ffc766>列奥尼达一世</color>和<color=#ffc766>贞德</color>的固有技能均为反击技能，且较容易获取，适合新手适用。 | H6: 3013|3001|3019 | I6: 3001|3019|3207 | J6: 3017|3207 | K6: 枪兵 | L6: 勇武 | M6: icon_packageitem | N6: 新手 | Q6: 新手反击枪
A7: 4 | B7: 新手暴击骑 | C7: TID_TEXT_LINEUP_GUIDE_TITLE_4 | D7: TID_TEXT_LINEUP_GUIDE_CONTENT_4 | E7: <color=#ffc766>关羽</color>的固有技能具备稀有的<color=#ffc766>暴击率</color>提升效果。触发暴击时，普通攻击和可暴击技能能够造成<color=#ffc766>双倍伤害</color>，因此，<color=#ffc766>致命一击</color>成为了他最为关键的装配技能。<color=#ffc766>杜加瓦蒂</color>提供的<color=#ffc766>连击状态</color>可以大幅提升普攻和技能的触发频率，是队伍中不可或缺的辅助英雄。 | F7: TID_TEXT_LINEUP_GUIDE_CONTENT_4 | G7: <color=#ffc766>关羽</color>的固有技能具备稀有的<color=#ffc766>暴击率</color>提升效果。触发暴击时，普通攻击和可暴击技能能够造成<color=#ffc766>双倍伤害</color>，因此，<color=#ffc766>致命一击</color>成为了他最为关键的装配技能。<color=#ffc766>杜加瓦蒂</color>提供的<color=#ffc766>连击状态</color>可以大幅提升普攻和技能的触发频率，是队伍中不可或缺的辅助英雄。 | H7: 4005|4019|4202 | I7: 4056|4019|4215 | J7: 4076|4202|42151 | K7: 骑兵 | L7: 勇武 | M7: icon_packageitem | N7: 新手 | Q7: 新手骑
A8: 5 | B8: 暴力输出谋伤剑 | C8: TID_TEXT_LINEUP_GUIDE_TITLE_5 | D8: TID_TEXT_LINEUP_GUIDE_CONTENT_5_1 | E8: 在<color=#ffc766>兵圣状态</color>中，<color=#ffc766>孙武</color>能够额外造成一次高额伤害。频繁触发固有技能并保持兵圣状态是这个阵容的核心策略。<color=#ffc766>腓力四世</color>可强化队伍的输出能力，<color=#ffc766>狄奥多拉</color>则兼具续航和增伤，队伍的第三人可根据英雄拥有情况灵活选择。 | F8: TID_TEXT_LINEUP_GUIDE_CONTENT_5_1 | G8: 在<color=#ffc766>兵圣状态</color>中，<color=#ffc766>孙武</color>能够额外造成一次高额伤害。频繁触发固有技能并保持兵圣状态是这个阵容的核心策略。<color=#ffc766>腓力四世</color>可强化队伍的输出能力，<color=#ffc766>狄奥多拉</color>则兼具续航和增伤，队伍的第三人可根据英雄拥有情况灵活选择。 | H8: 5014|5004 | I8: 5016|50041|5205 | J8: 5062|5016|5209 | K8: 剑士 | L8: 智谋 | M8: icon_packageitem | N8: 智谋 | Q8: 智谋剑
A9: 6 | B9: 新手统率剑 | C9: TID_TEXT_LINEUP_GUIDE_TITLE_6 | D9: TID_TEXT_LINEUP_GUIDE_CONTENT_6_1 | E9: <color=#ffc766>凯撒</color>和<color=#ffc766>织田信长</color>的固有技均为指挥技能，具有稳定的输出能力，适合新手前期使用。另一名副将可选择<color=#ffc766>李道玄</color>，组成完整的统率剑队伍。由于前期风格加成还未解锁，也可选择<color=#ffc766>约瑟芬</color>、<color=#ffc766>克里奥帕特拉</color>、<color=#ffc766>哈拉尔</color>等其他风格中个体能力更强的剑士英雄。 | F9: TID_TEXT_LINEUP_GUIDE_CONTENT_6_1 | G9: <color=#ffc766>凯撒</color>和<color=#ffc766>织田信长</color>的固有技均为指挥技能，具有稳定的输出能力，适合新手前期使用。另一名副将可选择<color=#ffc766>李道玄</color>，组成完整的统率剑队伍。由于前期风格加成还未解锁，也可选择<color=#ffc766>约瑟芬</color>、<color=#ffc766>克里奥帕特拉</color>、<color=#ffc766>哈拉尔</color>等其他风格中个体能力更强的剑士英雄。 | H9: 6003 | I9: 6002|2036 | J9: 6201|6004|6056 | K9: 剑士 | L9: 统率 | M9: icon_packageitem | N9: 新手 | Q9: 统帅剑
A10: 7 | B10: 传奇皇者真伤剑 | C10: TID_TEXT_LINEUP_GUIDE_TITLE_7 | D10: TID_TEXT_LINEUP_GUIDE_CONTENT_7_1 | E10: <color=#ffc766>亚瑟王</color>每两次触发固有技能后能进入<color=#ffc766>祝福状态</color>，此时攻击能<color=#ffc766>忽略敌军防御</color>，造成惊人伤害。<color=#ffc766>宫本武藏</color>自身输出能力很强，还能帮助亚瑟王更多地发动固有技能（需亚瑟王武力最高），是亚瑟王的最佳搭配之一。最后一名副将选择<color=#ffc766>君士坦丁大帝</color>，为队伍提供强大的续航辅助。该队伍输出和续航兼顾，具有非常强大的作战能力。 | F10: TID_TEXT_LINEUP_GUIDE_CONTENT_7_1 | G10: <color=#ffc766>亚瑟王</color>每两次触发固有技能后能进入<color=#ffc766>祝福状态</color>，此时攻击能<color=#ffc766>忽略敌军防御</color>，造成惊人伤害。<color=#ffc766>崔布瓦娜</color>能大大提升亚瑟王的固有主动技能发动频率，是其最佳的输出辅助副将。最后一名副将选择<color=#ffc766>君士坦丁大帝</color>，为队伍提供强大的续航辅助。该队伍输出和续航兼顾，具有非常强大的作战能力。 | H10: 7021 | I10: 7077|7091|7061 | J10: 7008|7055|7056 | K10: 剑士 | L10: 勇武 | M10: icon_packageitem | N10: 混合 | O10: 7 | P10: 1 | Q10: 亚瑟勇武剑
A11: 8 | B11: 攻城中坚勇武剑 | C11: TID_TEXT_LINEUP_GUIDE_TITLE_8 | D11: TID_TEXT_LINEUP_GUIDE_CONTENT_8 | E11: 本队最大特点是全体英雄都很容易获取，但却能有不俗的作战能力。<color=#ffc766>汉谟拉比和大卫王围绕溃散状态进行联动</color>，提升队伍的输出能力。在装配技能的选择上，可以考虑添加更多<color=#ffc766>施加溃散状态</color>的技能，以保持以上效果的稳定触发。注意该队三名英雄均具有很高的<color=#ffc766>摧城属性</color>，装配技能可替换成摧城技能作为攻城部队使用。 | F11: TID_TEXT_LINEUP_GUIDE_CONTENT_8 | G11: 本队最大特点是全体英雄都很容易获取，但却能有不俗的作战能力。<color=#ffc766>汉谟拉比和大卫王围绕溃散状态进行联动</color>，提升队伍的输出能力。在装配技能的选择上，可以考虑添加更多<color=#ffc766>施加溃散状态</color>的技能，以保持以上效果的稳定触发。注意该队三名英雄均具有很高的<color=#ffc766>摧城属性</color>，装配技能可替换成摧城技能作为攻城部队使用。 | H11: 8036 | I11: 8061 | J11: 8055 | K11: 剑士 | L11: 勇武 | M11: icon_packageitem | N11: 勇武 | Q11: 攻城剑
A12: 9 | B12: 稳定生存统率枪 | C12: TID_TEXT_LINEUP_GUIDE_TITLE_9_1 | D12: TID_TEXT_LINEUP_GUIDE_CONTENT_9_1 | E12: 统率枪阵容以<color=#ffc766>指挥技能</color>为主要的输出和治疗手段，<color=#ffc766>稳定性</color>是其最大特点。<color=#ffc766>屋大维</color>在每次我军触发一定次数固有指挥技能后，能提供额外的增伤效果，是该队伍的核心英雄。<color=#ffc766>凯撒</color>和<color=#ffc766>示巴女王</color>每隔9秒可各造成一次伤害和回复效果，具有稳定的作战能力。 | F12: TID_TEXT_LINEUP_GUIDE_CONTENT_9_1 | G12: 统率枪阵容以<color=#ffc766>指挥技能</color>为主要的输出和治疗手段，<color=#ffc766>稳定性</color>是其最大特点。<color=#ffc766>屋大维</color>在每次我军触发一定次数固有指挥技能后，能提供额外的增伤效果，是该队伍的核心英雄。<color=#ffc766>凯撒</color>和<color=#ffc766>示巴女王</color>每隔9秒可各造成一次伤害和回复效果，具有稳定的作战能力。 | H12: 9003 | I12: 9034|9213 | J12: 9064|9203 | K12: 枪兵 | L12: 统率 | M12: icon_packageitem | N12: 统率 | Q12: 指挥枪
A13: 10 | B13: 群战之王反击枪 | C13: TID_TEXT_LINEUP_GUIDE_TITLE_10 | D13: TID_TEXT_LINEUP_GUIDE_CONTENT_10_2 | E13: <color=#ffc766>理查一世</color>具有极高的武力属性，以及强大的反击能力，并且主将技能附加减速效果，能黏住敌人持续输出。<color=#ffc766>布狄卡</color>自身具有很高的反击伤害，还能进一步强化我军武力最高英雄的输出能力，与理查一世极其适配。<color=#ffc766>巴巴罗萨</color>是队伍持续输出的续航支柱，当血量降低时，续航能力逐渐变强！ | F13: TID_TEXT_LINEUP_GUIDE_CONTENT_10_2 | G13: <color=#ffc766>理查一世</color>具有极高的武力属性，以及强大的反击能力，并且主将技能附加减速效果，能黏住敌人持续输出。<color=#ffc766>布狄卡</color>自身具有很高的反击伤害，还能进一步强化我军武力最高英雄的输出能力，与理查一世极其适配。<color=#ffc766>巴巴罗萨</color>是队伍持续输出的续航支柱，当血量降低时，续航能力逐渐变强！ | H13: 10042|10013|10001 | I13: 10011|100131|100011 | J13: 10017|100191|10207 | K13: 枪兵 | L13: 勇武 | M13: icon_packageitem | N13: 勇武 | O13: 25 | P13: 2
A14: 11 | B14: 智勇双全智谋骑 | C14: TID_TEXT_LINEUP_GUIDE_TITLE_11 | D14: TID_TEXT_LINEUP_GUIDE_CONTENT_11_1 | E14: <color=#ffc766>汉尼拔</color>的固有技能能够<color=#ffc766>削弱敌军主将</color>的谋略和防御属性，搭配<color=#ffc766>压迫之袭</color>可实现全属性削弱。当<color=#ffc766>主将技能</color>触发时，汉尼拔能够获得敌军主将被削弱的部分属性，从而在一段时间内产生爆发伤害。<color=#ffc766>查士丁尼一世</color>能在我军英雄触发追击技能时提供回复和减伤效果，与汉尼拔形成很好的联动。<color=#ffc766>阿育王</color>可以提高<color=#ffc766>汉尼拔</color>固有技能的释放概率，增加属性削弱的覆盖率，同时使队伍进入<color=#ffc766>免控</color>状态。 | F14: TID_TEXT_LINEUP_GUIDE_CONTENT_11_1 | G14: <color=#ffc766>汉尼拔</color>的固有技能能够<color=#ffc766>削弱敌军主将</color>的谋略和防御属性，搭配<color=#ffc766>压迫之袭</color>可实现全属性削弱。当<color=#ffc766>主将技能</color>触发时，汉尼拔能够获得敌军主将被削弱的部分属性，从而在一段时间内产生爆发伤害。<color=#ffc766>查士丁尼一世</color>能在我军英雄触发追击技能时提供回复和减伤效果，与汉尼拔形成很好的联动。<color=#ffc766>阿育王</color>可以提高<color=#ffc766>汉尼拔</color>固有技能的释放概率，增加属性削弱的覆盖率，同时使队伍进入<color=#ffc766>免控</color>状态。 | H14: 11023|11004 | I14: 11010|110041|11210 | J14: 11075|11032|110042 | K14: 骑兵 | L14: 智谋 | M14: icon_packageitem | N14: 智谋 | Q14: 智谋骑
A15: 12 | B15: 兵扫六合决斗骑 | C15: TID_TEXT_LINEUP_GUIDE_TITLE_12 | D15: TID_TEXT_LINEUP_GUIDE_CONTENT_12_1 | E15: <color=#ffc766>熙德</color>能对处于<color=#ffc766>减速状态</color>的敌人造成额外伤害，因此野战是该阵容的强项。熙德的主将技会对攻击目标附加减速状态，因此装配技能需要选择<color=#ffc766>胜利怒吼</color>以提升队伍的怒气回复速率。副将<color=#ffc766>哈立德</color>能提升队伍的输出能力，而<color=#ffc766>示巴女王</color>则能为队伍带来更强的续航能力。也可选择<color=#ffc766>阿提拉</color>替换示巴女王，损失风格加成，换来全队连击效果，追求更极致的输出能力（注意此时熙德的<color=#ffc766>连击</color>技能可换为<color=#ffc766>弱点进攻</color>）。 | F15: TID_TEXT_LINEUP_GUIDE_CONTENT_12_1 | G15: <color=#ffc766>熙德</color>能对处于<color=#ffc766>减速状态</color>的敌人造成额外伤害，因此野战是该阵容的强项。熙德的主将技会对攻击目标附加减速状态，因此装配技能需要选择<color=#ffc766>胜利怒吼</color>以提升队伍的怒气回复速率。副将<color=#ffc766>哈立德</color>能提升队伍的输出能力，而<color=#ffc766>示巴女王</color>则能为队伍带来更强的续航能力。也可选择<color=#ffc766>阿提拉</color>替换示巴女王，损失风格加成，换来全队连击效果，追求更极致的输出能力（注意此时熙德的<color=#ffc766>连击</color>技能可换为<color=#ffc766>弱点进攻</color>）。 | H15: 12047 | I15: 12063|12064|12206 | J15: 120641|12032|12206 | K15: 骑兵 | L15: 统率 | M15: icon_packageitem | N15: 统率 | O15: 12 | P15: 1 | Q15: 决斗骑
A16: 13 | B16: 暴击致胜连击骑 | C16: TID_TEXT_LINEUP_GUIDE_TITLE_13 | D16: TID_TEXT_LINEUP_GUIDE_CONTENT_13 | E16: 相比<color=#ffc766>杜加瓦蒂</color>，<color=#ffc766>阿提拉</color>能为<color=#ffc766>全队</color>附加连击效果，配合提升暴击率的技能，能使整个队伍具有更强的爆发输出能力。<color=#ffc766>关羽</color>仍是队伍的核心输出英雄，另一名英雄选择<color=#ffc766>哈拉尔</color>，能进一步提升关羽的输出能力。也可选择<color=#ffc766>大流士一世</color>，装配技能选择追击技能，配合其固有技能带来的<color=#ffc766>忽视防御</color>效果，以及阿提拉附加的连击效果，组成双核输出队伍。该队是讲究极致输出，但防御能力稍弱的队伍。 | F16: TID_TEXT_LINEUP_GUIDE_CONTENT_13 | G16: 相比<color=#ffc766>杜加瓦蒂</color>，<color=#ffc766>阿提拉</color>能为<color=#ffc766>全队</color>附加连击效果，配合提升暴击率的技能，能使整个队伍具有更强的爆发输出能力。<color=#ffc766>关羽</color>仍是队伍的核心输出英雄，另一名英雄选择<color=#ffc766>哈拉尔</color>，能进一步提升关羽的输出能力。也可选择<color=#ffc766>大流士一世</color>，装配技能选择追击技能，配合其固有技能带来的<color=#ffc766>忽视防御</color>效果，以及阿提拉附加的连击效果，组成双核输出队伍。该队是讲究极致输出，但防御能力稍弱的队伍。 | H16: 13005|13019 | I16: 13056|130191 | J16: 13032|13076 | K16: 骑兵 | L16: 勇武 | M16: icon_packageitem | N16: 勇武 | Q16: 暴击骑
A17: 15 | B17: 状态控制智谋弓 | C17: TID_TEXT_LINEUP_GUIDE_TITLE_15 | D17: TID_TEXT_LINEUP_GUIDE_CONTENT_15 | E17: <color=#ffc766>苏莱曼一世</color>攻击处于<color=#ffc766>异常状态</color>中的敌人时，能产生额外效果，如攻击<color=#ffc766>燃烧状态</color>的敌人，能额外造成一次高额伤害。善德女王能为敌军施加<color=#ffc766>沉默状态</color>，与苏莱曼一世形成联动的同时，还能有效遏制以主动技能为主要输出手段的敌人。该队的装配技能尽量选择能附加燃烧状态的技能，以最大化苏莱曼一世的输出能力。需要注意的是，因为集结战斗中部队会不断切换目标，无法稳定的攻击燃烧状态中的敌军，会导致固有技能的输出效果降低。 | F17: TID_TEXT_LINEUP_GUIDE_CONTENT_15 | G17: <color=#ffc766>苏莱曼一世</color>攻击处于<color=#ffc766>异常状态</color>中的敌人时，能产生额外效果，如攻击<color=#ffc766>燃烧状态</color>的敌人，能额外造成一次高额伤害。善德女王能为敌军施加<color=#ffc766>沉默状态</color>，与苏莱曼一世形成联动的同时，还能有效遏制以主动技能为主要输出手段的敌人。该队的装配技能尽量选择能附加燃烧状态的技能，以最大化苏莱曼一世的输出能力。需要注意的是，因为集结战斗中部队会不断切换目标，无法稳定的攻击燃烧状态中的敌军，会导致固有技能的输出效果降低。 | H17: 15093|15020 | I17: 15092|150201 | J17: 15062|15092|15212 | K17: 弓兵 | L17: 智谋 | M17: icon_packageitem | N17: 智谋
A18: 16 | B18: 亚瑟王勇武骑 | C18: TID_TEXT_LINEUP_GUIDE_TITLE_16 | D18: TID_TEXT_LINEUP_GUIDE_CONTENT_16 | E18: 以<color=#ffc766>亚瑟王</color>为输出核心的骑兵队伍。亚瑟王在<color=#ffc766>祝福状态</color>下能无视敌方防御，伤害极高，装备追击技能时能与<color=#ffc766>阿提拉</color>固有技能提供的<color=#ffc766>连击效果</color>形成联动，使输出效率最大化。副将选择<color=#ffc766>哈拉尔</color>能更好地辅助亚瑟王进行输出，而选择<color=#ffc766>大流士一世</color>则能带来更强的输出能力。 | F18: TID_TEXT_LINEUP_GUIDE_CONTENT_16 | G18: 以<color=#ffc766>亚瑟王</color>为输出核心的骑兵队伍。亚瑟王在<color=#ffc766>祝福状态</color>下能无视敌方防御，伤害极高，装备追击技能时能与<color=#ffc766>阿提拉</color>固有技能提供的<color=#ffc766>连击效果</color>形成联动，使输出效率最大化。副将选择<color=#ffc766>哈拉尔</color>能更好地辅助亚瑟王进行输出，而选择<color=#ffc766>大流士一世</color>则能带来更强的输出能力。 | H18: 16021 | I18: 16056|16019 | J18: 16032|16076 | K18: 骑兵 | L18: 勇武 | M18: icon_packageitem | N18: 勇武 | Q18: 亚瑟勇武骑
A19: 17 | B19: 剑豪勇武剑 | C19: TID_TEXT_LINEUP_GUIDE_TITLE_17 | D19: TID_TEXT_LINEUP_GUIDE_CONTENT_17 | E19: <color=#ffc766>宫本武藏</color>自身具有较高的伤害，还能帮助队伍中武力最高的一名其他英雄额外发动固有主动技能，是主动体系队伍的强力主将。<color=#ffc766>君士坦丁大帝</color>能提供极强的续航能力，与宫本武藏形成良好的配合。另一名副将选择<color=#ffc766>汉谟拉比</color>进一步强化宫本武藏的输出能力。由于君士坦丁大帝的获取难度较高，也可选择<color=#ffc766>大卫王</color>，与汉谟拉比基于<color=#ffc766>溃散</color>状态形成联动，提供极强的团队输出强化能力。 | F19: TID_TEXT_LINEUP_GUIDE_CONTENT_17 | G19: <color=#ffc766>宫本武藏</color>自身具有较高的伤害，还能帮助队伍中武力最高的一名其他英雄额外发动固有主动技能，是主动体系队伍的强力主将。<color=#ffc766>君士坦丁大帝</color>能提供极强的续航能力，与宫本武藏形成良好的配合。另一名副将选择<color=#ffc766>崔布瓦娜</color>能大大提高宫本武藏固有主动技能的发动频率，提升伤害效率。由于君士坦丁大帝的获取难度较高，也可选择<color=#ffc766>汉谟拉比</color>作为替换英雄。 | H19: 17091|17036 | I19: 17077|17055|17056 | J19: 17008|17061|17056 | K19: 剑士 | L19: 勇武 | M19: icon_packageitem | N19: 勇武 | Q19: 勇武剑
A20: 18 | B20: 木兰连击弓 | C20: TID_TEXT_LINEUP_GUIDE_TITLE_18 | D20: TID_TEXT_LINEUP_GUIDE_CONTENT_18 | E20: 该队的核心是<color=#ffc766>阿提拉</color>，其为我军全体英雄附加的<color=#ffc766>连击</color>效果，能极大地提升<color=#ffc766>花木兰</color>和<color=#ffc766>约瑟芬</color>的输出能力！注意此时英雄的装配技能要尽量选择追击技能。副将位置也可用<color=#ffc766>大卫王</color>替换<color=#ffc766>约瑟芬</color>，大卫王虽然不是追击体系，但能强化花木兰的输出效果，形成以主将为核心输出的队伍构筑。 | F20: TID_TEXT_LINEUP_GUIDE_CONTENT_18 | G20: 该队的核心是<color=#ffc766>阿提拉</color>，其为我军全体英雄附加的<color=#ffc766>连击</color>效果，能极大地提升<color=#ffc766>花木兰</color>和<color=#ffc766>约瑟芬</color>的输出能力！注意此时英雄的装配技能要尽量选择追击技能。副将位置也可用<color=#ffc766>大卫王</color>替换<color=#ffc766>约瑟芬</color>，大卫王虽然不是追击体系，但能强化花木兰的输出效果，形成以主将为核心输出的队伍构筑。 | H20: 18009|18036 | I20: 180361|18055 | J20: 18032|18076 | K20: 弓兵 | L20: 勇武 | M20: icon_packageitem | N20: 勇武 | Q20: 连击弓
A21: 19 | B21: 吕布关羽无双骑 | C21: TID_TEXT_LINEUP_GUIDE_TITLE_19 | D21: TID_TEXT_LINEUP_GUIDE_CONTENT_19 | E21: 进阶暴击骑阵容。<color=#ffc766>暴击率</color>是该阵容的核心。<color=#ffc766>吕布</color>在队伍中任意英雄暴击后，有概率进行额外普攻；<color=#ffc766>关羽</color>则拥有高额的暴击率，开场暴击能与吕布配合，造成强力的开场爆发。<color=#ffc766>阿提拉</color>可以为队伍中的两名英雄提供连击状态，大幅提升整体伤害输出。 | F21: TID_TEXT_LINEUP_GUIDE_CONTENT_19 | G21: 进阶暴击骑阵容。<color=#ffc766>暴击率</color>是该阵容的核心。<color=#ffc766>吕布</color>在队伍中任意英雄暴击后，有概率进行额外普攻；<color=#ffc766>关羽</color>则拥有高额的暴击率，开场暴击能与吕布配合，造成强力的开场爆发。<color=#ffc766>阿提拉</color>可以为队伍中的两名英雄提供连击状态，大幅提升整体伤害输出。 | H21: {=_xlfn.TEXTJOIN("|", TRUE, IF(([1]英雄详细配置!B:B=A21)*(ISNUMBER([1]英雄详细配置!C:C)*([1]英雄详细配置!C:C=1)+ISBLANK([1]英雄详细配置!C:C)), [1]英雄详细配置!A:A, ""))} -> 19037|19005|19019 | I21: {=_xlfn.TEXTJOIN("|", TRUE, IF(([1]英雄详细配置!B:B=A21)*(ISNUMBER([1]英雄详细配置!C:C)*([1]英雄详细配置!C:C=2)+ISBLANK([1]英雄详细配置!C:C)), [1]英雄详细配置!A:A, ""))} -> 190051|19056|190191 | J21: {=_xlfn.TEXTJOIN("|", TRUE, IF(([1]英雄详细配置!B:B=A21)*(ISNUMBER([1]英雄详细配置!C:C)*([1]英雄详细配置!C:C=3)+ISBLANK([1]英雄详细配置!C:C)), [1]英雄详细配置!A:A, ""))} -> 19032|19076 | K21: 骑兵 | L21: 勇武 | M21: icon_packageitem | N21: 勇武 | O21: 19 | P21: 1
A22: 20 | B22: 贝利薇连击弓 | C22: TID_TEXT_LINEUP_GUIDE_TITLE_20 | D22: TID_TEXT_LINEUP_GUIDE_CONTENT_20 | E22: 该阵容是以<color=#ffc766>连击</color>为核心的追击阵容体系。<color=#ffc766>贝利薇</color>每回合有概率进入连击状态，搭配追击技能有着极强的输出能力，是队伍的核心。<color=#ffc766>花木兰</color>搭配追击技能也有着不俗的输出能力。<color=#ffc766>阿提拉</color>可以使队伍整体进入连击状态，提高连击覆盖率，进一步增加队伍的输出能力。 | F22: TID_TEXT_LINEUP_GUIDE_CONTENT_20 | G22: 该阵容是以<color=#ffc766>连击</color>为核心的追击阵容体系。<color=#ffc766>贝利薇</color>每回合有概率进入连击状态，搭配追击技能有着极强的输出能力，是队伍的核心。<color=#ffc766>花木兰</color>搭配追击技能也有着不俗的输出能力。<color=#ffc766>阿提拉</color>可以使队伍整体进入连击状态，提高连击覆盖率，进一步增加队伍的输出能力。 | H22: 20069 | I22: 20032|20076 | J22: 20009|20036 | K22: 弓兵 | L22: 勇武 | M22: icon_packageitem | N22: 勇武 | O22: 20 | P22: 1
A23: 21 | B23: 兰甘亨团辅枪 | C23: TID_TEXT_LINEUP_GUIDE_TITLE_21 | D23: TID_TEXT_LINEUP_GUIDE_CONTENT_21 | E23: 该阵容是以<color=#ffc766>兰甘亨</color>为核心的团队辅助阵容。<color=#ffc766>兰甘亨</color>的主将技和固有技能可以提升范围内玩家多支部队的伤害输出，并增加生存能力。<color=#ffc766>屋大维</color>能为部队提供额外的增伤效果。<color=#ffc766>示巴女王</color>则能带来更强的续航能力。队伍的整体输出能力一般，但生存和辅助能力优秀，能极大地提升玩家其他部队的整体作战能力。 | F23: TID_TEXT_LINEUP_GUIDE_CONTENT_21 | G23: 该阵容是以<color=#ffc766>兰甘亨</color>为核心的团队辅助阵容。<color=#ffc766>兰甘亨</color>的主将技和固有技能可以提升范围内玩家多支部队的伤害输出，并增加生存能力。<color=#ffc766>屋大维</color>能为部队提供额外的增伤效果。<color=#ffc766>示巴女王</color>则能带来更强的续航能力。队伍的整体输出能力一般，但生存和辅助能力优秀，能极大地提升玩家其他部队的整体作战能力。 | H23: 21078 | I23: 21034|21003 | J23: 21064|210031 | K23: 枪兵 | L23: 统率 | M23: icon_packageitem | N23: 统率
A24: 22 | B24: 游娣特威慑剑 | C24: TID_TEXT_LINEUP_GUIDE_TITLE_22 | D24: TID_TEXT_LINEUP_GUIDE_CONTENT_22 | E24: 以<color=#ffc766>游娣特</color>为核心的剑士阵容。<color=#ffc766>游娣特</color>的固有技能有着不俗的伤害，同时有概率附加<color=#ffc766>抵御</color>状态，叠加层数后还能提高主将技的伤害。<color=#ffc766>崔布瓦娜</color>可以提高<color=#ffc766>游娣特</color>固有技能的释放频率，增加队伍的输出和生存能力。<color=#ffc766>君士坦丁大帝</color>可以在<color=#ffc766>游娣特</color>释放固有技能后，提供伤害减免，极大增加队伍的生存能力。 | F24: TID_TEXT_LINEUP_GUIDE_CONTENT_22 | G24: 以<color=#ffc766>游娣特</color>为核心的剑士阵容。<color=#ffc766>游娣特</color>的固有技能有着不俗的伤害，同时有概率附加<color=#ffc766>抵御</color>状态，叠加层数后还能提高主将技的伤害。<color=#ffc766>崔布瓦娜</color>可以提高<color=#ffc766>游娣特</color>固有技能的释放频率，增加队伍的输出和生存能力。<color=#ffc766>君士坦丁大帝</color>可以在<color=#ffc766>游娣特</color>释放固有技能后，提供伤害减免，极大增加队伍的生存能力。 | H24: 22106 | I24: 22077|22091 | J24: 22008|220911|22061 | K24: 剑士 | L24: 勇武 | M24: icon_packageitem | N24: 勇武 | O24: 22 | P24: 1 | Q24: 勇武剑-2
A25: 23 | B25: 战国三杰剑 | C25: TID_TEXT_LINEUP_GUIDE_TITLE_23 | D25: TID_TEXT_LINEUP_GUIDE_CONTENT_23 | E25: <color=#ffc766>丰臣秀吉</color>自身具有不俗的伤害，还能提高队伍中武力最高的一名英雄的固有技能伤害。<color=#ffc766>织田信长</color>固有为指挥技能，具有稳定的输出能力。同时<color=#ffc766>德川家康</color>能提供很好的续航能力，并且可以使我军受到的技能伤害减少。该队伍攻守兼备，可适用于多种战斗场景，实力强劲。 | F25: TID_TEXT_LINEUP_GUIDE_CONTENT_23 | G25: <color=#ffc766>丰臣秀吉</color>自身具有不俗的伤害，还能提高队伍中武力最高的一名英雄的固有主动技能伤害。<color=#ffc766>织田信长</color>固有为指挥技能，具有稳定的输出能力。同时<color=#ffc766>德川家康</color>能提供很好的续航能力，并且可以使我军受到的技能伤害减少。该队伍攻守兼备，可适用于多种战斗场景，实力强劲。 | H25: 23104 | I25: 23002 | J25: 23102 | K25: 剑士 | L25: 统率 | M25: icon_packageitem | N25: 统率 | Q25: 统帅剑
A26: 24 | B26: 李成桂急智骑 | C26: TID_TEXT_LINEUP_GUIDE_TITLE_24 | D26: TID_TEXT_LINEUP_GUIDE_CONTENT_24 | E26: 该阵容是以<color=#ffc766>李成桂</color>为核心的骑兵输出阵容。<color=#ffc766>李成桂</color>可进入<color=#ffc766>急智</color>状态，搭配主动技能，有2次触发机会。<color=#ffc766>李裪</color>则为队伍提供减伤和恢复，增加阵容的续航能力。<color=#ffc766>示巴女王</color>每隔9秒可造成一次回复效果，提供稳定回复外，有概率缴械敌方部队。该队伍以主动输出为主，兼具稳定的减伤和回复。 | F26: TID_TEXT_LINEUP_GUIDE_CONTENT_24 | G26: 该阵容是以<color=#ffc766>李成桂</color>为核心的骑兵输出阵容。<color=#ffc766>李成桂</color>可进入<color=#ffc766>急智</color>状态，搭配主动技能，有2次触发机会。<color=#ffc766>李裪</color>则为队伍提供减伤和恢复，增加阵容的续航能力。<color=#ffc766>示巴女王</color>每隔9秒可造成一次回复效果，提供稳定回复外，有概率缴械敌方部队。该队伍以主动输出为主，兼具稳定的减伤和回复。 | H26: 24105 | I26: 24103 | J26: 24064 | K26: 骑兵 | L26: 统率 | M26: icon_packageitem | N26: 统率 | Q26: 统帅骑
A27: 25 | B27: 群战反击枪 | C27: TID_TEXT_LINEUP_GUIDE_TITLE_3 | D27: TID_TEXT_LINEUP_GUIDE_CONTENT_25 | E27: 反击技能在<color=#ffc766>面对大量敌人同时进攻时</color>，触发频率将提高，配合<color=#ffc766>巴巴罗萨</color>出色的减伤能力，很适合在战斗中用来承受伤害，并通过反击技能进行输出。该队伍中<color=#ffc766>理查一世</color>和<color=#ffc766>列奥尼达一世</color>的固有技能均为反击技能，且能够通过反击输出大量伤害，装配技能可以也选择反击技能，进一步提升伤害。队伍兼具输出和生存能力。 | F27: TID_TEXT_LINEUP_GUIDE_CONTENT_25 | G27: 反击技能在<color=#ffc766>面对大量敌人同时进攻时</color>，触发频率将提高，配合<color=#ffc766>巴巴罗萨</color>出色的减伤能力，很适合在战斗中用来承受伤害，并通过反击技能进行输出。该队伍中<color=#ffc766>理查一世</color>和<color=#ffc766>列奥尼达一世</color>的固有技能均为反击技能，且能够通过反击输出大量伤害，装配技能可以也选择反击技能，进一步提升伤害。队伍兼具输出和生存能力。 | H27: 25042|25013|25001 | I27: 250131|250011|25019 | J27: 25017|250191|25207 | K27: 枪兵 | L27: 勇武 | M27: icon_packageitem | N27: 勇武 | O27: 25 | P27: 1 | Q27: 反击枪
A28: 26 | B28: 李舜臣智谋弓 | C28: TID_TEXT_LINEUP_GUIDE_TITLE_26 | D28: TID_TEXT_LINEUP_GUIDE_CONTENT_26 | E28: <color=#ffc766>李舜臣</color>能够造成一次高额伤害，并且提高下一位英雄的技能伤害。善德女王能为敌军施加<color=#ffc766>沉默状态</color>，与李舜臣一世形成联动的同时，还能有效遏制以主动技能为主要输出手段的敌人。<color=#ffc766>狄奥多拉</color>则兼具续航和增伤。 | F28: TID_TEXT_LINEUP_GUIDE_CONTENT_26 | G28: <color=#ffc766>李舜臣</color>能够造成一次高额伤害，并且提高下一位英雄的技能伤害。善德女王能为敌军施加<color=#ffc766>沉默状态</color>，与李舜臣一世形成联动的同时，还能有效遏制以主动技能为主要输出手段的敌人。<color=#ffc766>狄奥多拉</color>则兼具续航和增伤。 | H28: 26020 | I28: 26092 | J28: 26062|26212 | K28: 弓兵 | L28: 智谋 | M28: icon_packageitem | N28: 智谋 | Q28: 智谋弓
A29: 27 | B29: 貂蝉采集队 | C29: TID_TEXT_LINEUP_GUIDE_TITLE_27 | D29: TID_TEXT_LINEUP_GUIDE_CONTENT_27 | E29: <color=#ffc766>貂蝉</color>固有技能可提升采集速度，且可以额外获得采集资源。<color=#ffc766>克里奥帕特拉</color>和<color=#ffc766>大流士一世</color>装配提升采集速度的技能，使得整个队伍的采集速度大幅度提高。 | F29: TID_TEXT_LINEUP_GUIDE_CONTENT_27 | G29: <color=#ffc766>貂蝉</color>固有技能可提升采集速度，且可以额外获得采集资源。<color=#ffc766>克里奥帕特拉</color>和<color=#ffc766>大流士一世</color>装配提升采集速度的技能，使得整个队伍的采集速度大幅度提高。 | H29: 27038 | I29: 27004 | J29: 27019 | K29: 骑兵 | L29: 智谋 | M29: icon_packageitem | N29: 新手 | Q29: 采集队
A30: 28 | B30: 群战之王反击枪 | C30: TID_TEXT_LINEUP_GUIDE_TITLE_28 | D30: TID_TEXT_LINEUP_GUIDE_CONTENT_28 | E30: <color=#ffc766>理查一世</color>具有极高的武力属性，以及强大的反击能力，并且主将技能附加减速效果，能黏住敌人持续输出。<color=#ffc766>布狄卡</color>自身具有很高的反击伤害，还能进一步强化我军武力最高英雄的输出能力，与理查一世极其适配。<color=#ffc766>曼萨穆萨</color>在造成伤害的同时，能为队伍提供减伤，增加队伍续航。 | F30: TID_TEXT_LINEUP_GUIDE_CONTENT_28 | G30: <color=#ffc766>理查一世</color>具有极高的武力属性，以及强大的反击能力，并且主将技能附加减速效果，能黏住敌人持续输出。<color=#ffc766>布狄卡</color>自身具有很高的反击伤害，还能进一步强化我军武力最高英雄的输出能力，与理查一世极其适配。<color=#ffc766>曼萨穆萨</color>在造成伤害的同时，能为队伍提供减伤，增加队伍续航。 | H30: 10042|10013|10001 | I30: 10011|100131|100011 | J30: 28107|10017|100191 | K30: 枪兵 | L30: 勇武 | M30: icon_packageitem | N30: 勇武 | O30: 25 | P30: 3 | R30: T+1
A31: 29 | B31: 贝利薇连击弓 | C31: TID_TEXT_LINEUP_GUIDE_TITLE_29 | D31: TID_TEXT_LINEUP_GUIDE_CONTENT_29 | E31: 该阵容是以<color=#ffc766>连击</color>为核心的追击阵容体系。<color=#ffc766>贝利薇</color>每回合有概率进入连击状态，搭配追击技能有着极强的输出能力，是队伍的核心。<color=#ffc766>阿提拉</color>可以使队伍整体进入连击状态，提高连击覆盖率，进一步增加队伍的输出能力。<color=#ffc766>穆罕穆德二世</color>可以提升队伍的伤害，同时为队伍提供减伤，弥补阵容缺少的生存能力。 | F31: TID_TEXT_LINEUP_GUIDE_CONTENT_29 | G31: 该阵容是以<color=#ffc766>连击</color>为核心的追击阵容体系。<color=#ffc766>贝利薇</color>每回合有概率进入连击状态，搭配追击技能有着极强的输出能力，是队伍的核心。<color=#ffc766>阿提拉</color>可以使队伍整体进入连击状态，提高连击覆盖率，进一步增加队伍的输出能力。<color=#ffc766>穆罕穆德二世</color>可以提升队伍的伤害，同时为队伍提供减伤，弥补阵容缺少的生存能力。 | H31: 20069 | I31: 20032|20076 | J31: 29115|20009|20036 | K31: 弓兵 | L31: 勇武 | M31: icon_packageitem | N31: 勇武 | O31: 20 | P31: 2
A32: 30 | B32: 游娣特威慑剑 | C32: TID_TEXT_LINEUP_GUIDE_TITLE_30 | D32: TID_TEXT_LINEUP_GUIDE_CONTENT_30 | E32: 以<color=#ffc766>游娣特</color>为核心的剑士阵容。<color=#ffc766>游娣特</color>的固有技能有着不俗的伤害，同时有概率附加<color=#ffc766>抵御</color>状态，叠加层数后还能提高主将技的伤害。<color=#ffc766>崔布瓦娜</color>可以提高<color=#ffc766>游娣特</color>固有技能的释放频率，增加队伍的输出能力。<color=#ffc766>穆罕穆德二世</color>可以为队伍增伤，同时提供伤害减免，增加队伍生存能力。 | F32: TID_TEXT_LINEUP_GUIDE_CONTENT_30 | G32: 以<color=#ffc766>游娣特</color>为核心的剑士阵容。<color=#ffc766>游娣特</color>的固有技能有着不俗的伤害，同时有概率附加<color=#ffc766>抵御</color>状态，叠加层数后还能提高主将技的伤害。<color=#ffc766>崔布瓦娜</color>可以提高<color=#ffc766>游娣特</color>固有技能的释放频率，增加队伍的输出能力。<color=#ffc766>穆罕穆德二世</color>可以为队伍增伤，同时提供伤害减免，增加队伍生存能力。 | H32: 22106 | I32: 22077|22091 | J32: 30115|22008|220911 | K32: 剑士 | L32: 勇武 | M32: icon_packageitem | N32: 勇武 | O32: 22 | P32: 2
A33: 31 | B33: 拉美西斯神佑剑 | C33: TID_TEXT_LINEUP_GUIDE_TITLE_31 | D33: TID_TEXT_LINEUP_GUIDE_CONTENT_31 | E33: <color=#ffc766>拉美西斯二世</color> 可以使自己进入<color=#ffc766>神佑</color> 状态，持续触发固有技能，是队伍的输出核心。<color=#ffc766>查理曼大帝</color>能触发主将固有主动技能，强化队伍的输出能力，<color=#ffc766>狄奥多拉</color>能为队伍提供减伤，同时增加主将的输出。 | F33: TID_TEXT_LINEUP_GUIDE_CONTENT_31 | G33: <color=#ffc766>拉美西斯二世</color> 可以使自己进入<color=#ffc766>神佑</color> 状态，持续触发固有技能，是队伍的输出核心。<color=#ffc766>查理曼大帝</color>能触发主将固有主动技能，强化队伍的输出能力，<color=#ffc766>狄奥多拉</color>能为队伍提供减伤，同时增加主将的输出。 | H33: 31116|31014 | I33: 31041|31016|5205 | J33: 31062|5016|5209 | K33: 剑士 | L33: 智谋 | M33: icon_packageitem | N33: 智谋
A34: 32 | B34: 拉美西斯神佑弓 | C34: TID_TEXT_LINEUP_GUIDE_TITLE_32 | D34: TID_TEXT_LINEUP_GUIDE_CONTENT_32 | E34: <color=#ffc766>拉美西斯二世</color> 可以使自己进入<color=#ffc766>神佑</color> 状态，持续触发固有技能，是队伍的输出核心。<color=#ffc766>苏莱曼一世</color>作为副将也能输出高额伤害。<color=#ffc766>查理曼大帝</color>能触发主将固有主动技能，强化队伍的输出能力。 | F34: TID_TEXT_LINEUP_GUIDE_CONTENT_32 | G34: <color=#ffc766>拉美西斯二世</color> 可以使自己进入<color=#ffc766>神佑</color> 状态，持续触发固有技能，是队伍的输出核心。<color=#ffc766>苏莱曼一世</color>作为副将也能输出高额伤害。<color=#ffc766>查理曼大帝</color>能触发主将固有主动技能，强化队伍的输出能力。 | H34: 32116|32093|32020 | I34: 32041|32092|150201 | J34: 32062|15092|15212 | K34: 弓兵 | L34: 智谋 | M34: icon_packageitem | N34: 智谋
A35: 33 | B35: 兵扫六合决斗骑 | C35: TID_TEXT_LINEUP_GUIDE_TITLE_12 | D35: TID_TEXT_LINEUP_GUIDE_CONTENT_33 | E35: <color=#ffc766>熙德</color>能对处于<color=#ffc766>减速状态</color>的敌人造成额外伤害，因此野战是该阵容的强项。熙德的主将技会对攻击目标附加减速状态，因此装配技能需要选择<color=#ffc766>胜利怒吼</color>以提升队伍的怒气回复速率。<color=#ffc766>萨拉丁</color>的固有技能能够回复怒气，提升主将技释放频率，增加队伍伤害。而<color=#ffc766>布什拉</color>则能为队伍带来更强的续航能力。也可选择<color=#ffc766>阿提拉</color>替换布什拉，损失风格加成，换来全队连击效果，追求更极致的输出能力（注意此时熙德的<color=#ffc766>连击</color>技能可换为<color=#ffc766>弱点进攻</color>）。 | F35: TID_TEXT_LINEUP_GUIDE_CONTENT_33 | G35: <color=#ffc766>熙德</color>能对处于<color=#ffc766>减速状态</color>的敌人造成额外伤害，因此野战是该阵容的强项。熙德的主将技会对攻击目标附加减速状态，因此装配技能需要选择<color=#ffc766>胜利怒吼</color>以提升队伍的怒气回复速率。<color=#ffc766>萨拉丁</color>的固有技能能够回复怒气，提升主将技释放频率，增加队伍伤害。而<color=#ffc766>布什拉</color>则能为队伍带来更强的续航能力。也可选择<color=#ffc766>阿提拉</color>替换布什拉，损失风格加成，换来全队连击效果，追求更极致的输出能力（注意此时熙德的<color=#ffc766>连击</color>技能可换为<color=#ffc766>弱点进攻</color>）。 | H35: 12047 | I35: 33012|12063|12064 | J35: 120641|12032|12206 | K35: 骑兵 | L35: 统率 | M35: icon_packageitem | N35: 统率 | O35: 12 | P35: 2
A36: 34 | B36: 群战之王反击枪 | C36: TID_TEXT_LINEUP_GUIDE_TITLE_28 | D36: TID_TEXT_LINEUP_GUIDE_CONTENT_34 | E36: <color=#ffc766>居鲁士大帝</color>固有技能在装配技能触发时，可以造成伤害，装配两个反击技能，通过高频率触发装配技能和和固有技能，输出大量伤害。<color=#ffc766>布狄卡</color>自身具有很高的反击伤害，还能进一步强化我军武力最高英雄的输出能力，与居鲁士大帝极其适配。<color=#ffc766>曼萨穆萨</color>在造成伤害的同时，能为队伍提供减伤，增加队伍生存能力。 | F36: TID_TEXT_LINEUP_GUIDE_CONTENT_34 | G36: <color=#ffc766>居鲁士大帝</color>固有技能在装配技能触发时，可以造成伤害，装配两个反击技能，通过高频率触发装配技能和和固有技能，输出大量伤害。<color=#ffc766>布狄卡</color>自身具有很高的反击伤害，还能进一步强化我军武力最高英雄的输出能力，与居鲁士大帝极其适配。<color=#ffc766>曼萨穆萨</color>在造成伤害的同时，能为队伍提供减伤，增加队伍生存能力。 | H36: {=_xlfn.TEXTJOIN("|", TRUE, IF(([1]英雄详细配置!B:B=A36)*(ISNUMBER([1]英雄详细配置!C:C)*([1]英雄详细配置!C:C=1)+ISBLANK([1]英雄详细配置!C:C)), [1]英雄详细配置!A:A, ""))} -> 34121|34042|34013 | I36: {=_xlfn.TEXTJOIN("|", TRUE, IF(([1]英雄详细配置!B:B=A36)*(ISNUMBER([1]英雄详细配置!C:C)*([1]英雄详细配置!C:C=2)+ISBLANK([1]英雄详细配置!C:C)), [1]英雄详细配置!A:A, ""))} -> 34011|340131|34001 | J36: {=_xlfn.TEXTJOIN("|", TRUE, IF(([1]英雄详细配置!B:B=A36)*(ISNUMBER([1]英雄详细配置!C:C)*([1]英雄详细配置!C:C=3)+ISBLANK([1]英雄详细配置!C:C)), [1]英雄详细配置!A:A, ""))} -> 34107|34017|34019 | K36: 枪兵 | L36: 勇武 | M36: icon_packageitem | N36: 勇武 | O36: 25 | P36: 4 | R36: T+2
A37: 35 | B37: 游娣特威慑剑 | C37: TID_TEXT_LINEUP_GUIDE_TITLE_30 | D37: TID_TEXT_LINEUP_GUIDE_CONTENT_35 | E37: 以<color=#ffc766>游娣特</color>为核心的剑士阵容。<color=#ffc766>游娣特</color>的固有技能有着不俗的伤害，同时有概率附加<color=#ffc766>抵御</color>状态，叠加层数后还能提高主将技的伤害。<color=#ffc766>穆罕穆德二世</color>可以为队伍增伤，同时提供伤害减免，增加队伍生存能力。<color=#ffc766>拉葛莎</color>可以为自身和主将附加<color=#ffc766>裁决</color>效果，释放固有主动技能时有概率额外触发，与<color=#ffc766>游娣特</color>十分契合。 | F37: TID_TEXT_LINEUP_GUIDE_CONTENT_35 | G37: 以<color=#ffc766>游娣特</color>为核心的剑士阵容。<color=#ffc766>游娣特</color>的固有技能有着不俗的伤害，同时有概率附加<color=#ffc766>抵御</color>状态，叠加层数后还能提高主将技的伤害。<color=#ffc766>穆罕穆德二世</color>可以为队伍增伤，同时提供伤害减免，增加队伍生存能力。<color=#ffc766>拉葛莎</color>可以为自身和主将附加<color=#ffc766>裁决</color>效果，释放固有主动技能时有概率额外触发，与<color=#ffc766>游娣特</color>十分契合。 | H37: {=_xlfn.TEXTJOIN("|", TRUE, IF(([1]英雄详细配置!B:B=A37)*(ISNUMBER([1]英雄详细配置!C:C)*([1]英雄详细配置!C:C=1)+ISBLANK([1]英雄详细配置!C:C)), [1]英雄详细配置!A:A, ""))} -> 35106 | I37: {=_xlfn.TEXTJOIN("|", TRUE, IF(([1]英雄详细配置!B:B=A37)*(ISNUMBER([1]英雄详细配置!C:C)*([1]英雄详细配置!C:C=2)+ISBLANK([1]英雄详细配置!C:C)), [1]英雄详细配置!A:A, ""))} -> 35008|35115|350911 | J37: {=_xlfn.TEXTJOIN("|", TRUE, IF(([1]英雄详细配置!B:B=A37)*(ISNUMBER([1]英雄详细配置!C:C)*([1]英雄详细配置!C:C=3)+ISBLANK([1]英雄详细配置!C:C)), [1]英雄详细配置!A:A, ""))} -> 35122|35077|35091 | K37: 剑士 | L37: 勇武 | M37: icon_packageitem | N37: 勇武 | O37: 22 | P37: 3
A38: 36 | B38: 传奇皇者真伤剑 | C38: TID_TEXT_LINEUP_GUIDE_TITLE_7 | D38: TID_TEXT_LINEUP_GUIDE_CONTENT_36 | E38: <color=#ffc766>亚瑟王</color>每两次触发固有技能后能进入<color=#ffc766>祝福状态</color>，此时攻击能<color=#ffc766>忽略敌军防御</color>，造成惊人伤害。<color=#ffc766>君士坦丁大帝</color>能为队伍提供强大的续航。<color=#ffc766>拉葛莎</color>能够为自身和主将附加<color=#ffc766>裁决</color>状态，释放固有主动技能时有概率额外触发，使亚瑟王更快更频繁的进入<color=#ffc766>祝福状态</color>。该队伍输出和续航兼顾，具有非常强大的作战能力。 | F38: TID_TEXT_LINEUP_GUIDE_CONTENT_36 | G38: <color=#ffc766>亚瑟王</color>每两次触发固有技能后能进入<color=#ffc766>祝福状态</color>，此时攻击能<color=#ffc766>忽略敌军防御</color>，造成惊人伤害。<color=#ffc766>君士坦丁大帝</color>能为队伍提供强大的续航。<color=#ffc766>拉葛莎</color>能够为自身和主将附加<color=#ffc766>裁决</color>状态，释放固有主动技能时有概率额外触发，使亚瑟王更快更频繁的进入<color=#ffc766>祝福状态</color>。该队伍输出和续航兼顾，具有非常强大的作战能力。 | H38: {=_xlfn.TEXTJOIN("|", TRUE, IF(([1]英雄详细配置!B:B=A38)*(ISNUMBER([1]英雄详细配置!C:C)*([1]英雄详细配置!C:C=1)+ISBLANK([1]英雄详细配置!C:C)), [1]英雄详细配置!A:A, ""))} -> 36021 | I38: {=_xlfn.TEXTJOIN("|", TRUE, IF(([1]英雄详细配置!B:B=A38)*(ISNUMBER([1]英雄详细配置!C:C)*([1]英雄详细配置!C:C=2)+ISBLANK([1]英雄详细配置!C:C)), [1]英雄详细配置!A:A, ""))} -> 36008|36115|360911 | J38: {=_xlfn.TEXTJOIN("|", TRUE, IF(([1]英雄详细配置!B:B=A38)*(ISNUMBER([1]英雄详细配置!C:C)*([1]英雄详细配置!C:C=3)+ISBLANK([1]英雄详细配置!C:C)), [1]英雄详细配置!A:A, ""))} -> 36122|36077|36091 | K38: 剑士 | L38: 勇武 | M38: icon_packageitem | N38: 勇武 | O38: 7 | P38: 2
A39: 37 | B39: 拉葛莎亚瑟裁决剑 | C39: TID_TEXT_LINEUP_GUIDE_TITLE_37 | D39: TID_TEXT_LINEUP_GUIDE_CONTENT_37 | E39: <color=#ffc766>拉葛莎</color>主将技能使自身和下一位英雄造成伤害时<color=#ffc766>无视敌军防御</color>，固有技能可以增加自身和下一位出手英雄的固有技能释放频率，与亚瑟王十分契合。<color=#ffc766>亚瑟王</color>在多次触发固有技能后，可以进入<color=#ffc766>祝福</color>状态，输出爆发性伤害。对于没有亚瑟王的玩家，也可以使用<color=#ffc766>游娣特</color>替代。最后一名副将可以选择<color=#ffc766>崔布瓦娜</color>，进一步提升队伍伤害。也可以选择<color=#ffc766>君士坦丁大帝</color>，为队伍提供强大的续航辅助。 | F39: TID_TEXT_LINEUP_GUIDE_CONTENT_37 | G39: <color=#ffc766>拉葛莎</color>主将技能使自身和下一位英雄造成伤害时<color=#ffc766>无视敌军防御</color>，固有技能可以增加自身和下一位出手英雄的固有技能释放频率，与亚瑟王十分契合。<color=#ffc766>亚瑟王</color>在多次触发固有技能后，可以进入<color=#ffc766>祝福</color>状态，输出爆发性伤害。对于没有亚瑟王的玩家，也可以使用<color=#ffc766>游娣特</color>替代。最后一名副将可以选择<color=#ffc766>崔布瓦娜</color>，进一步提升队伍伤害。也可以选择<color=#ffc766>君士坦丁大帝</color>，为队伍提供强大的续航辅助。 | H39: {=_xlfn.TEXTJOIN("|", TRUE, IF(([1]英雄详细配置!B:B=A39)*(ISNUMBER([1]英雄详细配置!C:C)*([1]英雄详细配置!C:C=1)+ISBLANK([1]英雄详细配置!C:C)), [1]英雄详细配置!A:A, ""))} -> 37122 | I39: {=_xlfn.TEXTJOIN("|", TRUE, IF(([1]英雄详细配置!B:B=A39)*(ISNUMBER([1]英雄详细配置!C:C)*([1]英雄详细配置!C:C=2)+ISBLANK([1]英雄详细配置!C:C)), [1]英雄详细配置!A:A, ""))} -> 37021|37106|37077 | J39: {=_xlfn.TEXTJOIN("|", TRUE, IF(([1]英雄详细配置!B:B=A39)*(ISNUMBER([1]英雄详细配置!C:C)*([1]英雄详细配置!C:C=3)+ISBLANK([1]英雄详细配置!C:C)), [1]英雄详细配置!A:A, ""))} -> 37008|37115|370771 | K39: 剑士 | L39: 勇武 | M39: icon_packageitem | N39: 勇武 | Q39: 勇武剑-3-亚瑟 | R39: 不展示
A40: 38 | B40: 贝利薇连击弓 | C40: TID_TEXT_LINEUP_GUIDE_TITLE_29 | D40: TID_TEXT_LINEUP_GUIDE_CONTENT_38 | E40: 该阵容是以<color=#ffc766>连击</color>为核心的追击阵容体系。<color=#ffc766>贝利薇</color>每回合有概率进入连击状态，搭配追击技能有着极强的输出能力，是队伍的核心。<color=#ffc766>罗宾汉</color>可以基于连击状态，提供高额的输出增益，与<color=#ffc766>贝利薇</color>十分契合。<color=#ffc766>穆罕穆德二世</color>可以提升队伍的伤害，同时为队伍提供减伤，弥补阵容缺少的生存能力。 | F40: TID_TEXT_LINEUP_GUIDE_CONTENT_38 | G40: 该阵容是以<color=#ffc766>连击</color>为核心的追击阵容体系。<color=#ffc766>贝利薇</color>每回合有概率进入连击状态，搭配追击技能有着极强的输出能力，是队伍的核心。<color=#ffc766>罗宾汉</color>可以基于连击状态，提供高额的输出增益，与<color=#ffc766>贝利薇</color>十分契合。<color=#ffc766>穆罕穆德二世</color>可以提升队伍的伤害，同时为队伍提供减伤，弥补阵容缺少的生存能力。 | H40: {=_xlfn.TEXTJOIN("|", TRUE, IF(([1]英雄详细配置!B:B=A40)*(ISNUMBER([1]英雄详细配置!C:C)*([1]英雄详细配置!C:C=1)+ISBLANK([1]英雄详细配置!C:C)), [1]英雄详细配置!A:A, ""))} -> 38069 | I40: {=_xlfn.TEXTJOIN("|", TRUE, IF(([1]英雄详细配置!B:B=A40)*(ISNUMBER([1]英雄详细配置!C:C)*([1]英雄详细配置!C:C=2)+ISBLANK([1]英雄详细配置!C:C)), [1]英雄详细配置!A:A, ""))} -> 38115|38009|38036 | J40: {=_xlfn.TEXTJOIN("|", TRUE, IF(([1]英雄详细配置!B:B=A40)*(ISNUMBER([1]英雄详细配置!C:C)*([1]英雄详细配置!C:C=3)+ISBLANK([1]英雄详细配置!C:C)), [1]英雄详细配置!A:A, ""))} -> 38123|38032|38076 | K40: 弓兵 | L40: 勇武 | M40: icon_packageitem | N40: 勇武 | O40: 20 | P40: 3
...

Sheet 英雄详细配置
A1: convert(ResHero.proto, table_HeroStrategyDetail, HeroStrategyDetail.pbin)
A2: id | B2: 所属阵容 | C2: 位置 | D2: 英雄名称 | E2: 英雄id | F2: 推荐技能id | G2: 玺戒id | H2: 玺戒名称（策划用 | I2: 玺戒技能（策划用 | J2: 英雄定位（策划用 | K2: 技能1 | L2: 技能2 | M2: 技能名1 | N2: 技能名2 | O2: 备注
A3: id | E3: heroId | F3: recommendId[|] | G3: equipId
A4: 1036 | B4: 1 | C4: 1 | D4: 约瑟芬 | E4: 36 | F4: =K4&"|"&L4 -> 200020|200072 | G4: 208 | H4: 怒狮之戒 | I4: 名门之后 | K4: 200020 | L4: 200072 | M4: 连击 | N4: 弱点进攻
A5: 1056 | B5: 1 | C5: 2 | D5: 哈拉尔 | E5: 56 | F5: =K5&"|"&L5 -> 200041|200015 | G5: 212 | H5: 夜狼之戒 | I5: 燃身战意 | K5: 200041 | L5: 200015 | M5: 饥渴之刃 | N5: 战争祝福
A6: 1211 | B6: 1 | D6: 高猛 | E6: 211 | F6: =K6&"|"&L6 -> 200043|200117 | G6: 212 | H6: 夜狼之戒 | I6: 燃身战意 | K6: 200043 | L6: 200117 | M6: 剑盾突击 | N6: 苦肉
A7: 1055 | B7: 1 | C7: 3 | D7: 大卫王 | E7: 55 | F7: =K7&"|"&L7 -> 200061|200009 | G7: 201 | H7: 暴熊之戒 | I7: 裸衣 | K7: 200061 | L7: 200009 | M7: 泰山压顶 | N7: 正义裁决
A8: 12111 | B8: 1 | D8: 高猛 | E8: 211 | F8: =K8&"|"&L8 -> 200043|200117 | G8: 201 | H8: 暴熊之戒 | I8: 裸衣 | K8: 200043 | L8: 200117 | M8: 剑盾突击 | N8: 苦肉
A9: 2009 | B9: 2 | C9: 1 | D9: 花木兰 | E9: 9 | F9: =K9&"|"&L9 -> 200072|200031 | G9: 201 | H9: 暴熊之戒 | I9: 裸衣 | K9: 200072 | L9: 200031 | M9: 弱点进攻 | N9: 慈悲终结
A10: 2036 | B10: 2 | C10: 2 | D10: 约瑟芬 | E10: 36 | F10: =K10&"|"&L10 -> 200020|200072 | G10: 210 | H10: 迅鹿之戒 | I10: 借势威吓 | K10: 200020 | L10: 200072 | M10: 连击 | N10: 弱点进攻
A11: 2055 | B11: 2 | D11: 大卫王 | E11: 55 | F11: =K11&"|"&L11 -> 200061|200009 | G11: 210 | H11: 迅鹿之戒 | I11: 借势威吓 | K11: 200061 | L11: 200009 | M11: 泰山压顶 | N11: 正义裁决
A12: 2208 | B12: 2 | D12: 崔如意 | E12: 208 | F12: =K12&"|"&L12 -> 200030|200032 | G12: 210 | H12: 迅鹿之戒 | I12: 借势威吓 | K12: 200030 | L12: 200032 | M12: 怒涛之击 | N12: 撕裂
A13: 2076 | B13: 2 | C13: 3 | D13: 杜加瓦蒂 | E13: 76 | F13: =K13&"|"&L13 -> 200125|200041 | G13: 212 | H13: 夜狼之戒 | I13: 燃身战意 | K13: 200125 | L13: 200041 | M13: 入阵曲 | N13: 饥渴之刃
A14: 20551 | B14: 2 | D14: 大卫王 | E14: 55 | F14: =K14&"|"&L14 -> 200061|200009 | G14: 212 | H14: 夜狼之戒 | I14: 燃身战意 | K14: 200061 | L14: 200009 | M14: 泰山压顶 | N14: 正义裁决
A15: 22081 | B15: 2 | D15: 崔如意 | E15: 208 | F15: =K15&"|"&L15 -> 200030|200032 | G15: 212 | H15: 夜狼之戒 | I15: 燃身战意 | K15: 200030 | L15: 200032 | M15: 怒涛之击 | N15: 撕裂
A16: 3013 | B16: 3 | C16: 1 | D16: 列奥尼达一世 | E16: 13 | F16: =K16&"|"&L16 -> 200100|200006 | G16: 213 | H16: 野猪之戒 | I16: 余烬之灼 | K16: 200100 | L16: 200006 | M16: 不屈反击 | N16: 风卷残云
A17: 3001 | B17: 3 | C17: 2 | D17: 贞德 | E17: 1 | F17: =K17&"|"&L17 -> 200068|200100 | G17: 211 | H17: 天鹰之戒 | I17: 绿洲之佑 | K17: 200068 | L17: 200100 | M17: 王者之剑 | N17: 不屈反击
A18: 3019 | B18: 3 | D18: 大流士一世 | E18: 19 | F18: =K18&"|"&L18 -> 200019|200072 | G18: 211 | H18: 天鹰之戒 | I18: 绿洲之佑 | K18: 200019 | L18: 200072 | M18: 冲锋的极意 | N18: 弱点进攻
A19: 3017 | B19: 3 | C19: 3 | D19: 巴巴罗萨 | E19: 17 | F19: =K19&"|"&L19 -> 200010|200042 | G19: 210 | H19: 迅鹿之戒 | I19: 借势威吓 | K19: 200010 | L19: 200042 | M19: 恩泽庇护 | N19: 百战之体
A20: 3207 | B20: 3 | D20: 武威 | E20: 207 | F20: =K20&"|"&L20 -> 200040|200120 | G20: 206 | H20: 灵獾之戒 | I20: 钢铁之躯 | K20: 200040 | L20: 200120 | M20: 反击 | N20: 阵鼓
A21: 4005 | B21: 4 | C21: 1 | D21: 关羽 | E21: 5 | F21: =K21&"|"&L21 -> 200027|200028 | G21: 208 | H21: 怒狮之戒 | I21: 名门之后 | K21: 200027 | L21: 200028 | M21: 战争狂热 | N21: 致命一击
A22: 4019 | B22: 4 | D22: 大流士一世 | E22: 19 | F22: =K22&"|"&L22 -> 200019|200072 | G22: 208 | H22: 怒狮之戒 | I22: 名门之后 | K22: 200019 | L22: 200072 | M22: 冲锋的极意 | N22: 弱点进攻
A23: 4202 | B23: 4 | D23: 纳尔西斯 | E23: 202 | F23: =K23&"|"&L23 -> 200026|200113 | G23: 203 | H23: 乌鸦之戒 | I23: 命运操弄 | J23: 武伤 | K23: 200026 | L23: 200113 | M23: 破怒斩 | N23: 激昂
A24: 4056 | B24: 4 | C24: 2 | D24: 哈拉尔 | E24: 56 | F24: =K24&"|"&L24 -> 200041|200015 | G24: 201 | H24: 暴熊之戒 | I24: 裸衣 | K24: 200041 | L24: 200015 | M24: 饥渴之刃 | N24: 战争祝福
A25: 40191 | B25: 4 | D25: 大流士一世 | E25: 19 | F25: =K25&"|"&L25 -> 200019|200072 | G25: 201 | H25: 暴熊之戒 | I25: 裸衣 | K25: 200019 | L25: 200072 | M25: 冲锋的极意 | N25: 弱点进攻
A26: 4215 | B26: 4 | D26: 凯索 | E26: 215 | F26: =K26&"|"&L26 -> 200030|200032 | G26: 201 | H26: 暴熊之戒 | I26: 裸衣 | J26: 增伤 | K26: 200030 | L26: 200032 | M26: 怒涛之击 | N26: 撕裂
A27: 4076 | B27: 4 | C27: 3 | D27: 杜加瓦蒂 | E27: 76 | F27: =K27&"|"&L27 -> 200125|200041 | G27: 212 | H27: 夜狼之戒 | I27: 燃身战意 | K27: 200125 | L27: 200041 | M27: 入阵曲 | N27: 饥渴之刃
A28: 42151 | B28: 4 | D28: 凯索 | E28: 215 | F28: =K28&"|"&L28 -> 200030|200032 | G28: 212 | H28: 夜狼之戒 | I28: 燃身战意 | J28: 增伤 | K28: 200030 | L28: 200032 | M28: 怒涛之击 | N28: 撕裂
A29: 5014 | B29: 5 | C29: 1 | D29: 孙武 | E29: 14 | F29: =K29&"|"&L29 -> 200063|200016 | G29: 109 | H29: 苍蓝之月 | I29: 毁灭的预示 | K29: 200063 | L29: 200016 | M29: 灵光乍现 | N29: 军神赠礼
A30: 5004 | B30: 5 | D30: 克里奥帕特拉 | E30: 4 | F30: =K30&"|"&L30 -> 200020|200074 | G30: 109 | H30: 苍蓝之月 | I30: 毁灭的预示 | K30: 200020 | L30: 200074 | M30: 连击 | N30: 压迫之袭
A31: 5016 | B31: 5 | C31: 2 | D31: 腓力四世 | E31: 16 | F31: =K31&"|"&L31 -> 200047|200016 | G31: 106 | H31: 天行骑士 | I31: 胜利的代价 | K31: 200047 | L31: 200016 | M31: 以战养战 | N31: 军神赠礼
A32: 50041 | B32: 5 | D32: 克里奥帕特拉 | E32: 4 | F32: =K32&"|"&L32 -> 200020|200074 | G32: 113 | H32: 静谧之水 | I32: 光明护佑 | K32: 200020 | L32: 200074 | M32: 连击 | N32: 压迫之袭
A33: 5205 | B33: 5 | D33: 巴尔达斯 | E33: 205 | F33: =K33&"|"&L33 -> 200124|200116 | G33: 210 | H33: 迅鹿之戒 | I33: 借势威吓 | J33: 谋伤，主将增伤 | K33: 200124 | L33: 200116 | M33: 伏击 | N33: 机变
A34: 5062 | B34: 5 | C34: 3 | D34: 狄奥多拉 | E34: 62 | F34: =K34&"|"&L34 -> 200047|200098 | G34: 111 | H34: 不动之山 | I34: 避芒击惰 | K34: 200047 | L34: 200098 | M34: 以战养战 | N34: 长生军团
A35: 50161 | B35: 5 | D35: 腓力四世 | E35: 16 | F35: =K35&"|"&L35 -> 200047|200016 | G35: 106 | H35: 天行骑士 | I35: 胜利的代价 | K35: 200047 | L35: 200016 | M35: 以战养战 | N35: 军神赠礼
A36: 5209 | B36: 5 | D36: 尼诺 | E36: 209 | F36: =K36&"|"&L36 -> 200114|200116 | G36: 206 | H36: 灵獾之戒 | I36: 钢铁之躯 | J36: 谋伤 | K36: 200114 | L36: 200116 | M36: 阳谋 | N36: 机变
A37: 6003 | B37: 6 | C37: 1 | D37: 凯撒 | E37: 3 | F37: =K37&"|"&L37 -> 200080|200068 | H37: #N/A | I37: #N/A | K37: 200080 | L37: 200068 | M37: 蛮勇侵袭 | N37: 王者之剑 | O37: 暂时没上
A38: 6002 | B38: 6 | C38: 2 | D38: 织田信长 | E38: 2 | F38: =K38&"|"&L38 -> 200080|200068 | H38: #N/A | I38: #N/A | K38: 200080 | L38: 200068 | M38: 蛮勇侵袭 | N38: 王者之剑
A39: 6036 | B39: 6 | D39: 约瑟芬 | E39: 36 | F39: =K39&"|"&L39 -> 200020|200072 | H39: #N/A | I39: #N/A | K39: 200020 | L39: 200072 | M39: 连击 | N39: 弱点进攻
A40: 6201 | B40: 6 | C40: 3 | D40: 李道玄 | E40: 201 | F40: =K40&"|"&L40 -> 200069|200122 | H40: #N/A | I40: #N/A | J40: 指挥武伤 | K40: 200069 | L40: 200122 | M40: 列阵御敌 | N40: 变阵
...

Sheet #阵容详细配置表(留档)
A1: convert(ResHero.proto, table_HeroTeamStrategyDetail, HeroTeamStrategyDetail.pbin)
A2: id | B2: 阵容名称（文本） | C2: 阵容名称 | D2: 阵容介绍 | E2: 阵容介绍（文本） | F2: 玺戒解锁后的阵容介绍 | G2: 玺戒解锁后的阵容介绍（文本） | H2: 槽位1英雄id | I2: 槽位2英雄id | J2: 槽位3英雄id | K2: 阵容兵种 | L2: 阵容风格 | M2: 显示icon图集 | N2: 标签文本
A3: id | C3: name | D3: desc | F3: unlockDesc | H3: pos1[|] | I3: pos2[|] | J3: pos3[|] | K3: soldierType | L3: battleStyle | M3: iconAtlas | N3: tagTxt
A4: 1 | B4: 开荒公主剑 | C4: TID_TEXT_LINEUP_GUIDE_TITLE_1 | D4: TID_TEXT_LINEUP_GUIDE_CONTENT_1 | E4: <color=#ffc766>哈拉尔</color>可提升我军主将<color=#ffc766>主动</color>和<color=#ffc766>追击</color>装配技能的伤害，<color=#ffc766>约瑟芬</color>装备<color=#ffc766>追击</color>技能可享受<color=#ffc766>哈拉尔</color>的增伤效果，同时<color=#ffc766>连击</color>技能可进一步提升约瑟芬固有和装配追击技能的输出效率。该队伍的英雄均容易获取，适合新手使用。 | F4: TID_TEXT_LINEUP_GUIDE_CONTENT_1 | G4: <color=#ffc766>哈拉尔</color>可提升我军主将<color=#ffc766>主动</color>和<color=#ffc766>追击</color>装配技能的伤害，<color=#ffc766>约瑟芬</color>装备<color=#ffc766>追击</color>技能可享受<color=#ffc766>哈拉尔</color>的增伤效果，同时<color=#ffc766>连击</color>技能可进一步提升约瑟芬固有和装配追击技能的输出效率。该队伍的英雄均容易获取，适合新手使用。 | H4: 1036 | I4: 1056|1211 | J4: 1055|1211 | K4: 剑士 | L4: 勇武 | M4: icon_packageitem | N4: 新手
A5: 2 | B5: 新手红颜弓 | C5: TID_TEXT_LINEUP_GUIDE_TITLE_2 | D5: TID_TEXT_LINEUP_GUIDE_CONTENT_2 | E5: <color=#ffc766>杜加瓦蒂</color>固有技能提供的<color=#ffc766>连击</color>效果，能极大的提升花木兰的输出效率。注意装配技能多选择追击技能，力争输出最大化。队伍的第三名英雄可选择<color=#ffc766>大卫王</color>，进一步提升<color=#ffc766>花木兰</color>的输出能力；也可选择<color=#ffc766>约瑟芬</color>，提升队伍的综合能力。 | F5: TID_TEXT_LINEUP_GUIDE_CONTENT_2 | G5: <color=#ffc766>杜加瓦蒂</color>固有技能提供的<color=#ffc766>连击</color>效果，能极大的提升花木兰的输出效率。注意装配技能多选择追击技能，力争输出最大化。队伍的第三名英雄可选择<color=#ffc766>大卫王</color>，进一步提升<color=#ffc766>花木兰</color>的输出能力；也可选择<color=#ffc766>约瑟芬</color>，提升队伍的综合能力。 | H5: 2009|2036 | I5: 2036|2055|2208 | J5: 2076|2055|2208 | K5: 弓兵 | L5: 勇武 | M5: icon_packageitem | N5: 新手
A6: 3 | B6: 群战反击枪 | C6: TID_TEXT_LINEUP_GUIDE_TITLE_3 | D6: TID_TEXT_LINEUP_GUIDE_CONTENT_3 | E6: 反击技能在<color=#ffc766>面对大量敌人同时进攻时</color>，触发频率将提高，配合<color=#ffc766>巴巴罗萨</color>出色的减伤能力，很适合在战斗中用来承受伤害，并通过反击技能进行输出。该队伍中<color=#ffc766>列奥尼达一世</color>和<color=#ffc766>贞德</color>的固有技能均为反击技能，且较容易获取，适合新手适用。 | F6: TID_TEXT_LINEUP_GUIDE_CONTENT_3 | G6: 反击技能在<color=#ffc766>面对大量敌人同时进攻时</color>，触发频率将提高，配合<color=#ffc766>巴巴罗萨</color>出色的减伤能力，很适合在战斗中用来承受伤害，并通过反击技能进行输出。该队伍中<color=#ffc766>列奥尼达一世</color>和<color=#ffc766>贞德</color>的固有技能均为反击技能，且较容易获取，适合新手适用。 | H6: 3013|3001|3019 | I6: 3001|3019|3207 | J6: 3017|3207 | K6: 枪兵 | L6: 勇武 | M6: icon_packageitem | N6: 勇武
A7: 4 | B7: 新手暴击骑 | C7: TID_TEXT_LINEUP_GUIDE_TITLE_4 | D7: TID_TEXT_LINEUP_GUIDE_CONTENT_4 | E7: <color=#ffc766>关羽</color>的固有技能具备稀有的<color=#ffc766>暴击率</color>提升效果。触发暴击时，普通攻击和可暴击技能能够造成<color=#ffc766>双倍伤害</color>，因此，<color=#ffc766>致命一击</color>成为了他最为关键的装配技能。<color=#ffc766>杜加瓦蒂</color>提供的<color=#ffc766>连击状态</color>可以大幅提升普攻和技能的触发频率，是队伍中不可或缺的辅助英雄。 | F7: TID_TEXT_LINEUP_GUIDE_CONTENT_4 | G7: <color=#ffc766>关羽</color>的固有技能具备稀有的<color=#ffc766>暴击率</color>提升效果。触发暴击时，普通攻击和可暴击技能能够造成<color=#ffc766>双倍伤害</color>，因此，<color=#ffc766>致命一击</color>成为了他最为关键的装配技能。<color=#ffc766>杜加瓦蒂</color>提供的<color=#ffc766>连击状态</color>可以大幅提升普攻和技能的触发频率，是队伍中不可或缺的辅助英雄。 | H7: 4005|4019|4202 | I7: 4056|4019|4215 | J7: 4076|4202|4215 | K7: 骑兵 | L7: 勇武 | M7: icon_packageitem | N7: 新手
A8: 5 | B8: 暴力输出谋伤剑 | C8: TID_TEXT_LINEUP_GUIDE_TITLE_5 | D8: TID_TEXT_LINEUP_GUIDE_CONTENT_5_1 | E8: 在<color=#ffc766>兵圣状态</color>中，<color=#ffc766>孙武</color>能够额外造成一次高额伤害。频繁触发固有技能并保持兵圣状态是这个阵容的核心策略。<color=#ffc766>腓力四世</color>可强化队伍的输出能力，<color=#ffc766>狄奥多拉</color>则兼具续航和增伤，队伍的第三人可根据英雄拥有情况灵活选择。 | F8: TID_TEXT_LINEUP_GUIDE_CONTENT_5_1 | G8: 在<color=#ffc766>兵圣状态</color>中，<color=#ffc766>孙武</color>能够额外造成一次高额伤害。频繁触发固有技能并保持兵圣状态是这个阵容的核心策略。<color=#ffc766>腓力四世</color>可强化队伍的输出能力，<color=#ffc766>狄奥多拉</color>则兼具续航和增伤，队伍的第三人可根据英雄拥有情况灵活选择。 | H8: 5014|5004 | I8: 5016|5004|5205 | J8: 5062|5016|5209 | K8: 剑士 | L8: 智谋 | M8: icon_packageitem | N8: 智谋
A9: 6 | B9: 新手统率剑 | C9: TID_TEXT_LINEUP_GUIDE_TITLE_6 | D9: TID_TEXT_LINEUP_GUIDE_CONTENT_6_1 | E9: <color=#ffc766>凯撒</color>和<color=#ffc766>织田信长</color>的固有技均为指挥技能，具有稳定的输出能力，适合新手前期使用。另一名副将可选择<color=#ffc766>李道玄</color>，组成完整的统率剑队伍。由于前期风格加成还未解锁，也可选择<color=#ffc766>约瑟芬</color>、<color=#ffc766>克里奥帕特拉</color>、<color=#ffc766>哈拉尔</color>等其他风格中个体能力更强的剑士英雄。 | F9: TID_TEXT_LINEUP_GUIDE_CONTENT_6_1 | G9: <color=#ffc766>凯撒</color>和<color=#ffc766>织田信长</color>的固有技均为指挥技能，具有稳定的输出能力，适合新手前期使用。另一名副将可选择<color=#ffc766>李道玄</color>，组成完整的统率剑队伍。由于前期风格加成还未解锁，也可选择<color=#ffc766>约瑟芬</color>、<color=#ffc766>克里奥帕特拉</color>、<color=#ffc766>哈拉尔</color>等其他风格中个体能力更强的剑士英雄。 | H9: 6003 | I9: 6002|2036 | J9: 6201|5004|1056 | K9: 剑士 | L9: 统率 | M9: icon_packageitem | N9: 新手
A10: 7 | B10: 传奇皇者真伤剑 | C10: TID_TEXT_LINEUP_GUIDE_TITLE_7 | D10: TID_TEXT_LINEUP_GUIDE_CONTENT_7_1 | E10: <color=#ffc766>亚瑟王</color>每两次触发固有技能后能进入<color=#ffc766>祝福状态</color>，此时攻击能<color=#ffc766>忽略敌军防御</color>，造成惊人伤害。<color=#ffc766>宫本武藏</color>自身输出能力很强，还能帮助亚瑟王更多地发动固有技能（需亚瑟王武力最高），是亚瑟王的最佳搭配之一。最后一名副将选择<color=#ffc766>君士坦丁大帝</color>，为队伍提供强大的续航辅助。该队伍输出和续航兼顾，具有非常强大的作战能力。 | F10: TID_TEXT_LINEUP_GUIDE_CONTENT_7_1 | G10: <color=#ffc766>亚瑟王</color>每两次触发固有技能后能进入<color=#ffc766>祝福状态</color>，此时攻击能<color=#ffc766>忽略敌军防御</color>，造成惊人伤害。<color=#ffc766>崔布瓦娜</color>能大大提升亚瑟王的固有主动技能发动频率，是其最佳的输出辅助副将。最后一名副将选择<color=#ffc766>君士坦丁大帝</color>，为队伍提供强大的续航辅助。该队伍输出和续航兼顾，具有非常强大的作战能力。 | H10: 7021 | I10: 7077|7091|7061 | J10: 7008|7055|7056 | K10: 剑士 | L10: 勇武 | M10: icon_packageitem | N10: 混合
A11: 8 | B11: 攻城中坚勇武剑 | C11: TID_TEXT_LINEUP_GUIDE_TITLE_8 | D11: TID_TEXT_LINEUP_GUIDE_CONTENT_8 | E11: 本队最大特点是全体英雄都很容易获取，但却能有不俗的作战能力。<color=#ffc766>汉谟拉比和大卫王围绕溃散状态进行联动</color>，提升队伍的输出能力。在装配技能的选择上，可以考虑添加更多<color=#ffc766>施加溃散状态</color>的技能，以保持以上效果的稳定触发。注意该队三名英雄均具有很高的<color=#ffc766>摧城属性</color>，装配技能可替换成摧城技能作为攻城部队使用。 | F11: TID_TEXT_LINEUP_GUIDE_CONTENT_8 | G11: 本队最大特点是全体英雄都很容易获取，但却能有不俗的作战能力。<color=#ffc766>汉谟拉比和大卫王围绕溃散状态进行联动</color>，提升队伍的输出能力。在装配技能的选择上，可以考虑添加更多<color=#ffc766>施加溃散状态</color>的技能，以保持以上效果的稳定触发。注意该队三名英雄均具有很高的<color=#ffc766>摧城属性</color>，装配技能可替换成摧城技能作为攻城部队使用。 | H11: 8036 | I11: 8061 | J11: 8055 | K11: 剑士 | L11: 勇武 | M11: icon_packageitem | N11: 勇武
A12: 9 | B12: 稳定生存统率枪 | C12: TID_TEXT_LINEUP_GUIDE_TITLE_9_1 | D12: TID_TEXT_LINEUP_GUIDE_CONTENT_9_1 | E12: 统率枪阵容以<color=#ffc766>指挥技能</color>为主要的输出和治疗手段，<color=#ffc766>稳定性</color>是其最大特点。<color=#ffc766>屋大维</color>在每次我军触发一定次数固有指挥技能后，能提供额外的增伤效果，是该队伍的核心英雄。<color=#ffc766>凯撒</color>和<color=#ffc766>示巴女王</color>每隔9秒可各造成一次伤害和回复效果，具有稳定的作战能力。 | F12: TID_TEXT_LINEUP_GUIDE_CONTENT_9_1 | G12: 统率枪阵容以<color=#ffc766>指挥技能</color>为主要的输出和治疗手段，<color=#ffc766>稳定性</color>是其最大特点。<color=#ffc766>屋大维</color>在每次我军触发一定次数固有指挥技能后，能提供额外的增伤效果，是该队伍的核心英雄。<color=#ffc766>凯撒</color>和<color=#ffc766>示巴女王</color>每隔9秒可各造成一次伤害和回复效果，具有稳定的作战能力。 | H12: 9003 | I12: 9034|9213 | J12: 9064|9203 | K12: 枪兵 | L12: 统率 | M12: icon_packageitem | N12: 统率
A13: 10 | B13: 群战之王反击枪 | C13: TID_TEXT_LINEUP_GUIDE_TITLE_10 | D13: TID_TEXT_LINEUP_GUIDE_CONTENT_10_1 | E13: <color=#ffc766>理查一世</color>具有极高的武力属性，以及强大的反击能力，并且主将技能附加减速效果，能黏住敌人持续输出。<color=#ffc766>列奥尼达一世</color>获取难度不高，但输出能力不俗。<color=#ffc766>巴巴罗萨</color>是队伍持续输出的续航支柱，当血量降低时，续航能力逐渐变强！此外，获取难度更低的<color=#ffc766>贞德</color>和<color=#ffc766>大流士一世</color>也可作为副将备选，进一步提升队伍输出效率。 | F13: TID_TEXT_LINEUP_GUIDE_CONTENT_10_1 | G13: <color=#ffc766>理查一世</color>具有极高的武力属性，以及强大的反击能力，并且主将技能附加减速效果，能黏住敌人持续输出。<color=#ffc766>列奥尼达一世</color>获取难度不高，但输出能力不俗。<color=#ffc766>巴巴罗萨</color>是队伍持续输出的续航支柱，当血量降低时，续航能力逐渐变强！此外，获取难度更低的<color=#ffc766>贞德</color>和<color=#ffc766>大流士一世</color>也可作为副将备选，进一步提升队伍输出效率。 | H13: 3042|3013|3001 | I13: 3013|3001|3019 | J13: 3017|3019|3207 | K13: 枪兵 | L13: 勇武 | M13: icon_packageitem | N13: 勇武
A14: 11 | B14: 智勇双全智谋骑 | C14: TID_TEXT_LINEUP_GUIDE_TITLE_11 | D14: TID_TEXT_LINEUP_GUIDE_CONTENT_11_1 | E14: <color=#ffc766>汉尼拔</color>的固有技能能够<color=#ffc766>削弱敌军主将</color>的谋略和防御属性，搭配<color=#ffc766>压迫之袭</color>可实现全属性削弱。当<color=#ffc766>主将技能</color>触发时，汉尼拔能够获得敌军主将被削弱的部分属性，从而在一段时间内产生爆发伤害。<color=#ffc766>查士丁尼一世</color>能在我军英雄触发追击技能时提供回复和减伤效果，与汉尼拔形成很好的联动。<color=#ffc766>阿提拉</color>提供的全体英雄连击效果非常适配该套体系，虽然风格不符，但仍是该队伍最好的辅助选择。注意选择阿提拉后，汉尼拔的<color=#ffc766>连击</color>技能可换为<color=#ffc766>战术冲锋</color>。 | F14: TID_TEXT_LINEUP_GUIDE_CONTENT_11_1 | G14: <color=#ffc766>汉尼拔</color>的固有技能能够<color=#ffc766>削弱敌军主将</color>的谋略和防御属性，搭配<color=#ffc766>压迫之袭</color>可实现全属性削弱。当<color=#ffc766>主将技能</color>触发时，汉尼拔能够获得敌军主将被削弱的部分属性，从而在一段时间内产生爆发伤害。<color=#ffc766>查士丁尼一世</color>能在我军英雄触发追击技能时提供回复和减伤效果，与汉尼拔形成很好的联动。<color=#ffc766>阿提拉</color>提供的全体英雄连击效果非常适配该套体系，虽然风格不符，但仍是该队伍最好的辅助选择。注意选择阿提拉后，汉尼拔的<color=#ffc766>连击</color>技能可换为<color=#ffc766>战术冲锋</color>。 | H14: 10023|10004 | I14: 10010|10004|10210 | J14: 40321|10004|10210 | K14: 骑兵 | L14: 智谋 | M14: icon_packageitem | N14: 智谋
A15: 12 | B15: 兵扫六合决斗骑 | C15: TID_TEXT_LINEUP_GUIDE_TITLE_12 | D15: TID_TEXT_LINEUP_GUIDE_CONTENT_12_1 | E15: <color=#ffc766>熙德</color>能对处于<color=#ffc766>减速状态</color>的敌人造成额外伤害，因此野战是该阵容的强项。熙德的主将技会对攻击目标附加减速状态，因此装配技能需要选择<color=#ffc766>胜利怒吼</color>以提升队伍的怒气回复速率。副将<color=#ffc766>哈立德</color>能提升队伍的输出能力，而<color=#ffc766>示巴女王</color>则能为队伍带来更强的续航能力。也可选择<color=#ffc766>阿提拉</color>替换示巴女王，损失风格加成，换来全队连击效果，追求更极致的输出能力（注意此时熙德的<color=#ffc766>连击</color>技能可换为<color=#ffc766>弱点进攻</color>）。 | F15: TID_TEXT_LINEUP_GUIDE_CONTENT_12_1 | G15: <color=#ffc766>熙德</color>能对处于<color=#ffc766>减速状态</color>的敌人造成额外伤害，因此野战是该阵容的强项。熙德的主将技会对攻击目标附加减速状态，因此装配技能需要选择<color=#ffc766>胜利怒吼</color>以提升队伍的怒气回复速率。副将<color=#ffc766>哈立德</color>能提升队伍的输出能力，而<color=#ffc766>示巴女王</color>则能为队伍带来更强的续航能力。也可选择<color=#ffc766>阿提拉</color>替换示巴女王，损失风格加成，换来全队连击效果，追求更极致的输出能力（注意此时熙德的<color=#ffc766>连击</color>技能可换为<color=#ffc766>弱点进攻</color>）。 | H15: 11047 | I15: 11063|9064|11206 | J15: 9064|40321|11206 | K15: 骑兵 | L15: 统率 | M15: icon_packageitem | N15: 统率
A16: 13 | B16: 暴击致胜连击骑 | C16: TID_TEXT_LINEUP_GUIDE_TITLE_13 | D16: TID_TEXT_LINEUP_GUIDE_CONTENT_13 | E16: 相比<color=#ffc766>杜加瓦蒂</color>，<color=#ffc766>阿提拉</color>能为<color=#ffc766>全队</color>附加连击效果，配合提升暴击率的技能，能使整个队伍具有更强的爆发输出能力。<color=#ffc766>关羽</color>仍是队伍的核心输出英雄，另一名英雄选择<color=#ffc766>哈拉尔</color>，能进一步提升关羽的输出能力。也可选择<color=#ffc766>大流士一世</color>，装配技能选择追击技能，配合其固有技能带来的<color=#ffc766>忽视防御</color>效果，以及阿提拉附加的连击效果，组成双核输出队伍。该队是讲究极致输出，但防御能力稍弱的队伍。 | F16: TID_TEXT_LINEUP_GUIDE_CONTENT_13 | G16: 相比<color=#ffc766>杜加瓦蒂</color>，<color=#ffc766>阿提拉</color>能为<color=#ffc766>全队</color>附加连击效果，配合提升暴击率的技能，能使整个队伍具有更强的爆发输出能力。<color=#ffc766>关羽</color>仍是队伍的核心输出英雄，另一名英雄选择<color=#ffc766>哈拉尔</color>，能进一步提升关羽的输出能力。也可选择<color=#ffc766>大流士一世</color>，装配技能选择追击技能，配合其固有技能带来的<color=#ffc766>忽视防御</color>效果，以及阿提拉附加的连击效果，组成双核输出队伍。该队是讲究极致输出，但防御能力稍弱的队伍。 | H16: 4005|4019 | I16: 4056|4019 | J16: 4032|4076 | K16: 骑兵 | L16: 勇武 | M16: icon_packageitem | N16: 勇武
A17: 15 | B17: 状态控制智谋弓 | C17: TID_TEXT_LINEUP_GUIDE_TITLE_15 | D17: TID_TEXT_LINEUP_GUIDE_CONTENT_15 | E17: <color=#ffc766>苏莱曼一世</color>攻击处于<color=#ffc766>异常状态</color>中的敌人时，能产生额外效果，如攻击<color=#ffc766>燃烧状态</color>的敌人，能额外造成一次高额伤害。善德女王能为敌军施加<color=#ffc766>沉默状态</color>，与苏莱曼一世形成联动的同时，还能有效遏制以主动技能为主要输出手段的敌人。该队的装配技能尽量选择能附加燃烧状态的技能，以最大化苏莱曼一世的输出能力。需要注意的是，因为集结战斗中部队会不断切换目标，无法稳定的攻击燃烧状态中的敌军，会导致固有技能的输出效果降低。 | F17: TID_TEXT_LINEUP_GUIDE_CONTENT_15 | G17: <color=#ffc766>苏莱曼一世</color>攻击处于<color=#ffc766>异常状态</color>中的敌人时，能产生额外效果，如攻击<color=#ffc766>燃烧状态</color>的敌人，能额外造成一次高额伤害。善德女王能为敌军施加<color=#ffc766>沉默状态</color>，与苏莱曼一世形成联动的同时，还能有效遏制以主动技能为主要输出手段的敌人。该队的装配技能尽量选择能附加燃烧状态的技能，以最大化苏莱曼一世的输出能力。需要注意的是，因为集结战斗中部队会不断切换目标，无法稳定的攻击燃烧状态中的敌军，会导致固有技能的输出效果降低。 | H17: 13093|13020 | I17: 13092|13020 | J17: 13062|13092|13212 | K17: 弓兵 | L17: 智谋 | M17: icon_packageitem | N17: 智谋
A18: 16 | B18: 亚瑟王勇武骑 | C18: TID_TEXT_LINEUP_GUIDE_TITLE_16 | D18: TID_TEXT_LINEUP_GUIDE_CONTENT_16 | E18: 以<color=#ffc766>亚瑟王</color>为输出核心的骑兵队伍。亚瑟王在<color=#ffc766>祝福状态</color>下能无视敌方防御，伤害极高，装备追击技能时能与<color=#ffc766>阿提拉</color>固有技能提供的<color=#ffc766>连击效果</color>形成联动，使输出效率最大化。副将选择<color=#ffc766>哈拉尔</color>能更好地辅助亚瑟王进行输出，而选择<color=#ffc766>大流士一世</color>则能带来更强的输出能力。 | F18: TID_TEXT_LINEUP_GUIDE_CONTENT_16 | G18: 以<color=#ffc766>亚瑟王</color>为输出核心的骑兵队伍。亚瑟王在<color=#ffc766>祝福状态</color>下能无视敌方防御，伤害极高，装备追击技能时能与<color=#ffc766>阿提拉</color>固有技能提供的<color=#ffc766>连击效果</color>形成联动，使输出效率最大化。副将选择<color=#ffc766>哈拉尔</color>能更好地辅助亚瑟王进行输出，而选择<color=#ffc766>大流士一世</color>则能带来更强的输出能力。 | H18: 14021 | I18: 14056|14019 | J18: 14032|14076 | K18: 骑兵 | L18: 勇武 | M18: icon_packageitem | N18: 勇武
A19: 17 | B19: 剑豪勇武剑 | C19: TID_TEXT_LINEUP_GUIDE_TITLE_17 | D19: TID_TEXT_LINEUP_GUIDE_CONTENT_17 | E19: <color=#ffc766>宫本武藏</color>自身具有较高的伤害，还能帮助队伍中武力最高的一名其他英雄额外发动固有主动技能，是主动体系队伍的强力主将。<color=#ffc766>君士坦丁大帝</color>能提供极强的续航能力，与宫本武藏形成良好的配合。另一名副将选择<color=#ffc766>汉谟拉比</color>进一步强化宫本武藏的输出能力。由于君士坦丁大帝的获取难度较高，也可选择<color=#ffc766>大卫王</color>，与汉谟拉比基于<color=#ffc766>溃散</color>状态形成联动，提供极强的团队输出强化能力。 | F19: TID_TEXT_LINEUP_GUIDE_CONTENT_17 | G19: <color=#ffc766>宫本武藏</color>自身具有较高的伤害，还能帮助队伍中武力最高的一名其他英雄额外发动固有主动技能，是主动体系队伍的强力主将。<color=#ffc766>君士坦丁大帝</color>能提供极强的续航能力，与宫本武藏形成良好的配合。另一名副将选择<color=#ffc766>崔布瓦娜</color>能大大提高宫本武藏固有主动技能的发动频率，提升伤害效率。由于君士坦丁大帝的获取难度较高，也可选择<color=#ffc766>汉谟拉比</color>作为替换英雄。 | H19: 70911|1036 | I19: 7077|7061|7056 | J19: 7008|7055|7056 | K19: 剑士 | L19: 勇武 | M19: icon_packageitem | N19: 勇武
A20: 18 | B20: 木兰连击弓 | C20: TID_TEXT_LINEUP_GUIDE_TITLE_18 | D20: TID_TEXT_LINEUP_GUIDE_CONTENT_18 | E20: 该队的核心是<color=#ffc766>阿提拉</color>，其为我军全体英雄附加的<color=#ffc766>连击</color>效果，能极大地提升<color=#ffc766>花木兰</color>和<color=#ffc766>约瑟芬</color>的输出能力！注意此时英雄的装配技能要尽量选择追击技能。副将位置也可用<color=#ffc766>大卫王</color>替换<color=#ffc766>约瑟芬</color>，大卫王虽然不是追击体系，但能强化花木兰的输出效果，形成以主将为核心输出的队伍构筑。 | F20: TID_TEXT_LINEUP_GUIDE_CONTENT_18 | G20: 该队的核心是<color=#ffc766>阿提拉</color>，其为我军全体英雄附加的<color=#ffc766>连击</color>效果，能极大地提升<color=#ffc766>花木兰</color>和<color=#ffc766>约瑟芬</color>的输出能力！注意此时英雄的装配技能要尽量选择追击技能。副将位置也可用<color=#ffc766>大卫王</color>替换<color=#ffc766>约瑟芬</color>，大卫王虽然不是追击体系，但能强化花木兰的输出效果，形成以主将为核心输出的队伍构筑。 | H20: 2009|20361 | I20: 20361|2055 | J20: 2032|2076 | K20: 弓兵 | L20: 勇武 | M20: icon_packageitem | N20: 勇武

Sheet #英雄详细配置（留档）
A1: convert(ResHero.proto, table_HeroStrategyDetail, HeroStrategyDetail.pbin)
A2: id | B2: 所属阵容 | C2: 英雄名称 | D2: 英雄id | E2: 推荐技能id | F2: 玺戒id | G2: 玺戒名称（策划用 | H2: 玺戒技能（策划用 | I2: 英雄定位（策划用 | J2: 技能1 | K2: 技能2 | L2: 技能名1 | M2: 技能名2 | N2: 备注
A3: id | D3: heroId | E3: recommendId[|] | F3: equipId
A4: 1036 | B4: 1 | C4: 约瑟芬 | D4: 36 | E4: =J4&"|"&K4 -> 200020|200072 | F4: 302 | G4: =INDEX('#玺戒参考'!$A:$E,MATCH(F4,'#玺戒参考'!$A:$A,0),2) -> 雏菊之戒 | H4: =INDEX('#玺戒参考'!$A:$E,MATCH(F4,'#玺戒参考'!$A:$A,0),5) -> 二连斩 | J4: =INDEX('#技能参考'!$A:$A,MATCH(L4,'#技能参考'!$B:$B,0),1) -> 200020 | K4: =INDEX('#技能参考'!$A:$A,MATCH(M4,'#技能参考'!$B:$B,0),1) -> 200072 | L4: 连击 | M4: 弱点进攻
A5: 1055 | B5: 1 | C5: 大卫王 | D5: 55 | E5: =J5&"|"&K5 -> 200061|200009 | F5: 201 | G5: =INDEX('#玺戒参考'!$A:$E,MATCH(F5,'#玺戒参考'!$A:$A,0),2) -> 暴熊之戒 | H5: =INDEX('#玺戒参考'!$A:$E,MATCH(F5,'#玺戒参考'!$A:$A,0),5) -> 裸衣 | J5: =INDEX('#技能参考'!$A:$A,MATCH(L5,'#技能参考'!$B:$B,0),1) -> 200061 | K5: =INDEX('#技能参考'!$A:$A,MATCH(M5,'#技能参考'!$B:$B,0),1) -> 200009 | L5: 泰山压顶 | M5: 正义裁决
A6: 1056 | B6: 1 | C6: 哈拉尔 | D6: 56 | E6: =J6&"|"&K6 -> 200041|200015 | F6: 212 | G6: =INDEX('#玺戒参考'!$A:$E,MATCH(F6,'#玺戒参考'!$A:$A,0),2) -> 夜狼之戒 | H6: =INDEX('#玺戒参考'!$A:$E,MATCH(F6,'#玺戒参考'!$A:$A,0),5) -> 燃身战意 | J6: =INDEX('#技能参考'!$A:$A,MATCH(L6,'#技能参考'!$B:$B,0),1) -> 200041 | K6: =INDEX('#技能参考'!$A:$A,MATCH(M6,'#技能参考'!$B:$B,0),1) -> 200015 | L6: 饥渴之刃 | M6: 战争祝福
A7: 1211 | B7: 1 | C7: 高猛 | D7: 211 | E7: =J7&"|"&K7 -> 200043|200117 | F7: 212 | G7: =INDEX('#玺戒参考'!$A:$E,MATCH(F7,'#玺戒参考'!$A:$A,0),2) -> 夜狼之戒 | H7: =INDEX('#玺戒参考'!$A:$E,MATCH(F7,'#玺戒参考'!$A:$A,0),5) -> 燃身战意 | J7: =INDEX('#技能参考'!$A:$A,MATCH(L7,'#技能参考'!$B:$B,0),1) -> 200043 | K7: =INDEX('#技能参考'!$A:$A,MATCH(M7,'#技能参考'!$B:$B,0),1) -> 200117 | L7: 剑盾突击 | M7: 苦肉
A8: 2009 | B8: 2 | C8: 花木兰 | D8: 9 | E8: =J8&"|"&K8 -> 200072|200031 | F8: 302 | G8: =INDEX('#玺戒参考'!$A:$E,MATCH(F8,'#玺戒参考'!$A:$A,0),2) -> 雏菊之戒 | H8: =INDEX('#玺戒参考'!$A:$E,MATCH(F8,'#玺戒参考'!$A:$A,0),5) -> 二连斩 | J8: =INDEX('#技能参考'!$A:$A,MATCH(L8,'#技能参考'!$B:$B,0),1) -> 200072 | K8: =INDEX('#技能参考'!$A:$A,MATCH(M8,'#技能参考'!$B:$B,0),1) -> 200031 | L8: 弱点进攻 | M8: 慈悲终结
A9: 2032 | B9: 2 | C9: 阿提拉 | D9: 32 | E9: =J9&"|"&K9 -> 200072|200031 | F9: 212 | G9: =INDEX('#玺戒参考'!$A:$E,MATCH(F9,'#玺戒参考'!$A:$A,0),2) -> 夜狼之戒 | H9: =INDEX('#玺戒参考'!$A:$E,MATCH(F9,'#玺戒参考'!$A:$A,0),5) -> 燃身战意 | J9: =INDEX('#技能参考'!$A:$A,MATCH(L9,'#技能参考'!$B:$B,0),1) -> 200072 | K9: =INDEX('#技能参考'!$A:$A,MATCH(M9,'#技能参考'!$B:$B,0),1) -> 200031 | L9: 弱点进攻 | M9: 慈悲终结
A10: 2036 | B10: 2 | C10: 约瑟芬 | D10: 36 | E10: =J10&"|"&K10 -> 200020|200072 | F10: 210 | G10: =INDEX('#玺戒参考'!$A:$E,MATCH(F10,'#玺戒参考'!$A:$A,0),2) -> 迅鹿之戒 | H10: =INDEX('#玺戒参考'!$A:$E,MATCH(F10,'#玺戒参考'!$A:$A,0),5) -> 借势威吓 | J10: =INDEX('#技能参考'!$A:$A,MATCH(L10,'#技能参考'!$B:$B,0),1) -> 200020 | K10: =INDEX('#技能参考'!$A:$A,MATCH(M10,'#技能参考'!$B:$B,0),1) -> 200072 | L10: 连击 | M10: 弱点进攻
A11: 20361 | B11: 2 | C11: 约瑟芬 | D11: 36 | E11: =J11&"|"&K11 -> 200072|200034 | F11: 302 | G11: =INDEX('#玺戒参考'!$A:$E,MATCH(F11,'#玺戒参考'!$A:$A,0),2) -> 雏菊之戒 | H11: =INDEX('#玺戒参考'!$A:$E,MATCH(F11,'#玺戒参考'!$A:$A,0),5) -> 二连斩 | J11: =INDEX('#技能参考'!$A:$A,MATCH(L11,'#技能参考'!$B:$B,0),1) -> 200072 | K11: =INDEX('#技能参考'!$A:$A,MATCH(M11,'#技能参考'!$B:$B,0),1) -> 200034 | L11: 弱点进攻 | M11: 持久战
A12: 2055 | B12: 2 | C12: 大卫王 | D12: 55 | E12: =J12&"|"&K12 -> 200061|200009 | F12: 201 | G12: =INDEX('#玺戒参考'!$A:$E,MATCH(F12,'#玺戒参考'!$A:$A,0),2) -> 暴熊之戒 | H12: =INDEX('#玺戒参考'!$A:$E,MATCH(F12,'#玺戒参考'!$A:$A,0),5) -> 裸衣 | J12: =INDEX('#技能参考'!$A:$A,MATCH(L12,'#技能参考'!$B:$B,0),1) -> 200061 | K12: =INDEX('#技能参考'!$A:$A,MATCH(M12,'#技能参考'!$B:$B,0),1) -> 200009 | L12: 泰山压顶 | M12: 正义裁决
A13: 2076 | B13: 2 | C13: 杜加瓦蒂 | D13: 76 | E13: =J13&"|"&K13 -> 200125|200041 | F13: 212 | G13: =INDEX('#玺戒参考'!$A:$E,MATCH(F13,'#玺戒参考'!$A:$A,0),2) -> 夜狼之戒 | H13: =INDEX('#玺戒参考'!$A:$E,MATCH(F13,'#玺戒参考'!$A:$A,0),5) -> 燃身战意 | J13: =INDEX('#技能参考'!$A:$A,MATCH(L13,'#技能参考'!$B:$B,0),1) -> 200125 | K13: =INDEX('#技能参考'!$A:$A,MATCH(M13,'#技能参考'!$B:$B,0),1) -> 200041 | L13: 入阵曲 | M13: 饥渴之刃
A14: 2208 | B14: 2 | C14: 崔如意 | D14: 208 | E14: =J14&"|"&K14 -> 200030|200032 | F14: 212 | G14: =INDEX('#玺戒参考'!$A:$E,MATCH(F14,'#玺戒参考'!$A:$A,0),2) -> 夜狼之戒 | H14: =INDEX('#玺戒参考'!$A:$E,MATCH(F14,'#玺戒参考'!$A:$A,0),5) -> 燃身战意 | J14: =INDEX('#技能参考'!$A:$A,MATCH(L14,'#技能参考'!$B:$B,0),1) -> 200030 | K14: =INDEX('#技能参考'!$A:$A,MATCH(M14,'#技能参考'!$B:$B,0),1) -> 200032 | L14: 怒涛之击 | M14: 撕裂
A15: 3001 | B15: 3 | C15: 贞德 | D15: 1 | E15: =J15&"|"&K15 -> 200068|200100 | F15: 211 | G15: =INDEX('#玺戒参考'!$A:$E,MATCH(F15,'#玺戒参考'!$A:$A,0),2) -> 天鹰之戒 | H15: =INDEX('#玺戒参考'!$A:$E,MATCH(F15,'#玺戒参考'!$A:$A,0),5) -> 绿洲之佑 | J15: =INDEX('#技能参考'!$A:$A,MATCH(L15,'#技能参考'!$B:$B,0),1) -> 200068 | K15: =INDEX('#技能参考'!$A:$A,MATCH(M15,'#技能参考'!$B:$B,0),1) -> 200100 | L15: 王者之剑 | M15: 不屈反击
... A24: 4019 | B24: 4 | C24: 大流士一世 | D24: 19 | E24: =J24&"|"&K24 -> 200019|200072 | F24: 303 | G24: =INDEX('#玺戒参考'!$A:$E,MATCH(F24,'#玺戒参考'!$A:$A,0),2) -> 鸢尾花之戒 | H24: =INDEX('#玺戒参考'!$A:$E,MATCH(F24,'#玺戒参考'!$A:$A,0),5) -> 锐锋 | J24: =INDEX('#技能参考'!$A:$A,MATCH(L24,'#技能参考'!$B:$B,0),1) -> 200019 | K24: =INDEX('#技能参考'!$A:$A,MATCH(M24,'#技能参考'!$B:$B,0),1) -> 200072 | L24: 冲锋的极意 | M24: 弱点进攻
A25: 4032 | B25: 4 | C25: 阿提拉 | D25: 32 | E25: =J25&"|"&K25 -> 200072|200036 | F25: 212 | G25: =INDEX('#玺戒参考'!$A:$E,MATCH(F25,'#玺戒参考'!$A:$A,0),2) -> 夜狼之戒 | H25: =INDEX('#玺戒参考'!$A:$E,MATCH(F25,'#玺戒参考'!$A:$A,0),5) -> 燃身战意 | J25: =INDEX('#技能参考'!$A:$A,MATCH(L25,'#技能参考'!$B:$B,0),1) -> 200072 | K25: =INDEX('#技能参考'!$A:$A,MATCH(M25,'#技能参考'!$B:$B,0),1) -> 200036 | L25: 弱点进攻 | M25: 破敌之眼 | N25: 关羽队辅助
A26: 40321 | B26: 4 | C26: 阿提拉 | D26: 32 | E26: =J26&"|"&K26 -> 200072|200031 | F26: 212 | G26: =INDEX('#玺戒参考'!$A:$E,MATCH(F26,'#玺戒参考'!$A:$A,0),2) -> 夜狼之戒 | H26: =INDEX('#玺戒参考'!$A:$E,MATCH(F26,'#玺戒参考'!$A:$A,0),5) -> 燃身战意 | J26: =INDEX('#技能参考'!$A:$A,MATCH(L26,'#技能参考'!$B:$B,0),1) -> 200072 | K26: =INDEX('#技能参考'!$A:$A,MATCH(M26,'#技能参考'!$B:$B,0),1) -> 200031 | L26: 弱点进攻 | M26: 慈悲终结 | N26: 汉尼拔、熙德队辅助
A27: 4056 | B27: 4 | C27: 哈拉尔 | D27: 56 | E27: =J27&"|"&K27 -> 200041|200015 | F27: 211 | G27: =INDEX('#玺戒参考'!$A:$E,MATCH(F27,'#玺戒参考'!$A:$A,0),2) -> 天鹰之戒 | H27: =INDEX('#玺戒参考'!$A:$E,MATCH(F27,'#玺戒参考'!$A:$A,0),5) -> 绿洲之佑 | J27: =INDEX('#技能参考'!$A:$A,MATCH(L27,'#技能参考'!$B:$B,0),1) -> 200041 | K27: =INDEX('#技能参考'!$A:$A,MATCH(M27,'#技能参考'!$B:$B,0),1) -> 200015 | L27: 饥渴之刃 | M27: 战争祝福
A28: 4076 | B28: 4 | C28: 杜加瓦蒂 | D28: 76 | E28: =J28&"|"&K28 -> 200125|200041 | F28: 212 | G28: =INDEX('#玺戒参考'!$A:$E,MATCH(F28,'#玺戒参考'!$A:$A,0),2) -> 夜狼之戒 | H28: =INDEX('#玺戒参考'!$A:$E,MATCH(F28,'#玺戒参考'!$A:$A,0),5) -> 燃身战意 | J28: =INDEX('#技能参考'!$A:$A,MATCH(L28,'#技能参考'!$B:$B,0),1) -> 200125 | K28: =INDEX('#技能参考'!$A:$A,MATCH(M28,'#技能参考'!$B:$B,0),1) -> 200041 | L28: 入阵曲 | M28: 饥渴之刃
