Workbook

Sheet 英雄流派
A1: convert(ResHero.proto, table_HeroFactionConf, HeroFactionConf.pbin)
A2: 流派id | B2: 要不要 | C2: 流派说明（策划用） | D2: 流派名称 | E2: 流派推荐描述 | F2: 流派Icon图集 | G2: 流派icon名称 | H2: 成就Id | I2: 推荐阵容 | J2: 第1阶段等级 | K2: 第1阶段奖励 | L2: 第2阶段等级 | M2: 第2阶段奖励 | N2: 第3阶段等级 | O2: 第3阶段奖励 | P2: 第4阶段等级 | Q2: 第4阶段奖励 | R2: 第5阶段等级 | S2: 第5阶段奖励 | V2: 1 | W2: 2 | X2: 3 | Y2: 11 | Z2: 12 | AA2: 13 | AB2: 21 | AC2: 22 | AD2: 23
A3: factionId | B3: open | D3: factionName | E3: des | F3: iconAtlas | G3: iconName | H3: heroAchievementId[;] | I3: recommend[|] | J3: stageReward[0].totalLevel | K3: stageReward[0].rewardId | L3: stageReward[1].totalLevel | M3: stageReward[1].rewardId | N3: stageReward[2].totalLevel | O3: stageReward[2].rewardId | P3: stageReward[3].totalLevel | Q3: stageReward[3].rewardId | R3: stageReward[4].totalLevel | S3: stageReward[4].rewardId
A4: 1 | B4: TRUE | C4: 智谋剑 | D4: TID_HeroFactionConf_1_factionName_CN_Main | E4: TID_HeroFactionConf_1_des_CN_Main | F4: icon_n_hero | G4: icon_achievement_01 | H4: =V4&";"&W4&";"&X4&";"&Y4&";"&Z4&";"&AB4&";"&AC4 -> 1001;1002;1003;1011;1012;1021;1022 | I4: 1001|1002|1003 | J4: =$U4*1 -> 7 | K4: 1707501 | L4: =$U4*2 -> 14 | M4: 1707502 | N4: =$U4*3 -> 21 | O4: 1707503 | P4: =$U4*4 -> 28 | Q4: 1707504 | R4: =$U4*5 -> 35 | S4: 1707505 | U4: 7 | V4: =$A4*1000+V$2 -> 1001 | W4: =$A4*1000+W$2 -> 1002 | X4: =$A4*1000+X$2 -> 1003 | Y4: =$A4*1000+Y$2 -> 1011 | Z4: =$A4*1000+Z$2 -> 1012 | AA4: =$A4*1000+AA$2 -> 1013 | AB4: =$A4*1000+AB$2 -> 1021 | AC4: =$A4*1000+AC$2 -> 1022 | AD4: =$A4*1000+AD$2 -> 1023
A5: 2 | B5: TRUE | C5: 智谋弓 | D5: TID_HeroFactionConf_2_factionName_CN_Main | E5: TID_HeroFactionConf_2_des_CN_Main | F5: icon_n_hero | G5: icon_achievement_07 | H5: =V5&";"&W5&";"&X5&";"&Y5&";"&Z5&";"&AB5&";"&AC5 -> 2001;2002;2003;2011;2012;2021;2022 | I5: 2001|2002|2003 | J5: =$U5*1 -> 7 | K5: 1707501 | L5: =$U5*2 -> 14 | M5: 1707502 | N5: =$U5*3 -> 21 | O5: 1707503 | P5: =$U5*4 -> 28 | Q5: 1707504 | R5: =$U5*5 -> 35 | S5: 1707505 | U5: 7 | V5: =$A5*1000+V$2 -> 2001 | W5: =$A5*1000+W$2 -> 2002 | X5: =$A5*1000+X$2 -> 2003 | Y5: =$A5*1000+Y$2 -> 2011 | Z5: =$A5*1000+Z$2 -> 2012 | AA5: =$A5*1000+AA$2 -> 2013 | AB5: =$A5*1000+AB$2 -> 2021 | AC5: =$A5*1000+AC$2 -> 2022 | AD5: =$A5*1000+AD$2 -> 2023
A6: 3 | B6: TRUE | C6: 指挥剑/指挥枪 | D6: TID_HeroFactionConf_3_factionName_CN_Main | E6: TID_HeroFactionConf_3_des_CN_Main | F6: icon_n_hero | G6: icon_achievement_02 | H6: =V6&";"&W6&";"&X6&";"&Y6&";"&Z6&";"&AB6&";"&AC6 -> 3001;3002;3003;3011;3012;3021;3022 | I6: 3001|3002|3003|3004|3005|3006 | J6: =$U6*1 -> 7 | K6: 1707501 | L6: =$U6*2 -> 14 | M6: 1707502 | N6: =$U6*3 -> 21 | O6: 1707503 | P6: =$U6*4 -> 28 | Q6: 1707504 | R6: =$U6*5 -> 35 | S6: 1707505 | U6: 7 | V6: =$A6*1000+V$2 -> 3001 | W6: =$A6*1000+W$2 -> 3002 | X6: =$A6*1000+X$2 -> 3003 | Y6: =$A6*1000+Y$2 -> 3011 | Z6: =$A6*1000+Z$2 -> 3012 | AA6: =$A6*1000+AA$2 -> 3013 | AB6: =$A6*1000+AB$2 -> 3021 | AC6: =$A6*1000+AC$2 -> 3022 | AD6: =$A6*1000+AD$2 -> 3023
A7: 4 | B7: TRUE | C7: 反击枪 | D7: TID_HeroFactionConf_4_factionName_CN_Main | E7: TID_HeroFactionConf_4_des_CN_Main | F7: icon_n_hero | G7: icon_achievement_03 | H7: =V7&";"&W7&";"&X7&";"&Y7&";"&Z7&";"&AB7&";"&AC7 -> 4001;4002;4003;4011;4012;4021;4022 | I7: 4001|4002|4003|4004 | J7: =$U7*1 -> 7 | K7: 1707501 | L7: =$U7*2 -> 14 | M7: 1707502 | N7: =$U7*3 -> 21 | O7: 1707503 | P7: =$U7*4 -> 28 | Q7: 1707504 | R7: =$U7*5 -> 35 | S7: 1707505 | U7: 7 | V7: =$A7*1000+V$2 -> 4001 | W7: =$A7*1000+W$2 -> 4002 | X7: =$A7*1000+X$2 -> 4003 | Y7: =$A7*1000+Y$2 -> 4011 | Z7: =$A7*1000+Z$2 -> 4012 | AA7: =$A7*1000+AA$2 -> 4013 | AB7: =$A7*1000+AB$2 -> 4021 | AC7: =$A7*1000+AC$2 -> 4022 | AD7: =$A7*1000+AD$2 -> 4023
A8: 5 | B8: TRUE | C8: 勇武骑/勇武弓/亚瑟骑 | D8: TID_HeroFactionConf_5_factionName_CN_Main | E8: TID_HeroFactionConf_5_des_CN_Main | F8: icon_n_hero | G8: icon_achievement_04 | H8: =V8&";"&W8&";"&X8&";"&Y8&";"&Z8&";"&AB8&";"&AC8 -> 5001;5002;5003;5011;5012;5021;5022 | I8: 5001|5002|5003|5004|5005|5006 | J8: =$U8*1 -> 7 | K8: 1707501 | L8: =$U8*2 -> 14 | M8: 1707502 | N8: =$U8*3 -> 21 | O8: 1707503 | P8: =$U8*4 -> 28 | Q8: 1707504 | R8: =$U8*5 -> 35 | S8: 1707505 | U8: 7 | V8: =$A8*1000+V$2 -> 5001 | W8: =$A8*1000+W$2 -> 5002 | X8: =$A8*1000+X$2 -> 5003 | Y8: =$A8*1000+Y$2 -> 5011 | Z8: =$A8*1000+Z$2 -> 5012 | AA8: =$A8*1000+AA$2 -> 5013 | AB8: =$A8*1000+AB$2 -> 5021 | AC8: =$A8*1000+AC$2 -> 5022 | AD8: =$A8*1000+AD$2 -> 5023
A9: 6 | B9: TRUE | C9: 智谋骑 | D9: TID_HeroFactionConf_6_factionName_CN_Main | E9: TID_HeroFactionConf_6_des_CN_Main | F9: icon_n_hero | G9: icon_achievement_05 | H9: =V9&";"&W9&";"&X9&";"&Y9&";"&Z9&";"&AB9&";"&AC9 -> 6001;6002;6003;6011;6012;6021;6022 | I9: 6001|6002|6003 | J9: =$U9*1 -> 7 | K9: 1707501 | L9: =$U9*2 -> 14 | M9: 1707502 | N9: =$U9*3 -> 21 | O9: 1707503 | P9: =$U9*4 -> 28 | Q9: 1707504 | R9: =$U9*5 -> 35 | S9: 1707505 | U9: 7 | V9: =$A9*1000+V$2 -> 6001 | W9: =$A9*1000+W$2 -> 6002 | X9: =$A9*1000+X$2 -> 6003 | Y9: =$A9*1000+Y$2 -> 6011 | Z9: =$A9*1000+Z$2 -> 6012 | AA9: =$A9*1000+AA$2 -> 6013 | AB9: =$A9*1000+AB$2 -> 6021 | AC9: =$A9*1000+AC$2 -> 6022 | AD9: =$A9*1000+AD$2 -> 6023
A10: 7 | B10: TRUE | C10: 女帝弓 | D10: TID_HeroFactionConf_7_factionName_CN_Main | E10: TID_HeroFactionConf_7_des_CN_Main | F10: icon_n_hero | G10: icon_achievement_06 | H10: =V10&";"&W10&";"&X10&";"&Y10&";"&Z10&";"&AB10&";"&AC10 -> 7001;7002;7003;7011;7012;7021;7022 | I10: 7001|7002 | J10: =$U10*1 -> 7 | K10: 1707501 | L10: =$U10*2 -> 14 | M10: 1707502 | N10: =$U10*3 -> 21 | O10: 1707503 | P10: =$U10*4 -> 28 | Q10: 1707504 | R10: =$U10*5 -> 35 | S10: 1707505 | U10: 7 | V10: =$A10*1000+V$2 -> 7001 | W10: =$A10*1000+W$2 -> 7002 | X10: =$A10*1000+X$2 -> 7003 | Y10: =$A10*1000+Y$2 -> 7011 | Z10: =$A10*1000+Z$2 -> 7012 | AA10: =$A10*1000+AA$2 -> 7013 | AB10: =$A10*1000+AB$2 -> 7021 | AC10: =$A10*1000+AC$2 -> 7022 | AD10: =$A10*1000+AD$2 -> 7023
A11: 8 | B11: FALSE | C11: 智谋剑/智谋弓 | D11: TID_HeroFactionConf_8_factionName_CN_Main | F11: icon_n_hero | G11: icon_achievement_06 | I11: 3001|3002 | J11: =$U11*1 -> 7 | K11: 1707501 | L11: =$U11*2 -> 14 | M11: 1707502 | N11: =$U11*3 -> 21 | O11: 1707503 | P11: =$U11*4 -> 28 | Q11: 1707504 | R11: =$U11*5 -> 35 | S11: 1707505 | U11: 7 | V11: =$A11*1000+V$2 -> 8001 | W11: =$A11*1000+W$2 -> 8002 | X11: =$A11*1000+X$2 -> 8003 | Y11: =$A11*1000+Y$2 -> 8011 | Z11: =$A11*1000+Z$2 -> 8012 | AA11: =$A11*1000+AA$2 -> 8013 | AB11: =$A11*1000+AB$2 -> 8021 | AC11: =$A11*1000+AC$2 -> 8022 | AD11: =$A11*1000+AD$2 -> 8023

Sheet 英雄成就
A1: convert(ResHero.proto, table_HeroAchievementConf, HeroAchievementConf.pbin)
A2: 成就Id | B2: 流派Id | C2: 成就名称 | D2: 成就描述 | E2: 进度值描述 | F2: 成就品质 | G2: 成就icon图集 | H2: 成就icon名称 | I2: 目标id | J2: 目标等级 | K2: 跳转id | L2: 跳转id(不关闭界面的跳转id) | M2: 实现条件组 | N2: 条件关系 | O2: 奖励id | Q2: 参数1 | R2: 参数2 | W2: 流派 | X2: 成就id | Y2: icon | Z2: 成就名称(源文本) | AA2: 成就描述(源文本) | AB2: 进度值描述(源文本)
A3: id | B3: factionId | C3: name | D3: des | E3: des2 | F3: level | G3: iconAtlas | H3: iconName | I3: realize.targetId | J3: realize.targetLevel | K3: realize.jumpId | L3: realize.jumpId2 | M3: realize.conditionGroup.condition.condOneOf | N3: realize.conditionGroup.conditionRelation | O3: realize.rewardId
A4: =W4*1000+X4 -> 1001 | B4: =IF(A4=0,"",INT(A4/1000)) -> 1 | C4: TID_HeroAchievementConf_1001_name_CN_Main | D4: TID_HeroAchievementConf_1001_des_CN_Main | E4: TID_HeroAchievementConf_1001_des2_CN_Main | F4: 1 | G4: icon_n_challengemanual | H4: ="icon_copper_"&Y4 -> icon_copper_07 | I4: =A4*100+J4 -> 100101 | J4: =IF(MOD(ROW()+2,5)=0,MOD(ROW()+2,5)+5,MOD(ROW()+2,5)) -> 1 | K4: 7253 | L4: 7253 | M4: ="achievementAccumulative{achieveId:"&Q4&",count:"&R4&"}" -> achievementAccumulative{achieveId:1001,count:40000} | N4: 条件与 | O4: 1707511 | Q4: =IF(0=A4,Q3,A4) -> 1001 | R4: 40000 | W4: 1 | X4: 1 | Y4: 07 | Z4: =IF($A4=0,"",IF(VLOOKUP($A4,成就条件映射!$A$4:$D$66,2)=0,"",VLOOKUP($A4,成就条件映射!$A$4:$D$66,2))) -> 攻克资源点 | AA4: =IF($A4=0,"",IF(VLOOKUP($A4,成就条件映射!$A$4:$D$66,3)=0,"",VLOOKUP($A4,成就条件映射!$A$4:$D$66,3))) -> 在与<color=#ffc766>资源点守军</color>战斗中，我方<color=#ffc766>剑士</color>部队使用<color=#ffc766>固有</color><color=#ffc766>主动技能</color>累计造成的<color=#ffc766>伤害量</color> | AB4: =IF($A4=0,"",IF(VLOOKUP($A4,成就条件映射!$A$4:$D$66,4)=0,"",VLOOKUP($A4,成就条件映射!$A$4:$D$66,4))) -> 当前累计伤害
B5: =IF(A5=0,"",INT(A5/1000)) | C5: =IF($A5=0,"",IF(VLOOKUP($A5,成就条件映射!$A$4:$D$66,2)=0,"",VLOOKUP($A5,成就条件映射!$A$4:$D$66,2))) | D5: =IF($A5=0,"",IF(VLOOKUP($A5,成就条件映射!$A$4:$D$66,3)=0,"",VLOOKUP($A5,成就条件映射!$A$4:$D$66,3))) | E5: =IF($A5=0,"",IF(VLOOKUP($A5,成就条件映射!$A$4:$D$66,4)=0,"",VLOOKUP($A5,成就条件映射!$A$4:$D$66,4))) | I5: =A4*100+J5 -> 100102 | J5: =IF(MOD(ROW()+2,5)=0,MOD(ROW()+2,5)+5,MOD(ROW()+2,5)) -> 2 | K5: 7253 | L5: 7253 | M5: ="achievementAccumulative{achieveId:"&Q5&",count:"&R5&"}" -> achievementAccumulative{achieveId:1001,count:650000} | N5: 条件与 | O5: 1707512 | Q5: =IF(0=A5,Q4,A5) -> 1001 | R5: 650000 | W5: 1 | X5: 1
B6: =IF(A6=0,"",INT(A6/1000)) | C6: =IF($A6=0,"",IF(VLOOKUP($A6,成就条件映射!$A$4:$D$66,2)=0,"",VLOOKUP($A6,成就条件映射!$A$4:$D$66,2))) | D6: =IF($A6=0,"",IF(VLOOKUP($A6,成就条件映射!$A$4:$D$66,3)=0,"",VLOOKUP($A6,成就条件映射!$A$4:$D$66,3))) | E6: =IF($A6=0,"",IF(VLOOKUP($A6,成就条件映射!$A$4:$D$66,4)=0,"",VLOOKUP($A6,成就条件映射!$A$4:$D$66,4))) | I6: =A4*100+J6 -> 100103 | J6: =IF(MOD(ROW()+2,5)=0,MOD(ROW()+2,5)+5,MOD(ROW()+2,5)) -> 3 | K6: 7253 | L6: 7253 | M6: ="achievementAccumulative{achieveId:"&Q6&",count:"&R6&"}" -> achievementAccumulative{achieveId:1001,count:4000000} | N6: 条件与 | O6: 1707513 | Q6: =IF(0=A6,Q5,A6) -> 1001 | R6: 4000000 | W6: 1 | X6: 1
B7: =IF(A7=0,"",INT(A7/1000)) | C7: =IF($A7=0,"",IF(VLOOKUP($A7,成就条件映射!$A$4:$D$66,2)=0,"",VLOOKUP($A7,成就条件映射!$A$4:$D$66,2))) | D7: =IF($A7=0,"",IF(VLOOKUP($A7,成就条件映射!$A$4:$D$66,3)=0,"",VLOOKUP($A7,成就条件映射!$A$4:$D$66,3))) | E7: =IF($A7=0,"",IF(VLOOKUP($A7,成就条件映射!$A$4:$D$66,4)=0,"",VLOOKUP($A7,成就条件映射!$A$4:$D$66,4))) | I7: =A4*100+J7 -> 100104 | J7: =IF(MOD(ROW()+2,5)=0,MOD(ROW()+2,5)+5,MOD(ROW()+2,5)) -> 4 | K7: 7253 | L7: 7253 | M7: ="achievementAccumulative{achieveId:"&Q7&",count:"&R7&"}" -> achievementAccumulative{achieveId:1001,count:15000000} | N7: 条件与 | O7: 1707514 | Q7: =IF(0=A7,Q6,A7) -> 1001 | R7: 15000000 | W7: 1 | X7: 1
B8: =IF(A8=0,"",INT(A8/1000)) | C8: =IF($A8=0,"",IF(VLOOKUP($A8,成就条件映射!$A$4:$D$66,2)=0,"",VLOOKUP($A8,成就条件映射!$A$4:$D$66,2))) | D8: =IF($A8=0,"",IF(VLOOKUP($A8,成就条件映射!$A$4:$D$66,3)=0,"",VLOOKUP($A8,成就条件映射!$A$4:$D$66,3))) | E8: =IF($A8=0,"",IF(VLOOKUP($A8,成就条件映射!$A$4:$D$66,4)=0,"",VLOOKUP($A8,成就条件映射!$A$4:$D$66,4))) | I8: =A4*100+J8 -> 100105 | J8: =IF(MOD(ROW()+2,5)=0,MOD(ROW()+2,5)+5,MOD(ROW()+2,5)) -> 5 | K8: 7253 | L8: 7253 | M8: ="achievementAccumulative{achieveId:"&Q8&",count:"&R8&"}" -> achievementAccumulative{achieveId:1001,count:30000000} | N8: 条件与 | O8: 1707515 | Q8: =IF(0=A8,Q7,A8) -> 1001 | R8: 30000000 | W8: 1 | X8: 1
A9: =W9*1000+X9 -> 1002 | B9: =IF(A9=0,"",INT(A9/1000)) -> 1 | C9: TID_HeroAchievementConf_1002_name_CN_Main | D9: TID_HeroAchievementConf_1002_des_CN_Main | E9: TID_HeroAchievementConf_1001_des2_CN_Main | F9: 1 | G9: icon_n_challengemanual | H9: ="icon_copper_"&Y9 -> icon_copper_10 | I9: =A9*100+J9 -> 100201 | J9: =IF(MOD(ROW()+2,5)=0,MOD(ROW()+2,5)+5,MOD(ROW()+2,5)) -> 1 | K9: 7254 | L9: 7254 | M9: ="achievementAccumulative{achieveId:"&Q9&",count:"&R9&"}" -> achievementAccumulative{achieveId:1002,count:40000} | N9: 条件与 | O9: 1707511 | Q9: =IF(0=A9,Q8,A9) -> 1002 | R9: 40000 | W9: 1 | X9: 2 | Y9: 10 | Z9: =IF($A9=0,"",IF(VLOOKUP($A9,成就条件映射!$A$4:$D$66,2)=0,"",VLOOKUP($A9,成就条件映射!$A$4:$D$66,2))) -> 蛮族讨伐 | AA9: =IF($A9=0,"",IF(VLOOKUP($A9,成就条件映射!$A$4:$D$66,3)=0,"",VLOOKUP($A9,成就条件映射!$A$4:$D$66,3))) -> 在与<color=#ffc766>野外蛮族</color>战斗中，我方<color=#ffc766>剑士</color>部队使用<color=#ffc766>固有</color><color=#ffc766>主动技能</color>累计造成的<color=#ffc766>伤害量</color> | AB9: =IF($A9=0,"",IF(VLOOKUP($A9,成就条件映射!$A$4:$D$66,4)=0,"",VLOOKUP($A9,成就条件映射!$A$4:$D$66,4))) -> 当前累计伤害
B10: =IF(A10=0,"",INT(A10/1000)) | C10: =IF($A10=0,"",IF(VLOOKUP($A10,成就条件映射!$A$4:$D$66,2)=0,"",VLOOKUP($A10,成就条件映射!$A$4:$D$66,2))) | D10: =IF($A10=0,"",IF(VLOOKUP($A10,成就条件映射!$A$4:$D$66,3)=0,"",VLOOKUP($A10,成就条件映射!$A$4:$D$66,3))) | E10: =IF($A10=0,"",IF(VLOOKUP($A10,成就条件映射!$A$4:$D$66,4)=0,"",VLOOKUP($A10,成就条件映射!$A$4:$D$66,4))) | I10: =A9*100+J10 -> 100202 | J10: =IF(MOD(ROW()+2,5)=0,MOD(ROW()+2,5)+5,MOD(ROW()+2,5)) -> 2 | K10: 7254 | L10: 7254 | M10: ="achievementAccumulative{achieveId:"&Q10&",count:"&R10&"}" -> achievementAccumulative{achieveId:1002,count:680000} | N10: 条件与 | O10: 1707512 | Q10: =IF(0=A10,Q9,A10) -> 1002 | R10: 680000 | W10: 1 | X10: 2
B11: =IF(A11=0,"",INT(A11/1000)) | C11: =IF($A11=0,"",IF(VLOOKUP($A11,成就条件映射!$A$4:$D$66,2)=0,"",VLOOKUP($A11,成就条件映射!$A$4:$D$66,2))) | D11: =IF($A11=0,"",IF(VLOOKUP($A11,成就条件映射!$A$4:$D$66,3)=0,"",VLOOKUP($A11,成就条件映射!$A$4:$D$66,3))) | E11: =IF($A11=0,"",IF(VLOOKUP($A11,成就条件映射!$A$4:$D$66,4)=0,"",VLOOKUP($A11,成就条件映射!$A$4:$D$66,4))) | I11: =A9*100+J11 -> 100203 | J11: =IF(MOD(ROW()+2,5)=0,MOD(ROW()+2,5)+5,MOD(ROW()+2,5)) -> 3 | K11: 7254 | L11: 7254 | M11: ="achievementAccumulative{achieveId:"&Q11&",count:"&R11&"}" -> achievementAccumulative{achieveId:1002,count:1600000} | N11: 条件与 | O11: 1707513 | Q11: =IF(0=A11,Q10,A11) -> 1002 | R11: 1600000 | W11: 1 | X11: 2
B12: =IF(A12=0,"",INT(A12/1000)) | C12: =IF($A12=0,"",IF(VLOOKUP($A12,成就条件映射!$A$4:$D$66,2)=0,"",VLOOKUP($A12,成就条件映射!$A$4:$D$66,2))) | D12: =IF($A12=0,"",IF(VLOOKUP($A12,成就条件映射!$A$4:$D$66,3)=0,"",VLOOKUP($A12,成就条件映射!$A$4:$D$66,3))) | E12: =IF($A12=0,"",IF(VLOOKUP($A12,成就条件映射!$A$4:$D$66,4)=0,"",VLOOKUP($A12,成就条件映射!$A$4:$D$66,4))) | I12: =A9*100+J12 -> 100204 | J12: =IF(MOD(ROW()+2,5)=0,MOD(ROW()+2,5)+5,MOD(ROW()+2,5)) -> 4 | K12: 7254 | L12: 7254 | M12: ="achievementAccumulative{achieveId:"&Q12&",count:"&R12&"}" -> achievementAccumulative{achieveId:1002,count:6300000} | N12: 条件与 | O12: 1707514 | Q12: =IF(0=A12,Q11,A12) -> 1002 | R12: 6300000 | W12: 1 | X12: 2
B13: =IF(A13=0,"",INT(A13/1000)) | C13: =IF($A13=0,"",IF(VLOOKUP($A13,成就条件映射!$A$4:$D$66,2)=0,"",VLOOKUP($A13,成就条件映射!$A$4:$D$66,2))) | D13: =IF($A13=0,"",IF(VLOOKUP($A13,成就条件映射!$A$4:$D$66,3)=0,"",VLOOKUP($A13,成就条件映射!$A$4:$D$66,3))) | E13: =IF($A13=0,"",IF(VLOOKUP($A13,成就条件映射!$A$4:$D$66,4)=0,"",VLOOKUP($A13,成就条件映射!$A$4:$D$66,4))) | I13: =A9*100+J13 -> 100205 | J13: =IF(MOD(ROW()+2,5)=0,MOD(ROW()+2,5)+5,MOD(ROW()+2,5)) -> 5 | K13: 7254 | L13: 7254 | M13: ="achievementAccumulative{achieveId:"&Q13&",count:"&R13&"}" -> achievementAccumulative{achieveId:1002,count:20000000} | N13: 条件与 | O13: 1707515 | Q13: =IF(0=A13,Q12,A13) -> 1002 | R13: 20000000 | W13: 1 | X13: 2
A14: =W14*1000+X14 -> 1003 | B14: =IF(A14=0,"",INT(A14/1000)) -> 1 | C14: TID_HeroAchievementConf_1003_name_CN_Main | D14: TID_HeroAchievementConf_1003_des_CN_Main | E14: TID_HeroAchievementConf_1001_des2_CN_Main | F14: 1 | G14: icon_n_challengemanual | H14: ="icon_copper_"&Y14 -> icon_copper_04 | I14: =A14*100+J14 -> 100301 | J14: =IF(MOD(ROW()+2,5)=0,MOD(ROW()+2,5)+5,MOD(ROW()+2,5)) -> 1 | M14: ="achievementAccumulative{achieveId:"&Q14&",count:"&R14&"}" -> achievementAccumulative{achieveId:1003,count:80000} | N14: 条件与 | O14: 1707511 | Q14: =IF(0=A14,Q13,A14) -> 1003 | R14: 80000 | W14: 1 | X14: 3 | Y14: 04 | Z14: =IF($A14=0,"",IF(VLOOKUP($A14,成就条件映射!$A$4:$D$66,2)=0,"",VLOOKUP($A14,成就条件映射!$A$4:$D$66,2))) -> 野战先锋 | AA14: =IF($A14=0,"",IF(VLOOKUP($A14,成就条件映射!$A$4:$D$66,3)=0,"",VLOOKUP($A14,成就条件映射!$A$4:$D$66,3))) -> 野外与<color=#ffc766>玩家</color>部队战斗中，我方<color=#ffc766>剑士</color>部队使用<color=#ffc766>固有</color><color=#ffc766>主动技能</color>累计对敌方玩家造成的<color=#ffc766>伤害量</color> | AB14: =IF($A14=0,"",IF(VLOOKUP($A14,成就条件映射!$A$4:$D$66,4)=0,"",VLOOKUP($A14,成就条件映射!$A$4:$D$66,4))) -> 当前累计伤害
B15: =IF(A15=0,"",INT(A15/1000)) | C15: =IF($A15=0,"",IF(VLOOKUP($A15,成就条件映射!$A$4:$D$66,2)=0,"",VLOOKUP($A15,成就条件映射!$A$4:$D$66,2))) | D15: =IF($A15=0,"",IF(VLOOKUP($A15,成就条件映射!$A$4:$D$66,3)=0,"",VLOOKUP($A15,成就条件映射!$A$4:$D$66,3))) | E15: =IF($A15=0,"",IF(VLOOKUP($A15,成就条件映射!$A$4:$D$66,4)=0,"",VLOOKUP($A15,成就条件映射!$A$4:$D$66,4))) | I15: =A14*100+J15 -> 100302 | J15: =IF(MOD(ROW()+2,5)=0,MOD(ROW()+2,5)+5,MOD(ROW()+2,5)) -> 2 | M15: ="achievementAccumulative{achieveId:"&Q15&",count:"&R15&"}" -> achievementAccumulative{achieveId:1003,count:300000} | N15: 条件与 | O15: 1707512 | Q15: =IF(0=A15,Q14,A15) -> 1003 | R15: 300000 | W15: 1 | X15: 3
B16: =IF(A16=0,"",INT(A16/1000)) | C16: =IF($A16=0,"",IF(VLOOKUP($A16,成就条件映射!$A$4:$D$66,2)=0,"",VLOOKUP($A16,成就条件映射!$A$4:$D$66,2))) | D16: =IF($A16=0,"",IF(VLOOKUP($A16,成就条件映射!$A$4:$D$66,3)=0,"",VLOOKUP($A16,成就条件映射!$A$4:$D$66,3))) | E16: =IF($A16=0,"",IF(VLOOKUP($A16,成就条件映射!$A$4:$D$66,4)=0,"",VLOOKUP($A16,成就条件映射!$A$4:$D$66,4))) | I16: =A14*100+J16 -> 100303 | J16: =IF(MOD(ROW()+2,5)=0,MOD(ROW()+2,5)+5,MOD(ROW()+2,5)) -> 3 | M16: ="achievementAccumulative{achieveId:"&Q16&",count:"&R16&"}" -> achievementAccumulative{achieveId:1003,count:1200000} | N16: 条件与 | O16: 1707513 | Q16: =IF(0=A16,Q15,A16) -> 1003 | R16: 1200000 | W16: 1 | X16: 3
B17: =IF(A17=0,"",INT(A17/1000)) | C17: =IF($A17=0,"",IF(VLOOKUP($A17,成就条件映射!$A$4:$D$66,2)=0,"",VLOOKUP($A17,成就条件映射!$A$4:$D$66,2))) | D17: =IF($A17=0,"",IF(VLOOKUP($A17,成就条件映射!$A$4:$D$66,3)=0,"",VLOOKUP($A17,成就条件映射!$A$4:$D$66,3))) | E17: =IF($A17=0,"",IF(VLOOKUP($A17,成就条件映射!$A$4:$D$66,4)=0,"",VLOOKUP($A17,成就条件映射!$A$4:$D$66,4))) | I17: =A14*100+J17 -> 100304 | J17: =IF(MOD(ROW()+2,5)=0,MOD(ROW()+2,5)+5,MOD(ROW()+2,5)) -> 4 | M17: ="achievementAccumulative{achieveId:"&Q17&",count:"&R17&"}" -> achievementAccumulative{achieveId:1003,count:4000000} | N17: 条件与 | O17: 1707514 | Q17: =IF(0=A17,Q16,A17) -> 1003 | R17: 4000000 | W17: 1 | X17: 3
B18: =IF(A18=0,"",INT(A18/1000)) | C18: =IF($A18=0,"",IF(VLOOKUP($A18,成就条件映射!$A$4:$D$66,2)=0,"",VLOOKUP($A18,成就条件映射!$A$4:$D$66,2))) | D18: =IF($A18=0,"",IF(VLOOKUP($A18,成就条件映射!$A$4:$D$66,3)=0,"",VLOOKUP($A18,成就条件映射!$A$4:$D$66,3))) | E18: =IF($A18=0,"",IF(VLOOKUP($A18,成就条件映射!$A$4:$D$66,4)=0,"",VLOOKUP($A18,成就条件映射!$A$4:$D$66,4))) | I18: =A14*100+J18 -> 100305 | J18: =IF(MOD(ROW()+2,5)=0,MOD(ROW()+2,5)+5,MOD(ROW()+2,5)) -> 5 | M18: ="achievementAccumulative{achieveId:"&Q18&",count:"&R18&"}" -> achievementAccumulative{achieveId:1003,count:10000000} | N18: 条件与 | O18: 1707515 | Q18: =IF(0=A18,Q17,A18) -> 1003 | R18: 10000000 | W18: 1 | X18: 3
A19: =W19*1000+X19 -> 1011 | B19: =IF(A19=0,"",INT(A19/1000)) -> 1 | C19: TID_HeroAchievementConf_1011_name_CN_Main | D19: TID_HeroAchievementConf_1011_des_CN_Main | E19: TID_HeroAchievementConf_1001_des2_CN_Main | F19: 2 | G19: icon_n_challengemanual | H19: ="icon_silver_"&Y19 -> icon_silver_17 | I19: =A19*100+J19 -> 101101 | J19: =IF(MOD(ROW()+2,5)=0,MOD(ROW()+2,5)+5,MOD(ROW()+2,5)) -> 1 | M19: ="achievementAccumulative{achieveId:"&Q19&",count:"&R19&"}" -> achievementAccumulative{achieveId:1011,count:10000} | N19: 条件与 | O19: 1707521 | Q19: =IF(0=A19,Q18,A19) -> 1011 | R19: 10000 | W19: 1 | X19: 11 | Y19: 17 | Z19: =IF($A19=0,"",IF(VLOOKUP($A19,成就条件映射!$A$4:$D$66,2)=0,"",VLOOKUP($A19,成就条件映射!$A$4:$D$66,2))) -> 临而不发 | AA19: =IF($A19=0,"",IF(VLOOKUP($A19,成就条件映射!$A$4:$D$66,3)=0,"",VLOOKUP($A19,成就条件映射!$A$4:$D$66,3))) -> <color=#ffc766>60秒</color>内，我方部队使用<color=#ffc766>准备技能</color>累计造成的<color=#ffc766>最大伤害量</color> | AB19: =IF($A19=0,"",IF(VLOOKUP($A19,成就条件映射!$A$4:$D$66,4)=0,"",VLOOKUP($A19,成就条件映射!$A$4:$D$66,4))) -> 当前累计伤害
B20: =IF(A20=0,"",INT(A20/1000)) | C20: =IF($A20=0,"",IF(VLOOKUP($A20,成就条件映射!$A$4:$D$66,2)=0,"",VLOOKUP($A20,成就条件映射!$A$4:$D$66,2))) | D20: =IF($A20=0,"",IF(VLOOKUP($A20,成就条件映射!$A$4:$D$66,3)=0,"",VLOOKUP($A20,成就条件映射!$A$4:$D$66,3))) | E20: =IF($A20=0,"",IF(VLOOKUP($A20,成就条件映射!$A$4:$D$66,4)=0,"",VLOOKUP($A20,成就条件映射!$A$4:$D$66,4))) | I20: =A19*100+J20 -> 101102 | J20: =IF(MOD(ROW()+2,5)=0,MOD(ROW()+2,5)+5,MOD(ROW()+2,5)) -> 2 | M20: ="achievementAccumulative{achieveId:"&Q20&",count:"&R20&"}" -> achievementAccumulative{achieveId:1011,count:20000} | N20: 条件与 | O20: 1707522 | Q20: =IF(0=A20,Q19,A20) -> 1011 | R20: 20000 | W20: 1 | X20: 11
B21: =IF(A21=0,"",INT(A21/1000)) | C21: =IF($A21=0,"",IF(VLOOKUP($A21,成就条件映射!$A$4:$D$66,2)=0,"",VLOOKUP($A21,成就条件映射!$A$4:$D$66,2))) | D21: =IF($A21=0,"",IF(VLOOKUP($A21,成就条件映射!$A$4:$D$66,3)=0,"",VLOOKUP($A21,成就条件映射!$A$4:$D$66,3))) | E21: =IF($A21=0,"",IF(VLOOKUP($A21,成就条件映射!$A$4:$D$66,4)=0,"",VLOOKUP($A21,成就条件映射!$A$4:$D$66,4))) | I21: =A19*100+J21 -> 101103 | J21: =IF(MOD(ROW()+2,5)=0,MOD(ROW()+2,5)+5,MOD(ROW()+2,5)) -> 3 | M21: ="achievementAccumulative{achieveId:"&Q21&",count:"&R21&"}" -> achievementAccumulative{achieveId:1011,count:40000} | N21: 条件与 | O21: 1707523 | Q21: =IF(0=A21,Q20,A21) -> 1011 | R21: 40000 | W21: 1 | X21: 11
B22: =IF(A22=0,"",INT(A22/1000)) | C22: =IF($A22=0,"",IF(VLOOKUP($A22,成就条件映射!$A$4:$D$66,2)=0,"",VLOOKUP($A22,成就条件映射!$A$4:$D$66,2))) | D22: =IF($A22=0,"",IF(VLOOKUP($A22,成就条件映射!$A$4:$D$66,3)=0,"",VLOOKUP($A22,成就条件映射!$A$4:$D$66,3))) | E22: =IF($A22=0,"",IF(VLOOKUP($A22,成就条件映射!$A$4:$D$66,4)=0,"",VLOOKUP($A22,成就条件映射!$A$4:$D$66,4))) | I22: =A19*100+J22 -> 101104 | J22: =IF(MOD(ROW()+2,5)=0,MOD(ROW()+2,5)+5,MOD(ROW()+2,5)) -> 4 | M22: ="achievementAccumulative{achieveId:"&Q22&",count:"&R22&"}" -> achievementAccumulative{achieveId:1011,count:70000} | N22: 条件与 | O22: 1707524 | Q22: =IF(0=A22,Q21,A22) -> 1011 | R22: 70000 | W22: 1 | X22: 11
B23: =IF(A23=0,"",INT(A23/1000)) | C23: =IF($A23=0,"",IF(VLOOKUP($A23,成就条件映射!$A$4:$D$66,2)=0,"",VLOOKUP($A23,成就条件映射!$A$4:$D$66,2))) | D23: =IF($A23=0,"",IF(VLOOKUP($A23,成就条件映射!$A$4:$D$66,3)=0,"",VLOOKUP($A23,成就条件映射!$A$4:$D$66,3))) | E23: =IF($A23=0,"",IF(VLOOKUP($A23,成就条件映射!$A$4:$D$66,4)=0,"",VLOOKUP($A23,成就条件映射!$A$4:$D$66,4))) | I23: =A19*100+J23 -> 101105 | J23: =IF(MOD(ROW()+2,5)=0,MOD(ROW()+2,5)+5,MOD(ROW()+2,5)) -> 5 | M23: ="achievementAccumulative{achieveId:"&Q23&",count:"&R23&"}" -> achievementAccumulative{achieveId:1011,count:80000} | N23: 条件与 | O23: 1707525 | Q23: =IF(0=A23,Q22,A23) -> 1011 | R23: 80000 | W23: 1 | X23: 11
A24: =W24*1000+X24 -> 1012 | B24: =IF(A24=0,"",INT(A24/1000)) -> 1 | C24: TID_HeroAchievementConf_1012_name_CN_Main | D24: TID_HeroAchievementConf_1012_des_CN_Main | E24: TID_HeroAchievementConf_1012_des2_CN_Main | F24: 2 | G24: icon_n_challengemanual | H24: ="icon_silver_"&Y24 -> icon_silver_08 | I24: =A24*100+J24 -> 101201 | J24: =IF(MOD(ROW()+2,5)=0,MOD(ROW()+2,5)+5,MOD(ROW()+2,5)) -> 1 | M24: ="achievementAccumulative{achieveId:"&Q24&",count:"&R24&"}" -> achievementAccumulative{achieveId:1012,count:1500} | N24: 条件与 | O24: 1707521 | Q24: =IF(0=A24,Q23,A24) -> 1012 | R24: 1500 | W24: 1 | X24: 12 | Y24: 08 | Z24: =IF($A24=0,"",IF(VLOOKUP($A24,成就条件映射!$A$4:$D$66,2)=0,"",VLOOKUP($A24,成就条件映射!$A$4:$D$66,2))) -> 一剑西来 | AA24: =IF($A24=0,"",IF(VLOOKUP($A24,成就条件映射!$A$4:$D$66,3)=0,"",VLOOKUP($A24,成就条件映射!$A$4:$D$66,3))) -> 我方<color=#ffc766>剑士</color>部队使用<color=#ffc766>固有</color><color=#ffc766>主动技能</color>造成的<color=#ffc766>单次最大伤害量</color> | AB24: =IF($A24=0,"",IF(VLOOKUP($A24,成就条件映射!$A$4:$D$66,4)=0,"",VLOOKUP($A24,成就条件映射!$A$4:$D$66,4))) -> 当前造成伤害
B25: =IF(A25=0,"",INT(A25/1000)) | C25: =IF($A25=0,"",IF(VLOOKUP($A25,成就条件映射!$A$4:$D$66,2)=0,"",VLOOKUP($A25,成就条件映射!$A$4:$D$66,2))) | D25: =IF($A25=0,"",IF(VLOOKUP($A25,成就条件映射!$A$4:$D$66,3)=0,"",VLOOKUP($A25,成就条件映射!$A$4:$D$66,3))) | E25: =IF($A25=0,"",IF(VLOOKUP($A25,成就条件映射!$A$4:$D$66,4)=0,"",VLOOKUP($A25,成就条件映射!$A$4:$D$66,4))) | I25: =A24*100+J25 -> 101202 | J25: =IF(MOD(ROW()+2,5)=0,MOD(ROW()+2,5)+5,MOD(ROW()+2,5)) -> 2 | M25: ="achievementAccumulative{achieveId:"&Q25&",count:"&R25&"}" -> achievementAccumulative{achieveId:1012,count:2800} | N25: 条件与 | O25: 1707522 | Q25: =IF(0=A25,Q24,A25) -> 1012 | R25: 2800 | W25: 1 | X25: 12
B26: =IF(A26=0,"",INT(A26/1000)) | C26: =IF($A26=0,"",IF(VLOOKUP($A26,成就条件映射!$A$4:$D$66,2)=0,"",VLOOKUP($A26,成就条件映射!$A$4:$D$66,2))) | D26: =IF($A26=0,"",IF(VLOOKUP($A26,成就条件映射!$A$4:$D$66,3)=0,"",VLOOKUP($A26,成就条件映射!$A$4:$D$66,3))) | E26: =IF($A26=0,"",IF(VLOOKUP($A26,成就条件映射!$A$4:$D$66,4)=0,"",VLOOKUP($A26,成就条件映射!$A$4:$D$66,4))) | I26: =A24*100+J26 -> 101203 | J26: =IF(MOD(ROW()+2,5)=0,MOD(ROW()+2,5)+5,MOD(ROW()+2,5)) -> 3 | M26: ="achievementAccumulative{achieveId:"&Q26&",count:"&R26&"}" -> achievementAccumulative{achieveId:1012,count:3500} | N26: 条件与 | O26: 1707523 | Q26: =IF(0=A26,Q25,A26) -> 1012 | R26: 3500 | W26: 1 | X26: 12
B27: =IF(A27=0,"",INT(A27/1000)) | C27: =IF($A27=0,"",IF(VLOOKUP($A27,成就条件映射!$A$4:$D$66,2)=0,"",VLOOKUP($A27,成就条件映射!$A$4:$D$66,2))) | D27: =IF($A27=0,"",IF(VLOOKUP($A27,成就条件映射!$A$4:$D$66,3)=0,"",VLOOKUP($A27,成就条件映射!$A$4:$D$66,3))) | E27: =IF($A27=0,"",IF(VLOOKUP($A27,成就条件映射!$A$4:$D$66,4)=0,"",VLOOKUP($A27,成就条件映射!$A$4:$D$66,4))) | I27: =A24*100+J27 -> 101204 | J27: =IF(MOD(ROW()+2,5)=0,MOD(ROW()+2,5)+5,MOD(ROW()+2,5)) -> 4 | M27: ="achievementAccumulative{achieveId:"&Q27&",count:"&R27&"}" -> achievementAccumulative{achieveId:1012,count:4200} | N27: 条件与 | O27: 1707524 | Q27: =IF(0=A27,Q26,A27) -> 1012 | R27: 4200 | W27: 1 | X27: 12
B28: =IF(A28=0,"",INT(A28/1000)) | C28: =IF($A28=0,"",IF(VLOOKUP($A28,成就条件映射!$A$4:$D$66,2)=0,"",VLOOKUP($A28,成就条件映射!$A$4:$D$66,2))) | D28: =IF($A28=0,"",IF(VLOOKUP($A28,成就条件映射!$A$4:$D$66,3)=0,"",VLOOKUP($A28,成就条件映射!$A$4:$D$66,3))) | E28: =IF($A28=0,"",IF(VLOOKUP($A28,成就条件映射!$A$4:$D$66,4)=0,"",VLOOKUP($A28,成就条件映射!$A$4:$D$66,4))) | I28: =A24*100+J28 -> 101205 | J28: =IF(MOD(ROW()+2,5)=0,MOD(ROW()+2,5)+5,MOD(ROW()+2,5)) -> 5 | M28: ="achievementAccumulative{achieveId:"&Q28&",count:"&R28&"}" -> achievementAccumulative{achieveId:1012,count:5300} | N28: 条件与 | O28: 1707525 | Q28: =IF(0=A28,Q27,A28) -> 1012 | R28: 5300 | W28: 1 | X28: 12
A29: =W29*1000+X29 -> 1013 | C29: TID_HeroAchievementConf_1013_name_CN_Main | D29: TID_HeroAchievementConf_1013_des_CN_Main | E29: TID_HeroAchievementConf_1001_des2_CN_Main | F29: 2 | G29: icon_n_challengemanual | H29: ="icon_silver_"&Y29 -> icon_silver_09 | I29: =A29*100+J29 -> 101301 | J29: =IF(MOD(ROW()+2,5)=0,MOD(ROW()+2,5)+5,MOD(ROW()+2,5)) -> 1 | M29: ="achievementAccumulative{achieveId:"&Q29&",count:"&R29&"}" -> achievementAccumulative{achieveId:1013,count:1} | N29: 条件与 | O29: 1707521 | Q29: =IF(0=A29,Q28,A29) -> 1013 | R29: 1 | W29: 1 | X29: 13 | Y29: 09 | Z29: =IF($A29=0,"",IF(VLOOKUP($A29,成就条件映射!$A$4:$D$66,2)=0,"",VLOOKUP($A29,成就条件映射!$A$4:$D$66,2))) -> 北斗七星阵 | AA29: =IF($A29=0,"",IF(VLOOKUP($A29,成就条件映射!$A$4:$D$66,3)=0,"",VLOOKUP($A29,成就条件映射!$A$4:$D$66,3))) -> <color=#ffc766>集结战斗</color>中，我方<color=#ffc766>剑士</color>部队使用<color=#ffc766>固有</color><color=#ffc766>主动技能</color>累计造成的<color=#ffc766>伤害量</color> | AB29: =IF($A29=0,"",IF(VLOOKUP($A29,成就条件映射!$A$4:$D$66,4)=0,"",VLOOKUP($A29,成就条件映射!$A$4:$D$66,4))) -> 当前累计伤害
B30: =IF(A30=0,"",INT(A30/1000)) | C30: =IF($A30=0,"",IF(VLOOKUP($A30,成就条件映射!$A$4:$D$66,2)=0,"",VLOOKUP($A30,成就条件映射!$A$4:$D$66,2))) | D30: =IF($A30=0,"",IF(VLOOKUP($A30,成就条件映射!$A$4:$D$66,3)=0,"",VLOOKUP($A30,成就条件映射!$A$4:$D$66,3))) | E30: =IF($A30=0,"",IF(VLOOKUP($A30,成就条件映射!$A$4:$D$66,4)=0,"",VLOOKUP($A30,成就条件映射!$A$4:$D$66,4))) | I30: =A29*100+J30 -> 101302 | J30: =IF(MOD(ROW()+2,5)=0,MOD(ROW()+2,5)+5,MOD(ROW()+2,5)) -> 2 | M30: ="achievementAccumulative{achieveId:"&Q30&",count:"&R30&"}" -> achievementAccumulative{achieveId:1013,count:2} | N30: 条件与 | O30: 1707522 | Q30: =IF(0=A30,Q29,A30) -> 1013 | R30: 2 | W30: 1 | X30: 13
B31: =IF(A31=0,"",INT(A31/1000)) | C31: =IF($A31=0,"",IF(VLOOKUP($A31,成就条件映射!$A$4:$D$66,2)=0,"",VLOOKUP($A31,成就条件映射!$A$4:$D$66,2))) | D31: =IF($A31=0,"",IF(VLOOKUP($A31,成就条件映射!$A$4:$D$66,3)=0,"",VLOOKUP($A31,成就条件映射!$A$4:$D$66,3))) | E31: =IF($A31=0,"",IF(VLOOKUP($A31,成就条件映射!$A$4:$D$66,4)=0,"",VLOOKUP($A31,成就条件映射!$A$4:$D$66,4))) | I31: =A29*100+J31 -> 101303 | J31: =IF(MOD(ROW()+2,5)=0,MOD(ROW()+2,5)+5,MOD(ROW()+2,5)) -> 3 | M31: ="achievementAccumulative{achieveId:"&Q31&",count:"&R31&"}" -> achievementAccumulative{achieveId:1013,count:3} | N31: 条件与 | O31: 1707523 | Q31: =IF(0=A31,Q30,A31) -> 1013 | R31: 3 | W31: 1 | X31: 13
B32: =IF(A32=0,"",INT(A32/1000)) | C32: =IF($A32=0,"",IF(VLOOKUP($A32,成就条件映射!$A$4:$D$66,2)=0,"",VLOOKUP($A32,成就条件映射!$A$4:$D$66,2))) | D32: =IF($A32=0,"",IF(VLOOKUP($A32,成就条件映射!$A$4:$D$66,3)=0,"",VLOOKUP($A32,成就条件映射!$A$4:$D$66,3))) | E32: =IF($A32=0,"",IF(VLOOKUP($A32,成就条件映射!$A$4:$D$66,4)=0,"",VLOOKUP($A32,成就条件映射!$A$4:$D$66,4))) | I32: =A29*100+J32 -> 101304 | J32: =IF(MOD(ROW()+2,5)=0,MOD(ROW()+2,5)+5,MOD(ROW()+2,5)) -> 4 | M32: ="achievementAccumulative{achieveId:"&Q32&",count:"&R32&"}" -> achievementAccumulative{achieveId:1013,count:4} | N32: 条件与 | O32: 1707524 | Q32: =IF(0=A32,Q31,A32) -> 1013 | R32: 4 | W32: 1 | X32: 13
B33: =IF(A33=0,"",INT(A33/1000)) | C33: =IF($A33=0,"",IF(VLOOKUP($A33,成就条件映射!$A$4:$D$66,2)=0,"",VLOOKUP($A33,成就条件映射!$A$4:$D$66,2))) | D33: =IF($A33=0,"",IF(VLOOKUP($A33,成就条件映射!$A$4:$D$66,3)=0,"",VLOOKUP($A33,成就条件映射!$A$4:$D$66,3))) | E33: =IF($A33=0,"",IF(VLOOKUP($A33,成就条件映射!$A$4:$D$66,4)=0,"",VLOOKUP($A33,成就条件映射!$A$4:$D$66,4))) | I33: =A29*100+J33 -> 101305 | J33: =IF(MOD(ROW()+2,5)=0,MOD(ROW()+2,5)+5,MOD(ROW()+2,5)) -> 5 | M33: ="achievementAccumulative{achieveId:"&Q33&",count:"&R33&"}" -> achievementAccumulative{achieveId:1013,count:5} | N33: 条件与 | O33: 1707525 | Q33: =IF(0=A33,Q32,A33) -> 1013 | R33: 5 | W33: 1 | X33: 13
A34: =W34*1000+X34 -> 1021 | B34: =IF(A34=0,"",INT(A34/1000)) -> 1 | C34: TID_HeroAchievementConf_1021_name_CN_Main | D34: TID_HeroAchievementConf_1021_des_CN_Main | E34: TID_HeroAchievementConf_1021_des2_CN_Main | F34: 3 | G34: icon_n_challengemanual | H34: ="icon_kim_"&Y34 -> icon_kim_20 | I34: =A34*100+J34 -> 102101 | J34: =IF(MOD(ROW()+2,5)=0,MOD(ROW()+2,5)+5,MOD(ROW()+2,5)) -> 1 | M34: ="achievementAccumulative{achieveId:"&Q34&",count:"&R34&"}" -> achievementAccumulative{achieveId:1021,count:50} | N34: 条件与 | O34: 1707531 | Q34: =IF(0=A34,Q33,A34) -> 1021 | R34: 50 | W34: 1 | X34: 21 | Y34: 20 | Z34: =IF($A34=0,"",IF(VLOOKUP($A34,成就条件映射!$A$4:$D$66,2)=0,"",VLOOKUP($A34,成就条件映射!$A$4:$D$66,2))) -> 兵家至圣 | AA34: =IF($A34=0,"",IF(VLOOKUP($A34,成就条件映射!$A$4:$D$66,3)=0,"",VLOOKUP($A34,成就条件映射!$A$4:$D$66,3))) -> 我方部队进入<color=#ffc766>兵圣状态</color>的次数 | AB34: =IF($A34=0,"",IF(VLOOKUP($A34,成就条件映射!$A$4:$D$66,4)=0,"",VLOOKUP($A34,成就条件映射!$A$4:$D$66,4))) -> 当前累计次数
B35: =IF(A35=0,"",INT(A35/1000)) | C35: =IF($A35=0,"",IF(VLOOKUP($A35,成就条件映射!$A$4:$D$66,2)=0,"",VLOOKUP($A35,成就条件映射!$A$4:$D$66,2))) | D35: =IF($A35=0,"",IF(VLOOKUP($A35,成就条件映射!$A$4:$D$66,3)=0,"",VLOOKUP($A35,成就条件映射!$A$4:$D$66,3))) | E35: =IF($A35=0,"",IF(VLOOKUP($A35,成就条件映射!$A$4:$D$66,4)=0,"",VLOOKUP($A35,成就条件映射!$A$4:$D$66,4))) | I35: =A34*100+J35 -> 102102 | J35: =IF(MOD(ROW()+2,5)=0,MOD(ROW()+2,5)+5,MOD(ROW()+2,5)) -> 2 | M35: ="achievementAccumulative{achieveId:"&Q35&",count:"&R35&"}" -> achievementAccumulative{achieveId:1021,count:300} | N35: 条件与 | O35: 1707532 | Q35: =IF(0=A35,Q34,A35) -> 1021 | R35: 300 | W35: 1 | X35: 21
B36: =IF(A36=0,"",INT(A36/1000)) | C36: =IF($A36=0,"",IF(VLOOKUP($A36,成就条件映射!$A$4:$D$66,2)=0,"",VLOOKUP($A36,成就条件映射!$A$4:$D$66,2))) | D36: =IF($A36=0,"",IF(VLOOKUP($A36,成就条件映射!$A$4:$D$66,3)=0,"",VLOOKUP($A36,成就条件映射!$A$4:$D$66,3))) | E36: =IF($A36=0,"",IF(VLOOKUP($A36,成就条件映射!$A$4:$D$66,4)=0,"",VLOOKUP($A36,成就条件映射!$A$4:$D$66,4))) | I36: =A34*100+J36 -> 102103 | J36: =IF(MOD(ROW()+2,5)=0,MOD(ROW()+2,5)+5,MOD(ROW()+2,5)) -> 3 | M36: ="achievementAccumulative{achieveId:"&Q36&",count:"&R36&"}" -> achievementAccumulative{achieveId:1021,count:1000} | N36: 条件与 | O36: 1707533 | Q36: =IF(0=A36,Q35,A36) -> 1021 | R36: 1000 | W36: 1 | X36: 21
B37: =IF(A37=0,"",INT(A37/1000)) | C37: =IF($A37=0,"",IF(VLOOKUP($A37,成就条件映射!$A$4:$D$66,2)=0,"",VLOOKUP($A37,成就条件映射!$A$4:$D$66,2))) | D37: =IF($A37=0,"",IF(VLOOKUP($A37,成就条件映射!$A$4:$D$66,3)=0,"",VLOOKUP($A37,成就条件映射!$A$4:$D$66,3))) | E37: =IF($A37=0,"",IF(VLOOKUP($A37,成就条件映射!$A$4:$D$66,4)=0,"",VLOOKUP($A37,成就条件映射!$A$4:$D$66,4))) | I37: =A34*100+J37 -> 102104 | J37: =IF(MOD(ROW()+2,5)=0,MOD(ROW()+2,5)+5,MOD(ROW()+2,5)) -> 4 | M37: ="achievementAccumulative{achieveId:"&Q37&",count:"&R37&"}" -> achievementAccumulative{achieveId:1021,count:3000} | N37: 条件与 | O37: 1707534 | Q37: =IF(0=A37,Q36,A37) -> 1021 | R37: 3000 | W37: 1 | X37: 21
B38: =IF(A38=0,"",INT(A38/1000)) | C38: =IF($A38=0,"",IF(VLOOKUP($A38,成就条件映射!$A$4:$D$66,2)=0,"",VLOOKUP($A38,成就条件映射!$A$4:$D$66,2))) | D38: =IF($A38=0,"",IF(VLOOKUP($A38,成就条件映射!$A$4:$D$66,3)=0,"",VLOOKUP($A38,成就条件映射!$A$4:$D$66,3))) | E38: =IF($A38=0,"",IF(VLOOKUP($A38,成就条件映射!$A$4:$D$66,4)=0,"",VLOOKUP($A38,成就条件映射!$A$4:$D$66,4))) | I38: =A34*100+J38 -> 102105 | J38: =IF(MOD(ROW()+2,5)=0,MOD(ROW()+2,5)+5,MOD(ROW()+2,5)) -> 5 | M38: ="achievementAccumulative{achieveId:"&Q38&",count:"&R38&"}" -> achievementAccumulative{achieveId:1021,count:6000} | N38: 条件与 | O38: 1707535 | Q38: =IF(0=A38,Q37,A38) -> 1021 | R38: 6000 | W38: 1 | X38: 21
A39: =W39*1000+X39 -> 1022 | B39: =IF(A39=0,"",INT(A39/1000)) -> 1 | C39: TID_HeroAchievementConf_1022_name_CN_Main | D39: TID_HeroAchievementConf_1022_des_CN_Main | E39: TID_HeroAchievementConf_1021_des2_CN_Main | F39: 3 | G39: icon_n_challengemanual | H39: ="icon_kim_"&Y39 -> icon_kim_05 | I39: =A39*100+J39 -> 102201 | J39: =IF(MOD(ROW()+2,5)=0,MOD(ROW()+2,5)+5,MOD(ROW()+2,5)) -> 1 | M39: ="achievementAccumulative{achieveId:"&Q39&",count:"&R39&"}" -> achievementAccumulative{achieveId:1022,count:40} | N39: 条件与 | O39: 1707531 | Q39: =IF(0=A39,Q38,A39) -> 1022 | R39: 40 | W39: 1 | X39: 22 | Y39: 05 | Z39: =IF($A39=0,"",IF(VLOOKUP($A39,成就条件映射!$A$4:$D$66,2)=0,"",VLOOKUP($A39,成就条件映射!$A$4:$D$66,2))) -> 决胜须臾 | AA39: =IF($A39=0,"",IF(VLOOKUP($A39,成就条件映射!$A$4:$D$66,3)=0,"",VLOOKUP($A39,成就条件映射!$A$4:$D$66,3))) -> 我方<color=#ffc766>剑士</color>部队<color=#ffc766>准备技能</color>进入准备状态后，<color=#ffc766>直接发动效果</color>的总次数 | AB39: =IF($A39=0,"",IF(VLOOKUP($A39,成就条件映射!$A$4:$D$66,4)=0,"",VLOOKUP($A39,成就条件映射!$A$4:$D$66,4))) -> 当前累计次数
B40: =IF(A40=0,"",INT(A40/1000)) | C40: =IF($A40=0,"",IF(VLOOKUP($A40,成就条件映射!$A$4:$D$66,2)=0,"",VLOOKUP($A40,成就条件映射!$A$4:$D$66,2))) | D40: =IF($A40=0,"",IF(VLOOKUP($A40,成就条件映射!$A$4:$D$66,3)=0,"",VLOOKUP($A40,成就条件映射!$A$4:$D$66,3))) | E40: =IF($A40=0,"",IF(VLOOKUP($A40,成就条件映射!$A$4:$D$66,4)=0,"",VLOOKUP($A40,成就条件映射!$A$4:$D$66,4))) | I40: =A39*100+J40 -> 102202 | J40: =IF(MOD(ROW()+2,5)=0,MOD(ROW()+2,5)+5,MOD(ROW()+2,5)) -> 2 | M40: ="achievementAccumulative{achieveId:"&Q40&",count:"&R40&"}" -> achievementAccumulative{achieveId:1022,count:240} | N40: 条件与 | O40: 1707532 | Q40: =IF(0=A40,Q39,A40) -> 1022 | R40: 240 | W40: 1 | X40: 22
...

Sheet 成就条件映射
A1: convert(ResHero.proto, table_AchievementRealizeCondition, AchievementRealizeCondition.pbin)
A2: 成就目标Id | B2: 成就名称 | C2: 成就描述 | D2: 目标描述 | E2: 条件类别 | F2: 己方兵种 | G2: 战场环境 | H2: 技能类别 | I2: 技能类别关系 | J2: 技能id | K2: 计数类别 | M2: 额外参数 | N2: 时间参数
A3: achieveId | E3: conditionType | F3: soldierType | G3: envType[;] | H3: skillType[;] | I3: skillTypeRelation | J3: skillId[;] | K3: countType | M3: extraInfo | N3: timeDurationSec
A4: =O4*1000+P4+(Q4-1)*10 -> 1001 | B4: 攻克资源点 | C4: 在与<color=#ffc766>资源点守军</color>战斗中，我方<color=#ffc766>剑士</color>部队使用<color=#ffc766>固有</color><color=#ffc766>主动技能</color>累计造成的<color=#ffc766>伤害量</color> | D4: 当前累计伤害 | E4: 累计型 | F4: 剑士 | G4: 打田 | H4: 主动技;固有技能 | I4: TRUE | K4: 伤害量 | O4: =INT((ROW()-4)/9)+1 -> 1 | P4: 1 | Q4: 1
A5: =O5*1000+P5+(Q5-1)*10 -> 1002 | B5: 蛮族讨伐 | C5: 在与<color=#ffc766>野外蛮族</color>战斗中，我方<color=#ffc766>剑士</color>部队使用<color=#ffc766>固有</color><color=#ffc766>主动技能</color>累计造成的<color=#ffc766>伤害量</color> | D5: 当前累计伤害 | E5: 累计型 | F5: 剑士 | G5: 打野 | H5: 主动技;固有技能 | I5: TRUE | K5: 伤害量 | O5: =INT((ROW()-4)/9)+1 -> 1 | P5: 2 | Q5: 1
A6: =O6*1000+P6+(Q6-1)*10 -> 1003 | B6: 野战先锋 | C6: 野外与<color=#ffc766>玩家</color>部队战斗中，我方<color=#ffc766>剑士</color>部队使用<color=#ffc766>固有</color><color=#ffc766>主动技能</color>累计对敌方玩家造成的<color=#ffc766>伤害量</color> | D6: 当前累计伤害 | E6: 累计型 | F6: 剑士 | G6: PVP | H6: 主动技;固有技能 | I6: TRUE | K6: 伤害量 | O6: =INT((ROW()-4)/9)+1 -> 1 | P6: 3 | Q6: 1
A7: =O7*1000+P7+(Q7-1)*10 -> 1011 | B7: 临而不发 | C7: <color=#ffc766>60秒</color>内，我方部队使用<color=#ffc766>准备技能</color>累计造成的<color=#ffc766>最大伤害量</color> | D7: 当前累计伤害 | E7: 限时型 | G7: 全部 | H7: 准备技能 | K7: 伤害量 | N7: 60 | O7: =INT((ROW()-4)/9)+1 -> 1 | P7: 1 | Q7: 2
A8: =O8*1000+P8+(Q8-1)*10 -> 1012 | B8: 一剑西来 | C8: 我方<color=#ffc766>剑士</color>部队使用<color=#ffc766>固有</color><color=#ffc766>主动技能</color>造成的<color=#ffc766>单次最大伤害量</color> | D8: 当前造成伤害 | E8: 单次触发型 | F8: 剑士 | G8: 全部 | H8: 主动技;固有技能 | I8: TRUE | K8: 单次触发最大 | O8: =INT((ROW()-4)/9)+1 -> 1 | P8: 2 | Q8: 2
A9: =O9*1000+P9+(Q9-1)*10 -> 1013 | B9: 北斗七星阵 | C9: <color=#ffc766>集结战斗</color>中，我方<color=#ffc766>剑士</color>部队使用<color=#ffc766>固有</color><color=#ffc766>主动技能</color>累计造成的<color=#ffc766>伤害量</color> | D9: 当前累计伤害 | E9: 累计型 | F9: 剑士 | G9: 身处集结 | H9: 主动技;固有技能 | I9: TRUE | K9: 伤害量 | O9: =INT((ROW()-4)/9)+1 -> 1 | P9: 3 | Q9: 2
A10: =O10*1000+P10+(Q10-1)*10 -> 1021 | B10: 兵家至圣 | C10: 我方部队进入<color=#ffc766>兵圣状态</color>的次数 | D10: 当前累计次数 | E10: 累计型 | G10: 全部 | J10: 101400;101401;101402;101403;101404 | K10: 触发次数 | O10: =INT((ROW()-4)/9)+1 -> 1 | P10: 1 | Q10: 3
A11: =O11*1000+P11+(Q11-1)*10 -> 1022 | B11: 决胜须臾 | C11: 我方<color=#ffc766>剑士</color>部队<color=#ffc766>准备技能</color>进入准备状态后，<color=#ffc766>直接发动效果</color>的总次数 | D11: 当前累计次数 | E11: 累计型 | F11: 剑士 | G11: 全部 | H11: 准备技能 | K11: 直接触发次数 | O11: =INT((ROW()-4)/9)+1 -> 1 | P11: 2 | Q11: 3
A12: =O12*1000+P12+(Q12-1)*10 -> 1023 | O12: =INT((ROW()-4)/9)+1 -> 1 | P12: 3 | Q12: 3
A13: =O13*1000+P13+(Q13-1)*10 -> 2001 | B13: 攻克资源点 | C13: 在与<color=#ffc766>资源点守军</color>战斗中，我方部队累计对敌军施加<color=#ffc766>燃烧</color>或<color=#ffc766>决水</color>状态的次数 | D13: 当前累计次数 | E13: 累计型 | G13: 打田 | J13: 121201;121202;121203;121204;200001;200060;200073;102001;102002;102003;102004 | K13: 触发次数 | O13: =INT((ROW()-4)/9)+1 -> 2 | P13: 1 | Q13: 1
A14: =O14*1000+P14+(Q14-1)*10 -> 2002 | B14: 蛮族讨伐 | C14: 在与<color=#ffc766>野外蛮族</color>战斗中，我方部队累计对敌军施加<color=#ffc766>燃烧</color>或<color=#ffc766>决水</color>状态的次数 | D14: 当前累计次数 | E14: 累计型 | G14: 打野 | J14: 121201;121202;121203;121204;200001;200060;200073;102001;102002;102003;102004 | K14: 触发次数 | O14: =INT((ROW()-4)/9)+1 -> 2 | P14: 2 | Q14: 1
A15: =O15*1000+P15+(Q15-1)*10 -> 2003 | B15: 野战先锋 | C15: 野外与<color=#ffc766>玩家</color>部队战斗中，我方部队累计对敌军施加<color=#ffc766>燃烧</color>或<color=#ffc766>决水</color>状态的次数 | D15: 当前累计次数 | E15: 累计型 | G15: PVP | J15: 121201;121202;121203;121204;200001;200060;200073;102001;102002;102003;102004 | K15: 触发次数 | O15: =INT((ROW()-4)/9)+1 -> 2 | P15: 3 | Q15: 1
A16: =O16*1000+P16+(Q16-1)*10 -> 2011 | B16: 才思泉涌 | C16: <color=#ffc766>30秒</color>内，我方部队累计发动<color=#ffc766>固有</color><color=#ffc766>主动技能</color>的<color=#ffc766>最大次数</color> | D16: 当前累计次数 | E16: 限时型 | G16: 全部 | H16: 主动技;固有技能 | I16: TRUE | K16: 触发次数 | N16: 30 | O16: =INT((ROW()-4)/9)+1 -> 2 | P16: 1 | Q16: 2
A17: =O17*1000+P17+(Q17-1)*10 -> 2012 | B17: 神箭天降 | C17: 我方<color=#ffc766>弓兵</color>部队使用<color=#ffc766>固有</color><color=#ffc766>主动技能</color>造成的<color=#ffc766>单次最大伤害量</color> | D17: 当前造成伤害 | E17: 单次触发型 | F17: 弓兵 | G17: 全部 | H17: 主动技;固有技能 | I17: TRUE | K17: 单次触发最大 | O17: =INT((ROW()-4)/9)+1 -> 2 | P17: 2 | Q17: 2
A18: =O18*1000+P18+(Q18-1)*10 -> 2013 | B18: 万军射潮 | C18: <color=#ffc766>集结战斗</color>中，我方<color=#ffc766>弓兵</color>部队使用<color=#ffc766>固有</color><color=#ffc766>主动技能</color>累计造成的<color=#ffc766>伤害量</color> | D18: 当前累计伤害 | E18: 累计型 | F18: 弓兵 | G18: 身处集结 | H18: 主动技;固有技能 | I18: TRUE | K18: 伤害量 | O18: =INT((ROW()-4)/9)+1 -> 2 | P18: 3 | Q18: 2
A19: =O19*1000+P19+(Q19-1)*10 -> 2021 | B19: 万象奇门 | C19: <color=#ffc766>万象奇门</color>技能累计<color=#ffc766>治疗</color>的士兵数 | D19: 当前累计治疗 | E19: 累计型 | G19: 全部 | J19: 103301;103302;103303;103304 | K19: 治疗量 | O19: =INT((ROW()-4)/9)+1 -> 2 | P19: 1 | Q19: 3
A20: =O20*1000+P20+(Q20-1)*10 -> 2022 | B20: 神乎其技 | C20: 我方<color=#ffc766>弓兵</color>部队<color=#ffc766>准备技能</color>进入准备状态后，<color=#ffc766>直接发动效果</color>的总次数 | D20: 当前累计次数 | E20: 累计型 | F20: 弓兵 | G20: 全部 | H20: 准备技能 | K20: 直接触发次数 | O20: =INT((ROW()-4)/9)+1 -> 2 | P20: 2 | Q20: 3
A21: =O21*1000+P21+(Q21-1)*10 -> 2023 | O21: =INT((ROW()-4)/9)+1 -> 2 | P21: 3 | Q21: 3
A22: =O22*1000+P22+(Q22-1)*10 -> 3001 | B22: 攻克资源点 | C22: 在与<color=#ffc766>资源点守军</color>战斗中，我方部队使用<color=#ffc766>指挥技能</color>累计造成的<color=#ffc766>伤害量</color> | D22: 当前累计伤害 | E22: 累计型 | G22: 打田 | H22: 指挥技 | K22: 伤害量 | O22: =INT((ROW()-4)/9)+1 -> 3 | P22: 1 | Q22: 1
A23: =O23*1000+P23+(Q23-1)*10 -> 3002 | B23: 蛮族讨伐 | C23: 在与<color=#ffc766>野外蛮族</color>战斗中，我方部队使用<color=#ffc766>指挥技能</color>累计造成的<color=#ffc766>伤害量</color> | D23: 当前累计伤害 | E23: 累计型 | G23: 打野 | H23: 指挥技 | K23: 伤害量 | O23: =INT((ROW()-4)/9)+1 -> 3 | P23: 2 | Q23: 1
A24: =O24*1000+P24+(Q24-1)*10 -> 3003 | B24: 野战先锋 | C24: 野外与<color=#ffc766>玩家</color>部队战斗中，我方部队使用<color=#ffc766>指挥技能</color>累计对敌方玩家造成的<color=#ffc766>伤害量</color> | D24: 当前累计伤害 | E24: 累计型 | G24: PVP | H24: 指挥技 | K24: 伤害量 | O24: =INT((ROW()-4)/9)+1 -> 3 | P24: 3 | Q24: 1
A25: =O25*1000+P25+(Q25-1)*10 -> 3011 | B25: 驭兵之道 | C25: <color=#ffc766>30秒</color>内，我方部队累计发动<color=#ffc766>指挥技能</color>的<color=#ffc766>最大次数</color> | D25: 当前累计次数 | E25: 限时型 | G25: 全部 | H25: 指挥技 | K25: 触发次数 | N25: 30 | O25: =INT((ROW()-4)/9)+1 -> 3 | P25: 1 | Q25: 2
A26: =O26*1000+P26+(Q26-1)*10 -> 3012 | B26: 铁军威严 | C26: <color=#ffc766>集结战斗</color>中，我方部队使用<color=#ffc766>指挥技能</color>累计造成的<color=#ffc766>伤害量</color> | D26: 当前累计伤害 | E26: 累计型 | G26: 身处集结 | H26: 指挥技 | K26: 伤害量 | O26: =INT((ROW()-4)/9)+1 -> 3 | P26: 2 | Q26: 2
A27: =O27*1000+P27+(Q27-1)*10 -> 3013 | B27: 手足同心 | C27: <color=#ffc766>60秒</color>内，我方部队累计<color=#ffc766>治疗</color>的士兵数 | D27: 当前累计治疗 | E27: 限时型 | G27: 全部 | H27: 全部 | K27: 治疗量 | N27: 60 | O27: =INT((ROW()-4)/9)+1 -> 3 | P27: 3 | Q27: 2
A28: =O28*1000+P28+(Q28-1)*10 -> 3021 | B28: 荣耀之证 | C28: <color=#ffc766>30秒</color>内，我方部队使用<color=#ffc766>指挥技能</color>累计造成的<color=#ffc766>最大伤害量</color> | D28: 当前累计伤害 | E28: 限时型 | G28: 全部 | H28: 指挥技 | K28: 伤害量 | N28: 30 | O28: =INT((ROW()-4)/9)+1 -> 3 | P28: 1 | Q28: 3
A29: =O29*1000+P29+(Q29-1)*10 -> 3022 | B29: 将军！ | C29: 我方部队使用<color=#ffc766>指挥技能</color>造成的<color=#ffc766>单次最大伤害量</color> | D29: 当前造成伤害 | E29: 单次触发型 | G29: 全部 | H29: 指挥技 | K29: 单次触发最大 | O29: =INT((ROW()-4)/9)+1 -> 3 | P29: 2 | Q29: 3
A30: =O30*1000+P30+(Q30-1)*10 -> 3023 | O30: =INT((ROW()-4)/9)+1 -> 3 | P30: 3 | Q30: 3
A31: =O31*1000+P31+(Q31-1)*10 -> 4001 | B31: 攻克资源点 | C31: 在与<color=#ffc766>资源点守军</color>战斗中，我方部队使用<color=#ffc766>被动技能</color>累计造成的<color=#ffc766>伤害量</color> | D31: 当前累计伤害 | E31: 累计型 | G31: 打田 | H31: 被动技 | K31: 伤害量 | O31: =INT((ROW()-4)/9)+1 -> 4 | P31: 1 | Q31: 1
A32: =O32*1000+P32+(Q32-1)*10 -> 4002 | B32: 蛮族讨伐 | C32: 在与<color=#ffc766>野外蛮族</color>战斗中，我方部队使用<color=#ffc766>被动技能</color>累计造成的<color=#ffc766>伤害量</color> | D32: 当前累计伤害 | E32: 累计型 | G32: 打野 | H32: 被动技 | K32: 伤害量 | O32: =INT((ROW()-4)/9)+1 -> 4 | P32: 2 | Q32: 1
A33: =O33*1000+P33+(Q33-1)*10 -> 4003 | B33: 野战先锋 | C33: 野外与<color=#ffc766>玩家</color>部队战斗中，我方部队使用<color=#ffc766>被动技能</color>累计对敌方玩家造成的<color=#ffc766>伤害量</color> | D33: 当前累计伤害 | E33: 累计型 | G33: PVP | H33: 被动技 | K33: 伤害量 | O33: =INT((ROW()-4)/9)+1 -> 4 | P33: 3 | Q33: 1
A34: =O34*1000+P34+(Q34-1)*10 -> 4011 | B34: 以牙还牙 | C34: <color=#ffc766>30秒</color>内，我方部队累计发动<color=#ffc766>反击</color>攻击的<color=#ffc766>最大次数</color> | D34: 当前累计次数 | E34: 限时型 | G34: 全部 | J34: 101101;101102;101103;101104;102501;102502;102503;102504;102701;102703;102704;200037;200040;200100;200119 | K34: 触发次数 | N34: 30 | O34: =INT((ROW()-4)/9)+1 -> 4 | P34: 1 | Q34: 2
A35: =O35*1000+P35+(Q35-1)*10 -> 4012 | B35: 巴巴罗萨 | C35: <color=#ffc766>不败誓言</color>技能累计<color=#ffc766>治疗</color>的士兵数 | D35: 当前累计治疗 | E35: 累计型 | G35: 全部 | J35: 101701;101702;101703;101704 | K35: 治疗量 | O35: =INT((ROW()-4)/9)+1 -> 4 | P35: 2 | Q35: 2
A36: =O36*1000+P36+(Q36-1)*10 -> 4013 | O36: =INT((ROW()-4)/9)+1 -> 4 | P36: 3 | Q36: 2
A37: =O37*1000+P37+(Q37-1)*10 -> 4021 | B37: 谁在打我？ | C37: <color=#ffc766>30秒</color>内，我方部队使用<color=#ffc766>反击</color>类技能累计造成的<color=#ffc766>最大伤害量</color> | D37: 当前累计伤害 | E37: 限时型 | G37: 全部 | J37: 101101;101102;101103;101104;102501;102502;102503;102504;102701;102703;102704;200037;200040;200100;200119 | K37: 伤害量 | N37: 30 | O37: =INT((ROW()-4)/9)+1 -> 4 | P37: 1 | Q37: 3
A38: =O38*1000+P38+(Q38-1)*10 -> 4022 | B38: 绝处逢生 | C38: 我方部队使用<color=#ffc766>被动技能</color>造成的<color=#ffc766>单次最大伤害量</color> | D38: 当前战胜人数 | E38: 单次触发型 | G38: 全部 | H38: 被动技 | K38: 单次触发最大 | N38: -1 | O38: =INT((ROW()-4)/9)+1 -> 4 | P38: 2 | Q38: 3
A39: =O39*1000+P39+(Q39-1)*10 -> 4023 | O39: =INT((ROW()-4)/9)+1 -> 4 | P39: 3 | Q39: 3
A40: =O40*1000+P40+(Q40-1)*10 -> 5001 | B40: 攻克资源点 | C40: 在与<color=#ffc766>资源点守军</color>战斗中，我方部队使用<color=#ffc766>追击技能</color>累计造成的<color=#ffc766>武力</color><color=#ffc766>伤害量</color> | D40: 当前累计伤害 | E40: 累计型 | G40: 打田 | H40: 追击技 | K40: 武力伤害 | O40: =INT((ROW()-4)/9)+1 -> 5 | P40: 1 | Q40: 1
...

Sheet 成就关键字
A1: convert(ResHero.proto, table_AchievementKeyWordsConf, AchievementKeyWordsConf.pbin)
A2: id | B2: 特性名 | C2: 特性解释
A3: id | B3: name | C3: desc
A4: 1 | B4: TID_AchievementKeyWordsConf_1_name_CN_Main | C4: TID_AchievementKeyWordsConf_1_desc_CN_Main
A5: 2 | B5: TID_AchievementKeyWordsConf_2_name_CN_Main | C5: TID_AchievementKeyWordsConf_2_desc_CN_Main
A6: 3 | B6: TID_AchievementKeyWordsConf_3_name_CN_Main | C6: TID_AchievementKeyWordsConf_3_desc_CN_Main
A7: 4 | B7: TID_AchievementKeyWordsConf_4_name_CN_Main | C7: TID_AchievementKeyWordsConf_4_desc_CN_Main
A8: 5 | B8: TID_AchievementKeyWordsConf_5_name_CN_Main | C8: TID_AchievementKeyWordsConf_5_desc_CN_Main
A9: 6 | B9: TID_AchievementKeyWordsConf_6_name_CN_Main | C9: TID_AchievementKeyWordsConf_6_desc_CN_Main
A10: 7 | B10: TID_AchievementKeyWordsConf_7_name_CN_Main | C10: TID_AchievementKeyWordsConf_7_desc_CN_Main
A11: 8 | B11: TID_AchievementKeyWordsConf_8_name_CN_Main | C11: TID_AchievementKeyWordsConf_8_desc_CN_Main
A12: 9 | B12: TID_AchievementKeyWordsConf_9_name_CN_Main | C12: TID_AchievementKeyWordsConf_9_desc_CN_Main
A13: 10 | B13: TID_AchievementKeyWordsConf_10_name_CN_Main | C13: TID_AchievementKeyWordsConf_10_desc_CN_Main
A14: 11 | B14: TID_AchievementKeyWordsConf_11_name_CN_Main | C14: TID_AchievementKeyWordsConf_11_desc_CN_Main
A15: 12 | B15: TID_AchievementKeyWordsConf_12_name_CN_Main | C15: TID_AchievementKeyWordsConf_12_desc_CN_Main
... A19: 16 | B19: TID_AchievementKeyWordsConf_16_name_CN_Main | C19: TID_AchievementKeyWordsConf_16_desc_CN_Main

Sheet 技能场景配置
A1: convert(ResBattleCore.proto, table_CombatEnv4HeroAchievementConf, CombatEnv4HeroAchievementConf.pbin)
A2: 战场环境 | B2: 攻击方类型 | C2: 防御方类型 | D2: 战斗地图场景
A3: env | B3: combatEnvUnits.attackerType | C3: combatEnvUnits.defenderType | D3: combatEnvUnits.worldScene
A4: PVP | B4: 部队 | C4: 部队 | D4: 大地图
B5: 部队 | C5: 集结部队 | D5: 大地图
A6: 打野 | B6: 部队 | C6: 野怪 | D6: 大地图
B7: 部队 | C7: 挑衅野怪 | D7: 大地图
A8: 打田 | B8: 部队 | C8: 资源田野怪 | D8: 大地图
A9: 身处集结 | B9: 集结部队 | C9: 所有类型 | D9: 大地图
B10: 玩家主城 | C10: 所有类型 | D10: 大地图
B11: 皇城主城 | C11: 所有类型 | D11: 大地图
B12: 皇城中立建筑 | C12: 所有类型 | D12: 大地图
B13: 名城关卡 | C13: 所有类型 | D13: 大地图
B14: 名城码头 | C14: 所有类型 | D14: 大地图
B15: 名城箭塔 | C15: 所有类型 | D15: 大地图
B16: 名城城墙 | C16: 所有类型 | D16: 大地图
B17: 名城其他建筑 | C17: 所有类型 | D17: 大地图
B18: 名城内城粮仓 | C18: 所有类型 | D18: 大地图
B19: 名城城门 | C19: 所有类型 | D19: 大地图
B20: 名城主城 | C20: 所有类型 | D20: 大地图
B21: 城镇 | C21: 所有类型 | D21: 大地图

Sheet 杂项配置
A1: convertTrans(ResHero.proto, table_HeroAchievementMiscConf, HeroAchievementMiscConf.pbin)
A2: ID | B2: id | C2: 0
A3: 对应时代的解锁流派个数 | B3: ageUnlockCount[|] | C3: 0|1|2|3
A4: 成就阶段名称 | B4: stageName[|] | C4: TID_HeroAchievementMiscConf_0_stageName_CN_Main|TID_HeroAchievementMiscConf_0_stageName_1057848373033_CN_Main|TID_HeroAchievementMiscConf_0_stageName_682240917164_CN_Main|TID_HeroAchievementMiscConf_0_stageName_440872424509_CN_Main|TID_HeroAchievementMiscConf_0_stageName_156580853841_CN_Main

Sheet 阶段奖励领取限制
A1: convert(ResHero.proto, table_StageRewardLimitConf, StageRewardLimitConf.pbin)
A2: 阶段 | B2: 可领取次数
A3: stateLevel | B3: rewardCnt
A4: 1 | B4: 3
A5: 2 | B5: 3
A6: 3 | B6: 3
A7: 4 | B7: 3
A8: 5 | B8: 3

Sheet 英雄推荐配置
A1: convert(ResHero.proto, table_HeroFactionRecommend, HeroFactionRecommend.pbin)
A2: 推荐Id | B2: 阵容名称 | C2: 推荐标签（付费） | D2: 战斗风格 | E2: 兵种类型 | F2: 阵容说明 | G2: 英雄1id | H2: 英雄1技能1【备注】 | I2: 英雄1技能1 | J2: 英雄1技能2【备注】 | K2: 英雄1技能2 | L2: 英雄1坐骑id | M2: 英雄2id | N2: 英雄2技能1【备注】 | O2: 英雄2技能1 | P2: 英雄2技能2【备注】 | Q2: 英雄2技能2 | R2: 英雄2坐骑id | S2: 英雄3id | T2: 英雄3技能1【备注】 | U2: 英雄3技能1 | V2: 英雄3技能2【备注】 | W2: 英雄3技能2 | X2: 英雄3坐骑id | Y2: 阵容大标题 | Z2: 标签1背景 | AA2: 推荐标签（赛季） | AB2: 推荐英雄Id | AC2: 推荐英雄技能 | AD2: 推荐马 | AE2: 推荐英雄Id | AF2: 推荐英雄技能 | AG2: 推荐马 | AH2: 推荐英雄Id | AI2: 推荐英雄技能 | AJ2: 推荐马 | AK2: 推荐英雄技能1 | AL2: 推荐英雄技能1 | AM2: 推荐英雄技能1 | AN2: 推荐英雄技能2 | AO2: 推荐英雄技能2 | AP2: 推荐英雄技能2
A3: id | B3: name | C3: tags[1] | D3: battleStyle | E3: soldierType | F3: des | Y3: title | Z3: imgIdx | AA3: tags[2] | AB3: heros[1].heroId | AC3: heros[1].skillId[|] | AD3: heros[1].horseId | AE3: heros[2].heroId | AF3: heros[2].skillId[|] | AG3: heros[2].horseId | AH3: heros[3].heroId | AI3: heros[3].skillId[|] | AJ3: heros[3].horseId | AK3: heroSkill[1].skillId[|] | AL3: heroSkill[2].skillId[|] | AM3: heroSkill[3].skillId[|] | AN3: heroSkill[4].skillId[|] | AO3: heroSkill[5].skillId[|] | AP3: heroSkill[6].skillId[|] | AQ3: heroSkill[7].skillId[|] | AR3: heroSkill[8].skillId[|] | AS3: heroSkill[9].skillId[|] | AT3: heroSkill[10].skillId[|] | AU3: heroSkill[11].skillId[|] | AV3: heroSkill[12].skillId[|]
A4: 1001 | B4: TID_HeroFactionRecommend_1001_name_CN_Main | C4: TID_HeroFactionRecommend_1001_tags_CN_Main | D4: 智谋 | E4: 剑士 | F4: TID_HeroFactionRecommend_1001_des_CN_Main | G4: 14 | H4: 军神赠礼 | I4: 200016 | J4: 灵光乍现 | K4: 200063 | L4: 703002 | M4: 18 | N4: 避芒击惰 | O4: 200065 | P4: 毁灭的预示 | Q4: 200008 | R4: 703105 | S4: 16 | T4: 胜利的代价 | U4: 200064 | V4: 燎天之火 | W4: 200060 | X4: 703002 | Y4: =B4 -> TID_HeroFactionRecommend_1001_name_CN_Main | Z4: =IF(C4="大神",3,IF(C4="进阶",2,IF(C4="标准",1,0))) -> 0 | AA4: S1 | AB4: =G4 -> 14 | AC4: =I4&"|"&K4 -> 200016|200063 | AD4: =L4 -> 703002 | AE4: =M4 -> 18 | AF4: =O4&"|"&Q4 -> 200065|200008 | AG4: =R4 -> 703105 | AH4: =S4 -> 16 | AI4: =U4&"|"&W4 -> 200064|200060 | AJ4: =X4 -> 703002 | AK4: =IF($AX4=0,"",VLOOKUP(AX4,'#Sheet1'!$N$2:$O$192,2,0)&"|"&VLOOKUP(AY4,'#Sheet1'!$N$2:$O$192,2,0)) -> 200008|200015 | AL4: =IF($AX4=0,"",VLOOKUP(AZ4,'#Sheet1'!$N$2:$O$192,2,0)&"|"&VLOOKUP(BA4,'#Sheet1'!$N$2:$O$192,2,0)) -> 200060|200042 | AM4: =IF($AX4=0,"",VLOOKUP(BB4,'#Sheet1'!$N$2:$O$192,2,0)&"|"&VLOOKUP(BC4,'#Sheet1'!$N$2:$O$192,2,0)) -> 200021|200116 | AN4: =IF($BD4=0,"",VLOOKUP(BD4,'#Sheet1'!$N$2:$O$192,2,0)&"|"&VLOOKUP(BE4,'#Sheet1'!$N$2:$O$192,2,0)) | AO4: =IF($BD4=0,"",VLOOKUP(BF4,'#Sheet1'!$N$2:$O$192,2,0)&"|"&VLOOKUP(BG4,'#Sheet1'!$N$2:$O$192,2,0)) | AP4: =IF($BD4=0,"",VLOOKUP(BH4,'#Sheet1'!$N$2:$O$192,2,0)&"|"&VLOOKUP(BI4,'#Sheet1'!$N$2:$O$192,2,0)) | AX4: 毁灭的预示 | AY4: 战争祝福 | AZ4: 燎天之火 | BA4: 百战之体 | BB4: 丰收祝福 | BC4: 机变
A5: 1002 | B5: TID_HeroFactionRecommend_1002_name_CN_Main | C5: TID_HeroFactionRecommend_1002_tags_CN_Main | D5: 智谋 | E5: 剑士 | F5: TID_HeroFactionRecommend_1002_des_CN_Main | G5: 14 | H5: 军神赠礼 | I5: 200016 | J5: 灵光乍现 | K5: 200063 | L5: 703002 | M5: 4 | N5: 连击 | O5: 200020 | P5: 压迫之袭 | Q5: 200074 | R5: 701005 | S5: 16 | T5: 毁灭的预示 | U5: 200008 | V5: 避芒击惰 | W5: 200065 | X5: 703002 | Y5: =B5 -> TID_HeroFactionRecommend_1002_name_CN_Main | Z5: =IF(C5="大神",3,IF(C5="进阶",2,IF(C5="标准",1,0))) -> 0 | AA5: S1 | AB5: =G5 -> 14 | AC5: =I5&"|"&K5 -> 200016|200063 | AD5: =L5 -> 703002 | AE5: =M5 -> 4 | AF5: =O5&"|"&Q5 -> 200020|200074 | AG5: =R5 -> 701005 | AH5: =S5 -> 16 | AI5: =U5&"|"&W5 -> 200008|200065 | AJ5: =X5 -> 703002 | AK5: =IF($AX5=0,"",VLOOKUP(AX5,'#Sheet1'!$N$2:$O$192,2,0)&"|"&VLOOKUP(AY5,'#Sheet1'!$N$2:$O$192,2,0)) -> 200008|200015 | AL5: =IF($AX5=0,"",VLOOKUP(AZ5,'#Sheet1'!$N$2:$O$192,2,0)&"|"&VLOOKUP(BA5,'#Sheet1'!$N$2:$O$192,2,0)) -> 200020|200115 | AM5: =IF($AX5=0,"",VLOOKUP(BB5,'#Sheet1'!$N$2:$O$192,2,0)&"|"&VLOOKUP(BC5,'#Sheet1'!$N$2:$O$192,2,0)) -> 200116|200060 | AN5: =IF($BD5=0,"",VLOOKUP(BD5,'#Sheet1'!$N$2:$O$192,2,0)&"|"&VLOOKUP(BE5,'#Sheet1'!$N$2:$O$192,2,0)) | AO5: =IF($BD5=0,"",VLOOKUP(BF5,'#Sheet1'!$N$2:$O$192,2,0)&"|"&VLOOKUP(BG5,'#Sheet1'!$N$2:$O$192,2,0)) | AP5: =IF($BD5=0,"",VLOOKUP(BH5,'#Sheet1'!$N$2:$O$192,2,0)&"|"&VLOOKUP(BI5,'#Sheet1'!$N$2:$O$192,2,0)) | AX5: 毁灭的预示 | AY5: 战争祝福 | AZ5: 连击 | BA5: 反间 | BB5: 机变 | BC5: 燎天之火
A6: 1003 | B6: TID_HeroFactionRecommend_1003_name_CN_Main | C6: TID_HeroFactionRecommend_1003_tags_CN_Main | D6: 智谋 | E6: 剑士 | F6: TID_HeroFactionRecommend_1003_des_CN_Main | G6: 16 | H6: 燎天之火 | I6: 200060 | J6: 以战养战 | K6: 200047 | L6: 703002 | M6: 4 | N6: 连击 | O6: 200020 | P6: 压迫之袭 | Q6: 200074 | R6: 701005 | S6: 205 | T6: 冲冠一怒 | U6: 200070 | V6: 光明护佑 | W6: 200011 | X6: 703002 | Y6: =B6 -> TID_HeroFactionRecommend_1003_name_CN_Main | Z6: =IF(C6="大神",3,IF(C6="进阶",2,IF(C6="标准",1,0))) -> 0 | AA6: S1 | AB6: =G6 -> 16 | AC6: =I6&"|"&K6 -> 200060|200047 | AD6: =L6 -> 703002 | AE6: =M6 -> 4 | AF6: =O6&"|"&Q6 -> 200020|200074 | AG6: =R6 -> 701005 | AH6: =S6 -> 205 | AI6: =U6&"|"&W6 -> 200070|200011 | AJ6: =X6 -> 703002 | AK6: =IF($AX6=0,"",VLOOKUP(AX6,'#Sheet1'!$N$2:$O$192,2,0)&"|"&VLOOKUP(AY6,'#Sheet1'!$N$2:$O$192,2,0)) -> 200116|200001 | AL6: =IF($AX6=0,"",VLOOKUP(AZ6,'#Sheet1'!$N$2:$O$192,2,0)&"|"&VLOOKUP(BA6,'#Sheet1'!$N$2:$O$192,2,0)) -> 200020|200115 | AM6: =IF($AX6=0,"",VLOOKUP(BB6,'#Sheet1'!$N$2:$O$192,2,0)&"|"&VLOOKUP(BC6,'#Sheet1'!$N$2:$O$192,2,0)) -> 200070|200021 | AN6: =IF($BD6=0,"",VLOOKUP(BD6,'#Sheet1'!$N$2:$O$192,2,0)&"|"&VLOOKUP(BE6,'#Sheet1'!$N$2:$O$192,2,0)) | AO6: =IF($BD6=0,"",VLOOKUP(BF6,'#Sheet1'!$N$2:$O$192,2,0)&"|"&VLOOKUP(BG6,'#Sheet1'!$N$2:$O$192,2,0)) | AP6: =IF($BD6=0,"",VLOOKUP(BH6,'#Sheet1'!$N$2:$O$192,2,0)&"|"&VLOOKUP(BI6,'#Sheet1'!$N$2:$O$192,2,0)) | AX6: 机变 | AY6: 火球轰击 | AZ6: 连击 | BA6: 反间 | BB6: 冲冠一怒 | BC6: 丰收祝福
A7: 2001 | B7: TID_HeroFactionRecommend_2001_name_CN_Main | C7: TID_HeroFactionRecommend_1001_tags_CN_Main | D7: 智谋 | E7: 弓兵 | F7: TID_HeroFactionRecommend_2001_des_CN_Main | G7: 33 | H7: 军神赠礼 | I7: 200016 | J7: 灵光乍现 | K7: 200063 | L7: 704002 | M7: 18 | N7: 避芒击惰 | O7: 200065 | P7: 胜利的代价 | Q7: 200064 | R7: 704105 | S7: 24 | T7: 以战养战 | U7: 200047 | V7: 侵蚀之焰 | W7: 200073 | X7: 704103 | Y7: =B7 -> TID_HeroFactionRecommend_2001_name_CN_Main | Z7: =IF(C7="大神",3,IF(C7="进阶",2,IF(C7="标准",1,0))) -> 0 | AA7: S1 | AB7: =G7 -> 33 | AC7: =I7&"|"&K7 -> 200016|200063 | AD7: =L7 -> 704002 | AE7: =M7 -> 18 | AF7: =O7&"|"&Q7 -> 200065|200064 | AG7: =R7 -> 704105 | AH7: =S7 -> 24 | AI7: =U7&"|"&W7 -> 200047|200073 | AJ7: =X7 -> 704103 | AK7: =IF($AX7=0,"",VLOOKUP(AX7,'#Sheet1'!$N$2:$O$192,2,0)&"|"&VLOOKUP(AY7,'#Sheet1'!$N$2:$O$192,2,0)) -> 200015|200063 | AL7: =IF($AX7=0,"",VLOOKUP(AZ7,'#Sheet1'!$N$2:$O$192,2,0)&"|"&VLOOKUP(BA7,'#Sheet1'!$N$2:$O$192,2,0)) -> 200060|200042 | AM7: =IF($AX7=0,"",VLOOKUP(BB7,'#Sheet1'!$N$2:$O$192,2,0)&"|"&VLOOKUP(BC7,'#Sheet1'!$N$2:$O$192,2,0)) -> 200021|200116 | AN7: =IF($BD7=0,"",VLOOKUP(BD7,'#Sheet1'!$N$2:$O$192,2,0)&"|"&VLOOKUP(BE7,'#Sheet1'!$N$2:$O$192,2,0)) | AO7: =IF($BD7=0,"",VLOOKUP(BF7,'#Sheet1'!$N$2:$O$192,2,0)&"|"&VLOOKUP(BG7,'#Sheet1'!$N$2:$O$192,2,0)) | AP7: =IF($BD7=0,"",VLOOKUP(BH7,'#Sheet1'!$N$2:$O$192,2,0)&"|"&VLOOKUP(BI7,'#Sheet1'!$N$2:$O$192,2,0)) | AX7: 战争祝福 | AY7: 灵光乍现 | AZ7: 燎天之火 | BA7: 百战之体 | BB7: 丰收祝福 | BC7: 机变
A8: 2002 | B8: TID_HeroFactionRecommend_2002_name_CN_Main | C8: TID_HeroFactionRecommend_1002_tags_CN_Main | D8: 智谋 | E8: 弓兵 | F8: TID_HeroFactionRecommend_2002_des_CN_Main | G8: 33 | H8: 军神赠礼 | I8: 200016 | J8: 灵光乍现 | K8: 200063 | L8: 704002 | M8: 20 | N8: 以战养战 | O8: 200047 | P8: 火球冲击 | Q8: 200001 | R8: 704105 | S8: 24 | T8: 毁灭的预示 | U8: 200008 | V8: 燎天之火 | W8: 200060 | X8: 704103 | Y8: =B8 -> TID_HeroFactionRecommend_2002_name_CN_Main | Z8: =IF(C8="大神",3,IF(C8="进阶",2,IF(C8="标准",1,0))) -> 0 | AA8: S1 | AB8: =G8 -> 33 | AC8: =I8&"|"&K8 -> 200016|200063 | AD8: =L8 -> 704002 | AE8: =M8 -> 20 | AF8: =O8&"|"&Q8 -> 200047|200001 | AG8: =R8 -> 704105 | AH8: =S8 -> 24 | AI8: =U8&"|"&W8 -> 200008|200060 | AJ8: =X8 -> 704103 | AK8: =IF($AX8=0,"",VLOOKUP(AX8,'#Sheet1'!$N$2:$O$192,2,0)&"|"&VLOOKUP(AY8,'#Sheet1'!$N$2:$O$192,2,0)) -> 200116|200047 | AL8: =IF($AX8=0,"",VLOOKUP(AZ8,'#Sheet1'!$N$2:$O$192,2,0)&"|"&VLOOKUP(BA8,'#Sheet1'!$N$2:$O$192,2,0)) -> 200011|200021 | AM8: =IF($AX8=0,"",VLOOKUP(BB8,'#Sheet1'!$N$2:$O$192,2,0)&"|"&VLOOKUP(BC8,'#Sheet1'!$N$2:$O$192,2,0)) -> 200015|200060 | AN8: =IF($BD8=0,"",VLOOKUP(BD8,'#Sheet1'!$N$2:$O$192,2,0)&"|"&VLOOKUP(BE8,'#Sheet1'!$N$2:$O$192,2,0)) | AO8: =IF($BD8=0,"",VLOOKUP(BF8,'#Sheet1'!$N$2:$O$192,2,0)&"|"&VLOOKUP(BG8,'#Sheet1'!$N$2:$O$192,2,0)) | AP8: =IF($BD8=0,"",VLOOKUP(BH8,'#Sheet1'!$N$2:$O$192,2,0)&"|"&VLOOKUP(BI8,'#Sheet1'!$N$2:$O$192,2,0)) | AX8: 机变 | AY8: 以战养战 | AZ8: 光明护佑 | BA8: 丰收祝福 | BB8: 战争祝福 | BC8: 燎天之火
A9: 2003 | B9: TID_HeroFactionRecommend_2003_name_CN_Main | C9: TID_HeroFactionRecommend_1003_tags_CN_Main | D9: 智谋 | E9: 弓兵 | F9: TID_HeroFactionRecommend_2003_des_CN_Main | G9: 20 | H9: 燎天之火 | I9: 200060 | J9: 以战养战 | K9: 200047 | L9: 704002 | M9: 4 | N9: 连击 | O9: 200020 | P9: 命运操弄 | Q9: 200014 | R9: 704105 | S9: 212 | T9: 冲冠一怒 | U9: 200070 | V9: 光明护佑 | W9: 200011 | X9: 700201 | Y9: =B9 -> TID_HeroFactionRecommend_2003_name_CN_Main | Z9: =IF(C9="大神",3,IF(C9="进阶",2,IF(C9="标准",1,0))) -> 0 | AA9: S1 | AB9: =G9 -> 20 | AC9: =I9&"|"&K9 -> 200060|200047 | AD9: =L9 -> 704002 | AE9: =M9 -> 4 | AF9: =O9&"|"&Q9 -> 200020|200014 | AG9: =R9 -> 704105 | AH9: =S9 -> 212 | AI9: =U9&"|"&W9 -> 200070|200011 | AJ9: =X9 -> 700201 | AK9: =IF($AX9=0,"",VLOOKUP(AX9,'#Sheet1'!$N$2:$O$192,2,0)&"|"&VLOOKUP(AY9,'#Sheet1'!$N$2:$O$192,2,0)) -> 200015|200001 | AL9: =IF($AX9=0,"",VLOOKUP(AZ9,'#Sheet1'!$N$2:$O$192,2,0)&"|"&VLOOKUP(BA9,'#Sheet1'!$N$2:$O$192,2,0)) -> 200020|200115 | AM9: =IF($AX9=0,"",VLOOKUP(BB9,'#Sheet1'!$N$2:$O$192,2,0)&"|"&VLOOKUP(BC9,'#Sheet1'!$N$2:$O$192,2,0)) -> 200025|200021 | AN9: =IF($BD9=0,"",VLOOKUP(BD9,'#Sheet1'!$N$2:$O$192,2,0)&"|"&VLOOKUP(BE9,'#Sheet1'!$N$2:$O$192,2,0)) | AO9: =IF($BD9=0,"",VLOOKUP(BF9,'#Sheet1'!$N$2:$O$192,2,0)&"|"&VLOOKUP(BG9,'#Sheet1'!$N$2:$O$192,2,0)) | AP9: =IF($BD9=0,"",VLOOKUP(BH9,'#Sheet1'!$N$2:$O$192,2,0)&"|"&VLOOKUP(BI9,'#Sheet1'!$N$2:$O$192,2,0)) | AX9: 战争祝福 | AY9: 火球轰击 | AZ9: 连击 | BA9: 反间 | BB9: 钢铁之躯 | BC9: 丰收祝福
A10: 3001 | B10: TID_HeroFactionRecommend_3001_name_CN_Main | C10: TID_HeroFactionRecommend_3001_tags_CN_Main | D10: 统率 | E10: 枪兵 | F10: TID_HeroFactionRecommend_3001_des_CN_Main | G10: 13 | H10: 蛮勇侵袭 | I10: 200080 | J10: 怒火猛攻 | K10: 200005 | L10: 702003 | M10: 34 | N10: 王者之剑 | O10: 200068 | P10: 沉默誓言 | Q10: 200012 | R10: 702003 | S10: 22 | T10: 三重攻势 | U10: 200013 | V10: 恩泽庇护 | W10: 200010 | X10: 702104 | Y10: =B10 -> TID_HeroFactionRecommend_3001_name_CN_Main | Z10: =IF(C10="大神",3,IF(C10="进阶",2,IF(C10="标准",1,0))) -> 0 | AA10: S1 | AB10: =G10 -> 13 | AC10: =I10&"|"&K10 -> 200080|200005 | AD10: =L10 -> 702003 | AE10: =M10 -> 34 | AF10: =O10&"|"&Q10 -> 200068|200012 | AG10: =R10 -> 702003 | AH10: =S10 -> 22 | AI10: =U10&"|"&W10 -> 200013|200010 | AJ10: =X10 -> 702104 | AK10: =IF($AX10=0,"",VLOOKUP(AX10,'#Sheet1'!$N$2:$O$192,2,0)&"|"&VLOOKUP(AY10,'#Sheet1'!$N$2:$O$192,2,0)) -> 200061|200037 | AL10: =IF($AX10=0,"",VLOOKUP(AZ10,'#Sheet1'!$N$2:$O$192,2,0)&"|"&VLOOKUP(BA10,'#Sheet1'!$N$2:$O$192,2,0)) -> 200069|200122 | AM10: =IF($AX10=0,"",VLOOKUP(BB10,'#Sheet1'!$N$2:$O$192,2,0)&"|"&VLOOKUP(BC10,'#Sheet1'!$N$2:$O$192,2,0)) -> 200042|200121 | AN10: =IF($BD10=0,"",VLOOKUP(BD10,'#Sheet1'!$N$2:$O$192,2,0)&"|"&VLOOKUP(BE10,'#Sheet1'!$N$2:$O$192,2,0)) | AO10: =IF($BD10=0,"",VLOOKUP(BF10,'#Sheet1'!$N$2:$O$192,2,0)&"|"&VLOOKUP(BG10,'#Sheet1'!$N$2:$O$192,2,0)) | AP10: =IF($BD10=0,"",VLOOKUP(BH10,'#Sheet1'!$N$2:$O$192,2,0)&"|"&VLOOKUP(BI10,'#Sheet1'!$N$2:$O$192,2,0)) | AX10: 泰山压顶 | AY10: 反戈一击 | AZ10: 列阵御敌 | BA10: 变阵 | BB10: 百战之体 | BC10: 掌军
