Workbook

Sheet 战力推荐参数
A1: convert(ResLord.proto, table_RecomPowerDevelopConf, RecomPowerDevelopConf.pbin)
A2: 主堡等级 | B2: 战斗力 | C2: 解锁的士兵等级 | D2: 档位 | E2: 选取分位 | F2: 上阵英雄平均等级 | G2: 部队最大带兵数量 | H2: 已研究科技数量 | I2: 已解锁建筑平均等级 | J2: 上阵英雄平均技能等级 | K2: 已穿戴装备数量 | L2: 已解锁部队数量
A3: level | B3: powerValue | C3: soldierLv | D3: confLevel | F3: heroLevel | G3: marchPopulation | H3: techCnt | I3: buildingAvgLv | J3: skillavgLv | K3: equitmentNum | L3: marchQueueCnt
A4: 1 | B4: =IF($A4="","",ROUND(_xlfn.XLOOKUP($A4,'#现网数据参考'!$A:$A,'#现网数据参考'!G:G)*IF($A4<=9,0.5,1),0)) -> 6069 | C4: =IF($A4="","",ROUND(_xlfn.XLOOKUP($A4,'#现网数据参考'!$A:$A,'#现网数据参考'!P:P),0)) -> 1 | D4: 1 | E4: 20 | F4: =ROUND(OFFSET('#现网数据参考'!$A$1,MATCH(OFFSET($A4,-MOD(ROW()-1,3),0),'#现网数据参考'!$A:$A,0)-1,MATCH(F$2&$E4,'#现网数据参考'!$3:$3,0)-1)*IF(OFFSET($A4,-MOD(ROW()-1,3),0)<=9,0.6,1),0) -> 1 | G4: =_xlfn.XLOOKUP(OFFSET($A4,-MOD(ROW()-1,3),0),'#出征索引'!A:A,'#出征索引'!B:B)+_xlfn.XLOOKUP(OFFSET($A4,-MOD(ROW()-1,3),0),'#出征索引'!A:A,'#出征索引'!C:C)*_xlfn.XLOOKUP(F4,'#出征索引'!E:E,'#出征索引'!F:F) -> 500 | H4: =ROUND(OFFSET('#现网数据参考'!$A$1,MATCH(OFFSET($A4,-MOD(ROW()-1,3),0),'#现网数据参考'!$A:$A,0)-1,MATCH(H$2&$E4,'#现网数据参考'!$3:$3,0)-1)*IF(OFFSET($A4,-MOD(ROW()-1,3),0)<=9,0.6,1),0) -> 1 | I4: =ROUND(OFFSET('#现网数据参考'!$A$1,MATCH(OFFSET($A4,-MOD(ROW()-1,3),0),'#现网数据参考'!$A:$A,0)-1,MATCH(I$2&$E4,'#现网数据参考'!$3:$3,0)-1)*IF(OFFSET($A4,-MOD(ROW()-1,3),0)<=9,0.6,1),0) -> 1 | J4: =ROUND(OFFSET('#现网数据参考'!$A$1,MATCH(OFFSET($A4,-MOD(ROW()-1,3),0),'#现网数据参考'!$A:$A,0)-1,MATCH(J$2&$E4,'#现网数据参考'!$3:$3,0)-1)*IF(OFFSET($A4,-MOD(ROW()-1,3),0)<=9,0.6,1),0) -> 1 | K4: =ROUND(OFFSET('#现网数据参考'!$A$1,MATCH(OFFSET($A4,-MOD(ROW()-1,3),0),'#现网数据参考'!$A:$A,0)-1,MATCH(K$2&$E4,'#现网数据参考'!$3:$3,0)-1)*IF(OFFSET($A4,-MOD(ROW()-1,3),0)<=9,0.6,1),0) -> 0 | L4: =ROUND(OFFSET('#现网数据参考'!$A$1,MATCH(OFFSET($A4,-MOD(ROW()-1,3),0),'#现网数据参考'!$A:$A,0)-1,MATCH(L$2&$E4,'#现网数据参考'!$3:$3,0)-1),0) -> 3
B5: =IF($A5="","",ROUND(_xlfn.XLOOKUP($A5,'#现网数据参考'!$A:$A,'#现网数据参考'!G:G)*IF($A5<=9,0.5,1),0)) | C5: =IF($A5="","",ROUND(_xlfn.XLOOKUP($A5,'#现网数据参考'!$A:$A,'#现网数据参考'!P:P),0)) | D5: 2 | E5: 40 | F5: =ROUND(OFFSET('#现网数据参考'!$A$1,MATCH(OFFSET($A5,-MOD(ROW()-1,3),0),'#现网数据参考'!$A:$A,0)-1,MATCH(F$2&$E5,'#现网数据参考'!$3:$3,0)-1)*IF(OFFSET($A5,-MOD(ROW()-1,3),0)<=9,0.6,1),0) -> 1 | G5: =_xlfn.XLOOKUP(OFFSET($A5,-MOD(ROW()-1,3),0),'#出征索引'!A:A,'#出征索引'!B:B)+_xlfn.XLOOKUP(OFFSET($A5,-MOD(ROW()-1,3),0),'#出征索引'!A:A,'#出征索引'!C:C)*_xlfn.XLOOKUP(F5,'#出征索引'!E:E,'#出征索引'!F:F) -> 500 | H5: =ROUND(OFFSET('#现网数据参考'!$A$1,MATCH(OFFSET($A5,-MOD(ROW()-1,3),0),'#现网数据参考'!$A:$A,0)-1,MATCH(H$2&$E5,'#现网数据参考'!$3:$3,0)-1)*IF(OFFSET($A5,-MOD(ROW()-1,3),0)<=9,0.6,1),0) -> 1 | I5: =ROUND(OFFSET('#现网数据参考'!$A$1,MATCH(OFFSET($A5,-MOD(ROW()-1,3),0),'#现网数据参考'!$A:$A,0)-1,MATCH(I$2&$E5,'#现网数据参考'!$3:$3,0)-1)*IF(OFFSET($A5,-MOD(ROW()-1,3),0)<=9,0.6,1),0) -> 1 | J5: =ROUND(OFFSET('#现网数据参考'!$A$1,MATCH(OFFSET($A5,-MOD(ROW()-1,3),0),'#现网数据参考'!$A:$A,0)-1,MATCH(J$2&$E5,'#现网数据参考'!$3:$3,0)-1)*IF(OFFSET($A5,-MOD(ROW()-1,3),0)<=9,0.6,1),0) -> 2 | K5: =ROUND(OFFSET('#现网数据参考'!$A$1,MATCH(OFFSET($A5,-MOD(ROW()-1,3),0),'#现网数据参考'!$A:$A,0)-1,MATCH(K$2&$E5,'#现网数据参考'!$3:$3,0)-1)*IF(OFFSET($A5,-MOD(ROW()-1,3),0)<=9,0.6,1),0) -> 0 | L5: =ROUND(OFFSET('#现网数据参考'!$A$1,MATCH(OFFSET($A5,-MOD(ROW()-1,3),0),'#现网数据参考'!$A:$A,0)-1,MATCH(L$2&$E5,'#现网数据参考'!$3:$3,0)-1),0) -> 3
B6: =IF($A6="","",ROUND(_xlfn.XLOOKUP($A6,'#现网数据参考'!$A:$A,'#现网数据参考'!G:G)*IF($A6<=9,0.5,1),0)) | C6: =IF($A6="","",ROUND(_xlfn.XLOOKUP($A6,'#现网数据参考'!$A:$A,'#现网数据参考'!P:P),0)) | D6: 3 | E6: 60 | F6: =ROUND(OFFSET('#现网数据参考'!$A$1,MATCH(OFFSET($A6,-MOD(ROW()-1,3),0),'#现网数据参考'!$A:$A,0)-1,MATCH(F$2&$E6,'#现网数据参考'!$3:$3,0)-1)*IF(OFFSET($A6,-MOD(ROW()-1,3),0)<=9,0.6,1),0) -> 1 | G6: =_xlfn.XLOOKUP(OFFSET($A6,-MOD(ROW()-1,3),0),'#出征索引'!A:A,'#出征索引'!B:B)+_xlfn.XLOOKUP(OFFSET($A6,-MOD(ROW()-1,3),0),'#出征索引'!A:A,'#出征索引'!C:C)*_xlfn.XLOOKUP(F6,'#出征索引'!E:E,'#出征索引'!F:F) -> 500 | H6: =ROUND(OFFSET('#现网数据参考'!$A$1,MATCH(OFFSET($A6,-MOD(ROW()-1,3),0),'#现网数据参考'!$A:$A,0)-1,MATCH(H$2&$E6,'#现网数据参考'!$3:$3,0)-1)*IF(OFFSET($A6,-MOD(ROW()-1,3),0)<=9,0.6,1),0) -> 2 | I6: =ROUND(OFFSET('#现网数据参考'!$A$1,MATCH(OFFSET($A6,-MOD(ROW()-1,3),0),'#现网数据参考'!$A:$A,0)-1,MATCH(I$2&$E6,'#现网数据参考'!$3:$3,0)-1)*IF(OFFSET($A6,-MOD(ROW()-1,3),0)<=9,0.6,1),0) -> 1 | J6: =ROUND(OFFSET('#现网数据参考'!$A$1,MATCH(OFFSET($A6,-MOD(ROW()-1,3),0),'#现网数据参考'!$A:$A,0)-1,MATCH(J$2&$E6,'#现网数据参考'!$3:$3,0)-1)*IF(OFFSET($A6,-MOD(ROW()-1,3),0)<=9,0.6,1),0) -> 2 | K6: =ROUND(OFFSET('#现网数据参考'!$A$1,MATCH(OFFSET($A6,-MOD(ROW()-1,3),0),'#现网数据参考'!$A:$A,0)-1,MATCH(K$2&$E6,'#现网数据参考'!$3:$3,0)-1)*IF(OFFSET($A6,-MOD(ROW()-1,3),0)<=9,0.6,1),0) -> 0 | L6: =ROUND(OFFSET('#现网数据参考'!$A$1,MATCH(OFFSET($A6,-MOD(ROW()-1,3),0),'#现网数据参考'!$A:$A,0)-1,MATCH(L$2&$E6,'#现网数据参考'!$3:$3,0)-1),0) -> 3
A7: 2 | B7: =IF($A7="","",ROUND(_xlfn.XLOOKUP($A7,'#现网数据参考'!$A:$A,'#现网数据参考'!G:G)*IF($A7<=9,0.5,1),0)) -> 13843 | C7: =IF($A7="","",ROUND(_xlfn.XLOOKUP($A7,'#现网数据参考'!$A:$A,'#现网数据参考'!P:P),0)) -> 1 | D7: 1 | E7: 20 | F7: =ROUND(OFFSET('#现网数据参考'!$A$1,MATCH(OFFSET($A7,-MOD(ROW()-1,3),0),'#现网数据参考'!$A:$A,0)-1,MATCH(F$2&$E7,'#现网数据参考'!$3:$3,0)-1)*IF(OFFSET($A7,-MOD(ROW()-1,3),0)<=9,0.6,1),0) -> 1 | G7: =_xlfn.XLOOKUP(OFFSET($A7,-MOD(ROW()-1,3),0),'#出征索引'!A:A,'#出征索引'!B:B)+_xlfn.XLOOKUP(OFFSET($A7,-MOD(ROW()-1,3),0),'#出征索引'!A:A,'#出征索引'!C:C)*_xlfn.XLOOKUP(F7,'#出征索引'!E:E,'#出征索引'!F:F) -> 600 | H7: =ROUND(OFFSET('#现网数据参考'!$A$1,MATCH(OFFSET($A7,-MOD(ROW()-1,3),0),'#现网数据参考'!$A:$A,0)-1,MATCH(H$2&$E7,'#现网数据参考'!$3:$3,0)-1)*IF(OFFSET($A7,-MOD(ROW()-1,3),0)<=9,0.6,1),0) -> 1 | I7: =ROUND(OFFSET('#现网数据参考'!$A$1,MATCH(OFFSET($A7,-MOD(ROW()-1,3),0),'#现网数据参考'!$A:$A,0)-1,MATCH(I$2&$E7,'#现网数据参考'!$3:$3,0)-1)*IF(OFFSET($A7,-MOD(ROW()-1,3),0)<=9,0.6,1),0) -> 1 | J7: =ROUND(OFFSET('#现网数据参考'!$A$1,MATCH(OFFSET($A7,-MOD(ROW()-1,3),0),'#现网数据参考'!$A:$A,0)-1,MATCH(J$2&$E7,'#现网数据参考'!$3:$3,0)-1)*IF(OFFSET($A7,-MOD(ROW()-1,3),0)<=9,0.6,1),0) -> 0 | K7: =ROUND(OFFSET('#现网数据参考'!$A$1,MATCH(OFFSET($A7,-MOD(ROW()-1,3),0),'#现网数据参考'!$A:$A,0)-1,MATCH(K$2&$E7,'#现网数据参考'!$3:$3,0)-1)*IF(OFFSET($A7,-MOD(ROW()-1,3),0)<=9,0.6,1),0) -> 0 | L7: =ROUND(OFFSET('#现网数据参考'!$A$1,MATCH(OFFSET($A7,-MOD(ROW()-1,3),0),'#现网数据参考'!$A:$A,0)-1,MATCH(L$2&$E7,'#现网数据参考'!$3:$3,0)-1),0) -> 3
B8: =IF($A8="","",ROUND(_xlfn.XLOOKUP($A8,'#现网数据参考'!$A:$A,'#现网数据参考'!G:G)*IF($A8<=9,0.5,1),0)) | C8: =IF($A8="","",ROUND(_xlfn.XLOOKUP($A8,'#现网数据参考'!$A:$A,'#现网数据参考'!P:P),0)) | D8: 2 | E8: 40 | F8: =ROUND(OFFSET('#现网数据参考'!$A$1,MATCH(OFFSET($A8,-MOD(ROW()-1,3),0),'#现网数据参考'!$A:$A,0)-1,MATCH(F$2&$E8,'#现网数据参考'!$3:$3,0)-1)*IF(OFFSET($A8,-MOD(ROW()-1,3),0)<=9,0.6,1),0) -> 1 | G8: =_xlfn.XLOOKUP(OFFSET($A8,-MOD(ROW()-1,3),0),'#出征索引'!A:A,'#出征索引'!B:B)+_xlfn.XLOOKUP(OFFSET($A8,-MOD(ROW()-1,3),0),'#出征索引'!A:A,'#出征索引'!C:C)*_xlfn.XLOOKUP(F8,'#出征索引'!E:E,'#出征索引'!F:F) -> 600 | H8: =ROUND(OFFSET('#现网数据参考'!$A$1,MATCH(OFFSET($A8,-MOD(ROW()-1,3),0),'#现网数据参考'!$A:$A,0)-1,MATCH(H$2&$E8,'#现网数据参考'!$3:$3,0)-1)*IF(OFFSET($A8,-MOD(ROW()-1,3),0)<=9,0.6,1),0) -> 1 | I8: =ROUND(OFFSET('#现网数据参考'!$A$1,MATCH(OFFSET($A8,-MOD(ROW()-1,3),0),'#现网数据参考'!$A:$A,0)-1,MATCH(I$2&$E8,'#现网数据参考'!$3:$3,0)-1)*IF(OFFSET($A8,-MOD(ROW()-1,3),0)<=9,0.6,1),0) -> 1 | J8: =ROUND(OFFSET('#现网数据参考'!$A$1,MATCH(OFFSET($A8,-MOD(ROW()-1,3),0),'#现网数据参考'!$A:$A,0)-1,MATCH(J$2&$E8,'#现网数据参考'!$3:$3,0)-1)*IF(OFFSET($A8,-MOD(ROW()-1,3),0)<=9,0.6,1),0) -> 1 | K8: =ROUND(OFFSET('#现网数据参考'!$A$1,MATCH(OFFSET($A8,-MOD(ROW()-1,3),0),'#现网数据参考'!$A:$A,0)-1,MATCH(K$2&$E8,'#现网数据参考'!$3:$3,0)-1)*IF(OFFSET($A8,-MOD(ROW()-1,3),0)<=9,0.6,1),0) -> 0 | L8: =ROUND(OFFSET('#现网数据参考'!$A$1,MATCH(OFFSET($A8,-MOD(ROW()-1,3),0),'#现网数据参考'!$A:$A,0)-1,MATCH(L$2&$E8,'#现网数据参考'!$3:$3,0)-1),0) -> 3
B9: =IF($A9="","",ROUND(_xlfn.XLOOKUP($A9,'#现网数据参考'!$A:$A,'#现网数据参考'!G:G)*IF($A9<=9,0.5,1),0)) | C9: =IF($A9="","",ROUND(_xlfn.XLOOKUP($A9,'#现网数据参考'!$A:$A,'#现网数据参考'!P:P),0)) | D9: 3 | E9: 60 | F9: =ROUND(OFFSET('#现网数据参考'!$A$1,MATCH(OFFSET($A9,-MOD(ROW()-1,3),0),'#现网数据参考'!$A:$A,0)-1,MATCH(F$2&$E9,'#现网数据参考'!$3:$3,0)-1)*IF(OFFSET($A9,-MOD(ROW()-1,3),0)<=9,0.6,1),0) -> 1 | G9: =_xlfn.XLOOKUP(OFFSET($A9,-MOD(ROW()-1,3),0),'#出征索引'!A:A,'#出征索引'!B:B)+_xlfn.XLOOKUP(OFFSET($A9,-MOD(ROW()-1,3),0),'#出征索引'!A:A,'#出征索引'!C:C)*_xlfn.XLOOKUP(F9,'#出征索引'!E:E,'#出征索引'!F:F) -> 600 | H9: =ROUND(OFFSET('#现网数据参考'!$A$1,MATCH(OFFSET($A9,-MOD(ROW()-1,3),0),'#现网数据参考'!$A:$A,0)-1,MATCH(H$2&$E9,'#现网数据参考'!$3:$3,0)-1)*IF(OFFSET($A9,-MOD(ROW()-1,3),0)<=9,0.6,1),0) -> 2 | I9: =ROUND(OFFSET('#现网数据参考'!$A$1,MATCH(OFFSET($A9,-MOD(ROW()-1,3),0),'#现网数据参考'!$A:$A,0)-1,MATCH(I$2&$E9,'#现网数据参考'!$3:$3,0)-1)*IF(OFFSET($A9,-MOD(ROW()-1,3),0)<=9,0.6,1),0) -> 1 | J9: =ROUND(OFFSET('#现网数据参考'!$A$1,MATCH(OFFSET($A9,-MOD(ROW()-1,3),0),'#现网数据参考'!$A:$A,0)-1,MATCH(J$2&$E9,'#现网数据参考'!$3:$3,0)-1)*IF(OFFSET($A9,-MOD(ROW()-1,3),0)<=9,0.6,1),0) -> 2 | K9: =ROUND(OFFSET('#现网数据参考'!$A$1,MATCH(OFFSET($A9,-MOD(ROW()-1,3),0),'#现网数据参考'!$A:$A,0)-1,MATCH(K$2&$E9,'#现网数据参考'!$3:$3,0)-1)*IF(OFFSET($A9,-MOD(ROW()-1,3),0)<=9,0.6,1),0) -> 0 | L9: =ROUND(OFFSET('#现网数据参考'!$A$1,MATCH(OFFSET($A9,-MOD(ROW()-1,3),0),'#现网数据参考'!$A:$A,0)-1,MATCH(L$2&$E9,'#现网数据参考'!$3:$3,0)-1),0) -> 3
A10: 3 | B10: =IF($A10="","",ROUND(_xlfn.XLOOKUP($A10,'#现网数据参考'!$A:$A,'#现网数据参考'!G:G)*IF($A10<=9,0.5,1),0)) -> 19364 | C10: =IF($A10="","",ROUND(_xlfn.XLOOKUP($A10,'#现网数据参考'!$A:$A,'#现网数据参考'!P:P),0)) -> 1 | D10: 1 | E10: 20 | F10: =ROUND(OFFSET('#现网数据参考'!$A$1,MATCH(OFFSET($A10,-MOD(ROW()-1,3),0),'#现网数据参考'!$A:$A,0)-1,MATCH(F$2&$E10,'#现网数据参考'!$3:$3,0)-1)*IF(OFFSET($A10,-MOD(ROW()-1,3),0)<=9,0.6,1),0) -> 1 | G10: =_xlfn.XLOOKUP(OFFSET($A10,-MOD(ROW()-1,3),0),'#出征索引'!A:A,'#出征索引'!B:B)+_xlfn.XLOOKUP(OFFSET($A10,-MOD(ROW()-1,3),0),'#出征索引'!A:A,'#出征索引'!C:C)*_xlfn.XLOOKUP(F10,'#出征索引'!E:E,'#出征索引'!F:F) -> 700 | H10: =ROUND(OFFSET('#现网数据参考'!$A$1,MATCH(OFFSET($A10,-MOD(ROW()-1,3),0),'#现网数据参考'!$A:$A,0)-1,MATCH(H$2&$E10,'#现网数据参考'!$3:$3,0)-1)*IF(OFFSET($A10,-MOD(ROW()-1,3),0)<=9,0.6,1),0) -> 1 | I10: =ROUND(OFFSET('#现网数据参考'!$A$1,MATCH(OFFSET($A10,-MOD(ROW()-1,3),0),'#现网数据参考'!$A:$A,0)-1,MATCH(I$2&$E10,'#现网数据参考'!$3:$3,0)-1)*IF(OFFSET($A10,-MOD(ROW()-1,3),0)<=9,0.6,1),0) -> 1 | J10: =ROUND(OFFSET('#现网数据参考'!$A$1,MATCH(OFFSET($A10,-MOD(ROW()-1,3),0),'#现网数据参考'!$A:$A,0)-1,MATCH(J$2&$E10,'#现网数据参考'!$3:$3,0)-1)*IF(OFFSET($A10,-MOD(ROW()-1,3),0)<=9,0.6,1),0) -> 0 | K10: =ROUND(OFFSET('#现网数据参考'!$A$1,MATCH(OFFSET($A10,-MOD(ROW()-1,3),0),'#现网数据参考'!$A:$A,0)-1,MATCH(K$2&$E10,'#现网数据参考'!$3:$3,0)-1)*IF(OFFSET($A10,-MOD(ROW()-1,3),0)<=9,0.6,1),0) -> 0 | L10: =ROUND(OFFSET('#现网数据参考'!$A$1,MATCH(OFFSET($A10,-MOD(ROW()-1,3),0),'#现网数据参考'!$A:$A,0)-1,MATCH(L$2&$E10,'#现网数据参考'!$3:$3,0)-1),0) -> 3
B11: =IF($A11="","",ROUND(_xlfn.XLOOKUP($A11,'#现网数据参考'!$A:$A,'#现网数据参考'!G:G)*IF($A11<=9,0.5,1),0)) | C11: =IF($A11="","",ROUND(_xlfn.XLOOKUP($A11,'#现网数据参考'!$A:$A,'#现网数据参考'!P:P),0)) | D11: 2 | E11: 40 | F11: =ROUND(OFFSET('#现网数据参考'!$A$1,MATCH(OFFSET($A11,-MOD(ROW()-1,3),0),'#现网数据参考'!$A:$A,0)-1,MATCH(F$2&$E11,'#现网数据参考'!$3:$3,0)-1)*IF(OFFSET($A11,-MOD(ROW()-1,3),0)<=9,0.6,1),0) -> 1 | G11: =_xlfn.XLOOKUP(OFFSET($A11,-MOD(ROW()-1,3),0),'#出征索引'!A:A,'#出征索引'!B:B)+_xlfn.XLOOKUP(OFFSET($A11,-MOD(ROW()-1,3),0),'#出征索引'!A:A,'#出征索引'!C:C)*_xlfn.XLOOKUP(F11,'#出征索引'!E:E,'#出征索引'!F:F) -> 700 | H11: =ROUND(OFFSET('#现网数据参考'!$A$1,MATCH(OFFSET($A11,-MOD(ROW()-1,3),0),'#现网数据参考'!$A:$A,0)-1,MATCH(H$2&$E11,'#现网数据参考'!$3:$3,0)-1)*IF(OFFSET($A11,-MOD(ROW()-1,3),0)<=9,0.6,1),0) -> 1 | I11: =ROUND(OFFSET('#现网数据参考'!$A$1,MATCH(OFFSET($A11,-MOD(ROW()-1,3),0),'#现网数据参考'!$A:$A,0)-1,MATCH(I$2&$E11,'#现网数据参考'!$3:$3,0)-1)*IF(OFFSET($A11,-MOD(ROW()-1,3),0)<=9,0.6,1),0) -> 1 | J11: =ROUND(OFFSET('#现网数据参考'!$A$1,MATCH(OFFSET($A11,-MOD(ROW()-1,3),0),'#现网数据参考'!$A:$A,0)-1,MATCH(J$2&$E11,'#现网数据参考'!$3:$3,0)-1)*IF(OFFSET($A11,-MOD(ROW()-1,3),0)<=9,0.6,1),0) -> 1 | K11: =ROUND(OFFSET('#现网数据参考'!$A$1,MATCH(OFFSET($A11,-MOD(ROW()-1,3),0),'#现网数据参考'!$A:$A,0)-1,MATCH(K$2&$E11,'#现网数据参考'!$3:$3,0)-1)*IF(OFFSET($A11,-MOD(ROW()-1,3),0)<=9,0.6,1),0) -> 0 | L11: =ROUND(OFFSET('#现网数据参考'!$A$1,MATCH(OFFSET($A11,-MOD(ROW()-1,3),0),'#现网数据参考'!$A:$A,0)-1,MATCH(L$2&$E11,'#现网数据参考'!$3:$3,0)-1),0) -> 3
B12: =IF($A12="","",ROUND(_xlfn.XLOOKUP($A12,'#现网数据参考'!$A:$A,'#现网数据参考'!G:G)*IF($A12<=9,0.5,1),0)) | C12: =IF($A12="","",ROUND(_xlfn.XLOOKUP($A12,'#现网数据参考'!$A:$A,'#现网数据参考'!P:P),0)) | D12: 3 | E12: 60 | F12: =ROUND(OFFSET('#现网数据参考'!$A$1,MATCH(OFFSET($A12,-MOD(ROW()-1,3),0),'#现网数据参考'!$A:$A,0)-1,MATCH(F$2&$E12,'#现网数据参考'!$3:$3,0)-1)*IF(OFFSET($A12,-MOD(ROW()-1,3),0)<=9,0.6,1),0) -> 1 | G12: =_xlfn.XLOOKUP(OFFSET($A12,-MOD(ROW()-1,3),0),'#出征索引'!A:A,'#出征索引'!B:B)+_xlfn.XLOOKUP(OFFSET($A12,-MOD(ROW()-1,3),0),'#出征索引'!A:A,'#出征索引'!C:C)*_xlfn.XLOOKUP(F12,'#出征索引'!E:E,'#出征索引'!F:F) -> 700 | H12: =ROUND(OFFSET('#现网数据参考'!$A$1,MATCH(OFFSET($A12,-MOD(ROW()-1,3),0),'#现网数据参考'!$A:$A,0)-1,MATCH(H$2&$E12,'#现网数据参考'!$3:$3,0)-1)*IF(OFFSET($A12,-MOD(ROW()-1,3),0)<=9,0.6,1),0) -> 1 | I12: =ROUND(OFFSET('#现网数据参考'!$A$1,MATCH(OFFSET($A12,-MOD(ROW()-1,3),0),'#现网数据参考'!$A:$A,0)-1,MATCH(I$2&$E12,'#现网数据参考'!$3:$3,0)-1)*IF(OFFSET($A12,-MOD(ROW()-1,3),0)<=9,0.6,1),0) -> 1 | J12: =ROUND(OFFSET('#现网数据参考'!$A$1,MATCH(OFFSET($A12,-MOD(ROW()-1,3),0),'#现网数据参考'!$A:$A,0)-1,MATCH(J$2&$E12,'#现网数据参考'!$3:$3,0)-1)*IF(OFFSET($A12,-MOD(ROW()-1,3),0)<=9,0.6,1),0) -> 1 | K12: =ROUND(OFFSET('#现网数据参考'!$A$1,MATCH(OFFSET($A12,-MOD(ROW()-1,3),0),'#现网数据参考'!$A:$A,0)-1,MATCH(K$2&$E12,'#现网数据参考'!$3:$3,0)-1)*IF(OFFSET($A12,-MOD(ROW()-1,3),0)<=9,0.6,1),0) -> 0 | L12: =ROUND(OFFSET('#现网数据参考'!$A$1,MATCH(OFFSET($A12,-MOD(ROW()-1,3),0),'#现网数据参考'!$A:$A,0)-1,MATCH(L$2&$E12,'#现网数据参考'!$3:$3,0)-1),0) -> 3
A13: 4 | B13: =IF($A13="","",ROUND(_xlfn.XLOOKUP($A13,'#现网数据参考'!$A:$A,'#现网数据参考'!G:G)*IF($A13<=9,0.5,1),0)) -> 26368 | C13: =IF($A13="","",ROUND(_xlfn.XLOOKUP($A13,'#现网数据参考'!$A:$A,'#现网数据参考'!P:P),0)) -> 1 | D13: 1 | E13: 20 | F13: =ROUND(OFFSET('#现网数据参考'!$A$1,MATCH(OFFSET($A13,-MOD(ROW()-1,3),0),'#现网数据参考'!$A:$A,0)-1,MATCH(F$2&$E13,'#现网数据参考'!$3:$3,0)-1)*IF(OFFSET($A13,-MOD(ROW()-1,3),0)<=9,0.6,1),0) -> 1 | G13: =_xlfn.XLOOKUP(OFFSET($A13,-MOD(ROW()-1,3),0),'#出征索引'!A:A,'#出征索引'!B:B)+_xlfn.XLOOKUP(OFFSET($A13,-MOD(ROW()-1,3),0),'#出征索引'!A:A,'#出征索引'!C:C)*_xlfn.XLOOKUP(F13,'#出征索引'!E:E,'#出征索引'!F:F) -> 800 | H13: =ROUND(OFFSET('#现网数据参考'!$A$1,MATCH(OFFSET($A13,-MOD(ROW()-1,3),0),'#现网数据参考'!$A:$A,0)-1,MATCH(H$2&$E13,'#现网数据参考'!$3:$3,0)-1)*IF(OFFSET($A13,-MOD(ROW()-1,3),0)<=9,0.6,1),0) -> 1 | I13: =ROUND(OFFSET('#现网数据参考'!$A$1,MATCH(OFFSET($A13,-MOD(ROW()-1,3),0),'#现网数据参考'!$A:$A,0)-1,MATCH(I$2&$E13,'#现网数据参考'!$3:$3,0)-1)*IF(OFFSET($A13,-MOD(ROW()-1,3),0)<=9,0.6,1),0) -> 1 | J13: =ROUND(OFFSET('#现网数据参考'!$A$1,MATCH(OFFSET($A13,-MOD(ROW()-1,3),0),'#现网数据参考'!$A:$A,0)-1,MATCH(J$2&$E13,'#现网数据参考'!$3:$3,0)-1)*IF(OFFSET($A13,-MOD(ROW()-1,3),0)<=9,0.6,1),0) -> 0 | K13: =ROUND(OFFSET('#现网数据参考'!$A$1,MATCH(OFFSET($A13,-MOD(ROW()-1,3),0),'#现网数据参考'!$A:$A,0)-1,MATCH(K$2&$E13,'#现网数据参考'!$3:$3,0)-1)*IF(OFFSET($A13,-MOD(ROW()-1,3),0)<=9,0.6,1),0) -> 0 | L13: =ROUND(OFFSET('#现网数据参考'!$A$1,MATCH(OFFSET($A13,-MOD(ROW()-1,3),0),'#现网数据参考'!$A:$A,0)-1,MATCH(L$2&$E13,'#现网数据参考'!$3:$3,0)-1),0) -> 3
B14: =IF($A14="","",ROUND(_xlfn.XLOOKUP($A14,'#现网数据参考'!$A:$A,'#现网数据参考'!G:G)*IF($A14<=9,0.5,1),0)) | C14: =IF($A14="","",ROUND(_xlfn.XLOOKUP($A14,'#现网数据参考'!$A:$A,'#现网数据参考'!P:P),0)) | D14: 2 | E14: 40 | F14: =ROUND(OFFSET('#现网数据参考'!$A$1,MATCH(OFFSET($A14,-MOD(ROW()-1,3),0),'#现网数据参考'!$A:$A,0)-1,MATCH(F$2&$E14,'#现网数据参考'!$3:$3,0)-1)*IF(OFFSET($A14,-MOD(ROW()-1,3),0)<=9,0.6,1),0) -> 2 | G14: =_xlfn.XLOOKUP(OFFSET($A14,-MOD(ROW()-1,3),0),'#出征索引'!A:A,'#出征索引'!B:B)+_xlfn.XLOOKUP(OFFSET($A14,-MOD(ROW()-1,3),0),'#出征索引'!A:A,'#出征索引'!C:C)*_xlfn.XLOOKUP(F14,'#出征索引'!E:E,'#出征索引'!F:F) -> 1000 | H14: =ROUND(OFFSET('#现网数据参考'!$A$1,MATCH(OFFSET($A14,-MOD(ROW()-1,3),0),'#现网数据参考'!$A:$A,0)-1,MATCH(H$2&$E14,'#现网数据参考'!$3:$3,0)-1)*IF(OFFSET($A14,-MOD(ROW()-1,3),0)<=9,0.6,1),0) -> 1 | I14: =ROUND(OFFSET('#现网数据参考'!$A$1,MATCH(OFFSET($A14,-MOD(ROW()-1,3),0),'#现网数据参考'!$A:$A,0)-1,MATCH(I$2&$E14,'#现网数据参考'!$3:$3,0)-1)*IF(OFFSET($A14,-MOD(ROW()-1,3),0)<=9,0.6,1),0) -> 1 | J14: =ROUND(OFFSET('#现网数据参考'!$A$1,MATCH(OFFSET($A14,-MOD(ROW()-1,3),0),'#现网数据参考'!$A:$A,0)-1,MATCH(J$2&$E14,'#现网数据参考'!$3:$3,0)-1)*IF(OFFSET($A14,-MOD(ROW()-1,3),0)<=9,0.6,1),0) -> 0 | K14: =ROUND(OFFSET('#现网数据参考'!$A$1,MATCH(OFFSET($A14,-MOD(ROW()-1,3),0),'#现网数据参考'!$A:$A,0)-1,MATCH(K$2&$E14,'#现网数据参考'!$3:$3,0)-1)*IF(OFFSET($A14,-MOD(ROW()-1,3),0)<=9,0.6,1),0) -> 0 | L14: =ROUND(OFFSET('#现网数据参考'!$A$1,MATCH(OFFSET($A14,-MOD(ROW()-1,3),0),'#现网数据参考'!$A:$A,0)-1,MATCH(L$2&$E14,'#现网数据参考'!$3:$3,0)-1),0) -> 3
B15: =IF($A15="","",ROUND(_xlfn.XLOOKUP($A15,'#现网数据参考'!$A:$A,'#现网数据参考'!G:G)*IF($A15<=9,0.5,1),0)) | C15: =IF($A15="","",ROUND(_xlfn.XLOOKUP($A15,'#现网数据参考'!$A:$A,'#现网数据参考'!P:P),0)) | D15: 3 | E15: 60 | F15: =ROUND(OFFSET('#现网数据参考'!$A$1,MATCH(OFFSET($A15,-MOD(ROW()-1,3),0),'#现网数据参考'!$A:$A,0)-1,MATCH(F$2&$E15,'#现网数据参考'!$3:$3,0)-1)*IF(OFFSET($A15,-MOD(ROW()-1,3),0)<=9,0.6,1),0) -> 2 | G15: =_xlfn.XLOOKUP(OFFSET($A15,-MOD(ROW()-1,3),0),'#出征索引'!A:A,'#出征索引'!B:B)+_xlfn.XLOOKUP(OFFSET($A15,-MOD(ROW()-1,3),0),'#出征索引'!A:A,'#出征索引'!C:C)*_xlfn.XLOOKUP(F15,'#出征索引'!E:E,'#出征索引'!F:F) -> 1000 | H15: =ROUND(OFFSET('#现网数据参考'!$A$1,MATCH(OFFSET($A15,-MOD(ROW()-1,3),0),'#现网数据参考'!$A:$A,0)-1,MATCH(H$2&$E15,'#现网数据参考'!$3:$3,0)-1)*IF(OFFSET($A15,-MOD(ROW()-1,3),0)<=9,0.6,1),0) -> 2 | I15: =ROUND(OFFSET('#现网数据参考'!$A$1,MATCH(OFFSET($A15,-MOD(ROW()-1,3),0),'#现网数据参考'!$A:$A,0)-1,MATCH(I$2&$E15,'#现网数据参考'!$3:$3,0)-1)*IF(OFFSET($A15,-MOD(ROW()-1,3),0)<=9,0.6,1),0) -> 1 | J15: =ROUND(OFFSET('#现网数据参考'!$A$1,MATCH(OFFSET($A15,-MOD(ROW()-1,3),0),'#现网数据参考'!$A:$A,0)-1,MATCH(J$2&$E15,'#现网数据参考'!$3:$3,0)-1)*IF(OFFSET($A15,-MOD(ROW()-1,3),0)<=9,0.6,1),0) -> 1 | K15: =ROUND(OFFSET('#现网数据参考'!$A$1,MATCH(OFFSET($A15,-MOD(ROW()-1,3),0),'#现网数据参考'!$A:$A,0)-1,MATCH(K$2&$E15,'#现网数据参考'!$3:$3,0)-1)*IF(OFFSET($A15,-MOD(ROW()-1,3),0)<=9,0.6,1),0) -> 0 | L15: =ROUND(OFFSET('#现网数据参考'!$A$1,MATCH(OFFSET($A15,-MOD(ROW()-1,3),0),'#现网数据参考'!$A:$A,0)-1,MATCH(L$2&$E15,'#现网数据参考'!$3:$3,0)-1),0) -> 3
A16: 5 | B16: =IF($A16="","",ROUND(_xlfn.XLOOKUP($A16,'#现网数据参考'!$A:$A,'#现网数据参考'!G:G)*IF($A16<=9,0.5,1),0)) -> 33330 | C16: =IF($A16="","",ROUND(_xlfn.XLOOKUP($A16,'#现网数据参考'!$A:$A,'#现网数据参考'!P:P),0)) -> 1 | D16: 1 | E16: 20 | F16: =ROUND(OFFSET('#现网数据参考'!$A$1,MATCH(OFFSET($A16,-MOD(ROW()-1,3),0),'#现网数据参考'!$A:$A,0)-1,MATCH(F$2&$E16,'#现网数据参考'!$3:$3,0)-1)*IF(OFFSET($A16,-MOD(ROW()-1,3),0)<=9,0.6,1),0) -> 4 | G16: =_xlfn.XLOOKUP(OFFSET($A16,-MOD(ROW()-1,3),0),'#出征索引'!A:A,'#出征索引'!B:B)+_xlfn.XLOOKUP(OFFSET($A16,-MOD(ROW()-1,3),0),'#出征索引'!A:A,'#出征索引'!C:C)*_xlfn.XLOOKUP(F16,'#出征索引'!E:E,'#出征索引'!F:F) -> 1700 | H16: =ROUND(OFFSET('#现网数据参考'!$A$1,MATCH(OFFSET($A16,-MOD(ROW()-1,3),0),'#现网数据参考'!$A:$A,0)-1,MATCH(H$2&$E16,'#现网数据参考'!$3:$3,0)-1)*IF(OFFSET($A16,-MOD(ROW()-1,3),0)<=9,0.6,1),0) -> 1 | I16: =ROUND(OFFSET('#现网数据参考'!$A$1,MATCH(OFFSET($A16,-MOD(ROW()-1,3),0),'#现网数据参考'!$A:$A,0)-1,MATCH(I$2&$E16,'#现网数据参考'!$3:$3,0)-1)*IF(OFFSET($A16,-MOD(ROW()-1,3),0)<=9,0.6,1),0) -> 2 | J16: =ROUND(OFFSET('#现网数据参考'!$A$1,MATCH(OFFSET($A16,-MOD(ROW()-1,3),0),'#现网数据参考'!$A:$A,0)-1,MATCH(J$2&$E16,'#现网数据参考'!$3:$3,0)-1)*IF(OFFSET($A16,-MOD(ROW()-1,3),0)<=9,0.6,1),0) -> 1 | K16: =ROUND(OFFSET('#现网数据参考'!$A$1,MATCH(OFFSET($A16,-MOD(ROW()-1,3),0),'#现网数据参考'!$A:$A,0)-1,MATCH(K$2&$E16,'#现网数据参考'!$3:$3,0)-1)*IF(OFFSET($A16,-MOD(ROW()-1,3),0)<=9,0.6,1),0) -> 0 | L16: =ROUND(OFFSET('#现网数据参考'!$A$1,MATCH(OFFSET($A16,-MOD(ROW()-1,3),0),'#现网数据参考'!$A:$A,0)-1,MATCH(L$2&$E16,'#现网数据参考'!$3:$3,0)-1),0) -> 3
B17: =IF($A17="","",ROUND(_xlfn.XLOOKUP($A17,'#现网数据参考'!$A:$A,'#现网数据参考'!G:G)*IF($A17<=9,0.5,1),0)) | C17: =IF($A17="","",ROUND(_xlfn.XLOOKUP($A17,'#现网数据参考'!$A:$A,'#现网数据参考'!P:P),0)) | D17: 2 | E17: 40 | F17: =ROUND(OFFSET('#现网数据参考'!$A$1,MATCH(OFFSET($A17,-MOD(ROW()-1,3),0),'#现网数据参考'!$A:$A,0)-1,MATCH(F$2&$E17,'#现网数据参考'!$3:$3,0)-1)*IF(OFFSET($A17,-MOD(ROW()-1,3),0)<=9,0.6,1),0) -> 6 | G17: =_xlfn.XLOOKUP(OFFSET($A17,-MOD(ROW()-1,3),0),'#出征索引'!A:A,'#出征索引'!B:B)+_xlfn.XLOOKUP(OFFSET($A17,-MOD(ROW()-1,3),0),'#出征索引'!A:A,'#出征索引'!C:C)*_xlfn.XLOOKUP(F17,'#出征索引'!E:E,'#出征索引'!F:F) -> 2100 | H17: =ROUND(OFFSET('#现网数据参考'!$A$1,MATCH(OFFSET($A17,-MOD(ROW()-1,3),0),'#现网数据参考'!$A:$A,0)-1,MATCH(H$2&$E17,'#现网数据参考'!$3:$3,0)-1)*IF(OFFSET($A17,-MOD(ROW()-1,3),0)<=9,0.6,1),0) -> 1 | I17: =ROUND(OFFSET('#现网数据参考'!$A$1,MATCH(OFFSET($A17,-MOD(ROW()-1,3),0),'#现网数据参考'!$A:$A,0)-1,MATCH(I$2&$E17,'#现网数据参考'!$3:$3,0)-1)*IF(OFFSET($A17,-MOD(ROW()-1,3),0)<=9,0.6,1),0) -> 2 | J17: =ROUND(OFFSET('#现网数据参考'!$A$1,MATCH(OFFSET($A17,-MOD(ROW()-1,3),0),'#现网数据参考'!$A:$A,0)-1,MATCH(J$2&$E17,'#现网数据参考'!$3:$3,0)-1)*IF(OFFSET($A17,-MOD(ROW()-1,3),0)<=9,0.6,1),0) -> 2 | K17: =ROUND(OFFSET('#现网数据参考'!$A$1,MATCH(OFFSET($A17,-MOD(ROW()-1,3),0),'#现网数据参考'!$A:$A,0)-1,MATCH(K$2&$E17,'#现网数据参考'!$3:$3,0)-1)*IF(OFFSET($A17,-MOD(ROW()-1,3),0)<=9,0.6,1),0) -> 0 | L17: =ROUND(OFFSET('#现网数据参考'!$A$1,MATCH(OFFSET($A17,-MOD(ROW()-1,3),0),'#现网数据参考'!$A:$A,0)-1,MATCH(L$2&$E17,'#现网数据参考'!$3:$3,0)-1),0) -> 3
B18: =IF($A18="","",ROUND(_xlfn.XLOOKUP($A18,'#现网数据参考'!$A:$A,'#现网数据参考'!G:G)*IF($A18<=9,0.5,1),0)) | C18: =IF($A18="","",ROUND(_xlfn.XLOOKUP($A18,'#现网数据参考'!$A:$A,'#现网数据参考'!P:P),0)) | D18: 3 | E18: 60 | F18: =ROUND(OFFSET('#现网数据参考'!$A$1,MATCH(OFFSET($A18,-MOD(ROW()-1,3),0),'#现网数据参考'!$A:$A,0)-1,MATCH(F$2&$E18,'#现网数据参考'!$3:$3,0)-1)*IF(OFFSET($A18,-MOD(ROW()-1,3),0)<=9,0.6,1),0) -> 6 | G18: =_xlfn.XLOOKUP(OFFSET($A18,-MOD(ROW()-1,3),0),'#出征索引'!A:A,'#出征索引'!B:B)+_xlfn.XLOOKUP(OFFSET($A18,-MOD(ROW()-1,3),0),'#出征索引'!A:A,'#出征索引'!C:C)*_xlfn.XLOOKUP(F18,'#出征索引'!E:E,'#出征索引'!F:F) -> 2100 | H18: =ROUND(OFFSET('#现网数据参考'!$A$1,MATCH(OFFSET($A18,-MOD(ROW()-1,3),0),'#现网数据参考'!$A:$A,0)-1,MATCH(H$2&$E18,'#现网数据参考'!$3:$3,0)-1)*IF(OFFSET($A18,-MOD(ROW()-1,3),0)<=9,0.6,1),0) -> 1 | I18: =ROUND(OFFSET('#现网数据参考'!$A$1,MATCH(OFFSET($A18,-MOD(ROW()-1,3),0),'#现网数据参考'!$A:$A,0)-1,MATCH(I$2&$E18,'#现网数据参考'!$3:$3,0)-1)*IF(OFFSET($A18,-MOD(ROW()-1,3),0)<=9,0.6,1),0) -> 2 | J18: =ROUND(OFFSET('#现网数据参考'!$A$1,MATCH(OFFSET($A18,-MOD(ROW()-1,3),0),'#现网数据参考'!$A:$A,0)-1,MATCH(J$2&$E18,'#现网数据参考'!$3:$3,0)-1)*IF(OFFSET($A18,-MOD(ROW()-1,3),0)<=9,0.6,1),0) -> 2 | K18: =ROUND(OFFSET('#现网数据参考'!$A$1,MATCH(OFFSET($A18,-MOD(ROW()-1,3),0),'#现网数据参考'!$A:$A,0)-1,MATCH(K$2&$E18,'#现网数据参考'!$3:$3,0)-1)*IF(OFFSET($A18,-MOD(ROW()-1,3),0)<=9,0.6,1),0) -> 0 | L18: =ROUND(OFFSET('#现网数据参考'!$A$1,MATCH(OFFSET($A18,-MOD(ROW()-1,3),0),'#现网数据参考'!$A:$A,0)-1,MATCH(L$2&$E18,'#现网数据参考'!$3:$3,0)-1),0) -> 3
A19: 6 | B19: =IF($A19="","",ROUND(_xlfn.XLOOKUP($A19,'#现网数据参考'!$A:$A,'#现网数据参考'!G:G)*IF($A19<=9,0.5,1),0)) -> 41499 | C19: =IF($A19="","",ROUND(_xlfn.XLOOKUP($A19,'#现网数据参考'!$A:$A,'#现网数据参考'!P:P),0)) -> 1 | D19: 1 | E19: 20 | F19: =ROUND(OFFSET('#现网数据参考'!$A$1,MATCH(OFFSET($A19,-MOD(ROW()-1,3),0),'#现网数据参考'!$A:$A,0)-1,MATCH(F$2&$E19,'#现网数据参考'!$3:$3,0)-1)*IF(OFFSET($A19,-MOD(ROW()-1,3),0)<=9,0.6,1),0) -> 6 | G19: =_xlfn.XLOOKUP(OFFSET($A19,-MOD(ROW()-1,3),0),'#出征索引'!A:A,'#出征索引'!B:B)+_xlfn.XLOOKUP(OFFSET($A19,-MOD(ROW()-1,3),0),'#出征索引'!A:A,'#出征索引'!C:C)*_xlfn.XLOOKUP(F19,'#出征索引'!E:E,'#出征索引'!F:F) -> 2400 | H19: =ROUND(OFFSET('#现网数据参考'!$A$1,MATCH(OFFSET($A19,-MOD(ROW()-1,3),0),'#现网数据参考'!$A:$A,0)-1,MATCH(H$2&$E19,'#现网数据参考'!$3:$3,0)-1)*IF(OFFSET($A19,-MOD(ROW()-1,3),0)<=9,0.6,1),0) -> 1 | I19: =ROUND(OFFSET('#现网数据参考'!$A$1,MATCH(OFFSET($A19,-MOD(ROW()-1,3),0),'#现网数据参考'!$A:$A,0)-1,MATCH(I$2&$E19,'#现网数据参考'!$3:$3,0)-1)*IF(OFFSET($A19,-MOD(ROW()-1,3),0)<=9,0.6,1),0) -> 2 | J19: =ROUND(OFFSET('#现网数据参考'!$A$1,MATCH(OFFSET($A19,-MOD(ROW()-1,3),0),'#现网数据参考'!$A:$A,0)-1,MATCH(J$2&$E19,'#现网数据参考'!$3:$3,0)-1)*IF(OFFSET($A19,-MOD(ROW()-1,3),0)<=9,0.6,1),0) -> 2 | K19: =ROUND(OFFSET('#现网数据参考'!$A$1,MATCH(OFFSET($A19,-MOD(ROW()-1,3),0),'#现网数据参考'!$A:$A,0)-1,MATCH(K$2&$E19,'#现网数据参考'!$3:$3,0)-1)*IF(OFFSET($A19,-MOD(ROW()-1,3),0)<=9,0.6,1),0) -> 0 | L19: =ROUND(OFFSET('#现网数据参考'!$A$1,MATCH(OFFSET($A19,-MOD(ROW()-1,3),0),'#现网数据参考'!$A:$A,0)-1,MATCH(L$2&$E19,'#现网数据参考'!$3:$3,0)-1),0) -> 3
B20: =IF($A20="","",ROUND(_xlfn.XLOOKUP($A20,'#现网数据参考'!$A:$A,'#现网数据参考'!G:G)*IF($A20<=9,0.5,1),0)) | C20: =IF($A20="","",ROUND(_xlfn.XLOOKUP($A20,'#现网数据参考'!$A:$A,'#现网数据参考'!P:P),0)) | D20: 2 | E20: 40 | F20: =ROUND(OFFSET('#现网数据参考'!$A$1,MATCH(OFFSET($A20,-MOD(ROW()-1,3),0),'#现网数据参考'!$A:$A,0)-1,MATCH(F$2&$E20,'#现网数据参考'!$3:$3,0)-1)*IF(OFFSET($A20,-MOD(ROW()-1,3),0)<=9,0.6,1),0) -> 6 | G20: =_xlfn.XLOOKUP(OFFSET($A20,-MOD(ROW()-1,3),0),'#出征索引'!A:A,'#出征索引'!B:B)+_xlfn.XLOOKUP(OFFSET($A20,-MOD(ROW()-1,3),0),'#出征索引'!A:A,'#出征索引'!C:C)*_xlfn.XLOOKUP(F20,'#出征索引'!E:E,'#出征索引'!F:F) -> 2400 | H20: =ROUND(OFFSET('#现网数据参考'!$A$1,MATCH(OFFSET($A20,-MOD(ROW()-1,3),0),'#现网数据参考'!$A:$A,0)-1,MATCH(H$2&$E20,'#现网数据参考'!$3:$3,0)-1)*IF(OFFSET($A20,-MOD(ROW()-1,3),0)<=9,0.6,1),0) -> 2 | I20: =ROUND(OFFSET('#现网数据参考'!$A$1,MATCH(OFFSET($A20,-MOD(ROW()-1,3),0),'#现网数据参考'!$A:$A,0)-1,MATCH(I$2&$E20,'#现网数据参考'!$3:$3,0)-1)*IF(OFFSET($A20,-MOD(ROW()-1,3),0)<=9,0.6,1),0) -> 2 | J20: =ROUND(OFFSET('#现网数据参考'!$A$1,MATCH(OFFSET($A20,-MOD(ROW()-1,3),0),'#现网数据参考'!$A:$A,0)-1,MATCH(J$2&$E20,'#现网数据参考'!$3:$3,0)-1)*IF(OFFSET($A20,-MOD(ROW()-1,3),0)<=9,0.6,1),0) -> 2 | K20: =ROUND(OFFSET('#现网数据参考'!$A$1,MATCH(OFFSET($A20,-MOD(ROW()-1,3),0),'#现网数据参考'!$A:$A,0)-1,MATCH(K$2&$E20,'#现网数据参考'!$3:$3,0)-1)*IF(OFFSET($A20,-MOD(ROW()-1,3),0)<=9,0.6,1),0) -> 0 | L20: =ROUND(OFFSET('#现网数据参考'!$A$1,MATCH(OFFSET($A20,-MOD(ROW()-1,3),0),'#现网数据参考'!$A:$A,0)-1,MATCH(L$2&$E20,'#现网数据参考'!$3:$3,0)-1),0) -> 3
B21: =IF($A21="","",ROUND(_xlfn.XLOOKUP($A21,'#现网数据参考'!$A:$A,'#现网数据参考'!G:G)*IF($A21<=9,0.5,1),0)) | C21: =IF($A21="","",ROUND(_xlfn.XLOOKUP($A21,'#现网数据参考'!$A:$A,'#现网数据参考'!P:P),0)) | D21: 3 | E21: 60 | F21: =ROUND(OFFSET('#现网数据参考'!$A$1,MATCH(OFFSET($A21,-MOD(ROW()-1,3),0),'#现网数据参考'!$A:$A,0)-1,MATCH(F$2&$E21,'#现网数据参考'!$3:$3,0)-1)*IF(OFFSET($A21,-MOD(ROW()-1,3),0)<=9,0.6,1),0) -> 8 | G21: =_xlfn.XLOOKUP(OFFSET($A21,-MOD(ROW()-1,3),0),'#出征索引'!A:A,'#出征索引'!B:B)+_xlfn.XLOOKUP(OFFSET($A21,-MOD(ROW()-1,3),0),'#出征索引'!A:A,'#出征索引'!C:C)*_xlfn.XLOOKUP(F21,'#出征索引'!E:E,'#出征索引'!F:F) -> 2800 | H21: =ROUND(OFFSET('#现网数据参考'!$A$1,MATCH(OFFSET($A21,-MOD(ROW()-1,3),0),'#现网数据参考'!$A:$A,0)-1,MATCH(H$2&$E21,'#现网数据参考'!$3:$3,0)-1)*IF(OFFSET($A21,-MOD(ROW()-1,3),0)<=9,0.6,1),0) -> 2 | I21: =ROUND(OFFSET('#现网数据参考'!$A$1,MATCH(OFFSET($A21,-MOD(ROW()-1,3),0),'#现网数据参考'!$A:$A,0)-1,MATCH(I$2&$E21,'#现网数据参考'!$3:$3,0)-1)*IF(OFFSET($A21,-MOD(ROW()-1,3),0)<=9,0.6,1),0) -> 2 | J21: =ROUND(OFFSET('#现网数据参考'!$A$1,MATCH(OFFSET($A21,-MOD(ROW()-1,3),0),'#现网数据参考'!$A:$A,0)-1,MATCH(J$2&$E21,'#现网数据参考'!$3:$3,0)-1)*IF(OFFSET($A21,-MOD(ROW()-1,3),0)<=9,0.6,1),0) -> 3 | K21: =ROUND(OFFSET('#现网数据参考'!$A$1,MATCH(OFFSET($A21,-MOD(ROW()-1,3),0),'#现网数据参考'!$A:$A,0)-1,MATCH(K$2&$E21,'#现网数据参考'!$3:$3,0)-1)*IF(OFFSET($A21,-MOD(ROW()-1,3),0)<=9,0.6,1),0) -> 0 | L21: =ROUND(OFFSET('#现网数据参考'!$A$1,MATCH(OFFSET($A21,-MOD(ROW()-1,3),0),'#现网数据参考'!$A:$A,0)-1,MATCH(L$2&$E21,'#现网数据参考'!$3:$3,0)-1),0) -> 3
A22: 7 | B22: =IF($A22="","",ROUND(_xlfn.XLOOKUP($A22,'#现网数据参考'!$A:$A,'#现网数据参考'!G:G)*IF($A22<=9,0.5,1),0)) -> 50856 | C22: =IF($A22="","",ROUND(_xlfn.XLOOKUP($A22,'#现网数据参考'!$A:$A,'#现网数据参考'!P:P),0)) -> 2 | D22: 1 | E22: 20 | F22: =ROUND(OFFSET('#现网数据参考'!$A$1,MATCH(OFFSET($A22,-MOD(ROW()-1,3),0),'#现网数据参考'!$A:$A,0)-1,MATCH(F$2&$E22,'#现网数据参考'!$3:$3,0)-1)*IF(OFFSET($A22,-MOD(ROW()-1,3),0)<=9,0.6,1),0) -> 6 | G22: =_xlfn.XLOOKUP(OFFSET($A22,-MOD(ROW()-1,3),0),'#出征索引'!A:A,'#出征索引'!B:B)+_xlfn.XLOOKUP(OFFSET($A22,-MOD(ROW()-1,3),0),'#出征索引'!A:A,'#出征索引'!C:C)*_xlfn.XLOOKUP(F22,'#出征索引'!E:E,'#出征索引'!F:F) -> 2900 | H22: =ROUND(OFFSET('#现网数据参考'!$A$1,MATCH(OFFSET($A22,-MOD(ROW()-1,3),0),'#现网数据参考'!$A:$A,0)-1,MATCH(H$2&$E22,'#现网数据参考'!$3:$3,0)-1)*IF(OFFSET($A22,-MOD(ROW()-1,3),0)<=9,0.6,1),0) -> 2 | I22: =ROUND(OFFSET('#现网数据参考'!$A$1,MATCH(OFFSET($A22,-MOD(ROW()-1,3),0),'#现网数据参考'!$A:$A,0)-1,MATCH(I$2&$E22,'#现网数据参考'!$3:$3,0)-1)*IF(OFFSET($A22,-MOD(ROW()-1,3),0)<=9,0.6,1),0) -> 2 | J22: =ROUND(OFFSET('#现网数据参考'!$A$1,MATCH(OFFSET($A22,-MOD(ROW()-1,3),0),'#现网数据参考'!$A:$A,0)-1,MATCH(J$2&$E22,'#现网数据参考'!$3:$3,0)-1)*IF(OFFSET($A22,-MOD(ROW()-1,3),0)<=9,0.6,1),0) -> 2 | K22: =ROUND(OFFSET('#现网数据参考'!$A$1,MATCH(OFFSET($A22,-MOD(ROW()-1,3),0),'#现网数据参考'!$A:$A,0)-1,MATCH(K$2&$E22,'#现网数据参考'!$3:$3,0)-1)*IF(OFFSET($A22,-MOD(ROW()-1,3),0)<=9,0.6,1),0) -> 0 | L22: =ROUND(OFFSET('#现网数据参考'!$A$1,MATCH(OFFSET($A22,-MOD(ROW()-1,3),0),'#现网数据参考'!$A:$A,0)-1,MATCH(L$2&$E22,'#现网数据参考'!$3:$3,0)-1),0) -> 3
B23: =IF($A23="","",ROUND(_xlfn.XLOOKUP($A23,'#现网数据参考'!$A:$A,'#现网数据参考'!G:G)*IF($A23<=9,0.5,1),0)) | C23: =IF($A23="","",ROUND(_xlfn.XLOOKUP($A23,'#现网数据参考'!$A:$A,'#现网数据参考'!P:P),0)) | D23: 2 | E23: 40 | F23: =ROUND(OFFSET('#现网数据参考'!$A$1,MATCH(OFFSET($A23,-MOD(ROW()-1,3),0),'#现网数据参考'!$A:$A,0)-1,MATCH(F$2&$E23,'#现网数据参考'!$3:$3,0)-1)*IF(OFFSET($A23,-MOD(ROW()-1,3),0)<=9,0.6,1),0) -> 7 | G23: =_xlfn.XLOOKUP(OFFSET($A23,-MOD(ROW()-1,3),0),'#出征索引'!A:A,'#出征索引'!B:B)+_xlfn.XLOOKUP(OFFSET($A23,-MOD(ROW()-1,3),0),'#出征索引'!A:A,'#出征索引'!C:C)*_xlfn.XLOOKUP(F23,'#出征索引'!E:E,'#出征索引'!F:F) -> 3100 | H23: =ROUND(OFFSET('#现网数据参考'!$A$1,MATCH(OFFSET($A23,-MOD(ROW()-1,3),0),'#现网数据参考'!$A:$A,0)-1,MATCH(H$2&$E23,'#现网数据参考'!$3:$3,0)-1)*IF(OFFSET($A23,-MOD(ROW()-1,3),0)<=9,0.6,1),0) -> 2 | I23: =ROUND(OFFSET('#现网数据参考'!$A$1,MATCH(OFFSET($A23,-MOD(ROW()-1,3),0),'#现网数据参考'!$A:$A,0)-1,MATCH(I$2&$E23,'#现网数据参考'!$3:$3,0)-1)*IF(OFFSET($A23,-MOD(ROW()-1,3),0)<=9,0.6,1),0) -> 3 | J23: =ROUND(OFFSET('#现网数据参考'!$A$1,MATCH(OFFSET($A23,-MOD(ROW()-1,3),0),'#现网数据参考'!$A:$A,0)-1,MATCH(J$2&$E23,'#现网数据参考'!$3:$3,0)-1)*IF(OFFSET($A23,-MOD(ROW()-1,3),0)<=9,0.6,1),0) -> 2 | K23: =ROUND(OFFSET('#现网数据参考'!$A$1,MATCH(OFFSET($A23,-MOD(ROW()-1,3),0),'#现网数据参考'!$A:$A,0)-1,MATCH(K$2&$E23,'#现网数据参考'!$3:$3,0)-1)*IF(OFFSET($A23,-MOD(ROW()-1,3),0)<=9,0.6,1),0) -> 0 | L23: =ROUND(OFFSET('#现网数据参考'!$A$1,MATCH(OFFSET($A23,-MOD(ROW()-1,3),0),'#现网数据参考'!$A:$A,0)-1,MATCH(L$2&$E23,'#现网数据参考'!$3:$3,0)-1),0) -> 3
B24: =IF($A24="","",ROUND(_xlfn.XLOOKUP($A24,'#现网数据参考'!$A:$A,'#现网数据参考'!G:G)*IF($A24<=9,0.5,1),0)) | C24: =IF($A24="","",ROUND(_xlfn.XLOOKUP($A24,'#现网数据参考'!$A:$A,'#现网数据参考'!P:P),0)) | D24: 3 | E24: 60 | F24: =ROUND(OFFSET('#现网数据参考'!$A$1,MATCH(OFFSET($A24,-MOD(ROW()-1,3),0),'#现网数据参考'!$A:$A,0)-1,MATCH(F$2&$E24,'#现网数据参考'!$3:$3,0)-1)*IF(OFFSET($A24,-MOD(ROW()-1,3),0)<=9,0.6,1),0) -> 9 | G24: =_xlfn.XLOOKUP(OFFSET($A24,-MOD(ROW()-1,3),0),'#出征索引'!A:A,'#出征索引'!B:B)+_xlfn.XLOOKUP(OFFSET($A24,-MOD(ROW()-1,3),0),'#出征索引'!A:A,'#出征索引'!C:C)*_xlfn.XLOOKUP(F24,'#出征索引'!E:E,'#出征索引'!F:F) -> 3500 | H24: =ROUND(OFFSET('#现网数据参考'!$A$1,MATCH(OFFSET($A24,-MOD(ROW()-1,3),0),'#现网数据参考'!$A:$A,0)-1,MATCH(H$2&$E24,'#现网数据参考'!$3:$3,0)-1)*IF(OFFSET($A24,-MOD(ROW()-1,3),0)<=9,0.6,1),0) -> 4 | I24: =ROUND(OFFSET('#现网数据参考'!$A$1,MATCH(OFFSET($A24,-MOD(ROW()-1,3),0),'#现网数据参考'!$A:$A,0)-1,MATCH(I$2&$E24,'#现网数据参考'!$3:$3,0)-1)*IF(OFFSET($A24,-MOD(ROW()-1,3),0)<=9,0.6,1),0) -> 3 | J24: =ROUND(OFFSET('#现网数据参考'!$A$1,MATCH(OFFSET($A24,-MOD(ROW()-1,3),0),'#现网数据参考'!$A:$A,0)-1,MATCH(J$2&$E24,'#现网数据参考'!$3:$3,0)-1)*IF(OFFSET($A24,-MOD(ROW()-1,3),0)<=9,0.6,1),0) -> 3 | K24: =ROUND(OFFSET('#现网数据参考'!$A$1,MATCH(OFFSET($A24,-MOD(ROW()-1,3),0),'#现网数据参考'!$A:$A,0)-1,MATCH(K$2&$E24,'#现网数据参考'!$3:$3,0)-1)*IF(OFFSET($A24,-MOD(ROW()-1,3),0)<=9,0.6,1),0) -> 0 | L24: =ROUND(OFFSET('#现网数据参考'!$A$1,MATCH(OFFSET($A24,-MOD(ROW()-1,3),0),'#现网数据参考'!$A:$A,0)-1,MATCH(L$2&$E24,'#现网数据参考'!$3:$3,0)-1),0) -> 3
A25: 8 | B25: =IF($A25="","",ROUND(_xlfn.XLOOKUP($A25,'#现网数据参考'!$A:$A,'#现网数据参考'!G:G)*IF($A25<=9,0.5,1),0)) -> 60209 | C25: =IF($A25="","",ROUND(_xlfn.XLOOKUP($A25,'#现网数据参考'!$A:$A,'#现网数据参考'!P:P),0)) -> 2 | D25: 1 | E25: 20 | F25: =ROUND(OFFSET('#现网数据参考'!$A$1,MATCH(OFFSET($A25,-MOD(ROW()-1,3),0),'#现网数据参考'!$A:$A,0)-1,MATCH(F$2&$E25,'#现网数据参考'!$3:$3,0)-1)*IF(OFFSET($A25,-MOD(ROW()-1,3),0)<=9,0.6,1),0) -> 7 | G25: =_xlfn.XLOOKUP(OFFSET($A25,-MOD(ROW()-1,3),0),'#出征索引'!A:A,'#出征索引'!B:B)+_xlfn.XLOOKUP(OFFSET($A25,-MOD(ROW()-1,3),0),'#出征索引'!A:A,'#出征索引'!C:C)*_xlfn.XLOOKUP(F25,'#出征索引'!E:E,'#出征索引'!F:F) -> 3600 | H25: =ROUND(OFFSET('#现网数据参考'!$A$1,MATCH(OFFSET($A25,-MOD(ROW()-1,3),0),'#现网数据参考'!$A:$A,0)-1,MATCH(H$2&$E25,'#现网数据参考'!$3:$3,0)-1)*IF(OFFSET($A25,-MOD(ROW()-1,3),0)<=9,0.6,1),0) -> 2 | I25: =ROUND(OFFSET('#现网数据参考'!$A$1,MATCH(OFFSET($A25,-MOD(ROW()-1,3),0),'#现网数据参考'!$A:$A,0)-1,MATCH(I$2&$E25,'#现网数据参考'!$3:$3,0)-1)*IF(OFFSET($A25,-MOD(ROW()-1,3),0)<=9,0.6,1),0) -> 3 | J25: =ROUND(OFFSET('#现网数据参考'!$A$1,MATCH(OFFSET($A25,-MOD(ROW()-1,3),0),'#现网数据参考'!$A:$A,0)-1,MATCH(J$2&$E25,'#现网数据参考'!$3:$3,0)-1)*IF(OFFSET($A25,-MOD(ROW()-1,3),0)<=9,0.6,1),0) -> 2 | K25: =ROUND(OFFSET('#现网数据参考'!$A$1,MATCH(OFFSET($A25,-MOD(ROW()-1,3),0),'#现网数据参考'!$A:$A,0)-1,MATCH(K$2&$E25,'#现网数据参考'!$3:$3,0)-1)*IF(OFFSET($A25,-MOD(ROW()-1,3),0)<=9,0.6,1),0) -> 0 | L25: =ROUND(OFFSET('#现网数据参考'!$A$1,MATCH(OFFSET($A25,-MOD(ROW()-1,3),0),'#现网数据参考'!$A:$A,0)-1,MATCH(L$2&$E25,'#现网数据参考'!$3:$3,0)-1),0) -> 3
B26: =IF($A26="","",ROUND(_xlfn.XLOOKUP($A26,'#现网数据参考'!$A:$A,'#现网数据参考'!G:G)*IF($A26<=9,0.5,1),0)) | C26: =IF($A26="","",ROUND(_xlfn.XLOOKUP($A26,'#现网数据参考'!$A:$A,'#现网数据参考'!P:P),0)) | D26: 2 | E26: 40 | F26: =ROUND(OFFSET('#现网数据参考'!$A$1,MATCH(OFFSET($A26,-MOD(ROW()-1,3),0),'#现网数据参考'!$A:$A,0)-1,MATCH(F$2&$E26,'#现网数据参考'!$3:$3,0)-1)*IF(OFFSET($A26,-MOD(ROW()-1,3),0)<=9,0.6,1),0) -> 9 | G26: =_xlfn.XLOOKUP(OFFSET($A26,-MOD(ROW()-1,3),0),'#出征索引'!A:A,'#出征索引'!B:B)+_xlfn.XLOOKUP(OFFSET($A26,-MOD(ROW()-1,3),0),'#出征索引'!A:A,'#出征索引'!C:C)*_xlfn.XLOOKUP(F26,'#出征索引'!E:E,'#出征索引'!F:F) -> 4000 | H26: =ROUND(OFFSET('#现网数据参考'!$A$1,MATCH(OFFSET($A26,-MOD(ROW()-1,3),0),'#现网数据参考'!$A:$A,0)-1,MATCH(H$2&$E26,'#现网数据参考'!$3:$3,0)-1)*IF(OFFSET($A26,-MOD(ROW()-1,3),0)<=9,0.6,1),0) -> 2 | I26: =ROUND(OFFSET('#现网数据参考'!$A$1,MATCH(OFFSET($A26,-MOD(ROW()-1,3),0),'#现网数据参考'!$A:$A,0)-1,MATCH(I$2&$E26,'#现网数据参考'!$3:$3,0)-1)*IF(OFFSET($A26,-MOD(ROW()-1,3),0)<=9,0.6,1),0) -> 3 | J26: =ROUND(OFFSET('#现网数据参考'!$A$1,MATCH(OFFSET($A26,-MOD(ROW()-1,3),0),'#现网数据参考'!$A:$A,0)-1,MATCH(J$2&$E26,'#现网数据参考'!$3:$3,0)-1)*IF(OFFSET($A26,-MOD(ROW()-1,3),0)<=9,0.6,1),0) -> 3 | K26: =ROUND(OFFSET('#现网数据参考'!$A$1,MATCH(OFFSET($A26,-MOD(ROW()-1,3),0),'#现网数据参考'!$A:$A,0)-1,MATCH(K$2&$E26,'#现网数据参考'!$3:$3,0)-1)*IF(OFFSET($A26,-MOD(ROW()-1,3),0)<=9,0.6,1),0) -> 0 | L26: =ROUND(OFFSET('#现网数据参考'!$A$1,MATCH(OFFSET($A26,-MOD(ROW()-1,3),0),'#现网数据参考'!$A:$A,0)-1,MATCH(L$2&$E26,'#现网数据参考'!$3:$3,0)-1),0) -> 3
B27: =IF($A27="","",ROUND(_xlfn.XLOOKUP($A27,'#现网数据参考'!$A:$A,'#现网数据参考'!G:G)*IF($A27<=9,0.5,1),0)) | C27: =IF($A27="","",ROUND(_xlfn.XLOOKUP($A27,'#现网数据参考'!$A:$A,'#现网数据参考'!P:P),0)) | D27: 3 | E27: 60 | F27: =ROUND(OFFSET('#现网数据参考'!$A$1,MATCH(OFFSET($A27,-MOD(ROW()-1,3),0),'#现网数据参考'!$A:$A,0)-1,MATCH(F$2&$E27,'#现网数据参考'!$3:$3,0)-1)*IF(OFFSET($A27,-MOD(ROW()-1,3),0)<=9,0.6,1),0) -> 11 | G27: =_xlfn.XLOOKUP(OFFSET($A27,-MOD(ROW()-1,3),0),'#出征索引'!A:A,'#出征索引'!B:B)+_xlfn.XLOOKUP(OFFSET($A27,-MOD(ROW()-1,3),0),'#出征索引'!A:A,'#出征索引'!C:C)*_xlfn.XLOOKUP(F27,'#出征索引'!E:E,'#出征索引'!F:F) -> 4400 | H27: =ROUND(OFFSET('#现网数据参考'!$A$1,MATCH(OFFSET($A27,-MOD(ROW()-1,3),0),'#现网数据参考'!$A:$A,0)-1,MATCH(H$2&$E27,'#现网数据参考'!$3:$3,0)-1)*IF(OFFSET($A27,-MOD(ROW()-1,3),0)<=9,0.6,1),0) -> 5 | I27: =ROUND(OFFSET('#现网数据参考'!$A$1,MATCH(OFFSET($A27,-MOD(ROW()-1,3),0),'#现网数据参考'!$A:$A,0)-1,MATCH(I$2&$E27,'#现网数据参考'!$3:$3,0)-1)*IF(OFFSET($A27,-MOD(ROW()-1,3),0)<=9,0.6,1),0) -> 3 | J27: =ROUND(OFFSET('#现网数据参考'!$A$1,MATCH(OFFSET($A27,-MOD(ROW()-1,3),0),'#现网数据参考'!$A:$A,0)-1,MATCH(J$2&$E27,'#现网数据参考'!$3:$3,0)-1)*IF(OFFSET($A27,-MOD(ROW()-1,3),0)<=9,0.6,1),0) -> 3 | K27: =ROUND(OFFSET('#现网数据参考'!$A$1,MATCH(OFFSET($A27,-MOD(ROW()-1,3),0),'#现网数据参考'!$A:$A,0)-1,MATCH(K$2&$E27,'#现网数据参考'!$3:$3,0)-1)*IF(OFFSET($A27,-MOD(ROW()-1,3),0)<=9,0.6,1),0) -> 0 | L27: =ROUND(OFFSET('#现网数据参考'!$A$1,MATCH(OFFSET($A27,-MOD(ROW()-1,3),0),'#现网数据参考'!$A:$A,0)-1,MATCH(L$2&$E27,'#现网数据参考'!$3:$3,0)-1),0) -> 3
A28: 9 | B28: =IF($A28="","",ROUND(_xlfn.XLOOKUP($A28,'#现网数据参考'!$A:$A,'#现网数据参考'!G:G)*IF($A28<=9,0.5,1),0)) -> 77491 | C28: =IF($A28="","",ROUND(_xlfn.XLOOKUP($A28,'#现网数据参考'!$A:$A,'#现网数据参考'!P:P),0)) -> 2 | D28: 1 | E28: 20 | F28: =ROUND(OFFSET('#现网数据参考'!$A$1,MATCH(OFFSET($A28,-MOD(ROW()-1,3),0),'#现网数据参考'!$A:$A,0)-1,MATCH(F$2&$E28,'#现网数据参考'!$3:$3,0)-1)*IF(OFFSET($A28,-MOD(ROW()-1,3),0)<=9,0.6,1),0) -> 8 | G28: =_xlfn.XLOOKUP(OFFSET($A28,-MOD(ROW()-1,3),0),'#出征索引'!A:A,'#出征索引'!B:B)+_xlfn.XLOOKUP(OFFSET($A28,-MOD(ROW()-1,3),0),'#出征索引'!A:A,'#出征索引'!C:C)*_xlfn.XLOOKUP(F28,'#出征索引'!E:E,'#出征索引'!F:F) -> 4300 | H28: =ROUND(OFFSET('#现网数据参考'!$A$1,MATCH(OFFSET($A28,-MOD(ROW()-1,3),0),'#现网数据参考'!$A:$A,0)-1,MATCH(H$2&$E28,'#现网数据参考'!$3:$3,0)-1)*IF(OFFSET($A28,-MOD(ROW()-1,3),0)<=9,0.6,1),0) -> 2 | I28: =ROUND(OFFSET('#现网数据参考'!$A$1,MATCH(OFFSET($A28,-MOD(ROW()-1,3),0),'#现网数据参考'!$A:$A,0)-1,MATCH(I$2&$E28,'#现网数据参考'!$3:$3,0)-1)*IF(OFFSET($A28,-MOD(ROW()-1,3),0)<=9,0.6,1),0) -> 3 | J28: =ROUND(OFFSET('#现网数据参考'!$A$1,MATCH(OFFSET($A28,-MOD(ROW()-1,3),0),'#现网数据参考'!$A:$A,0)-1,MATCH(J$2&$E28,'#现网数据参考'!$3:$3,0)-1)*IF(OFFSET($A28,-MOD(ROW()-1,3),0)<=9,0.6,1),0) -> 2 | K28: =ROUND(OFFSET('#现网数据参考'!$A$1,MATCH(OFFSET($A28,-MOD(ROW()-1,3),0),'#现网数据参考'!$A:$A,0)-1,MATCH(K$2&$E28,'#现网数据参考'!$3:$3,0)-1)*IF(OFFSET($A28,-MOD(ROW()-1,3),0)<=9,0.6,1),0) -> 0 | L28: =ROUND(OFFSET('#现网数据参考'!$A$1,MATCH(OFFSET($A28,-MOD(ROW()-1,3),0),'#现网数据参考'!$A:$A,0)-1,MATCH(L$2&$E28,'#现网数据参考'!$3:$3,0)-1),0) -> 3
B29: =IF($A29="","",ROUND(_xlfn.XLOOKUP($A29,'#现网数据参考'!$A:$A,'#现网数据参考'!G:G)*IF($A29<=9,0.5,1),0)) | C29: =IF($A29="","",ROUND(_xlfn.XLOOKUP($A29,'#现网数据参考'!$A:$A,'#现网数据参考'!P:P),0)) | D29: 2 | E29: 40 | F29: =ROUND(OFFSET('#现网数据参考'!$A$1,MATCH(OFFSET($A29,-MOD(ROW()-1,3),0),'#现网数据参考'!$A:$A,0)-1,MATCH(F$2&$E29,'#现网数据参考'!$3:$3,0)-1)*IF(OFFSET($A29,-MOD(ROW()-1,3),0)<=9,0.6,1),0) -> 10 | G29: =_xlfn.XLOOKUP(OFFSET($A29,-MOD(ROW()-1,3),0),'#出征索引'!A:A,'#出征索引'!B:B)+_xlfn.XLOOKUP(OFFSET($A29,-MOD(ROW()-1,3),0),'#出征索引'!A:A,'#出征索引'!C:C)*_xlfn.XLOOKUP(F29,'#出征索引'!E:E,'#出征索引'!F:F) -> 4700 | H29: =ROUND(OFFSET('#现网数据参考'!$A$1,MATCH(OFFSET($A29,-MOD(ROW()-1,3),0),'#现网数据参考'!$A:$A,0)-1,MATCH(H$2&$E29,'#现网数据参考'!$3:$3,0)-1)*IF(OFFSET($A29,-MOD(ROW()-1,3),0)<=9,0.6,1),0) -> 4 | I29: =ROUND(OFFSET('#现网数据参考'!$A$1,MATCH(OFFSET($A29,-MOD(ROW()-1,3),0),'#现网数据参考'!$A:$A,0)-1,MATCH(I$2&$E29,'#现网数据参考'!$3:$3,0)-1)*IF(OFFSET($A29,-MOD(ROW()-1,3),0)<=9,0.6,1),0) -> 3 | J29: =ROUND(OFFSET('#现网数据参考'!$A$1,MATCH(OFFSET($A29,-MOD(ROW()-1,3),0),'#现网数据参考'!$A:$A,0)-1,MATCH(J$2&$E29,'#现网数据参考'!$3:$3,0)-1)*IF(OFFSET($A29,-MOD(ROW()-1,3),0)<=9,0.6,1),0) -> 3 | K29: =ROUND(OFFSET('#现网数据参考'!$A$1,MATCH(OFFSET($A29,-MOD(ROW()-1,3),0),'#现网数据参考'!$A:$A,0)-1,MATCH(K$2&$E29,'#现网数据参考'!$3:$3,0)-1)*IF(OFFSET($A29,-MOD(ROW()-1,3),0)<=9,0.6,1),0) -> 0 | L29: =ROUND(OFFSET('#现网数据参考'!$A$1,MATCH(OFFSET($A29,-MOD(ROW()-1,3),0),'#现网数据参考'!$A:$A,0)-1,MATCH(L$2&$E29,'#现网数据参考'!$3:$3,0)-1),0) -> 3
B30: =IF($A30="","",ROUND(_xlfn.XLOOKUP($A30,'#现网数据参考'!$A:$A,'#现网数据参考'!G:G)*IF($A30<=9,0.5,1),0)) | C30: =IF($A30="","",ROUND(_xlfn.XLOOKUP($A30,'#现网数据参考'!$A:$A,'#现网数据参考'!P:P),0)) | D30: 3 | E30: 60 | F30: =ROUND(OFFSET('#现网数据参考'!$A$1,MATCH(OFFSET($A30,-MOD(ROW()-1,3),0),'#现网数据参考'!$A:$A,0)-1,MATCH(F$2&$E30,'#现网数据参考'!$3:$3,0)-1)*IF(OFFSET($A30,-MOD(ROW()-1,3),0)<=9,0.6,1),0) -> 12 | G30: =_xlfn.XLOOKUP(OFFSET($A30,-MOD(ROW()-1,3),0),'#出征索引'!A:A,'#出征索引'!B:B)+_xlfn.XLOOKUP(OFFSET($A30,-MOD(ROW()-1,3),0),'#出征索引'!A:A,'#出征索引'!C:C)*_xlfn.XLOOKUP(F30,'#出征索引'!E:E,'#出征索引'!F:F) -> 5100 | H30: =ROUND(OFFSET('#现网数据参考'!$A$1,MATCH(OFFSET($A30,-MOD(ROW()-1,3),0),'#现网数据参考'!$A:$A,0)-1,MATCH(H$2&$E30,'#现网数据参考'!$3:$3,0)-1)*IF(OFFSET($A30,-MOD(ROW()-1,3),0)<=9,0.6,1),0) -> 6 | I30: =ROUND(OFFSET('#现网数据参考'!$A$1,MATCH(OFFSET($A30,-MOD(ROW()-1,3),0),'#现网数据参考'!$A:$A,0)-1,MATCH(I$2&$E30,'#现网数据参考'!$3:$3,0)-1)*IF(OFFSET($A30,-MOD(ROW()-1,3),0)<=9,0.6,1),0) -> 4 | J30: =ROUND(OFFSET('#现网数据参考'!$A$1,MATCH(OFFSET($A30,-MOD(ROW()-1,3),0),'#现网数据参考'!$A:$A,0)-1,MATCH(J$2&$E30,'#现网数据参考'!$3:$3,0)-1)*IF(OFFSET($A30,-MOD(ROW()-1,3),0)<=9,0.6,1),0) -> 4 | K30: =ROUND(OFFSET('#现网数据参考'!$A$1,MATCH(OFFSET($A30,-MOD(ROW()-1,3),0),'#现网数据参考'!$A:$A,0)-1,MATCH(K$2&$E30,'#现网数据参考'!$3:$3,0)-1)*IF(OFFSET($A30,-MOD(ROW()-1,3),0)<=9,0.6,1),0) -> 0 | L30: =ROUND(OFFSET('#现网数据参考'!$A$1,MATCH(OFFSET($A30,-MOD(ROW()-1,3),0),'#现网数据参考'!$A:$A,0)-1,MATCH(L$2&$E30,'#现网数据参考'!$3:$3,0)-1),0) -> 3
A31: 10 | B31: =IF($A31="","",ROUND(_xlfn.XLOOKUP($A31,'#现网数据参考'!$A:$A,'#现网数据参考'!G:G)*IF($A31<=9,0.5,1),0)) -> 200923 | C31: =IF($A31="","",ROUND(_xlfn.XLOOKUP($A31,'#现网数据参考'!$A:$A,'#现网数据参考'!P:P),0)) -> 2 | D31: 1 | E31: 20 | F31: =ROUND(OFFSET('#现网数据参考'!$A$1,MATCH(OFFSET($A31,-MOD(ROW()-1,3),0),'#现网数据参考'!$A:$A,0)-1,MATCH(F$2&$E31,'#现网数据参考'!$3:$3,0)-1)*IF(OFFSET($A31,-MOD(ROW()-1,3),0)<=9,0.6,1),0) -> 17 | G31: =_xlfn.XLOOKUP(OFFSET($A31,-MOD(ROW()-1,3),0),'#出征索引'!A:A,'#出征索引'!B:B)+_xlfn.XLOOKUP(OFFSET($A31,-MOD(ROW()-1,3),0),'#出征索引'!A:A,'#出征索引'!C:C)*_xlfn.XLOOKUP(F31,'#出征索引'!E:E,'#出征索引'!F:F) -> 6600 | H31: =ROUND(OFFSET('#现网数据参考'!$A$1,MATCH(OFFSET($A31,-MOD(ROW()-1,3),0),'#现网数据参考'!$A:$A,0)-1,MATCH(H$2&$E31,'#现网数据参考'!$3:$3,0)-1)*IF(OFFSET($A31,-MOD(ROW()-1,3),0)<=9,0.6,1),0) -> 4 | I31: =ROUND(OFFSET('#现网数据参考'!$A$1,MATCH(OFFSET($A31,-MOD(ROW()-1,3),0),'#现网数据参考'!$A:$A,0)-1,MATCH(I$2&$E31,'#现网数据参考'!$3:$3,0)-1)*IF(OFFSET($A31,-MOD(ROW()-1,3),0)<=9,0.6,1),0) -> 6 | J31: =ROUND(OFFSET('#现网数据参考'!$A$1,MATCH(OFFSET($A31,-MOD(ROW()-1,3),0),'#现网数据参考'!$A:$A,0)-1,MATCH(J$2&$E31,'#现网数据参考'!$3:$3,0)-1)*IF(OFFSET($A31,-MOD(ROW()-1,3),0)<=9,0.6,1),0) -> 4 | K31: =ROUND(OFFSET('#现网数据参考'!$A$1,MATCH(OFFSET($A31,-MOD(ROW()-1,3),0),'#现网数据参考'!$A:$A,0)-1,MATCH(K$2&$E31,'#现网数据参考'!$3:$3,0)-1)*IF(OFFSET($A31,-MOD(ROW()-1,3),0)<=9,0.6,1),0) -> 0 | L31: =ROUND(OFFSET('#现网数据参考'!$A$1,MATCH(OFFSET($A31,-MOD(ROW()-1,3),0),'#现网数据参考'!$A:$A,0)-1,MATCH(L$2&$E31,'#现网数据参考'!$3:$3,0)-1),0) -> 3
B32: =IF($A32="","",ROUND(_xlfn.XLOOKUP($A32,'#现网数据参考'!$A:$A,'#现网数据参考'!G:G)*IF($A32<=9,0.5,1),0)) | C32: =IF($A32="","",ROUND(_xlfn.XLOOKUP($A32,'#现网数据参考'!$A:$A,'#现网数据参考'!P:P),0)) | D32: 2 | E32: 40 | F32: =ROUND(OFFSET('#现网数据参考'!$A$1,MATCH(OFFSET($A32,-MOD(ROW()-1,3),0),'#现网数据参考'!$A:$A,0)-1,MATCH(F$2&$E32,'#现网数据参考'!$3:$3,0)-1)*IF(OFFSET($A32,-MOD(ROW()-1,3),0)<=9,0.6,1),0) -> 20 | G32: =_xlfn.XLOOKUP(OFFSET($A32,-MOD(ROW()-1,3),0),'#出征索引'!A:A,'#出征索引'!B:B)+_xlfn.XLOOKUP(OFFSET($A32,-MOD(ROW()-1,3),0),'#出征索引'!A:A,'#出征索引'!C:C)*_xlfn.XLOOKUP(F32,'#出征索引'!E:E,'#出征索引'!F:F) -> 7200 | H32: =ROUND(OFFSET('#现网数据参考'!$A$1,MATCH(OFFSET($A32,-MOD(ROW()-1,3),0),'#现网数据参考'!$A:$A,0)-1,MATCH(H$2&$E32,'#现网数据参考'!$3:$3,0)-1)*IF(OFFSET($A32,-MOD(ROW()-1,3),0)<=9,0.6,1),0) -> 9 | I32: =ROUND(OFFSET('#现网数据参考'!$A$1,MATCH(OFFSET($A32,-MOD(ROW()-1,3),0),'#现网数据参考'!$A:$A,0)-1,MATCH(I$2&$E32,'#现网数据参考'!$3:$3,0)-1)*IF(OFFSET($A32,-MOD(ROW()-1,3),0)<=9,0.6,1),0) -> 6 | J32: =ROUND(OFFSET('#现网数据参考'!$A$1,MATCH(OFFSET($A32,-MOD(ROW()-1,3),0),'#现网数据参考'!$A:$A,0)-1,MATCH(J$2&$E32,'#现网数据参考'!$3:$3,0)-1)*IF(OFFSET($A32,-MOD(ROW()-1,3),0)<=9,0.6,1),0) -> 6 | K32: =ROUND(OFFSET('#现网数据参考'!$A$1,MATCH(OFFSET($A32,-MOD(ROW()-1,3),0),'#现网数据参考'!$A:$A,0)-1,MATCH(K$2&$E32,'#现网数据参考'!$3:$3,0)-1)*IF(OFFSET($A32,-MOD(ROW()-1,3),0)<=9,0.6,1),0) -> 0 | L32: =ROUND(OFFSET('#现网数据参考'!$A$1,MATCH(OFFSET($A32,-MOD(ROW()-1,3),0),'#现网数据参考'!$A:$A,0)-1,MATCH(L$2&$E32,'#现网数据参考'!$3:$3,0)-1),0) -> 3
B33: =IF($A33="","",ROUND(_xlfn.XLOOKUP($A33,'#现网数据参考'!$A:$A,'#现网数据参考'!G:G)*IF($A33<=9,0.5,1),0)) | C33: =IF($A33="","",ROUND(_xlfn.XLOOKUP($A33,'#现网数据参考'!$A:$A,'#现网数据参考'!P:P),0)) | D33: 3 | E33: 60 | F33: =ROUND(OFFSET('#现网数据参考'!$A$1,MATCH(OFFSET($A33,-MOD(ROW()-1,3),0),'#现网数据参考'!$A:$A,0)-1,MATCH(F$2&$E33,'#现网数据参考'!$3:$3,0)-1)*IF(OFFSET($A33,-MOD(ROW()-1,3),0)<=9,0.6,1),0) -> 23 | G33: =_xlfn.XLOOKUP(OFFSET($A33,-MOD(ROW()-1,3),0),'#出征索引'!A:A,'#出征索引'!B:B)+_xlfn.XLOOKUP(OFFSET($A33,-MOD(ROW()-1,3),0),'#出征索引'!A:A,'#出征索引'!C:C)*_xlfn.XLOOKUP(F33,'#出征索引'!E:E,'#出征索引'!F:F) -> 7800 | H33: =ROUND(OFFSET('#现网数据参考'!$A$1,MATCH(OFFSET($A33,-MOD(ROW()-1,3),0),'#现网数据参考'!$A:$A,0)-1,MATCH(H$2&$E33,'#现网数据参考'!$3:$3,0)-1)*IF(OFFSET($A33,-MOD(ROW()-1,3),0)<=9,0.6,1),0) -> 12 | I33: =ROUND(OFFSET('#现网数据参考'!$A$1,MATCH(OFFSET($A33,-MOD(ROW()-1,3),0),'#现网数据参考'!$A:$A,0)-1,MATCH(I$2&$E33,'#现网数据参考'!$3:$3,0)-1)*IF(OFFSET($A33,-MOD(ROW()-1,3),0)<=9,0.6,1),0) -> 7 | J33: =ROUND(OFFSET('#现网数据参考'!$A$1,MATCH(OFFSET($A33,-MOD(ROW()-1,3),0),'#现网数据参考'!$A:$A,0)-1,MATCH(J$2&$E33,'#现网数据参考'!$3:$3,0)-1)*IF(OFFSET($A33,-MOD(ROW()-1,3),0)<=9,0.6,1),0) -> 8 | K33: =ROUND(OFFSET('#现网数据参考'!$A$1,MATCH(OFFSET($A33,-MOD(ROW()-1,3),0),'#现网数据参考'!$A:$A,0)-1,MATCH(K$2&$E33,'#现网数据参考'!$3:$3,0)-1)*IF(OFFSET($A33,-MOD(ROW()-1,3),0)<=9,0.6,1),0) -> 0 | L33: =ROUND(OFFSET('#现网数据参考'!$A$1,MATCH(OFFSET($A33,-MOD(ROW()-1,3),0),'#现网数据参考'!$A:$A,0)-1,MATCH(L$2&$E33,'#现网数据参考'!$3:$3,0)-1),0) -> 3
A34: 11 | B34: =IF($A34="","",ROUND(_xlfn.XLOOKUP($A34,'#现网数据参考'!$A:$A,'#现网数据参考'!G:G)*IF($A34<=9,0.5,1),0)) -> 266852 | C34: =IF($A34="","",ROUND(_xlfn.XLOOKUP($A34,'#现网数据参考'!$A:$A,'#现网数据参考'!P:P),0)) -> 2 | D34: 1 | E34: 20 | F34: =ROUND(OFFSET('#现网数据参考'!$A$1,MATCH(OFFSET($A34,-MOD(ROW()-1,3),0),'#现网数据参考'!$A:$A,0)-1,MATCH(F$2&$E34,'#现网数据参考'!$3:$3,0)-1)*IF(OFFSET($A34,-MOD(ROW()-1,3),0)<=9,0.6,1),0) -> 21 | G34: =_xlfn.XLOOKUP(OFFSET($A34,-MOD(ROW()-1,3),0),'#出征索引'!A:A,'#出征索引'!B:B)+_xlfn.XLOOKUP(OFFSET($A34,-MOD(ROW()-1,3),0),'#出征索引'!A:A,'#出征索引'!C:C)*_xlfn.XLOOKUP(F34,'#出征索引'!E:E,'#出征索引'!F:F) -> 8400 | H34: =ROUND(OFFSET('#现网数据参考'!$A$1,MATCH(OFFSET($A34,-MOD(ROW()-1,3),0),'#现网数据参考'!$A:$A,0)-1,MATCH(H$2&$E34,'#现网数据参考'!$3:$3,0)-1)*IF(OFFSET($A34,-MOD(ROW()-1,3),0)<=9,0.6,1),0) -> 9 | I34: =ROUND(OFFSET('#现网数据参考'!$A$1,MATCH(OFFSET($A34,-MOD(ROW()-1,3),0),'#现网数据参考'!$A:$A,0)-1,MATCH(I$2&$E34,'#现网数据参考'!$3:$3,0)-1)*IF(OFFSET($A34,-MOD(ROW()-1,3),0)<=9,0.6,1),0) -> 7 | J34: =ROUND(OFFSET('#现网数据参考'!$A$1,MATCH(OFFSET($A34,-MOD(ROW()-1,3),0),'#现网数据参考'!$A:$A,0)-1,MATCH(J$2&$E34,'#现网数据参考'!$3:$3,0)-1)*IF(OFFSET($A34,-MOD(ROW()-1,3),0)<=9,0.6,1),0) -> 6 | K34: =ROUND(OFFSET('#现网数据参考'!$A$1,MATCH(OFFSET($A34,-MOD(ROW()-1,3),0),'#现网数据参考'!$A:$A,0)-1,MATCH(K$2&$E34,'#现网数据参考'!$3:$3,0)-1)*IF(OFFSET($A34,-MOD(ROW()-1,3),0)<=9,0.6,1),0) -> 0 | L34: =ROUND(OFFSET('#现网数据参考'!$A$1,MATCH(OFFSET($A34,-MOD(ROW()-1,3),0),'#现网数据参考'!$A:$A,0)-1,MATCH(L$2&$E34,'#现网数据参考'!$3:$3,0)-1),0) -> 3
B35: =IF($A35="","",ROUND(_xlfn.XLOOKUP($A35,'#现网数据参考'!$A:$A,'#现网数据参考'!G:G)*IF($A35<=9,0.5,1),0)) | C35: =IF($A35="","",ROUND(_xlfn.XLOOKUP($A35,'#现网数据参考'!$A:$A,'#现网数据参考'!P:P),0)) | D35: 2 | E35: 40 | F35: =ROUND(OFFSET('#现网数据参考'!$A$1,MATCH(OFFSET($A35,-MOD(ROW()-1,3),0),'#现网数据参考'!$A:$A,0)-1,MATCH(F$2&$E35,'#现网数据参考'!$3:$3,0)-1)*IF(OFFSET($A35,-MOD(ROW()-1,3),0)<=9,0.6,1),0) -> 25 | G35: =_xlfn.XLOOKUP(OFFSET($A35,-MOD(ROW()-1,3),0),'#出征索引'!A:A,'#出征索引'!B:B)+_xlfn.XLOOKUP(OFFSET($A35,-MOD(ROW()-1,3),0),'#出征索引'!A:A,'#出征索引'!C:C)*_xlfn.XLOOKUP(F35,'#出征索引'!E:E,'#出征索引'!F:F) -> 9200 | H35: =ROUND(OFFSET('#现网数据参考'!$A$1,MATCH(OFFSET($A35,-MOD(ROW()-1,3),0),'#现网数据参考'!$A:$A,0)-1,MATCH(H$2&$E35,'#现网数据参考'!$3:$3,0)-1)*IF(OFFSET($A35,-MOD(ROW()-1,3),0)<=9,0.6,1),0) -> 13 | I35: =ROUND(OFFSET('#现网数据参考'!$A$1,MATCH(OFFSET($A35,-MOD(ROW()-1,3),0),'#现网数据参考'!$A:$A,0)-1,MATCH(I$2&$E35,'#现网数据参考'!$3:$3,0)-1)*IF(OFFSET($A35,-MOD(ROW()-1,3),0)<=9,0.6,1),0) -> 8 | J35: =ROUND(OFFSET('#现网数据参考'!$A$1,MATCH(OFFSET($A35,-MOD(ROW()-1,3),0),'#现网数据参考'!$A:$A,0)-1,MATCH(J$2&$E35,'#现网数据参考'!$3:$3,0)-1)*IF(OFFSET($A35,-MOD(ROW()-1,3),0)<=9,0.6,1),0) -> 8 | K35: =ROUND(OFFSET('#现网数据参考'!$A$1,MATCH(OFFSET($A35,-MOD(ROW()-1,3),0),'#现网数据参考'!$A:$A,0)-1,MATCH(K$2&$E35,'#现网数据参考'!$3:$3,0)-1)*IF(OFFSET($A35,-MOD(ROW()-1,3),0)<=9,0.6,1),0) -> 0 | L35: =ROUND(OFFSET('#现网数据参考'!$A$1,MATCH(OFFSET($A35,-MOD(ROW()-1,3),0),'#现网数据参考'!$A:$A,0)-1,MATCH(L$2&$E35,'#现网数据参考'!$3:$3,0)-1),0) -> 3
B36: =IF($A36="","",ROUND(_xlfn.XLOOKUP($A36,'#现网数据参考'!$A:$A,'#现网数据参考'!G:G)*IF($A36<=9,0.5,1),0)) | C36: =IF($A36="","",ROUND(_xlfn.XLOOKUP($A36,'#现网数据参考'!$A:$A,'#现网数据参考'!P:P),0)) | D36: 3 | E36: 60 | F36: =ROUND(OFFSET('#现网数据参考'!$A$1,MATCH(OFFSET($A36,-MOD(ROW()-1,3),0),'#现网数据参考'!$A:$A,0)-1,MATCH(F$2&$E36,'#现网数据参考'!$3:$3,0)-1)*IF(OFFSET($A36,-MOD(ROW()-1,3),0)<=9,0.6,1),0) -> 28 | G36: =_xlfn.XLOOKUP(OFFSET($A36,-MOD(ROW()-1,3),0),'#出征索引'!A:A,'#出征索引'!B:B)+_xlfn.XLOOKUP(OFFSET($A36,-MOD(ROW()-1,3),0),'#出征索引'!A:A,'#出征索引'!C:C)*_xlfn.XLOOKUP(F36,'#出征索引'!E:E,'#出征索引'!F:F) -> 9800 | H36: =ROUND(OFFSET('#现网数据参考'!$A$1,MATCH(OFFSET($A36,-MOD(ROW()-1,3),0),'#现网数据参考'!$A:$A,0)-1,MATCH(H$2&$E36,'#现网数据参考'!$3:$3,0)-1)*IF(OFFSET($A36,-MOD(ROW()-1,3),0)<=9,0.6,1),0) -> 17 | I36: =ROUND(OFFSET('#现网数据参考'!$A$1,MATCH(OFFSET($A36,-MOD(ROW()-1,3),0),'#现网数据参考'!$A:$A,0)-1,MATCH(I$2&$E36,'#现网数据参考'!$3:$3,0)-1)*IF(OFFSET($A36,-MOD(ROW()-1,3),0)<=9,0.6,1),0) -> 8 | J36: =ROUND(OFFSET('#现网数据参考'!$A$1,MATCH(OFFSET($A36,-MOD(ROW()-1,3),0),'#现网数据参考'!$A:$A,0)-1,MATCH(J$2&$E36,'#现网数据参考'!$3:$3,0)-1)*IF(OFFSET($A36,-MOD(ROW()-1,3),0)<=9,0.6,1),0) -> 10 | K36: =ROUND(OFFSET('#现网数据参考'!$A$1,MATCH(OFFSET($A36,-MOD(ROW()-1,3),0),'#现网数据参考'!$A:$A,0)-1,MATCH(K$2&$E36,'#现网数据参考'!$3:$3,0)-1)*IF(OFFSET($A36,-MOD(ROW()-1,3),0)<=9,0.6,1),0) -> 0 | L36: =ROUND(OFFSET('#现网数据参考'!$A$1,MATCH(OFFSET($A36,-MOD(ROW()-1,3),0),'#现网数据参考'!$A:$A,0)-1,MATCH(L$2&$E36,'#现网数据参考'!$3:$3,0)-1),0) -> 3
A37: 12 | B37: =IF($A37="","",ROUND(_xlfn.XLOOKUP($A37,'#现网数据参考'!$A:$A,'#现网数据参考'!G:G)*IF($A37<=9,0.5,1),0)) -> 368589 | C37: =IF($A37="","",ROUND(_xlfn.XLOOKUP($A37,'#现网数据参考'!$A:$A,'#现网数据参考'!P:P),0)) -> 2 | D37: 1 | E37: 20 | F37: =ROUND(OFFSET('#现网数据参考'!$A$1,MATCH(OFFSET($A37,-MOD(ROW()-1,3),0),'#现网数据参考'!$A:$A,0)-1,MATCH(F$2&$E37,'#现网数据参考'!$3:$3,0)-1)*IF(OFFSET($A37,-MOD(ROW()-1,3),0)<=9,0.6,1),0) -> 22 | G37: =_xlfn.XLOOKUP(OFFSET($A37,-MOD(ROW()-1,3),0),'#出征索引'!A:A,'#出征索引'!B:B)+_xlfn.XLOOKUP(OFFSET($A37,-MOD(ROW()-1,3),0),'#出征索引'!A:A,'#出征索引'!C:C)*_xlfn.XLOOKUP(F37,'#出征索引'!E:E,'#出征索引'!F:F) -> 14200 | H37: =ROUND(OFFSET('#现网数据参考'!$A$1,MATCH(OFFSET($A37,-MOD(ROW()-1,3),0),'#现网数据参考'!$A:$A,0)-1,MATCH(H$2&$E37,'#现网数据参考'!$3:$3,0)-1)*IF(OFFSET($A37,-MOD(ROW()-1,3),0)<=9,0.6,1),0) -> 14 | I37: =ROUND(OFFSET('#现网数据参考'!$A$1,MATCH(OFFSET($A37,-MOD(ROW()-1,3),0),'#现网数据参考'!$A:$A,0)-1,MATCH(I$2&$E37,'#现网数据参考'!$3:$3,0)-1)*IF(OFFSET($A37,-MOD(ROW()-1,3),0)<=9,0.6,1),0) -> 8 | J37: =ROUND(OFFSET('#现网数据参考'!$A$1,MATCH(OFFSET($A37,-MOD(ROW()-1,3),0),'#现网数据参考'!$A:$A,0)-1,MATCH(J$2&$E37,'#现网数据参考'!$3:$3,0)-1)*IF(OFFSET($A37,-MOD(ROW()-1,3),0)<=9,0.6,1),0) -> 7 | K37: =ROUND(OFFSET('#现网数据参考'!$A$1,MATCH(OFFSET($A37,-MOD(ROW()-1,3),0),'#现网数据参考'!$A:$A,0)-1,MATCH(K$2&$E37,'#现网数据参考'!$3:$3,0)-1)*IF(OFFSET($A37,-MOD(ROW()-1,3),0)<=9,0.6,1),0) -> 0 | L37: =ROUND(OFFSET('#现网数据参考'!$A$1,MATCH(OFFSET($A37,-MOD(ROW()-1,3),0),'#现网数据参考'!$A:$A,0)-1,MATCH(L$2&$E37,'#现网数据参考'!$3:$3,0)-1),0) -> 3
B38: =IF($A38="","",ROUND(_xlfn.XLOOKUP($A38,'#现网数据参考'!$A:$A,'#现网数据参考'!G:G)*IF($A38<=9,0.5,1),0)) | C38: =IF($A38="","",ROUND(_xlfn.XLOOKUP($A38,'#现网数据参考'!$A:$A,'#现网数据参考'!P:P),0)) | D38: 2 | E38: 40 | F38: =ROUND(OFFSET('#现网数据参考'!$A$1,MATCH(OFFSET($A38,-MOD(ROW()-1,3),0),'#现网数据参考'!$A:$A,0)-1,MATCH(F$2&$E38,'#现网数据参考'!$3:$3,0)-1)*IF(OFFSET($A38,-MOD(ROW()-1,3),0)<=9,0.6,1),0) -> 25 | G38: =_xlfn.XLOOKUP(OFFSET($A38,-MOD(ROW()-1,3),0),'#出征索引'!A:A,'#出征索引'!B:B)+_xlfn.XLOOKUP(OFFSET($A38,-MOD(ROW()-1,3),0),'#出征索引'!A:A,'#出征索引'!C:C)*_xlfn.XLOOKUP(F38,'#出征索引'!E:E,'#出征索引'!F:F) -> 15400 | H38: =ROUND(OFFSET('#现网数据参考'!$A$1,MATCH(OFFSET($A38,-MOD(ROW()-1,3),0),'#现网数据参考'!$A:$A,0)-1,MATCH(H$2&$E38,'#现网数据参考'!$3:$3,0)-1)*IF(OFFSET($A38,-MOD(ROW()-1,3),0)<=9,0.6,1),0) -> 19 | I38: =ROUND(OFFSET('#现网数据参考'!$A$1,MATCH(OFFSET($A38,-MOD(ROW()-1,3),0),'#现网数据参考'!$A:$A,0)-1,MATCH(I$2&$E38,'#现网数据参考'!$3:$3,0)-1)*IF(OFFSET($A38,-MOD(ROW()-1,3),0)<=9,0.6,1),0) -> 9 | J38: =ROUND(OFFSET('#现网数据参考'!$A$1,MATCH(OFFSET($A38,-MOD(ROW()-1,3),0),'#现网数据参考'!$A:$A,0)-1,MATCH(J$2&$E38,'#现网数据参考'!$3:$3,0)-1)*IF(OFFSET($A38,-MOD(ROW()-1,3),0)<=9,0.6,1),0) -> 9 | K38: =ROUND(OFFSET('#现网数据参考'!$A$1,MATCH(OFFSET($A38,-MOD(ROW()-1,3),0),'#现网数据参考'!$A:$A,0)-1,MATCH(K$2&$E38,'#现网数据参考'!$3:$3,0)-1)*IF(OFFSET($A38,-MOD(ROW()-1,3),0)<=9,0.6,1),0) -> 0 | L38: =ROUND(OFFSET('#现网数据参考'!$A$1,MATCH(OFFSET($A38,-MOD(ROW()-1,3),0),'#现网数据参考'!$A:$A,0)-1,MATCH(L$2&$E38,'#现网数据参考'!$3:$3,0)-1),0) -> 3
B39: =IF($A39="","",ROUND(_xlfn.XLOOKUP($A39,'#现网数据参考'!$A:$A,'#现网数据参考'!G:G)*IF($A39<=9,0.5,1),0)) | C39: =IF($A39="","",ROUND(_xlfn.XLOOKUP($A39,'#现网数据参考'!$A:$A,'#现网数据参考'!P:P),0)) | D39: 3 | E39: 60 | F39: =ROUND(OFFSET('#现网数据参考'!$A$1,MATCH(OFFSET($A39,-MOD(ROW()-1,3),0),'#现网数据参考'!$A:$A,0)-1,MATCH(F$2&$E39,'#现网数据参考'!$3:$3,0)-1)*IF(OFFSET($A39,-MOD(ROW()-1,3),0)<=9,0.6,1),0) -> 29 | G39: =_xlfn.XLOOKUP(OFFSET($A39,-MOD(ROW()-1,3),0),'#出征索引'!A:A,'#出征索引'!B:B)+_xlfn.XLOOKUP(OFFSET($A39,-MOD(ROW()-1,3),0),'#出征索引'!A:A,'#出征索引'!C:C)*_xlfn.XLOOKUP(F39,'#出征索引'!E:E,'#出征索引'!F:F) -> 17000 | H39: =ROUND(OFFSET('#现网数据参考'!$A$1,MATCH(OFFSET($A39,-MOD(ROW()-1,3),0),'#现网数据参考'!$A:$A,0)-1,MATCH(H$2&$E39,'#现网数据参考'!$3:$3,0)-1)*IF(OFFSET($A39,-MOD(ROW()-1,3),0)<=9,0.6,1),0) -> 23 | I39: =ROUND(OFFSET('#现网数据参考'!$A$1,MATCH(OFFSET($A39,-MOD(ROW()-1,3),0),'#现网数据参考'!$A:$A,0)-1,MATCH(I$2&$E39,'#现网数据参考'!$3:$3,0)-1)*IF(OFFSET($A39,-MOD(ROW()-1,3),0)<=9,0.6,1),0) -> 9 | J39: =ROUND(OFFSET('#现网数据参考'!$A$1,MATCH(OFFSET($A39,-MOD(ROW()-1,3),0),'#现网数据参考'!$A:$A,0)-1,MATCH(J$2&$E39,'#现网数据参考'!$3:$3,0)-1)*IF(OFFSET($A39,-MOD(ROW()-1,3),0)<=9,0.6,1),0) -> 10 | K39: =ROUND(OFFSET('#现网数据参考'!$A$1,MATCH(OFFSET($A39,-MOD(ROW()-1,3),0),'#现网数据参考'!$A:$A,0)-1,MATCH(K$2&$E39,'#现网数据参考'!$3:$3,0)-1)*IF(OFFSET($A39,-MOD(ROW()-1,3),0)<=9,0.6,1),0) -> 0 | L39: =ROUND(OFFSET('#现网数据参考'!$A$1,MATCH(OFFSET($A39,-MOD(ROW()-1,3),0),'#现网数据参考'!$A:$A,0)-1,MATCH(L$2&$E39,'#现网数据参考'!$3:$3,0)-1),0) -> 3
A40: 13 | B40: =IF($A40="","",ROUND(_xlfn.XLOOKUP($A40,'#现网数据参考'!$A:$A,'#现网数据参考'!G:G)*IF($A40<=9,0.5,1),0)) -> 498578 | C40: =IF($A40="","",ROUND(_xlfn.XLOOKUP($A40,'#现网数据参考'!$A:$A,'#现网数据参考'!P:P),0)) -> 3 | D40: 1 | E40: 20 | F40: =ROUND(OFFSET('#现网数据参考'!$A$1,MATCH(OFFSET($A40,-MOD(ROW()-1,3),0),'#现网数据参考'!$A:$A,0)-1,MATCH(F$2&$E40,'#现网数据参考'!$3:$3,0)-1)*IF(OFFSET($A40,-MOD(ROW()-1,3),0)<=9,0.6,1),0) -> 25 | G40: =_xlfn.XLOOKUP(OFFSET($A40,-MOD(ROW()-1,3),0),'#出征索引'!A:A,'#出征索引'!B:B)+_xlfn.XLOOKUP(OFFSET($A40,-MOD(ROW()-1,3),0),'#出征索引'!A:A,'#出征索引'!C:C)*_xlfn.XLOOKUP(F40,'#出征索引'!E:E,'#出征索引'!F:F) -> 16400 | H40: =ROUND(OFFSET('#现网数据参考'!$A$1,MATCH(OFFSET($A40,-MOD(ROW()-1,3),0),'#现网数据参考'!$A:$A,0)-1,MATCH(H$2&$E40,'#现网数据参考'!$3:$3,0)-1)*IF(OFFSET($A40,-MOD(ROW()-1,3),0)<=9,0.6,1),0) -> 21 | I40: =ROUND(OFFSET('#现网数据参考'!$A$1,MATCH(OFFSET($A40,-MOD(ROW()-1,3),0),'#现网数据参考'!$A:$A,0)-1,MATCH(I$2&$E40,'#现网数据参考'!$3:$3,0)-1)*IF(OFFSET($A40,-MOD(ROW()-1,3),0)<=9,0.6,1),0) -> 9 | J40: =ROUND(OFFSET('#现网数据参考'!$A$1,MATCH(OFFSET($A40,-MOD(ROW()-1,3),0),'#现网数据参考'!$A:$A,0)-1,MATCH(J$2&$E40,'#现网数据参考'!$3:$3,0)-1)*IF(OFFSET($A40,-MOD(ROW()-1,3),0)<=9,0.6,1),0) -> 8 | K40: =ROUND(OFFSET('#现网数据参考'!$A$1,MATCH(OFFSET($A40,-MOD(ROW()-1,3),0),'#现网数据参考'!$A:$A,0)-1,MATCH(K$2&$E40,'#现网数据参考'!$3:$3,0)-1)*IF(OFFSET($A40,-MOD(ROW()-1,3),0)<=9,0.6,1),0) -> 0 | L40: =ROUND(OFFSET('#现网数据参考'!$A$1,MATCH(OFFSET($A40,-MOD(ROW()-1,3),0),'#现网数据参考'!$A:$A,0)-1,MATCH(L$2&$E40,'#现网数据参考'!$3:$3,0)-1),0) -> 3
...

Sheet #现网数据参考
B1: 战斗力 | C1: 战斗力 | D1: 战斗力 | E1: 战斗力 | F1: 战斗力 | G1: 战斗力 | H1: 战斗力 | I1: 战斗力 | J1: 战斗力 | K1: 解锁的士兵等级 | L1: 解锁的士兵等级 | M1: 解锁的士兵等级 | N1: 解锁的士兵等级 | O1: 解锁的士兵等级 | P1: 解锁的士兵等级 | Q1: 解锁的士兵等级 | R1: 解锁的士兵等级 | S1: 解锁的士兵等级 | T1: 已研究科技数量 | U1: 已研究科技数量 | V1: 已研究科技数量 | W1: 已研究科技数量 | X1: 已研究科技数量 | Y1: 已研究科技数量 | Z1: 已研究科技数量 | AA1: 已研究科技数量 | AB1: 已研究科技数量 | AC1: 已解锁部队数量 | AD1: 已解锁部队数量 | AE1: 已解锁部队数量 | AF1: 已解锁部队数量 | AG1: 已解锁部队数量 | AH1: 已解锁部队数量 | AI1: 已解锁部队数量 | AJ1: 已解锁部队数量 | AK1: 已解锁部队数量 | AL1: 已穿戴装备数量 | AM1: 已穿戴装备数量 | AN1: 已穿戴装备数量 | AO1: 已穿戴装备数量 | AP1: 已穿戴装备数量 | AQ1: 已穿戴装备数量 | AR1: 已穿戴装备数量 | AS1: 已穿戴装备数量 | AT1: 已穿戴装备数量 | AU1: 已解锁建筑平均等级 | AV1: 已解锁建筑平均等级 | AW1: 已解锁建筑平均等级 | AX1: 已解锁建筑平均等级 | AY1: 已解锁建筑平均等级 | AZ1: 已解锁建筑平均等级 | BA1: 已解锁建筑平均等级 | BB1: 已解锁建筑平均等级 | BC1: 已解锁建筑平均等级 | BD1: 上阵英雄平均等级 | BE1: 上阵英雄平均等级 | BF1: 上阵英雄平均等级 | BG1: 上阵英雄平均等级 | BH1: 上阵英雄平均等级 | BI1: 上阵英雄平均等级 | BJ1: 上阵英雄平均等级 | BK1: 上阵英雄平均等级 | BL1: 上阵英雄平均等级 | BM1: 上阵英雄平均技能等级 | BN1: 上阵英雄平均技能等级 | BO1: 上阵英雄平均技能等级 | BP1: 上阵英雄平均技能等级 | BQ1: 上阵英雄平均技能等级 | BR1: 上阵英雄平均技能等级 | BS1: 上阵英雄平均技能等级 | BT1: 上阵英雄平均技能等级 | BU1: 上阵英雄平均技能等级
B2: 10 | C2: 20 | D2: 30 | E2: 40 | F2: 50 | G2: 60 | H2: 70 | I2: 80 | J2: 90 | K2: 10 | L2: 20 | M2: 30 | N2: 40 | O2: 50 | P2: 60 | Q2: 70 | R2: 80 | S2: 90 | T2: 10 | U2: 20 | V2: 30 | W2: 40 | X2: 50 | Y2: 60 | Z2: 70 | AA2: 80 | AB2: 90 | AC2: 10 | AD2: 20 | AE2: 30 | AF2: 40 | AG2: 50 | AH2: 60 | AI2: 70 | AJ2: 80 | AK2: 90 | AL2: 10 | AM2: 20 | AN2: 30 | AO2: 40 | AP2: 50 | AQ2: 60 | AR2: 70 | AS2: 80 | AT2: 90 | AU2: 10 | AV2: 20 | AW2: 30 | AX2: 40 | AY2: 50 | AZ2: 60 | BA2: 70 | BB2: 80 | BC2: 90 | BD2: 10 | BE2: 20 | BF2: 30 | BG2: 40 | BH2: 50 | BI2: 60 | BJ2: 70 | BK2: 80 | BL2: 90 | BM2: 10 | BN2: 20 | BO2: 30 | BP2: 40 | BQ2: 50 | BR2: 60 | BS2: 70 | BT2: 80 | BU2: 90
B3: =B1&B2 -> 战斗力10 | C3: =C1&C2 -> 战斗力20 | D3: =D1&D2 -> 战斗力30 | E3: =E1&E2 -> 战斗力40 | F3: =F1&F2 -> 战斗力50 | G3: =G1&G2 -> 战斗力60 | H3: =H1&H2 -> 战斗力70 | I3: =I1&I2 -> 战斗力80 | ... BU3: =BU1&BU2 -> 上阵英雄平均技能等级90
A4: CastleLevel | B4: power_10_percentile | C4: power_20_percentile | D4: power_30_percentile | E4: power_40_percentile | F4: power_50_percentile | G4: power_60_percentile | H4: power_70_percentile | I4: power_80_percentile | J4: power_90_percentile | K4: SoldierLevel_10_percentile | L4: SoldierLevel_20_percentile | M4: SoldierLevel_30_percentile | N4: SoldierLevel_40_percentile | O4: SoldierLevel_50_percentile | P4: SoldierLevel_60_percentile | Q4: SoldierLevel_70_percentile | R4: SoldierLevel_80_percentile | S4: SoldierLevel_90_percentile | T4: tech_count_10_percentile | U4: tech_count_20_percentile | V4: tech_count_30_percentile | W4: tech_count_40_percentile | X4: tech_count_50_percentile | Y4: tech_count_60_percentile | Z4: tech_count_70_percentile | AA4: tech_count_80_percentile | AB4: tech_count_90_percentile | AC4: marchQueueCnt_10_percentile | AD4: marchQueueCnt_20_percentile | AE4: marchQueueCnt_30_percentile | AF4: marchQueueCnt_40_percentile | AG4: marchQueueCnt_50_percentile | AH4: marchQueueCnt_60_percentile | AI4: marchQueueCnt_70_percentile | AJ4: marchQueueCnt_80_percentile | AK4: marchQueueCnt_90_percentile | AL4: EquipNum_10_percentile | AM4: EquipNum_20_percentile | AN4: EquipNum_30_percentile | AO4: EquipNum_40_percentile | AP4: EquipNum_50_percentile | AQ4: EquipNum_60_percentile | AR4: EquipNum_70_percentile | AS4: EquipNum_80_percentile | AT4: EquipNum_90_percentile | AU4: building_avg_level_10_percentile | AV4: building_avg_level_20_percentile | AW4: building_avg_level_30_percentile | AX4: building_avg_level_40_percentile | AY4: building_avg_level_50_percentile | AZ4: building_avg_level_60_percentile | BA4: building_avg_level_70_percentile | BB4: building_avg_level_80_percentile | BC4: building_avg_level_90_percentile | BD4: HeroAvgLevel_10_percentile | BE4: HeroAvgLevel_20_percentile | BF4: HeroAvgLevel_30_percentile | BG4: HeroAvgLevel_40_percentile | BH4: HeroAvgLevel_50_percentile | BI4: HeroAvgLevel_60_percentile | BJ4: HeroAvgLevel_70_percentile | BK4: HeroAvgLevel_80_percentile | BL4: HeroAvgLevel_90_percentile | BM4: HeroAvgSkillLevel_10_percentile | BN4: HeroAvgSkillLevel_20_percentile | BO4: HeroAvgSkillLevel_30_percentile | BP4: HeroAvgSkillLevel_40_percentile | BQ4: HeroAvgSkillLevel_50_percentile | BR4: HeroAvgSkillLevel_60_percentile | BS4: HeroAvgSkillLevel_70_percentile | BT4: HeroAvgSkillLevel_80_percentile | BU4: HeroAvgSkillLevel_90_percentile
A5: 1 | B5: 11209 | C5: 11395 | D5: 11581 | E5: 11766 | F5: 11952 | G5: 12137 | H5: 12323 | I5: 12509 | J5: 27625 | K5: 1 | L5: 1 | M5: 1 | N5: 1 | O5: 1 | P5: 1 | Q5: 1.18 | R5: 1.45 | S5: 1.73 | T5: 2 | U5: 2 | V5: 2.08 | W5: 2.35 | X5: 2.63 | Y5: 2.9 | Z5: 4.4 | AA5: 5.8 | AB5: 6.9 | AC5: 3 | AD5: 3 | AE5: 3 | AF5: 3 | AG5: 3 | AH5: 3 | AI5: 3 | AJ5: 3 | AK5: 3 | AU5: 1 | AV5: 1 | AW5: 1 | AX5: 1 | AY5: 1 | AZ5: 1 | BA5: 1 | BB5: 1 | BC5: 1 | BD5: 1 | BE5: 1 | BF5: 1 | BG5: 1 | BH5: 1 | BI5: 1 | BJ5: 1 | BK5: 1 | BL5: 1 | BM5: 0.73 | BN5: 0.9 | BO5: 1.57 | BP5: 2.5 | BQ5: 3.33 | BR5: 4.03 | BS5: 5.28 | BT5: 5.97 | BU5: 6.32
A6: 2 | B6: 27646 | C6: 27665 | D6: 27666 | E6: 27666 | F6: 27685 | G6: 27686 | H6: 37417 | I6: 38666 | J6: 38685 | K6: 1 | L6: 1 | M6: 1 | N6: 1 | O6: 1 | P6: 1 | Q6: 1 | R6: 1 | S6: 1.5 | T6: 2 | U6: 2 | V6: 2.17 | W6: 2.33 | X6: 2.5 | Y6: 2.67 | Z6: 2.83 | AA6: 3 | AB6: 5 | AC6: 3 | AD6: 3 | AE6: 3 | AF6: 3 | AG6: 3 | AH6: 3 | AI6: 3 | AJ6: 3 | AK6: 3 | AU6: 1.11 | AV6: 1.11 | AW6: 1.11 | AX6: 1.12 | AY6: 1.12 | AZ6: 1.12 | BA6: 1.12 | BB6: 1.12 | BC6: 1.22 | BD6: 1 | BE6: 1 | BF6: 1 | BG6: 1 | BH6: 1 | BI6: 1 | BJ6: 1 | BK6: 1 | BL6: 1 | BM6: 0.67 | BN6: 0.67 | BO6: 0.67 | BP6: 0.98 | BQ6: 2.22 | BR6: 3.47 | BS6: 4.71 | BT6: 5.67 | BU6: 6.43
