Workbook

Sheet 成就配置
A1: convert(ResSurvival.proto,table_SurvivalAccomplishmentConf,SurvivalAccomplishmentConf.pbin)
A2: 成就id | B2: 名称TID | C2: 名称文本 | D2: 描述TID | E2: 描述文本 | F2: 页签 | G2: 备注 | H2: 稀有度 | I2: 图集 | J2: 图标 | K2: 成就条件 | L2: 奖励id | M2: 成就点 | N2: 解锁内容底框样式 | O2: 解锁内容icon图集 | P2: 解锁内容icon | Q2: 解锁内容文本 | R2: 解锁备注 | S2: 图鉴跳转 | T2: 跳转塔罗牌Id | U2: 客户端是否Open控制 | V2: 客户端是否Open控制
A3: id | B3: name | D3: desc | F3: tab | H3: priority | I3: atlas | J3: icon | K3: conditionGroup.condition.condOneOf | L3: rewardId | M3: point | N3: unlock.type | O3: unlock.atlas | P3: unlock.icon | Q3: unlock.desc | S3: unlock.skillId | T3: unlockTarotId | U3: clientShowCondition.conditionRelation | V3: clientShowCondition.conditions[1].condOneOf
A4: 100101 | B4: TID_Survivor_Achievement_Name_100101 | C4: =INDEX([1]文本!$B:$B,MATCH(B4,[1]文本!$A:$A,0)) -> 穿越屏障 | D4: TID_Survivor_Achievement_Des_100101 | E4: =INDEX([1]文本!$B:$B,MATCH(D4,[1]文本!$A:$A,0)) -> 击败<color=#ffc766>图尔坎</color>和<color=#ffc766>投石车部队</color> | F4: 99 | H4: 3 | I4: icon_achievement | J4: icon_ordinary_056 | K4: winSurvivalGame{levelId:1001, count:1} | M4: 5
A5: 100102 | B5: TID_Survivor_Achievement_Name_100102 | C5: =INDEX([1]文本!$B:$B,MATCH(B5,[1]文本!$A:$A,0)) -> 直取敌营 | D5: TID_Survivor_Achievement_Des_100102 | E5: =INDEX([1]文本!$B:$B,MATCH(D5,[1]文本!$A:$A,0)) -> 击败<color=#ffc766>蒙杜克</color> | F5: 99 | H5: 3 | I5: icon_achievement | J5: icon_ordinary_085 | K5: winSurvivalGame{levelId:1002, count:1} | M5: 5
A6: 101001 | B6: TID_Survivor_Achievement_Name_110001 | C6: =INDEX([1]文本!$B:$B,MATCH(B6,[1]文本!$A:$A,0)) -> 蛮族克星 I | D6: TID_Survivor_Achievement_Des_110001 | E6: =INDEX([1]文本!$B:$B,MATCH(D6,[1]文本!$A:$A,0)) -> 累计击败<color=#ffc766>[%d1]</color>名敌人 | F6: 1 | H6: 3 | I6: icon_achievement | J6: icon_ordinary_122 | K6: killSurvivalMonster{count:20000} | M6: 10 | N6: 4 | O6: ui_g_icon | P6: pic_g_achievement_02 | Q6: TID_Survivor_Achievement_Unlock_3 | R6: 解锁<color=#ffc766>重新随机</color>功能，挑战时升级后有额外的重新随机机会
A7: 101002 | B7: TID_Survivor_Achievement_Name_110002 | C7: =INDEX([1]文本!$B:$B,MATCH(B7,[1]文本!$A:$A,0)) -> 蛮族克星 II | D7: TID_Survivor_Achievement_Des_110002 | E7: =INDEX([1]文本!$B:$B,MATCH(D7,[1]文本!$A:$A,0)) -> 累计击败<color=#ffc766>[%d1]</color>名敌人 | F7: 1 | H7: 4 | I7: icon_achievement | J7: icon_ordinary_122 | K7: killSurvivalMonster{count:75000} | M7: 30 | N7: 32 | O7: icon_g_survivalskill | P7: icon_survivalskill_hong_005a | Q7: TID_Survivor_Achievement_Unlock_6 | R7: 解锁战法：<color=#ffc766>火壶抛掷</color>，可以在战地幸存者挑战时使用 | S7: 100506
A8: 101003 | B8: TID_Survivor_Achievement_Name_110003 | C8: =INDEX([1]文本!$B:$B,MATCH(B8,[1]文本!$A:$A,0)) -> 蛮族克星 III | D8: TID_Survivor_Achievement_Des_110003 | E8: =INDEX([1]文本!$B:$B,MATCH(D8,[1]文本!$A:$A,0)) -> 累计击败<color=#ffc766>[%d1]</color>名敌人 | F8: 1 | H8: 5 | I8: icon_achievement | J8: icon_ordinary_122 | K8: killSurvivalMonster{count:100000} | M8: 50
A9: 101004 | B9: TID_Survivor_Achievement_Name_110010 | C9: 蛮族克星 IIII | D9: TID_Survivor_Achievement_Des_110010 | E9: 累计击败<color=#ffc766>[%d1]</color>名敌人 | F9: 1 | H9: 5 | I9: icon_achievement | J9: icon_ordinary_122 | K9: killSurvivalMonster{count:150000} | M9: 70
A10: 101005 | B10: TID_Survivor_Achievement_Name_110011 | C10: 蛮族克星 IIIII | D10: TID_Survivor_Achievement_Des_110011 | E10: 累计击败<color=#ffc766>[%d1]</color>名敌人 | F10: 1 | H10: 5 | I10: icon_achievement | J10: icon_ordinary_122 | K10: killSurvivalMonster{count:200000} | M10: 100
A11: 110004 | B11: TID_Survivor_Achievement_Name_110004 | C11: =INDEX([1]文本!$B:$B,MATCH(B11,[1]文本!$A:$A,0)) -> 野蛮边陲 | D11: TID_Survivor_Achievement_Des_110004 | E11: =INDEX([1]文本!$B:$B,MATCH(D11,[1]文本!$A:$A,0)) -> 通过<color=#ffc766>第[%d1]章野蛮边陲</color>的全部普通关卡 | F11: 1 | H11: 4 | I11: icon_achievement | J11: icon_ordinary_117 | K11: winSurvivalGame{levelId:1002, count:1} | M11: 10 | N11: 32 | O11: icon_g_survivalskill | P11: icon_survivalskill_hong_001a | Q11: TID_Survivor_Achievement_Unlock_5 | R11: 解锁战法：<color=#ffc766>冰霜投石</color>，可以在战地幸存者挑战时使用 | S11: 100406
A12: 110005 | B12: TID_Survivor_Achievement_Name_110005 | C12: =INDEX([1]文本!$B:$B,MATCH(B12,[1]文本!$A:$A,0)) -> 死亡荒漠 | D12: TID_Survivor_Achievement_Des_110005 | E12: =INDEX([1]文本!$B:$B,MATCH(D12,[1]文本!$A:$A,0)) -> 通过<color=#ffc766>第[%d1]章死亡荒漠</color>的全部普通关卡 | F12: 1 | H12: 4 | I12: icon_achievement | J12: icon_ordinary_117 | K12: winSurvivalGame{levelId:2004, count:1} | M12: 30 | N12: 32 | O12: icon_g_survivalskill | P12: icon_survivalskill_hong_009a | Q12: TID_Survivor_Achievement_Unlock_4 | R12: 解锁战法：<color=#ffc766>讨罪经文</color>，可以在战地幸存者挑战时使用 | S12: 100806
A13: 110006 | B13: TID_Survivor_Achievement_Name_110006 | C13: =INDEX([1]文本!$B:$B,MATCH(B13,[1]文本!$A:$A,0)) -> 斗兽场 | D13: TID_Survivor_Achievement_Des_110006 | E13: =INDEX([1]文本!$B:$B,MATCH(D13,[1]文本!$A:$A,0)) -> 通过<color=#ffc766>第[%d1]章斗兽场</color>的全部普通关卡 | F13: 1 | H13: 4 | I13: icon_achievement | J13: icon_ordinary_117 | K13: winSurvivalGame{levelId:3004, count:1} | M13: 50 | N13: 32 | O13: icon_g_survivalskill | P13: icon_survivalskill_hong_014a | Q13: TID_Survivor_Achievement_Unlock_7 | R13: 解锁战法：<color=#ffc766>野蛮冲撞</color>，可以在战地幸存者挑战时使用 | S13: 101506
A14: 110007 | B14: TID_Survivor_Achievement_Name_110007 | C14: =INDEX([1]文本!$B:$B,MATCH(B14,[1]文本!$A:$A,0)) -> 金字塔 | D14: TID_Survivor_Achievement_Des_110007 | E14: =INDEX([1]文本!$B:$B,MATCH(D14,[1]文本!$A:$A,0)) -> 通过<color=#ffc766>第[%d1]章金字塔</color>的全部普通关卡 | F14: 1 | H14: 4 | I14: icon_achievement | J14: icon_ordinary_117 | K14: winSurvivalGame{levelId:4004, count:1} | M14: 70
A15: 110008 | B15: TID_Survivor_Achievement_Name_110008 | C15: =INDEX([1]文本!$B:$B,MATCH(B15,[1]文本!$A:$A,0)) -> 狮身人面像 | D15: TID_Survivor_Achievement_Des_110008 | E15: =INDEX([1]文本!$B:$B,MATCH(D15,[1]文本!$A:$A,0)) -> 通过<color=#ffc766>第[%d1]章狮身人面像</color>的全部普通关卡 | F15: 1 | H15: 4 | I15: icon_achievement | J15: icon_ordinary_117 | K15: winSurvivalGame{levelId:5004, count:1} | M15: 100
A16: 110009 | B16: TID_Survivor_Achievement_Name_110009 | C16: 密林小径 | D16: TID_Survivor_Achievement_Des_110009 | E16: 通过第[%d1]章密林小径的全部普通关卡 | F16: 99 | H16: 4 | I16: icon_achievement | J16: icon_ordinary_117 | K16: winSurvivalGame{levelId:7003, count:1}
A17: 203601 | B17: TID_Survivor_Achievement_Name_203601 | C17: =INDEX([1]文本!$B:$B,MATCH(B17,[1]文本!$A:$A,0)) -> 约瑟芬历练 I | D17: TID_Survivor_Achievement_Des_203601 | E17: =INDEX([1]文本!$B:$B,MATCH(D17,[1]文本!$A:$A,0)) -> 使用<color=#ffc766>约瑟芬</color>获得<color=#ffc766>1</color>局战地幸存者的胜利 | F17: 2 | H17: 3 | I17: icon_achievement | J17: icon_ordinary_093 | K17: winSurvivalGame{mainHeroId:36, count:1} | M17: 30
A18: 203602 | B18: TID_Survivor_Achievement_Name_203602 | C18: =INDEX([1]文本!$B:$B,MATCH(B18,[1]文本!$A:$A,0)) -> 约瑟芬历练 II | D18: TID_Survivor_Achievement_Des_203602 | E18: =INDEX([1]文本!$B:$B,MATCH(D18,[1]文本!$A:$A,0)) -> 使用<color=#ffc766>约瑟芬</color>累计击败<color=#ffc766>[%d1]</color>名敌人 | F18: 2 | H18: 4 | I18: icon_achievement | J18: icon_ordinary_093 | K18: killSurvivalMonster{mainHeroId:36, count:10000} | M18: 50
A19: 203603 | B19: TID_Survivor_Achievement_Name_203603 | C19: =INDEX([1]文本!$B:$B,MATCH(B19,[1]文本!$A:$A,0)) -> 约瑟芬历练 III | D19: TID_Survivor_Achievement_Des_203603 | E19: =INDEX([1]文本!$B:$B,MATCH(D19,[1]文本!$A:$A,0)) -> 使用<color=#ffc766>约瑟芬</color>累计击败<color=#ffc766>[%d1]</color>名敌人 | F19: 2 | H19: 5 | I19: icon_achievement | J19: icon_ordinary_094 | K19: killSurvivalMonster{mainHeroId:36, count:20000} | M19: 100 | N19: 2 | O19: icon_g_survivalheroskill | P19: icon_survivalheroskill_009 | Q19: TID_Survivor_Achievement_Unlock_11 | R19: 解锁花木兰的主动技：<color=#ffc766>飞燕步法</color>
A20: 200101 | B20: TID_Survivor_Achievement_Name_200101 | C20: =INDEX([1]文本!$B:$B,MATCH(B20,[1]文本!$A:$A,0)) -> 贞德历练 I | D20: TID_Survivor_Achievement_Des_200101 | E20: =INDEX([1]文本!$B:$B,MATCH(D20,[1]文本!$A:$A,0)) -> 使用<color=#ffc766>贞德</color>获得<color=#ffc766>1</color>局战地幸存者的胜利 | F20: 2 | H20: 3 | I20: icon_achievement | J20: icon_ordinary_139 | K20: winSurvivalGame{mainHeroId:1, count:1} | M20: 30
A21: 200102 | B21: TID_Survivor_Achievement_Name_200102 | C21: =INDEX([1]文本!$B:$B,MATCH(B21,[1]文本!$A:$A,0)) -> 贞德历练 II | D21: TID_Survivor_Achievement_Des_200102 | E21: =INDEX([1]文本!$B:$B,MATCH(D21,[1]文本!$A:$A,0)) -> 使用<color=#ffc766>贞德</color>累计击败<color=#ffc766>[%d1]</color>名敌人 | F21: 2 | H21: 4 | I21: icon_achievement | J21: icon_ordinary_139 | K21: killSurvivalMonster{mainHeroId:1, count:10000} | M21: 50
A22: 200103 | B22: TID_Survivor_Achievement_Name_200103 | C22: =INDEX([1]文本!$B:$B,MATCH(B22,[1]文本!$A:$A,0)) -> 贞德历练 III | D22: TID_Survivor_Achievement_Des_200103 | E22: =INDEX([1]文本!$B:$B,MATCH(D22,[1]文本!$A:$A,0)) -> 使用<color=#ffc766>贞德</color>累计击败<color=#ffc766>[%d1]</color>名敌人 | F22: 2 | H22: 5 | I22: icon_achievement | J22: icon_ordinary_140 | K22: killSurvivalMonster{mainHeroId:1, count:20000} | M22: 100
A23: 201901 | B23: TID_Survivor_Achievement_Name_201901 | C23: =INDEX([1]文本!$B:$B,MATCH(B23,[1]文本!$A:$A,0)) -> 大流士一世历练 I | D23: TID_Survivor_Achievement_Des_201901 | E23: =INDEX([1]文本!$B:$B,MATCH(D23,[1]文本!$A:$A,0)) -> 使用<color=#ffc766>大流士一世</color>获得<color=#ffc766>1</color>局战地幸存者的胜利 | F23: 2 | H23: 3 | I23: icon_achievement | J23: icon_ordinary_142 | K23: winSurvivalGame{mainHeroId:19, count:1} | M23: 30
A24: 201902 | B24: TID_Survivor_Achievement_Name_201902 | C24: =INDEX([1]文本!$B:$B,MATCH(B24,[1]文本!$A:$A,0)) -> 大流士一世历练 II | D24: TID_Survivor_Achievement_Des_201902 | E24: =INDEX([1]文本!$B:$B,MATCH(D24,[1]文本!$A:$A,0)) -> 使用<color=#ffc766>大流士一世</color>累计击败<color=#ffc766>[%d1]</color>名敌人 | F24: 2 | H24: 4 | I24: icon_achievement | J24: icon_ordinary_142 | K24: killSurvivalMonster{mainHeroId:19, count:12000} | M24: 50
A25: 201903 | B25: TID_Survivor_Achievement_Name_201903 | C25: =INDEX([1]文本!$B:$B,MATCH(B25,[1]文本!$A:$A,0)) -> 大流士一世历练 III | D25: TID_Survivor_Achievement_Des_201903 | E25: =INDEX([1]文本!$B:$B,MATCH(D25,[1]文本!$A:$A,0)) -> 使用<color=#ffc766>大流士一世</color>累计击败<color=#ffc766>[%d1]</color>名敌人 | F25: 2 | H25: 5 | I25: icon_achievement | J25: icon_ordinary_143 | K25: killSurvivalMonster{mainHeroId:19, count:25000} | M25: 100
A26: 200901 | B26: TID_Survivor_Achievement_Name_110012 | C26: 花木兰历练 I | D26: TID_Survivor_Achievement_Des_110012 | E26: 使用<color=#ffc766>花木兰</color>获得<color=#ffc766>1</color>局战地幸存者的胜利 | F26: 2 | H26: 3 | I26: icon_achievement | J26: icon_ordinary_116 | K26: winSurvivalGame{mainHeroId:9, count:1} | M26: 30
A27: 200902 | B27: TID_Survivor_Achievement_Name_110013 | C27: 花木兰历练 II | D27: TID_Survivor_Achievement_Des_110013 | E27: 使用<color=#ffc766>花木兰</color>累计击败<color=#ffc766>[%d1]</color>名敌人 | F27: 2 | H27: 4 | I27: icon_achievement | J27: icon_ordinary_116 | K27: killSurvivalMonster{mainHeroId:9, count:10000} | M27: 50
A28: 200903 | B28: TID_Survivor_Achievement_Name_110014 | C28: 花木兰历练 III | D28: TID_Survivor_Achievement_Des_110014 | E28: 使用<color=#ffc766>花木兰</color>累计击败<color=#ffc766>[%d1]</color>名敌人 | F28: 2 | H28: 5 | I28: icon_achievement | J28: icon_ordinary_119 | K28: killSurvivalMonster{mainHeroId:9, count:20000} | M28: 100
A29: 201301 | B29: TID_Survivor_Achievement_Name_110015 | C29: 列奥尼达历练 I | D29: TID_Survivor_Achievement_Des_110015 | E29: 使用<color=#ffc766>列奥尼达</color>获得<color=#ffc766>1</color>局战地幸存者的胜利 | F29: 2 | H29: 3 | I29: icon_achievement | J29: icon_ordinary_120 | K29: winSurvivalGame{mainHeroId:13, count:1} | M29: 30
A30: 201302 | B30: TID_Survivor_Achievement_Name_110016 | C30: 列奥尼达历练 II | D30: TID_Survivor_Achievement_Des_110016 | E30: 使用<color=#ffc766>列奥尼达</color>累计击败<color=#ffc766>[%d1]</color>名敌人 | F30: 2 | H30: 4 | I30: icon_achievement | J30: icon_ordinary_120 | K30: killSurvivalMonster{mainHeroId:13, count:10000} | M30: 50
A31: 201303 | B31: TID_Survivor_Achievement_Name_110017 | C31: 列奥尼达历练 III | D31: TID_Survivor_Achievement_Des_110017 | E31: 使用<color=#ffc766>列奥尼达</color>累计击败<color=#ffc766>[%d1]</color>名敌人 | F31: 2 | H31: 5 | I31: icon_achievement | J31: icon_ordinary_121 | K31: killSurvivalMonster{mainHeroId:13, count:20000} | M31: 100
A32: 204201 | B32: TID_Survivor_Achievement_Name_204201 | C32: 理查一世历练 I | D32: TID_Survivor_Achievement_Des_204201 | E32: 使用<color=#ffc766>理查一世</color>获得<color=#ffc766>1</color>局战地幸存者的胜利 | F32: 2 | H32: 3 | I32: icon_achievement | J32: icon_ordinary_149 | K32: winSurvivalGame{mainHeroId:42, count:1} | M32: 30
A33: 204202 | B33: TID_Survivor_Achievement_Name_204202 | C33: 理查一世历练 II | D33: TID_Survivor_Achievement_Des_204202 | E33: 使用<color=#ffc766>理查一世</color>累计击败<color=#ffc766>[%d1]</color>名敌人 | F33: 2 | H33: 4 | I33: icon_achievement | J33: icon_ordinary_149 | K33: killSurvivalMonster{mainHeroId:42, count:10000} | M33: 50
A34: 204203 | B34: TID_Survivor_Achievement_Name_204203 | C34: 理查一世历练 III | D34: TID_Survivor_Achievement_Des_204203 | E34: 使用<color=#ffc766>理查一世</color>累计击败<color=#ffc766>[%d1]</color>名敌人 | F34: 2 | H34: 5 | I34: icon_achievement | J34: icon_ordinary_149 | K34: killSurvivalMonster{mainHeroId:42, count:20000} | M34: 100
A35: 300151 | B35: TID_Survivor_Achievement_Name_300151 | C35: =INDEX([1]文本!$B:$B,MATCH(B35,[1]文本!$A:$A,0)) -> 居合斩精通 | D35: TID_Survivor_Achievement_Des_300151 | E35: =INDEX([1]文本!$B:$B,MATCH(D35,[1]文本!$A:$A,0)) -> 获得一次强化战法：<color=#ffc766>裂空</color> | F35: 3 | H35: 3 | I35: icon_achievement | J35: icon_ordinary_107 | K35: obtainSkillInSurvivalGame{skillId:100151, count:1} | M35: 10
A36: 300251 | B36: TID_Survivor_Achievement_Name_300251 | C36: =INDEX([1]文本!$B:$B,MATCH(B36,[1]文本!$A:$A,0)) -> 飞刀术精通 | D36: TID_Survivor_Achievement_Des_300251 | E36: =INDEX([1]文本!$B:$B,MATCH(D36,[1]文本!$A:$A,0)) -> 获得一次强化战法：<color=#ffc766>银瀑</color> | F36: 3 | H36: 3 | I36: icon_achievement | J36: icon_ordinary_121 | K36: obtainSkillInSurvivalGame{skillId:100251, count:1} | M36: 10
A37: 300351 | B37: TID_Survivor_Achievement_Name_300351 | C37: =INDEX([1]文本!$B:$B,MATCH(B37,[1]文本!$A:$A,0)) -> 收割者精通 | D37: TID_Survivor_Achievement_Des_300351 | E37: =INDEX([1]文本!$B:$B,MATCH(D37,[1]文本!$A:$A,0)) -> 获得一次强化战法：<color=#ffc766>死亡轮舞</color> | F37: 3 | H37: 3 | I37: icon_achievement | J37: icon_ordinary_088 | K37: obtainSkillInSurvivalGame{skillId:100351, count:1} | M37: 10
A38: 300451 | B38: TID_Survivor_Achievement_Name_300451 | C38: =INDEX([1]文本!$B:$B,MATCH(B38,[1]文本!$A:$A,0)) -> 冰霜投石精通 | D38: TID_Survivor_Achievement_Des_300451 | E38: =INDEX([1]文本!$B:$B,MATCH(D38,[1]文本!$A:$A,0)) -> 获得一次强化战法：<color=#ffc766>雪葬</color> | F38: 3 | H38: 3 | I38: icon_achievement | J38: icon_ordinary_033 | K38: obtainSkillInSurvivalGame{skillId:100451, count:1} | M38: 10
A39: 300551 | B39: TID_Survivor_Achievement_Name_300551 | C39: =INDEX([1]文本!$B:$B,MATCH(B39,[1]文本!$A:$A,0)) -> 火壶抛掷精通 | D39: TID_Survivor_Achievement_Des_300551 | E39: =INDEX([1]文本!$B:$B,MATCH(D39,[1]文本!$A:$A,0)) -> 获得一次强化战法：<color=#ffc766>凤陨</color> | F39: 3 | H39: 3 | I39: icon_achievement | J39: icon_ordinary_014 | K39: obtainSkillInSurvivalGame{skillId:100551, count:1} | M39: 10
A40: 300651 | B40: TID_Survivor_Achievement_Name_300651 | C40: =INDEX([1]文本!$B:$B,MATCH(B40,[1]文本!$A:$A,0)) -> 舷炮齐射精通 | D40: TID_Survivor_Achievement_Des_300651 | E40: =INDEX([1]文本!$B:$B,MATCH(D40,[1]文本!$A:$A,0)) -> 获得一次强化战法：<color=#ffc766>毁灭绽放</color> | F40: 3 | H40: 3 | I40: icon_achievement | J40: icon_ordinary_005 | K40: obtainSkillInSurvivalGame{skillId:100651, count:1} | M40: 10
...

Sheet 成就点配置
A1: convert(ResSurvival.proto,table_SurvivalAccomplishmentPointConf,SurvivalAccomplishmentPointConf.pbin)
A2: 成就等级 | B2: 成就点上限 | C2: 奖励id
A3: level | B3: pointUpper | C3: rewardId
A4: 1 | B4: 60 | C4: 6609601
A5: 2 | B5: 150 | C5: 6609602
A6: 3 | B6: 270 | C6: 6609603
A7: 4 | B7: 400 | C7: 6609604
A8: 5 | B8: 540 | C8: 6609605
A9: 6 | B9: 700 | C9: 6609606
A10: 7 | B10: 870 | C10: 6609607
A11: 8 | B11: 1100 | C11: 6609608
A12: 9 | B12: 1340 | C12: 6609609
A13: 10 | B13: 1600 | C13: 6609610
A14: 11 | B14: 1900 | C14: 6609611
A15: 12 | B15: 2250 | C15: 6609612
... A18: 15 | B18: 3600 | C18: 6609615

Sheet 成就页签配置
A1: convert(ResSurvival.proto,table_SurvivalAccomplishmentCategoryConf,SurvivalAccomplishmentCategoryConf.pbin)
A2: 页签ID | B2: TID | C2: 名称文本 | D2: 备注 | E2: 解锁条件配置 | F2: 解锁条件配置1 | G2: 解锁条件配置2
A3: id | B3: name | E3: unlockCond.conditionRelation | F3: unlockCond.conditions[1].condOneOf | G3: unlockCond.conditions[2].condOneOf
A4: 1 | B4: TID_Survivor_Achievement_Sheet_2 | C4: 战斗挑战 | D4: 战斗相关成就 | E4: 条件与 | F4: alwaysTrue{}
A5: 2 | B5: TID_Survivor_Achievement_Sheet_4 | C5: 英雄历练 | D5: 英雄相关成就 | E5: 条件与 | F5: alwaysTrue{}
A6: 3 | B6: TID_Survivor_Achievement_Sheet_3 | C6: 战法大师 | D6: 技能相关成就 | E6: 条件与 | F6: alwaysTrue{}
A7: 4 | B7: TID_Survivor_Achievement_Sheet_6 | C7: 天赋成长 | D7: 天赋金币相关 | E7: 条件与 | F7: alwaysFalse{}
A8: 5 | B8: TID_Survivor_Achievement_Sheet_5 | C8: 战地探索 | D8: 寻宝系统成就 | E8: 条件与 | F8: gameLevel{level: 3004}
A9: 6 | B9: TID_Survivor_Achievement_Sheet_7 | C9: 帝国赐福 | D9: 塔罗牌相关 | E9: 条件与 | F9: gameLevel{level: 5001} | G9: featureUnlock{featureId: 3016}
A10: 99 | B10: TID_Survivor_Achievement_Sheet_0 | C10: 隐藏成就 | D10: 不开放的成就 | E10: 条件与 | F10: alwaysFalse{}
